Workbook

Sheet 薪酬预算校准表
B3: 薪酬预算校准表
B5: 当年实际截止月份 | C5: =人力资源规划一览表!C4 -> 44469
B6: 预算科目 | D6: ="B"&YEAR($C$5)+1 -> B2022 | E6: 校准状态 | F6: ="A"&YEAR($C$5)-1 -> A2020 | G6: ="E"&YEAR($C$5) -> E2021 | H6: ="E"&YEAR($C$5)&"/A"&YEAR($C$5) -> E2021/A2021 | K6: ="B"&YEAR($C$5)+1 -> B2022 | L6: ="B"&YEAR($C$5)+1&"/E"&YEAR($C$5) -> B2022/E2021 | O6: 说明
D7: (大帐) | F7: (细账) | G7: (细账) | H7: 变动额 | I7: % | J7: 分析 | K7: (细账) | L7: 变动额 | M7: % | N7: 分析
B8: 营业收入 | C8: ① | D8: 9300 | E8: =IF(AND(K8>=D8,K8/D8<=1.2),"已校准",IF(K8<D8,"未校准","可接受")) -> 未校准 | F8: 8700 | G8: 8900 | H8: =G8-F8 -> 200 | I8: =IFERROR(G8/F8-1,"NA") -> 0.023 | K8: 9000 | L8: =K8-G8 -> 100 | M8: =IFERROR(K8/J8-1,"NA") -> NA | O8: 依据公司、责任中心OTR填写
B9: 毛利率 | C9: ② | D9: 0.33 | F9: 0.34 | G9: 0.36 | H9: =G9-F9 -> 0.02 | I9: =IFERROR(G9/F9-1,"NA") -> 0.059 | K9: 0.35 | L9: =K9-G9 -> -0.01 | M9: =IFERROR(K9/J9-1,"NA") -> NA | O9: 依据公司、责任中心OTR选择填写
B10: 毛利额 | C10: ③ | D10: =D8*D9 -> 3069 | E10: =IF(AND(K10>=D10,K10/D10<=1.2),"已校准",IF(K10<D10,"未校准","可接受")) -> 已校准 | F10: =F8*F9 -> 2958 | G10: =G8*G9 -> 3204 | H10: =G10-F10 -> 246 | I10: =IFERROR(G10/F10-1,"NA") -> 0.083 | K10: =K8*K9 -> 3150 | L10: =K10-G10 -> -54 | M10: =IFERROR(K10/J10-1,"NA") -> NA | O10: ③=①*②
B12: 薪酬总包分配率 | C12: ④ | D12: 0.37 | F12: =F13/F10 -> 0.36 | G12: =G13/G10 -> 0.33 | H12: =G12-F12 -> -0.03 | I12: =IFERROR(G12/F12-1,"NA") -> -0.083 | K12: =K13/K10 -> 0.34 | L12: =K12-G12 -> 0.01 | M12: =IFERROR(K12/J12-1,"NA") -> NA | O12: 1.薪酬总包占毛利的比率。 2.毛利扣除所有管理成本后，为股东和劳动者共有剩余利润，薪酬总包分配率实质是劳动者与股东的分配比率。 3.应参照行业范围确认。
B13: 薪酬总包金额 | C13: ⑤ | D13: =D10*D12 -> 1136 | E13: =IF(AND(K13<=D13,D13/K13<=1.2),"已校准",IF(K13>D13,"未校准","可接受")) -> 已校准 | F13: =SUMIFS(薪酬明细!$O:$O,薪酬明细!$H:$H,">="&DATE(YEAR($C$5)-1,1,1),薪酬明细!$H:$H,"<="&EOMONTH(DATE(YEAR($C$5)-1,12,31),0),薪酬明细!$A:$A,"A")/10000 -> 1062 | G13: =SUMIFS(薪酬明细!$O:$O,薪酬明细!$H:$H,">="&DATE(YEAR($C$5),1,1),薪酬明细!$H:$H,"<="&EOMONTH(DATE(YEAR($C$5),MONTH($C$5),1),0),薪酬明细!A:A,"A")/10000+SUMIFS(薪酬明细!$O:$O,薪酬明细!$H:$H,">="&DATE(YEAR($C$5),MONTH($C$5)+1,1),薪酬明细!$H:$H,"<="&EOMONTH(DATE(YEAR($C$5),12,31),0),薪酬明细!A:A,"E")/10000 -> 1062 | H13: =G13-F13 -> 0 | I13: =IFERROR(G13/F13-1,"NA") -> 0 | K13: =SUMIFS(薪酬明细!$O:$O,薪酬明细!$H:$H,">="&DATE(YEAR($C$5)+1,1,1),薪酬明细!$H:$H,"<="&EOMONTH(DATE(YEAR($C$5)+1,12,31),0),薪酬明细!$A:$A,"B")/10000 -> 1062 | L13: =K13-G13 -> 0 | M13: =IFERROR(K13/J13-1,"NA") -> NA | O13: ⑤=③*④
B15: 固定薪酬总额 | C15: ⑥ | D15: 720 | E15: =IF(AND(K15<=D15,D15/K15<=1.2),"已校准",IF(K15>D15,"未校准","可接受")) -> 已校准 | F15: =SUMIFS(薪酬明细!$L:$L,薪酬明细!$H:$H,">="&DATE(YEAR($C$5)-1,1,1),薪酬明细!$H:$H,"<="&EOMONTH(DATE(YEAR($C$5)-1,12,31),0),薪酬明细!$A:$A,"A")/10000 -> 710 | G15: =SUMIFS(薪酬明细!$L:$L,薪酬明细!$H:$H,">="&DATE(YEAR($C$5),1,1),薪酬明细!$H:$H,"<="&EOMONTH(DATE(YEAR($C$5),MONTH($C$5),1),0),薪酬明细!A:A,"A")/10000+SUMIFS(薪酬明细!$L:$L,薪酬明细!$H:$H,">="&DATE(YEAR($C$5),MONTH($C$5)+1,1),薪酬明细!$H:$H,"<="&EOMONTH(DATE(YEAR($C$5),12,31),0),薪酬明细!A:A,"E")/10000 -> 710 | H15: =G15-F15 -> 0 | I15: =IFERROR(G15/F15-1,"NA") -> 0 | K15: =SUMIFS(薪酬明细!$L:$L,薪酬明细!$H:$H,">="&DATE(YEAR($C$5)+1,1,1),薪酬明细!$H:$H,"<="&EOMONTH(DATE(YEAR($C$5)+1,12,31),0),薪酬明细!$A:$A,"B")/10000 -> 710 | L15: =K15-G15 -> 0 | M15: =IFERROR(K15/J15-1,"NA") -> NA | O15: 根据各岗位人数和固定薪资标准计算
B16: 固定薪酬/营业收入 | C16: ⑦ | D16: =IFERROR(D15/D$8,"NA") -> 0.077 | F16: =IFERROR(F15/F$8,"NA") -> 0.082 | G16: =IFERROR(G15/G$8,"NA") -> 0.08 | H16: =G16-F16 -> -0.002 | I16: =IFERROR(G16/F16-1,"NA") -> -0.024 | K16: =IFERROR(K15/K$8,"NA") -> 0.079 | L16: =K16-G16 -> -0.001 | M16: =IFERROR(K16/J16-1,"NA") -> NA | O16: 占收入总额的比值
B17: 变动薪酬金额 | C17: ⑧ | D17: =D13-D15-D19 -> 341 | F17: =SUMIFS(薪酬明细!$M:$M,薪酬明细!$H:$H,">="&DATE(YEAR($C$5)-1,1,1),薪酬明细!$H:$H,"<="&EOMONTH(DATE(YEAR($C$5)-1,12,31),0),薪酬明细!$A:$A,"A")/10000 -> 276 | G17: =SUMIFS(薪酬明细!$M:$M,薪酬明细!$H:$H,">="&DATE(YEAR($C$5),1,1),薪酬明细!$H:$H,"<="&EOMONTH(DATE(YEAR($C$5),MONTH($C$5),1),0),薪酬明细!A:A,"A")/10000+SUMIFS(薪酬明细!$M:$M,薪酬明细!$H:$H,">="&DATE(YEAR($C$5),MONTH($C$5)+1,1),薪酬明细!$H:$H,"<="&EOMONTH(DATE(YEAR($C$5),12,31),0),薪酬明细!A:A,"E")/10000 -> 276 | H17: =G17-F17 -> 0 | I17: =IFERROR(G17/F17-1,"NA") -> 0 | K17: =SUMIFS(薪酬明细!$M:$M,薪酬明细!$H:$H,">="&DATE(YEAR($C$5)+1,1,1),薪酬明细!$H:$H,"<="&EOMONTH(DATE(YEAR($C$5)+1,12,31),0),薪酬明细!$A:$A,"B")/10000 -> 275 | L17: =K17-G17 -> -1 | M17: =IFERROR(K17/J17-1,"NA") -> NA | O17: ⑧=⑤-⑥-⑩
B18: 变动薪酬/营业收入 | C18: ⑨ | D18: =D17/D$8 -> 0.037 | E18: =IF(AND(K18<=D18,D18/K18<=1.2),"已校准",IF(K18>D18,"未校准","可接受")) -> 已校准 | F18: =F17/F$8 -> 0.032 | G18: =G17/G$8 -> 0.031 | H18: =G18-F18 -> -0.001 | I18: =IFERROR(G18/F18-1,"NA") -> -0.031 | K18: =K17/K$8 -> 0.031 | L18: =K18-G18 -> 0 | M18: =IFERROR(K18/J18-1,"NA") -> NA | O18: 占收入总额的比值
B19: 其他薪酬金额 | C19: ⑩ | D19: 75 | E19: =IF(AND(K19<=D19,D19/K19<=1.2),"已校准",IF(K19>D19,"未校准","可接受")) -> 未校准 | F19: =SUMIFS(薪酬明细!$N:$N,薪酬明细!$H:$H,">="&DATE(YEAR($C$5)-1,1,1),薪酬明细!$H:$H,"<="&EOMONTH(DATE(YEAR($C$5)-1,12,31),0),薪酬明细!$A:$A,"A")/10000 -> 76 | G19: =SUMIFS(薪酬明细!$N:$N,薪酬明细!$H:$H,">="&DATE(YEAR($C$5),1,1),薪酬明细!$H:$H,"<="&EOMONTH(DATE(YEAR($C$5),MONTH($C$5),1),0),薪酬明细!A:A,"A")/10000+SUMIFS(薪酬明细!$N:$N,薪酬明细!$H:$H,">="&DATE(YEAR($C$5),MONTH($C$5)+1,1),薪酬明细!$H:$H,"<="&EOMONTH(DATE(YEAR($C$5),12,31),0),薪酬明细!A:A,"E")/10000 -> 76 | H19: =G19-F19 -> 0 | I19: =IFERROR(G19/F19-1,"NA") -> 0 | K19: =SUMIFS(薪酬明细!$N:$N,薪酬明细!$H:$H,">="&DATE(YEAR($C$5)+1,1,1),薪酬明细!$H:$H,"<="&EOMONTH(DATE(YEAR($C$5)+1,12,31),0),薪酬明细!$A:$A,"B")/10000 -> 76 | L19: =K19-G19 -> 0 | M19: =IFERROR(K19/J19-1,"NA") -> NA | O19: 根据各岗位人数和其他薪资标准（如补贴等）计算
B20: 其他薪酬/营业收入 | C20: ⑪ | D20: =D19/D$8 -> 0.008 | F20: =F19/F$8 -> 0.009 | G20: =G19/G$8 -> 0.009 | H20: =G20-F20 -> 0 | I20: =IFERROR(G20/F20-1,"NA") -> 0 | K20: =K19/K$8 -> 0.008 | L20: =K20-G20 -> -0.001 | M20: =IFERROR(K20/J20-1,"NA") -> NA | O20: 占收入总额的比值
B22: 五险一金金额 | D22: =D13*D23 -> 341 | E22: =IF(AND(K22<=D22,D22/K22<=1.2),"已校准",IF(K22>D22,"未校准","可接受")) -> 可接受 | F22: =SUMIFS(社保明细!$J:$J,社保明细!$H:$H,">="&DATE(YEAR($C$5)-1,1,1),社保明细!$H:$H,"<="&EOMONTH(DATE(YEAR($C$5)-1,12,31),0),社保明细!$A:$A,"A")/10000 -> 208 | G22: =SUMIFS(社保明细!J:J,社保明细!$H:$H,">="&DATE(YEAR($C$5),1,1),社保明细!$H:$H,"<="&EOMONTH(DATE(YEAR($C$5),MONTH($C$5),1),0),社保明细!$A:$A,"A")/10000+SUMIFS(社保明细!J:J,社保明细!$H:$H,">="&DATE(YEAR($C$5),MONTH($C$5)+1,1),社保明细!$H:$H,"<="&EOMONTH(DATE(YEAR($C$5),12,31),0),社保明细!$A:$A,"E")/10000 -> 208 | H22: =G22-F22 -> 0 | I22: =IFERROR(G22/F22-1,"NA") -> 0 | K22: =SUMIFS(社保明细!$J:$J,社保明细!$H:$H,">="&DATE(YEAR($C$5)+1,1,1),社保明细!$H:$H,"<="&EOMONTH(DATE(YEAR($C$5)+1,12,31),0),社保明细!$A:$A,"B")/10000 -> 208 | L22: =K22-G22 -> 0 | M22: =IFERROR(K22/J22-1,"NA") -> NA | O22: 公司所承担的员工五险一金或其他法定保险占薪酬总额的比例
B23: 五险一金/薪酬总包 | D23: 0.3 | F23: =F22/F13 -> 0.196 | G23: =G22/G13 -> 0.196 | H23: =G23-F23 -> 0 | I23: =IFERROR(G23/F23-1,"NA") -> 0 | K23: =K22/K13 -> 0.196 | L23: =K23-G23 -> 0 | M23: =IFERROR(K23/J23-1,"NA") -> NA | O23: 公司所承担的员工五险一金或其他法定保险占薪酬总额的比例
B24: 福利费总额 | D24: =D13*D25 -> 159 | E24: =IF(AND(K24<=D24,D24/K24<=1.2),"已校准",IF(K24>D24,"未校准","可接受")) -> 可接受 | F24: =SUMIFS(福利费明细!$F:$F,福利费明细!$E:$E,">="&DATE(YEAR($C$5)-1,1,1),福利费明细!$E:$E,"<="&EOMONTH(DATE(YEAR($C$5)-1,12,31),0),福利费明细!$A:$A,"A")/10000 -> 50 | G24: =SUMIFS(福利费明细!$F:$F,福利费明细!$E:$E,">="&DATE(YEAR($C$5),1,1),福利费明细!$E:$E,"<="&EOMONTH(DATE(YEAR($C$5),MONTH($C$5),1),0),福利费明细!$A:$A,"A")/10000+SUMIFS(福利费明细!$F:$F,福利费明细!$E:$E,">="&DATE(YEAR($C$5),MONTH($C$5)+1,1),福利费明细!$E:$E,"<="&EOMONTH(DATE(YEAR($C$5),12,31),0),福利费明细!$A:$A,"E")/10000 -> 50 | H24: =G24-F24 -> 0 | I24: =IFERROR(G24/F24-1,"NA") -> 0 | K24: =SUMIFS(福利费明细!$F:$F,福利费明细!$E:$E,">="&DATE(YEAR($C$5)+1,1,1),福利费明细!$E:$E,"<="&EOMONTH(DATE(YEAR($C$5)+1,12,31),0),福利费明细!$A:$A,"B")/10000 -> 50 | L24: =K24-G24 -> 0 | M24: =IFERROR(K24/J24-1,"NA") -> NA | O24: 集体福利费用，如集体食堂
B25: 福利费/薪酬总包 | D25: 0.14 | F25: =F24/F13 -> 0.05 | G25: =G24/G13 -> 0.05 | H25: =G25-F25 -> 0 | I25: =IFERROR(G25/F25-1,"NA") -> 0 | K25: =K24/K13 -> 0.05 | L25: =K25-G25 -> 0 | M25: =IFERROR(K25/J25-1,"NA") -> NA | O25: 福利费占薪酬总包的比例
B26: 招聘费用总额 | D26: 11 | E26: =IF(AND(K26<=D26,D26/K26<=1.2),"已校准",IF(K26>D26,"未校准","可接受")) -> 未校准 | F26: =SUMIFS(招聘费明细!$G:$G,招聘费明细!$F:$F,">="&DATE(YEAR($C$5)-1,1,1),招聘费明细!$F:$F,"<="&EOMONTH(DATE(YEAR($C$5)-1,12,31),0),招聘费明细!$A:$A,"A")/10000 -> 11 | G26: =SUMIFS(招聘费明细!$G:$G,招聘费明细!$F:$F,">="&DATE(YEAR($C$5),1,1),招聘费明细!$F:$F,"<="&EOMONTH(DATE(YEAR($C$5),MONTH($C$5),1),0),招聘费明细!$A:$A,"A")/10000+SUMIFS(招聘费明细!$G:$G,招聘费明细!$F:$F,">="&DATE(YEAR($C$5),MONTH($C$5)+1,1),招聘费明细!$F:$F,"<="&EOMONTH(DATE(YEAR($C$5),12,31),0),招聘费明细!$A:$A,"E")/10000 -> 7 | H26: =G26-F26 -> -4 | I26: =IFERROR(G26/F26-1,"NA") -> 0 | K26: =SUMIFS(招聘费明细!$G:$G,招聘费明细!$F:$F,">="&DATE(YEAR($C$5)+1,1,1),招聘费明细!$F:$F,"<="&EOMONTH(DATE(YEAR($C$5)+1,12,31),0),招聘费明细!$A:$A,"B")/10000 -> 12 | L26: =K26-G26 -> 5 | M26: =IFERROR(K26/J26-1,"NA") -> NA | O26: 招聘的各种开支
B27: 招聘费/薪酬总包 | D27: =D26/D$13 -> 0.01 | F27: =F26/F$13 -> 0.01 | G27: =G26/G$13 -> 0.007 | H27: =G27-F27 -> 0 | I27: =IFERROR(G27/F27-1,"NA") -> -0.3 | K27: =K26/K$13 -> 0.011 | L27: =K27-G27 -> 0.004 | M27: =IFERROR(K27/J27-1,"NA") -> NA | O27: 招聘开支占薪酬总包的比例
B28: 培训费用总额 | D28: =D13*D29 -> 17 | E28: =IF(AND(K28<=D28,D28/K28<=1.2),"已校准",IF(K28>D28,"未校准","可接受")) -> 未校准 | F28: =SUMIFS(培训费明细!$G:$G,培训费明细!$F:$F,">="&DATE(YEAR($C$5)-1,1,1),培训费明细!$F:$F,"<="&EOMONTH(DATE(YEAR($C$5)-1,12,31),0),培训费明细!$A:$A,"A")/10000 -> 3 | G28: =SUMIFS(培训费明细!$G:$G,培训费明细!$F:$F,">="&DATE(YEAR($C$5),1,1),培训费明细!$F:$F,"<="&EOMONTH(DATE(YEAR($C$5),MONTH($C$5),1),0),培训费明细!$A:$A,"A")/10000+SUMIFS(培训费明细!$G:$G,培训费明细!$F:$F,">="&DATE(YEAR($C$5),MONTH($C$5)+1,1),培训费明细!$F:$F,"<="&EOMONTH(DATE(YEAR($C$5),12,31),0),培训费明细!$A:$A,"E")/10000 -> 22 | H28: =G28-F28 -> 19 | I28: =IFERROR(G28/F28-1,"NA") -> 6 | K28: =SUMIFS(培训费明细!$G:$G,培训费明细!$F:$F,">="&DATE(YEAR($C$5)+1,1,1),培训费明细!$F:$F,"<="&EOMONTH(DATE(YEAR($C$5)+1,12,31),0),培训费明细!$A:$A,"B")/10000 -> 30 | L28: =K28-G28 -> 8 | M28: =IFERROR(K28/J28-1,"NA") -> NA | O28: 用于团队学习成长的各种开支
B29: 培训费/薪酬总包 | D29: 0.015 | F29: =F28/F13 -> 0.003 | G29: =G28/G13 -> 0.021 | H29: =G29-F29 -> 0.018 | I29: =IFERROR(G29/F29-1,"NA") -> 6 | K29: =K28/K13 -> 0.028 | L29: =K29-G29 -> 0.007 | M29: =IFERROR(K29/J29-1,"NA") -> NA | O29: 学习培训成本占薪酬总包的比例
B31: 平均员工人数 | D31: =SUMIFS(薪酬明细!$K:$K,薪酬明细!$H:$H,">="&DATE(YEAR($C$5)-1,1,1),薪酬明细!$H:$H,"<="&EOMONTH(DATE(YEAR($C$5)-1,12,31),0),薪酬明细!$A:$A,"A")/12 -> 73 | F31: =SUMIFS(薪酬明细!$K:$K,薪酬明细!$H:$H,">="&DATE(YEAR($C$5)-1,1,1),薪酬明细!$H:$H,"<="&EOMONTH(DATE(YEAR($C$5)-1,12,31),0),薪酬明细!$A:$A,"A")/12 -> 73 | G31: =SUMIFS(薪酬明细!$K:$K,薪酬明细!$H:$H,">="&DATE(YEAR($C$5)-1,1,1),薪酬明细!$H:$H,"<="&EOMONTH(DATE(YEAR($C$5)-1,12,31),0),薪酬明细!$A:$A,"A")/12 -> 73 | H31: =G31-F31 -> 0 | I31: =IFERROR(G31/F31-1,"NA") -> 0 | K31: =SUMIFS(薪酬明细!$K:$K,薪酬明细!$H:$H,">="&DATE(YEAR($C$5)-1,1,1),薪酬明细!$H:$H,"<="&EOMONTH(DATE(YEAR($C$5)-1,12,31),0),薪酬明细!$A:$A,"A")/12 -> 73 | L31: =K31-G31 -> 0 | M31: =IFERROR(K31/J31-1,"NA") -> NA | O31: 年人数总和/12
B32: 年均人效 | D32: =D8/D31 -> 127 | E32: =IF(AND(K32>=D32,K32/D32<=1.2),"已校准",IF(K32<D32,"未校准","可接受")) -> 未校准 | F32: =F8/F31 -> 119 | G32: =G8/G31 -> 122 | H32: =G32-F32 -> 3 | I32: =IFERROR(G32/F32-1,"NA") -> 0 | K32: =K8/K31 -> 123 | L32: =K32-G32 -> 1 | M32: =IFERROR(K32/J32-1,"NA") -> NA | O32: 年销售额/年人数总和
B33: 年均薪酬 | D33: =D13/D31 -> 16 | F33: =F13/F31 -> 15 | G33: =G13/G31 -> 15 | H33: =G33-F33 -> 0 | I33: =IFERROR(G33/F33-1,"NA") -> 0 | K33: =K13/K31 -> 15 | L33: =K33-G33 -> 0 | M33: =IFERROR(K33/J33-1,"NA") -> NA | O33: 年薪酬总额/年人数总和
B34: 人效工资比 | D34: =D32/D33 -> 7.9 | E34: =IF(AND(K34>=D34,K34/D34<=1.2),"已校准",IF(K34<D34,"未校准","可接受")) -> 已校准 | F34: =F32/F33 -> 7.9 | G34: =G32/G33 -> 8.1 | H34: =G34-F34 -> 0 | I34: =IFERROR(G34/F34-1,"NA") -> 0 | K34: =K32/K33 -> 8.2 | L34: =K34-G34 -> 0 | M34: =IFERROR(K34/J34-1,"NA") -> NA | O34: 年均人效/年均薪酬
B36: A:实际数 E:估计数 B:预算数 YTD：从年初到当年实际截止日 YTG：当年实际截止日次日到年底
C37: 需要手工填入数据
C38: 需要手工填入分析说明
B40: 可接受 | C40: 上级预算与下级预算未校准，但差异不影响战略落地。可接受
B41: 未校准 | C41: 上级预算与下级预算的差异幅度超过可接受幅度，需要调整预算
B42: 已校准 | C42: 上级预算与下级预算的差异幅度在可接受幅度范围内。

Sheet 人力资源数据汇总
B2: 人力资源分类汇总表
C3: 当年实际截止月份 | G3: 44469
B5: 金额单位：万元 | G5: ="A"&YEAR($G$3)-1&"FY" -> A2020FY | H5: 其中： | T5: ="E"&YEAR($G$3)&"FY" -> E2021FY | U5: ="A"&YEAR($G$3)&TEXT(MONTH($G$3),"00")&"YTD" -> A202109YTD | V5: 其中： | AH5: ="E"&YEAR($G$3)&TEXT(MONTH($G$3),"00")&"YTG" -> E202109YTG | AI5: 其中： | AU5: ="B"&YEAR($G$3)+1&"FY" -> B2022FY | AV5: 其中：
G6: =LEFT(G5,1) -> A | H6: =LEFT(G5,1) -> A | I6: =H6 -> A | J6: =I6 -> A | K6: =J6 -> A | L6: =K6 -> A | M6: =L6 -> A | N6: =M6 -> A | O6: =N6 -> A | P6: =O6 -> A | ... S6: =R6 -> A | T6: =LEFT(T5,1) -> E | U6: =LEFT(U5,1) -> A | V6: =LEFT(U5,1) -> A | W6: =V6 -> A | X6: =W6 -> A | Y6: =X6 -> A | Z6: =Y6 -> A | AA6: =Z6 -> A | AB6: =AA6 -> A | AC6: =AB6 -> A | AD6: =AC6 -> A | ... AG6: =AF6 -> A | AH6: =LEFT(AH5,1) -> E | AI6: =LEFT(AH5,1) -> E | AJ6: =AI6 -> E | AK6: =AJ6 -> E | AL6: =AK6 -> E | AM6: =AL6 -> E | AN6: =AM6 -> E | AO6: =AN6 -> E | AP6: =AO6 -> E | AQ6: =AP6 -> E | ... AT6: =AS6 -> E | AU6: =LEFT(AU5,1) -> B | AV6: =LEFT(AU5,1) -> B | AW6: =AV6 -> B | AX6: =AW6 -> B | AY6: =AX6 -> B | AZ6: =AY6 -> B | BA6: =AZ6 -> B | BB6: =BA6 -> B | BC6: =BB6 -> B | BD6: =BC6 -> B | ... BG6: =BF6 -> B
G7: 合计 | H7: =YEAR($G$3)-1 -> 2020 | I7: =H7 -> 2020 | J7: =I7 -> 2020 | K7: =J7 -> 2020 | L7: =K7 -> 2020 | M7: =L7 -> 2020 | N7: =M7 -> 2020 | O7: =N7 -> 2020 | P7: =O7 -> 2020 | ... S7: =R7 -> 2020 | T7: 合计 | U7: 合计 | V7: =YEAR($G$3) -> 2021 | W7: =V7 -> 2021 | X7: =W7 -> 2021 | Y7: =X7 -> 2021 | Z7: =Y7 -> 2021 | AA7: =Z7 -> 2021 | AB7: =AA7 -> 2021 | AC7: =AB7 -> 2021 | AD7: =AC7 -> 2021 | ... AG7: =AF7 -> 2021 | AH7: 合计 | AI7: =YEAR($G$3) -> 2021 | AJ7: =AI7 -> 2021 | AK7: =AJ7 -> 2021 | AL7: =AK7 -> 2021 | AM7: =AL7 -> 2021 | AN7: =AM7 -> 2021 | AO7: =AN7 -> 2021 | AP7: =AO7 -> 2021 | AQ7: =AP7 -> 2021 | ... AT7: =AS7 -> 2021 | AU7: 合计 | AV7: =YEAR($G$3)+1 -> 2022 | AW7: =AV7 -> 2022 | AX7: =AW7 -> 2022 | AY7: =AX7 -> 2022 | AZ7: =AY7 -> 2022 | BA7: =AZ7 -> 2022 | BB7: =BA7 -> 2022 | BC7: =BB7 -> 2022 | BD7: =BC7 -> 2022 | ... BG7: =BF7 -> 2022
H8: 1 | I8: 2 | J8: 3 | K8: 4 | L8: 5 | M8: 6 | N8: 7 | O8: 8 | P8: 9 | Q8: 10 | R8: 11 | S8: 12 | V8: 1 | W8: 2 | X8: 3 | Y8: 4 | Z8: 5 | AA8: 6 | AB8: 7 | AC8: 8 | AD8: 9 | AE8: 10 | AF8: 11 | AG8: 12 | AI8: 1 | AJ8: 2 | AK8: 3 | AL8: 4 | AM8: 5 | AN8: 6 | AO8: 7 | AP8: 8 | AQ8: 9 | AR8: 10 | AS8: 11 | AT8: 12 | AV8: 1 | AW8: 2 | AX8: 3 | AY8: 4 | AZ8: 5 | BA8: 6 | BB8: 7 | BC8: 8 | BD8: 9 | BE8: 10 | BF8: 11 | BG8: 12
G9: =DATE(YEAR($G$3)-1,1,1) -> 43831 | H9: =DATE(H7,H8,1) -> 43831 | I9: =DATE(I7,I8,1) -> 43862 | J9: =DATE(J7,J8,1) -> 43891 | K9: =DATE(K7,K8,1) -> 43922 | L9: =DATE(L7,L8,1) -> 43952 | M9: =DATE(M7,M8,1) -> 43983 | N9: =DATE(N7,N8,1) -> 44013 | O9: =DATE(O7,O8,1) -> 44044 | ... S9: =DATE(S7,S8,1) -> 44166 | T9: =DATE(YEAR($G$3),1,1) -> 44197 | U9: =DATE(YEAR($G$3),1,1) -> 44197 | V9: =DATE(V7,V8,1) -> 44197 | W9: =DATE(W7,W8,1) -> 44228 | X9: =DATE(X7,X8,1) -> 44256 | Y9: =DATE(Y7,Y8,1) -> 44287 | Z9: =DATE(Z7,Z8,1) -> 44317 | AA9: =DATE(AA7,AA8,1) -> 44348 | AB9: =DATE(AB7,AB8,1) -> 44378 | AC9: =DATE(AC7,AC8,1) -> 44409 | ... AG9: =DATE(AG7,AG8,1) -> 44531 | AH9: =DATE(YEAR($G$3),MONTH($G$3)+1,1) -> 44470 | AI9: =DATE(AI7,AI8,1) -> 44197 | AJ9: =DATE(AJ7,AJ8,1) -> 44228 | AK9: =DATE(AK7,AK8,1) -> 44256 | AL9: =DATE(AL7,AL8,1) -> 44287 | AM9: =DATE(AM7,AM8,1) -> 44317 | AN9: =DATE(AN7,AN8,1) -> 44348 | AO9: =DATE(AO7,AO8,1) -> 44378 | AP9: =DATE(AP7,AP8,1) -> 44409 | ... AT9: =DATE(AT7,AT8,1) -> 44531 | AU9: =DATE(YEAR($G$3)+1,1,1) -> 44562 | AV9: =DATE(AV7,AV8,1) -> 44562 | AW9: =DATE(AW7,AW8,1) -> 44593 | AX9: =DATE(AX7,AX8,1) -> 44621 | AY9: =DATE(AY7,AY8,1) -> 44652 | AZ9: =DATE(AZ7,AZ8,1) -> 44682 | BA9: =DATE(BA7,BA8,1) -> 44713 | BB9: =DATE(BB7,BB8,1) -> 44743 | BC9: =DATE(BC7,BC8,1) -> 44774 | ... BG9: =DATE(BG7,BG8,1) -> 44896
G10: =EOMONTH(DATE(YEAR($G$3)-1,12,1),0) -> 44196 | H10: =EOMONTH(H9,0) -> 43861 | I10: =EOMONTH(I9,0) -> 43890 | J10: =EOMONTH(J9,0) -> 43921 | K10: =EOMONTH(K9,0) -> 43951 | L10: =EOMONTH(L9,0) -> 43982 | M10: =EOMONTH(M9,0) -> 44012 | N10: =EOMONTH(N9,0) -> 44043 | O10: =EOMONTH(O9,0) -> 44074 | ... S10: =EOMONTH(S9,0) -> 44196 | T10: =EOMONTH(DATE(YEAR($G$3),12,1),0) -> 44561 | U10: =EOMONTH(DATE(YEAR($G$3),MONTH(G3),1),0) -> 44469 | V10: =EOMONTH(V9,0) -> 44227 | W10: =EOMONTH(W9,0) -> 44255 | X10: =EOMONTH(X9,0) -> 44286 | Y10: =EOMONTH(Y9,0) -> 44316 | Z10: =EOMONTH(Z9,0) -> 44347 | AA10: =EOMONTH(AA9,0) -> 44377 | AB10: =EOMONTH(AB9,0) -> 44408 | AC10: =EOMONTH(AC9,0) -> 44439 | ... AG10: =EOMONTH(AG9,0) -> 44561 | AH10: =EOMONTH(DATE(YEAR($G$3),12,1),0) -> 44561 | AI10: =EOMONTH(AI9,0) -> 44227 | AJ10: =EOMONTH(AJ9,0) -> 44255 | AK10: =EOMONTH(AK9,0) -> 44286 | AL10: =EOMONTH(AL9,0) -> 44316 | AM10: =EOMONTH(AM9,0) -> 44347 | AN10: =EOMONTH(AN9,0) -> 44377 | AO10: =EOMONTH(AO9,0) -> 44408 | AP10: =EOMONTH(AP9,0) -> 44439 | ... AT10: =EOMONTH(AT9,0) -> 44561 | AU10: =EOMONTH(DATE(YEAR($G$3)+1,12,1),0) -> 44926 | AV10: =EOMONTH(AV9,0) -> 44592 | AW10: =EOMONTH(AW9,0) -> 44620 | AX10: =EOMONTH(AX9,0) -> 44651 | AY10: =EOMONTH(AY9,0) -> 44681 | AZ10: =EOMONTH(AZ9,0) -> 44712 | BA10: =EOMONTH(BA9,0) -> 44742 | BB10: =EOMONTH(BB9,0) -> 44773 | BC10: =EOMONTH(BC9,0) -> 44804 | ... BG10: =EOMONTH(BG9,0) -> 44926
B11: 注册人数
B12: 合计 | E12: * | F12: * | G12: =COUNTIFS(人员状况!$C:$C,$E12,人员状况!$D:$D,$F12,人员状况!$G:$G,"<="&G$10,人员状况!$H:$H,">="&G$10+1) -> 70 | H12: =COUNTIFS(人员状况!$C:$C,$E12,人员状况!$D:$D,$F12,人员状况!$G:$G,"<="&H$10,人员状况!$H:$H,">="&H$10+1) -> 71 | I12: =COUNTIFS(人员状况!$C:$C,$E12,人员状况!$D:$D,$F12,人员状况!$G:$G,"<="&I$10,人员状况!$H:$H,">="&I$10+1) -> 71 | J12: =COUNTIFS(人员状况!$C:$C,$E12,人员状况!$D:$D,$F12,人员状况!$G:$G,"<="&J$10,人员状况!$H:$H,">="&J$10+1) -> 71 | K12: =COUNTIFS(人员状况!$C:$C,$E12,人员状况!$D:$D,$F12,人员状况!$G:$G,"<="&K$10,人员状况!$H:$H,">="&K$10+1) -> 71 | L12: =COUNTIFS(人员状况!$C:$C,$E12,人员状况!$D:$D,$F12,人员状况!$G:$G,"<="&L$10,人员状况!$H:$H,">="&L$10+1) -> 71 | M12: =COUNTIFS(人员状况!$C:$C,$E12,人员状况!$D:$D,$F12,人员状况!$G:$G,"<="&M$10,人员状况!$H:$H,">="&M$10+1) -> 71 | N12: =COUNTIFS(人员状况!$C:$C,$E12,人员状况!$D:$D,$F12,人员状况!$G:$G,"<="&N$10,人员状况!$H:$H,">="&N$10+1) -> 71 | ... S12: =COUNTIFS(人员状况!$C:$C,$E12,人员状况!$D:$D,$F12,人员状况!$G:$G,"<="&S$10,人员状况!$H:$H,">="&S$10+1) -> 70 | T12: =AT12 -> 68 | U12: =COUNTIFS(人员状况!$C:$C,$E12,人员状况!$D:$D,$F12,人员状况!$G:$G,"<="&U$10,人员状况!$H:$H,">="&U$10+1) -> 69 | V12: =IF(MONTH($G$3)>=V$8,COUNTIFS(人员状况!$C:$C,$E12,人员状况!$D:$D,$F12,人员状况!$G:$G,"<="&V$10,人员状况!$H:$H,">="&V$10+1),0) -> 70 | W12: =IF(MONTH($G$3)>=W$8,COUNTIFS(人员状况!$C:$C,$E12,人员状况!$D:$D,$F12,人员状况!$G:$G,"<="&W$10,人员状况!$H:$H,">="&W$10+1),0) -> 70 | X12: =IF(MONTH($G$3)>=X$8,COUNTIFS(人员状况!$C:$C,$E12,人员状况!$D:$D,$F12,人员状况!$G:$G,"<="&X$10,人员状况!$H:$H,">="&X$10+1),0) -> 70 | Y12: =IF(MONTH($G$3)>=Y$8,COUNTIFS(人员状况!$C:$C,$E12,人员状况!$D:$D,$F12,人员状况!$G:$G,"<="&Y$10,人员状况!$H:$H,">="&Y$10+1),0) -> 68 | Z12: =IF(MONTH($G$3)>=Z$8,COUNTIFS(人员状况!$C:$C,$E12,人员状况!$D:$D,$F12,人员状况!$G:$G,"<="&Z$10,人员状况!$H:$H,">="&Z$10+1),0) -> 69 | AA12: =IF(MONTH($G$3)>=AA$8,COUNTIFS(人员状况!$C:$C,$E12,人员状况!$D:$D,$F12,人员状况!$G:$G,"<="&AA$10,人员状况!$H:$H,">="&AA$10+1),0) -> 69 | AB12: =IF(MONTH($G$3)>=AB$8,COUNTIFS(人员状况!$C:$C,$E12,人员状况!$D:$D,$F12,人员状况!$G:$G,"<="&AB$10,人员状况!$H:$H,">="&AB$10+1),0) -> 70 | AC12: =IF(MONTH($G$3)>=AC$8,COUNTIFS(人员状况!$C:$C,$E12,人员状况!$D:$D,$F12,人员状况!$G:$G,"<="&AC$10,人员状况!$H:$H,">="&AC$10+1),0) -> 69 | ... AG12: =IF(MONTH($G$3)>=AG$8,COUNTIFS(人员状况!$C:$C,$E12,人员状况!$D:$D,$F12,人员状况!$G:$G,"<="&AG$10,人员状况!$H:$H,">="&AG$10+1),0) -> 0 | AH12: =AT12 -> 68 | AI12: =IF(MONTH($G$3)>=AI$8,0,S12+SUMIFS(预计变动!$F:$F,预计变动!$A:$A,$E12,预计变动!$B:$B,$F12,预计变动!$I:$I,">="&AI$9,预计变动!$I:$I,"<="&AI$10)) -> 0 | AJ12: =IF(MONTH($G$3)>=AJ$8,0,IF(V12=0,AI12,V12)+SUMIFS(预计变动!$F:$F,预计变动!$A:$A,$E12,预计变动!$B:$B,$F12,预计变动!$I:$I,">="&AJ$9,预计变动!$I:$I,"<="&AJ$10)) -> 0 | AK12: =IF(MONTH($G$3)>=AK$8,0,IF(W12=0,AJ12,W12)+SUMIFS(预计变动!$F:$F,预计变动!$A:$A,$E12,预计变动!$B:$B,$F12,预计变动!$I:$I,">="&AK$9,预计变动!$I:$I,"<="&AK$10)) -> 0 | AL12: =IF(MONTH($G$3)>=AL$8,0,IF(X12=0,AK12,X12)+SUMIFS(预计变动!$F:$F,预计变动!$A:$A,$E12,预计变动!$B:$B,$F12,预计变动!$I:$I,">="&AL$9,预计变动!$I:$I,"<="&AL$10)) -> 0 | AM12: =IF(MONTH($G$3)>=AM$8,0,IF(Y12=0,AL12,Y12)+SUMIFS(预计变动!$F:$F,预计变动!$A:$A,$E12,预计变动!$B:$B,$F12,预计变动!$I:$I,">="&AM$9,预计变动!$I:$I,"<="&AM$10)) -> 0 | AN12: =IF(MONTH($G$3)>=AN$8,0,IF(Z12=0,AM12,Z12)+SUMIFS(预计变动!$F:$F,预计变动!$A:$A,$E12,预计变动!$B:$B,$F12,预计变动!$I:$I,">="&AN$9,预计变动!$I:$I,"<="&AN$10)) -> 0 | AO12: =IF(MONTH($G$3)>=AO$8,0,IF(AA12=0,AN12,AA12)+SUMIFS(预计变动!$F:$F,预计变动!$A:$A,$E12,预计变动!$B:$B,$F12,预计变动!$I:$I,">="&AO$9,预计变动!$I:$I,"<="&AO$10)) -> 0 | AP12: =IF(MONTH($G$3)>=AP$8,0,IF(AB12=0,AO12,AB12)+SUMIFS(预计变动!$F:$F,预计变动!$A:$A,$E12,预计变动!$B:$B,$F12,预计变动!$I:$I,">="&AP$9,预计变动!$I:$I,"<="&AP$10)) -> 0 | AQ12: =IF(MONTH($G$3)>=AQ$8,0,IF(AC12=0,AP12,AC12)+SUMIFS(预计变动!$F:$F,预计变动!$A:$A,$E12,预计变动!$B:$B,$F12,预计变动!$I:$I,">="&AQ$9,预计变动!$I:$I,"<="&AQ$10)) -> 0 | AR12: =IF(MONTH($G$3)>AR$8,0,IF(AD12=0,AQ12,AD12)+SUMIFS(预计变动!$F:$F,预计变动!$A:$A,$E12,预计变动!$B:$B,$F12,预计变动!$I:$I,">="&AR$9,预计变动!$I:$I,"<="&AR$10)) -> 69 | AS12: =IF(MONTH($G$3)>AS$8,0,IF(AE12=0,AR12,AE12)+SUMIFS(预计变动!$F:$F,预计变动!$A:$A,$E12,预计变动!$B:$B,$F12,预计变动!$I:$I,">="&AS$9,预计变动!$I:$I,"<="&AS$10)) -> 70 | AT12: =IF(MONTH($G$3)>AT$8,0,IF(AF12=0,AS12,AF12)+SUMIFS(预计变动!$F:$F,预计变动!$A:$A,$E12,预计变动!$B:$B,$F12,预计变动!$I:$I,">="&AT$9,预计变动!$I:$I,"<="&AT$10)) -> 68 | AU12: =BG12 -> 74 | AV12: =AT12+SUMIFS(预计变动!$F:$F,预计变动!$A:$A,$E12,预计变动!$B:$B,$F12,预计变动!$I:$I,">="&AV$9,预计变动!$I:$I,"<="&AV$10) -> 68 | AW12: =AV12+SUMIFS(预计变动!$F:$F,预计变动!$A:$A,$E12,预计变动!$B:$B,$F12,预计变动!$I:$I,">="&AW$9,预计变动!$I:$I,"<="&AW$10) -> 68 | AX12: =AW12+SUMIFS(预计变动!$F:$F,预计变动!$A:$A,$E12,预计变动!$B:$B,$F12,预计变动!$I:$I,">="&AX$9,预计变动!$I:$I,"<="&AX$10) -> 73 | AY12: =AX12+SUMIFS(预计变动!$F:$F,预计变动!$A:$A,$E12,预计变动!$B:$B,$F12,预计变动!$I:$I,">="&AY$9,预计变动!$I:$I,"<="&AY$10) -> 73 | AZ12: =AY12+SUMIFS(预计变动!$F:$F,预计变动!$A:$A,$E12,预计变动!$B:$B,$F12,预计变动!$I:$I,">="&AZ$9,预计变动!$I:$I,"<="&AZ$10) -> 74 | BA12: =AZ12+SUMIFS(预计变动!$F:$F,预计变动!$A:$A,$E12,预计变动!$B:$B,$F12,预计变动!$I:$I,">="&BA$9,预计变动!$I:$I,"<="&BA$10) -> 74 | BB12: =BA12+SUMIFS(预计变动!$F:$F,预计变动!$A:$A,$E12,预计变动!$B:$B,$F12,预计变动!$I:$I,">="&BB$9,预计变动!$I:$I,"<="&BB$10) -> 74 | BC12: =BB12+SUMIFS(预计变动!$F:$F,预计变动!$A:$A,$E12,预计变动!$B:$B,$F12,预计变动!$I:$I,">="&BC$9,预计变动!$I:$I,"<="&BC$10) -> 74 | BD12: =BC12+SUMIFS(预计变动!$F:$F,预计变动!$A:$A,$E12,预计变动!$B:$B,$F12,预计变动!$I:$I,">="&BD$9,预计变动!$I:$I,"<="&BD$10) -> 74 | ... BG12: =BF12+SUMIFS(预计变动!$F:$F,预计变动!$A:$A,$E12,预计变动!$B:$B,$F12,预计变动!$I:$I,">="&BG$9,预计变动!$I:$I,"<="&BG$10) -> 74
C13: 流程中心 | E13: =IF(C13<>"",C13,#REF!) -> 流程中心 | F13: =IF(D13<>"",D13,"*") -> * | G13: =COUNTIFS(人员状况!$C:$C,$E13,人员状况!$D:$D,$F13,人员状况!$G:$G,"<="&G$10,人员状况!$H:$H,">="&G$10+1) -> 34 | H13: =COUNTIFS(人员状况!$C:$C,$E13,人员状况!$D:$D,$F13,人员状况!$G:$G,"<="&H$10,人员状况!$H:$H,">="&H$10+1) -> 35 | I13: =COUNTIFS(人员状况!$C:$C,$E13,人员状况!$D:$D,$F13,人员状况!$G:$G,"<="&I$10,人员状况!$H:$H,">="&I$10+1) -> 35 | J13: =COUNTIFS(人员状况!$C:$C,$E13,人员状况!$D:$D,$F13,人员状况!$G:$G,"<="&J$10,人员状况!$H:$H,">="&J$10+1) -> 35 | K13: =COUNTIFS(人员状况!$C:$C,$E13,人员状况!$D:$D,$F13,人员状况!$G:$G,"<="&K$10,人员状况!$H:$H,">="&K$10+1) -> 35 | L13: =COUNTIFS(人员状况!$C:$C,$E13,人员状况!$D:$D,$F13,人员状况!$G:$G,"<="&L$10,人员状况!$H:$H,">="&L$10+1) -> 35 | M13: =COUNTIFS(人员状况!$C:$C,$E13,人员状况!$D:$D,$F13,人员状况!$G:$G,"<="&M$10,人员状况!$H:$H,">="&M$10+1) -> 35 | N13: =COUNTIFS(人员状况!$C:$C,$E13,人员状况!$D:$D,$F13,人员状况!$G:$G,"<="&N$10,人员状况!$H:$H,">="&N$10+1) -> 35 | ... S13: =COUNTIFS(人员状况!$C:$C,$E13,人员状况!$D:$D,$F13,人员状况!$G:$G,"<="&S$10,人员状况!$H:$H,">="&S$10+1) -> 34 | T13: =AT13 -> 31 | U13: =COUNTIFS(人员状况!$C:$C,$E13,人员状况!$D:$D,$F13,人员状况!$G:$G,"<="&U$10,人员状况!$H:$H,">="&U$10+1) -> 32 | V13: =IF(MONTH($G$3)>=V$8,COUNTIFS(人员状况!$C:$C,$E13,人员状况!$D:$D,$F13,人员状况!$G:$G,"<="&V$10,人员状况!$H:$H,">="&V$10+1),0) -> 34 | W13: =IF(MONTH($G$3)>=W$8,COUNTIFS(人员状况!$C:$C,$E13,人员状况!$D:$D,$F13,人员状况!$G:$G,"<="&W$10,人员状况!$H:$H,">="&W$10+1),0) -> 34 | X13: =IF(MONTH($G$3)>=X$8,COUNTIFS(人员状况!$C:$C,$E13,人员状况!$D:$D,$F13,人员状况!$G:$G,"<="&X$10,人员状况!$H:$H,">="&X$10+1),0) -> 34 | Y13: =IF(MONTH($G$3)>=Y$8,COUNTIFS(人员状况!$C:$C,$E13,人员状况!$D:$D,$F13,人员状况!$G:$G,"<="&Y$10,人员状况!$H:$H,">="&Y$10+1),0) -> 32 | Z13: =IF(MONTH($G$3)>=Z$8,COUNTIFS(人员状况!$C:$C,$E13,人员状况!$D:$D,$F13,人员状况!$G:$G,"<="&Z$10,人员状况!$H:$H,">="&Z$10+1),0) -> 33 | AA13: =IF(MONTH($G$3)>=AA$8,COUNTIFS(人员状况!$C:$C,$E13,人员状况!$D:$D,$F13,人员状况!$G:$G,"<="&AA$10,人员状况!$H:$H,">="&AA$10+1),0) -> 33 | AB13: =IF(MONTH($G$3)>=AB$8,COUNTIFS(人员状况!$C:$C,$E13,人员状况!$D:$D,$F13,人员状况!$G:$G,"<="&AB$10,人员状况!$H:$H,">="&AB$10+1),0) -> 33 | AC13: =IF(MONTH($G$3)>=AC$8,COUNTIFS(人员状况!$C:$C,$E13,人员状况!$D:$D,$F13,人员状况!$G:$G,"<="&AC$10,人员状况!$H:$H,">="&AC$10+1),0) -> 32 | ... AG13: =IF(MONTH($G$3)>=AG$8,COUNTIFS(人员状况!$C:$C,$E13,人员状况!$D:$D,$F13,人员状况!$G:$G,"<="&AG$10,人员状况!$H:$H,">="&AG$10+1),0) -> 0 | AH13: =AT13 -> 31 | AI13: =IF(MONTH($G$3)>=AI$8,0,S13+SUMIFS(预计变动!$F:$F,预计变动!$A:$A,$E13,预计变动!$B:$B,$F13,预计变动!$I:$I,">="&AI$9,预计变动!$I:$I,"<="&AI$10)) -> 0 | AJ13: =IF(MONTH($G$3)>=AJ$8,0,IF(V13=0,AI13,V13)+SUMIFS(预计变动!$F:$F,预计变动!$A:$A,$E13,预计变动!$B:$B,$F13,预计变动!$I:$I,">="&AJ$9,预计变动!$I:$I,"<="&AJ$10)) -> 0 | AK13: =IF(MONTH($G$3)>=AK$8,0,IF(W13=0,AJ13,W13)+SUMIFS(预计变动!$F:$F,预计变动!$A:$A,$E13,预计变动!$B:$B,$F13,预计变动!$I:$I,">="&AK$9,预计变动!$I:$I,"<="&AK$10)) -> 0 | AL13: =IF(MONTH($G$3)>=AL$8,0,IF(X13=0,AK13,X13)+SUMIFS(预计变动!$F:$F,预计变动!$A:$A,$E13,预计变动!$B:$B,$F13,预计变动!$I:$I,">="&AL$9,预计变动!$I:$I,"<="&AL$10)) -> 0 | AM13: =IF(MONTH($G$3)>=AM$8,0,IF(Y13=0,AL13,Y13)+SUMIFS(预计变动!$F:$F,预计变动!$A:$A,$E13,预计变动!$B:$B,$F13,预计变动!$I:$I,">="&AM$9,预计变动!$I:$I,"<="&AM$10)) -> 0 | AN13: =IF(MONTH($G$3)>=AN$8,0,IF(Z13=0,AM13,Z13)+SUMIFS(预计变动!$F:$F,预计变动!$A:$A,$E13,预计变动!$B:$B,$F13,预计变动!$I:$I,">="&AN$9,预计变动!$I:$I,"<="&AN$10)) -> 0 | AO13: =IF(MONTH($G$3)>=AO$8,0,IF(AA13=0,AN13,AA13)+SUMIFS(预计变动!$F:$F,预计变动!$A:$A,$E13,预计变动!$B:$B,$F13,预计变动!$I:$I,">="&AO$9,预计变动!$I:$I,"<="&AO$10)) -> 0 | AP13: =IF(MONTH($G$3)>=AP$8,0,IF(AB13=0,AO13,AB13)+SUMIFS(预计变动!$F:$F,预计变动!$A:$A,$E13,预计变动!$B:$B,$F13,预计变动!$I:$I,">="&AP$9,预计变动!$I:$I,"<="&AP$10)) -> 0 | AQ13: =IF(MONTH($G$3)>=AQ$8,0,IF(AC13=0,AP13,AC13)+SUMIFS(预计变动!$F:$F,预计变动!$A:$A,$E13,预计变动!$B:$B,$F13,预计变动!$I:$I,">="&AQ$9,预计变动!$I:$I,"<="&AQ$10)) -> 0 | AR13: =IF(MONTH($G$3)>AR$8,0,IF(AD13=0,AQ13,AD13)+SUMIFS(预计变动!$F:$F,预计变动!$A:$A,$E13,预计变动!$B:$B,$F13,预计变动!$I:$I,">="&AR$9,预计变动!$I:$I,"<="&AR$10)) -> 32 | AS13: =IF(MONTH($G$3)>AS$8,0,IF(AE13=0,AR13,AE13)+SUMIFS(预计变动!$F:$F,预计变动!$A:$A,$E13,预计变动!$B:$B,$F13,预计变动!$I:$I,">="&AS$9,预计变动!$I:$I,"<="&AS$10)) -> 33 | AT13: =IF(MONTH($G$3)>AT$8,0,IF(AF13=0,AS13,AF13)+SUMIFS(预计变动!$F:$F,预计变动!$A:$A,$E13,预计变动!$B:$B,$F13,预计变动!$I:$I,">="&AT$9,预计变动!$I:$I,"<="&AT$10)) -> 31 | AU13: =BG13 -> 37 | AV13: =AT13+SUMIFS(预计变动!$F:$F,预计变动!$A:$A,$E13,预计变动!$B:$B,$F13,预计变动!$I:$I,">="&AV$9,预计变动!$I:$I,"<="&AV$10) -> 31 | AW13: =AV13+SUMIFS(预计变动!$F:$F,预计变动!$A:$A,$E13,预计变动!$B:$B,$F13,预计变动!$I:$I,">="&AW$9,预计变动!$I:$I,"<="&AW$10) -> 31 | AX13: =AW13+SUMIFS(预计变动!$F:$F,预计变动!$A:$A,$E13,预计变动!$B:$B,$F13,预计变动!$I:$I,">="&AX$9,预计变动!$I:$I,"<="&AX$10) -> 36 | AY13: =AX13+SUMIFS(预计变动!$F:$F,预计变动!$A:$A,$E13,预计变动!$B:$B,$F13,预计变动!$I:$I,">="&AY$9,预计变动!$I:$I,"<="&AY$10) -> 36 | AZ13: =AY13+SUMIFS(预计变动!$F:$F,预计变动!$A:$A,$E13,预计变动!$B:$B,$F13,预计变动!$I:$I,">="&AZ$9,预计变动!$I:$I,"<="&AZ$10) -> 37 | BA13: =AZ13+SUMIFS(预计变动!$F:$F,预计变动!$A:$A,$E13,预计变动!$B:$B,$F13,预计变动!$I:$I,">="&BA$9,预计变动!$I:$I,"<="&BA$10) -> 37 | BB13: =BA13+SUMIFS(预计变动!$F:$F,预计变动!$A:$A,$E13,预计变动!$B:$B,$F13,预计变动!$I:$I,">="&BB$9,预计变动!$I:$I,"<="&BB$10) -> 37 | BC13: =BB13+SUMIFS(预计变动!$F:$F,预计变动!$A:$A,$E13,预计变动!$B:$B,$F13,预计变动!$I:$I,">="&BC$9,预计变动!$I:$I,"<="&BC$10) -> 37 | BD13: =BC13+SUMIFS(预计变动!$F:$F,预计变动!$A:$A,$E13,预计变动!$B:$B,$F13,预计变动!$I:$I,">="&BD$9,预计变动!$I:$I,"<="&BD$10) -> 37 | ... BG13: =BF13+SUMIFS(预计变动!$F:$F,预计变动!$A:$A,$E13,预计变动!$B:$B,$F13,预计变动!$I:$I,">="&BG$9,预计变动!$I:$I,"<="&BG$10) -> 37
D14: 销售中心 | E14: =IF(C14<>"",C14,E13) -> 流程中心 | F14: =IF(D14<>"",D14,"*") -> 销售中心 | G14: =COUNTIFS(人员状况!$C:$C,$E14,人员状况!$D:$D,$F14,人员状况!$G:$G,"<="&G$10,人员状况!$H:$H,">="&G$10+1) -> 13 | H14: =COUNTIFS(人员状况!$C:$C,$E14,人员状况!$D:$D,$F14,人员状况!$G:$G,"<="&H$10,人员状况!$H:$H,">="&H$10+1) -> 13 | I14: =COUNTIFS(人员状况!$C:$C,$E14,人员状况!$D:$D,$F14,人员状况!$G:$G,"<="&I$10,人员状况!$H:$H,">="&I$10+1) -> 13 | J14: =COUNTIFS(人员状况!$C:$C,$E14,人员状况!$D:$D,$F14,人员状况!$G:$G,"<="&J$10,人员状况!$H:$H,">="&J$10+1) -> 13 | K14: =COUNTIFS(人员状况!$C:$C,$E14,人员状况!$D:$D,$F14,人员状况!$G:$G,"<="&K$10,人员状况!$H:$H,">="&K$10+1) -> 13 | L14: =COUNTIFS(人员状况!$C:$C,$E14,人员状况!$D:$D,$F14,人员状况!$G:$G,"<="&L$10,人员状况!$H:$H,">="&L$10+1) -> 13 | M14: =COUNTIFS(人员状况!$C:$C,$E14,人员状况!$D:$D,$F14,人员状况!$G:$G,"<="&M$10,人员状况!$H:$H,">="&M$10+1) -> 13 | N14: =COUNTIFS(人员状况!$C:$C,$E14,人员状况!$D:$D,$F14,人员状况!$G:$G,"<="&N$10,人员状况!$H:$H,">="&N$10+1) -> 13 | ... S14: =COUNTIFS(人员状况!$C:$C,$E14,人员状况!$D:$D,$F14,人员状况!$G:$G,"<="&S$10,人员状况!$H:$H,">="&S$10+1) -> 13 | T14: =AT14 -> 13 | U14: =COUNTIFS(人员状况!$C:$C,$E14,人员状况!$D:$D,$F14,人员状况!$G:$G,"<="&U$10,人员状况!$H:$H,">="&U$10+1) -> 13 | V14: =IF(MONTH($G$3)>=V$8,COUNTIFS(人员状况!$C:$C,$E14,人员状况!$D:$D,$F14,人员状况!$G:$G,"<="&V$10,人员状况!$H:$H,">="&V$10+1),0) -> 13 | W14: =IF(MONTH($G$3)>=W$8,COUNTIFS(人员状况!$C:$C,$E14,人员状况!$D:$D,$F14,人员状况!$G:$G,"<="&W$10,人员状况!$H:$H,">="&W$10+1),0) -> 13 | X14: =IF(MONTH($G$3)>=X$8,COUNTIFS(人员状况!$C:$C,$E14,人员状况!$D:$D,$F14,人员状况!$G:$G,"<="&X$10,人员状况!$H:$H,">="&X$10+1),0) -> 13 | Y14: =IF(MONTH($G$3)>=Y$8,COUNTIFS(人员状况!$C:$C,$E14,人员状况!$D:$D,$F14,人员状况!$G:$G,"<="&Y$10,人员状况!$H:$H,">="&Y$10+1),0) -> 13 | Z14: =IF(MONTH($G$3)>=Z$8,COUNTIFS(人员状况!$C:$C,$E14,人员状况!$D:$D,$F14,人员状况!$G:$G,"<="&Z$10,人员状况!$H:$H,">="&Z$10+1),0) -> 14 | AA14: =IF(MONTH($G$3)>=AA$8,COUNTIFS(人员状况!$C:$C,$E14,人员状况!$D:$D,$F14,人员状况!$G:$G,"<="&AA$10,人员状况!$H:$H,">="&AA$10+1),0) -> 14 | AB14: =IF(MONTH($G$3)>=AB$8,COUNTIFS(人员状况!$C:$C,$E14,人员状况!$D:$D,$F14,人员状况!$G:$G,"<="&AB$10,人员状况!$H:$H,">="&AB$10+1),0) -> 14 | AC14: =IF(MONTH($G$3)>=AC$8,COUNTIFS(人员状况!$C:$C,$E14,人员状况!$D:$D,$F14,人员状况!$G:$G,"<="&AC$10,人员状况!$H:$H,">="&AC$10+1),0) -> 13 | ... AG14: =IF(MONTH($G$3)>=AG$8,COUNTIFS(人员状况!$C:$C,$E14,人员状况!$D:$D,$F14,人员状况!$G:$G,"<="&AG$10,人员状况!$H:$H,">="&AG$10+1),0) -> 0 | AH14: =AT14 -> 13 | AI14: =IF(MONTH($G$3)>=AI$8,0,S14+SUMIFS(预计变动!$F:$F,预计变动!$A:$A,$E14,预计变动!$B:$B,$F14,预计变动!$I:$I,">="&AI$9,预计变动!$I:$I,"<="&AI$10)) -> 0 | AJ14: =IF(MONTH($G$3)>=AJ$8,0,IF(V14=0,AI14,V14)+SUMIFS(预计变动!$F:$F,预计变动!$A:$A,$E14,预计变动!$B:$B,$F14,预计变动!$I:$I,">="&AJ$9,预计变动!$I:$I,"<="&AJ$10)) -> 0 | AK14: =IF(MONTH($G$3)>=AK$8,0,IF(W14=0,AJ14,W14)+SUMIFS(预计变动!$F:$F,预计变动!$A:$A,$E14,预计变动!$B:$B,$F14,预计变动!$I:$I,">="&AK$9,预计变动!$I:$I,"<="&AK$10)) -> 0 | AL14: =IF(MONTH($G$3)>=AL$8,0,IF(X14=0,AK14,X14)+SUMIFS(预计变动!$F:$F,预计变动!$A:$A,$E14,预计变动!$B:$B,$F14,预计变动!$I:$I,">="&AL$9,预计变动!$I:$I,"<="&AL$10)) -> 0 | AM14: =IF(MONTH($G$3)>=AM$8,0,IF(Y14=0,AL14,Y14)+SUMIFS(预计变动!$F:$F,预计变动!$A:$A,$E14,预计变动!$B:$B,$F14,预计变动!$I:$I,">="&AM$9,预计变动!$I:$I,"<="&AM$10)) -> 0 | AN14: =IF(MONTH($G$3)>=AN$8,0,IF(Z14=0,AM14,Z14)+SUMIFS(预计变动!$F:$F,预计变动!$A:$A,$E14,预计变动!$B:$B,$F14,预计变动!$I:$I,">="&AN$9,预计变动!$I:$I,"<="&AN$10)) -> 0 | AO14: =IF(MONTH($G$3)>=AO$8,0,IF(AA14=0,AN14,AA14)+SUMIFS(预计变动!$F:$F,预计变动!$A:$A,$E14,预计变动!$B:$B,$F14,预计变动!$I:$I,">="&AO$9,预计变动!$I:$I,"<="&AO$10)) -> 0 | AP14: =IF(MONTH($G$3)>=AP$8,0,IF(AB14=0,AO14,AB14)+SUMIFS(预计变动!$F:$F,预计变动!$A:$A,$E14,预计变动!$B:$B,$F14,预计变动!$I:$I,">="&AP$9,预计变动!$I:$I,"<="&AP$10)) -> 0 | AQ14: =IF(MONTH($G$3)>=AQ$8,0,IF(AC14=0,AP14,AC14)+SUMIFS(预计变动!$F:$F,预计变动!$A:$A,$E14,预计变动!$B:$B,$F14,预计变动!$I:$I,">="&AQ$9,预计变动!$I:$I,"<="&AQ$10)) -> 0 | AR14: =IF(MONTH($G$3)>AR$8,0,IF(AD14=0,AQ14,AD14)+SUMIFS(预计变动!$F:$F,预计变动!$A:$A,$E14,预计变动!$B:$B,$F14,预计变动!$I:$I,">="&AR$9,预计变动!$I:$I,"<="&AR$10)) -> 13 | AS14: =IF(MONTH($G$3)>AS$8,0,IF(AE14=0,AR14,AE14)+SUMIFS(预计变动!$F:$F,预计变动!$A:$A,$E14,预计变动!$B:$B,$F14,预计变动!$I:$I,">="&AS$9,预计变动!$I:$I,"<="&AS$10)) -> 13 | AT14: =IF(MONTH($G$3)>AT$8,0,IF(AF14=0,AS14,AF14)+SUMIFS(预计变动!$F:$F,预计变动!$A:$A,$E14,预计变动!$B:$B,$F14,预计变动!$I:$I,">="&AT$9,预计变动!$I:$I,"<="&AT$10)) -> 13 | AU14: =BG14 -> 14 | AV14: =AT14+SUMIFS(预计变动!$F:$F,预计变动!$A:$A,$E14,预计变动!$B:$B,$F14,预计变动!$I:$I,">="&AV$9,预计变动!$I:$I,"<="&AV$10) -> 13 | AW14: =AV14+SUMIFS(预计变动!$F:$F,预计变动!$A:$A,$E14,预计变动!$B:$B,$F14,预计变动!$I:$I,">="&AW$9,预计变动!$I:$I,"<="&AW$10) -> 13 | AX14: =AW14+SUMIFS(预计变动!$F:$F,预计变动!$A:$A,$E14,预计变动!$B:$B,$F14,预计变动!$I:$I,">="&AX$9,预计变动!$I:$I,"<="&AX$10) -> 13 | AY14: =AX14+SUMIFS(预计变动!$F:$F,预计变动!$A:$A,$E14,预计变动!$B:$B,$F14,预计变动!$I:$I,">="&AY$9,预计变动!$I:$I,"<="&AY$10) -> 13 | AZ14: =AY14+SUMIFS(预计变动!$F:$F,预计变动!$A:$A,$E14,预计变动!$B:$B,$F14,预计变动!$I:$I,">="&AZ$9,预计变动!$I:$I,"<="&AZ$10) -> 14 | BA14: =AZ14+SUMIFS(预计变动!$F:$F,预计变动!$A:$A,$E14,预计变动!$B:$B,$F14,预计变动!$I:$I,">="&BA$9,预计变动!$I:$I,"<="&BA$10) -> 14 | BB14: =BA14+SUMIFS(预计变动!$F:$F,预计变动!$A:$A,$E14,预计变动!$B:$B,$F14,预计变动!$I:$I,">="&BB$9,预计变动!$I:$I,"<="&BB$10) -> 14 | BC14: =BB14+SUMIFS(预计变动!$F:$F,预计变动!$A:$A,$E14,预计变动!$B:$B,$F14,预计变动!$I:$I,">="&BC$9,预计变动!$I:$I,"<="&BC$10) -> 14 | BD14: =BC14+SUMIFS(预计变动!$F:$F,预计变动!$A:$A,$E14,预计变动!$B:$B,$F14,预计变动!$I:$I,">="&BD$9,预计变动!$I:$I,"<="&BD$10) -> 14 | ... BG14: =BF14+SUMIFS(预计变动!$F:$F,预计变动!$A:$A,$E14,预计变动!$B:$B,$F14,预计变动!$I:$I,">="&BG$9,预计变动!$I:$I,"<="&BG$10) -> 14
D15: 制造中心 | E15: =IF(C15<>"",C15,E14) -> 流程中心 | F15: =IF(D15<>"",D15,"*") -> 制造中心 | G15: =COUNTIFS(人员状况!$C:$C,$E15,人员状况!$D:$D,$F15,人员状况!$G:$G,"<="&G$10,人员状况!$H:$H,">="&G$10+1) -> 21 | H15: =COUNTIFS(人员状况!$C:$C,$E15,人员状况!$D:$D,$F15,人员状况!$G:$G,"<="&H$10,人员状况!$H:$H,">="&H$10+1) -> 22 | I15: =COUNTIFS(人员状况!$C:$C,$E15,人员状况!$D:$D,$F15,人员状况!$G:$G,"<="&I$10,人员状况!$H:$H,">="&I$10+1) -> 22 | J15: =COUNTIFS(人员状况!$C:$C,$E15,人员状况!$D:$D,$F15,人员状况!$G:$G,"<="&J$10,人员状况!$H:$H,">="&J$10+1) -> 22 | K15: =COUNTIFS(人员状况!$C:$C,$E15,人员状况!$D:$D,$F15,人员状况!$G:$G,"<="&K$10,人员状况!$H:$H,">="&K$10+1) -> 22 | L15: =COUNTIFS(人员状况!$C:$C,$E15,人员状况!$D:$D,$F15,人员状况!$G:$G,"<="&L$10,人员状况!$H:$H,">="&L$10+1) -> 22 | M15: =COUNTIFS(人员状况!$C:$C,$E15,人员状况!$D:$D,$F15,人员状况!$G:$G,"<="&M$10,人员状况!$H:$H,">="&M$10+1) -> 22 | N15: =COUNTIFS(人员状况!$C:$C,$E15,人员状况!$D:$D,$F15,人员状况!$G:$G,"<="&N$10,人员状况!$H:$H,">="&N$10+1) -> 22 | ... S15: =COUNTIFS(人员状况!$C:$C,$E15,人员状况!$D:$D,$F15,人员状况!$G:$G,"<="&S$10,人员状况!$H:$H,">="&S$10+1) -> 21 | T15: =AT15 -> 18 | U15: =COUNTIFS(人员状况!$C:$C,$E15,人员状况!$D:$D,$F15,人员状况!$G:$G,"<="&U$10,人员状况!$H:$H,">="&U$10+1) -> 19 | V15: =IF(MONTH($G$3)>=V$8,COUNTIFS(人员状况!$C:$C,$E15,人员状况!$D:$D,$F15,人员状况!$G:$G,"<="&V$10,人员状况!$H:$H,">="&V$10+1),0) -> 21 | W15: =IF(MONTH($G$3)>=W$8,COUNTIFS(人员状况!$C:$C,$E15,人员状况!$D:$D,$F15,人员状况!$G:$G,"<="&W$10,人员状况!$H:$H,">="&W$10+1),0) -> 21 | X15: =IF(MONTH($G$3)>=X$8,COUNTIFS(人员状况!$C:$C,$E15,人员状况!$D:$D,$F15,人员状况!$G:$G,"<="&X$10,人员状况!$H:$H,">="&X$10+1),0) -> 21 | Y15: =IF(MONTH($G$3)>=Y$8,COUNTIFS(人员状况!$C:$C,$E15,人员状况!$D:$D,$F15,人员状况!$G:$G,"<="&Y$10,人员状况!$H:$H,">="&Y$10+1),0) -> 19 | Z15: =IF(MONTH($G$3)>=Z$8,COUNTIFS(人员状况!$C:$C,$E15,人员状况!$D:$D,$F15,人员状况!$G:$G,"<="&Z$10,人员状况!$H:$H,">="&Z$10+1),0) -> 19 | AA15: =IF(MONTH($G$3)>=AA$8,COUNTIFS(人员状况!$C:$C,$E15,人员状况!$D:$D,$F15,人员状况!$G:$G,"<="&AA$10,人员状况!$H:$H,">="&AA$10+1),0) -> 19 | AB15: =IF(MONTH($G$3)>=AB$8,COUNTIFS(人员状况!$C:$C,$E15,人员状况!$D:$D,$F15,人员状况!$G:$G,"<="&AB$10,人员状况!$H:$H,">="&AB$10+1),0) -> 19 | AC15: =IF(MONTH($G$3)>=AC$8,COUNTIFS(人员状况!$C:$C,$E15,人员状况!$D:$D,$F15,人员状况!$G:$G,"<="&AC$10,人员状况!$H:$H,">="&AC$10+1),0) -> 19 | ... AG15: =IF(MONTH($G$3)>=AG$8,COUNTIFS(人员状况!$C:$C,$E15,人员状况!$D:$D,$F15,人员状况!$G:$G,"<="&AG$10,人员状况!$H:$H,">="&AG$10+1),0) -> 0 | AH15: =AT15 -> 18 | AI15: =IF(MONTH($G$3)>=AI$8,0,S15+SUMIFS(预计变动!$F:$F,预计变动!$A:$A,$E15,预计变动!$B:$B,$F15,预计变动!$I:$I,">="&AI$9,预计变动!$I:$I,"<="&AI$10)) -> 0 | AJ15: =IF(MONTH($G$3)>=AJ$8,0,IF(V15=0,AI15,V15)+SUMIFS(预计变动!$F:$F,预计变动!$A:$A,$E15,预计变动!$B:$B,$F15,预计变动!$I:$I,">="&AJ$9,预计变动!$I:$I,"<="&AJ$10)) -> 0 | AK15: =IF(MONTH($G$3)>=AK$8,0,IF(W15=0,AJ15,W15)+SUMIFS(预计变动!$F:$F,预计变动!$A:$A,$E15,预计变动!$B:$B,$F15,预计变动!$I:$I,">="&AK$9,预计变动!$I:$I,"<="&AK$10)) -> 0 | AL15: =IF(MONTH($G$3)>=AL$8,0,IF(X15=0,AK15,X15)+SUMIFS(预计变动!$F:$F,预计变动!$A:$A,$E15,预计变动!$B:$B,$F15,预计变动!$I:$I,">="&AL$9,预计变动!$I:$I,"<="&AL$10)) -> 0 | AM15: =IF(MONTH($G$3)>=AM$8,0,IF(Y15=0,AL15,Y15)+SUMIFS(预计变动!$F:$F,预计变动!$A:$A,$E15,预计变动!$B:$B,$F15,预计变动!$I:$I,">="&AM$9,预计变动!$I:$I,"<="&AM$10)) -> 0 | AN15: =IF(MONTH($G$3)>=AN$8,0,IF(Z15=0,AM15,Z15)+SUMIFS(预计变动!$F:$F,预计变动!$A:$A,$E15,预计变动!$B:$B,$F15,预计变动!$I:$I,">="&AN$9,预计变动!$I:$I,"<="&AN$10)) -> 0 | AO15: =IF(MONTH($G$3)>=AO$8,0,IF(AA15=0,AN15,AA15)+SUMIFS(预计变动!$F:$F,预计变动!$A:$A,$E15,预计变动!$B:$B,$F15,预计变动!$I:$I,">="&AO$9,预计变动!$I:$I,"<="&AO$10)) -> 0 | AP15: =IF(MONTH($G$3)>=AP$8,0,IF(AB15=0,AO15,AB15)+SUMIFS(预计变动!$F:$F,预计变动!$A:$A,$E15,预计变动!$B:$B,$F15,预计变动!$I:$I,">="&AP$9,预计变动!$I:$I,"<="&AP$10)) -> 0 | AQ15: =IF(MONTH($G$3)>=AQ$8,0,IF(AC15=0,AP15,AC15)+SUMIFS(预计变动!$F:$F,预计变动!$A:$A,$E15,预计变动!$B:$B,$F15,预计变动!$I:$I,">="&AQ$9,预计变动!$I:$I,"<="&AQ$10)) -> 0 | AR15: =IF(MONTH($G$3)>AR$8,0,IF(AD15=0,AQ15,AD15)+SUMIFS(预计变动!$F:$F,预计变动!$A:$A,$E15,预计变动!$B:$B,$F15,预计变动!$I:$I,">="&AR$9,预计变动!$I:$I,"<="&AR$10)) -> 19 | AS15: =IF(MONTH($G$3)>AS$8,0,IF(AE15=0,AR15,AE15)+SUMIFS(预计变动!$F:$F,预计变动!$A:$A,$E15,预计变动!$B:$B,$F15,预计变动!$I:$I,">="&AS$9,预计变动!$I:$I,"<="&AS$10)) -> 20 | AT15: =IF(MONTH($G$3)>AT$8,0,IF(AF15=0,AS15,AF15)+SUMIFS(预计变动!$F:$F,预计变动!$A:$A,$E15,预计变动!$B:$B,$F15,预计变动!$I:$I,">="&AT$9,预计变动!$I:$I,"<="&AT$10)) -> 18 | AU15: =BG15 -> 23 | AV15: =AT15+SUMIFS(预计变动!$F:$F,预计变动!$A:$A,$E15,预计变动!$B:$B,$F15,预计变动!$I:$I,">="&AV$9,预计变动!$I:$I,"<="&AV$10) -> 18 | AW15: =AV15+SUMIFS(预计变动!$F:$F,预计变动!$A:$A,$E15,预计变动!$B:$B,$F15,预计变动!$I:$I,">="&AW$9,预计变动!$I:$I,"<="&AW$10) -> 18 | AX15: =AW15+SUMIFS(预计变动!$F:$F,预计变动!$A:$A,$E15,预计变动!$B:$B,$F15,预计变动!$I:$I,">="&AX$9,预计变动!$I:$I,"<="&AX$10) -> 23 | AY15: =AX15+SUMIFS(预计变动!$F:$F,预计变动!$A:$A,$E15,预计变动!$B:$B,$F15,预计变动!$I:$I,">="&AY$9,预计变动!$I:$I,"<="&AY$10) -> 23 | AZ15: =AY15+SUMIFS(预计变动!$F:$F,预计变动!$A:$A,$E15,预计变动!$B:$B,$F15,预计变动!$I:$I,">="&AZ$9,预计变动!$I:$I,"<="&AZ$10) -> 23 | BA15: =AZ15+SUMIFS(预计变动!$F:$F,预计变动!$A:$A,$E15,预计变动!$B:$B,$F15,预计变动!$I:$I,">="&BA$9,预计变动!$I:$I,"<="&BA$10) -> 23 | BB15: =BA15+SUMIFS(预计变动!$F:$F,预计变动!$A:$A,$E15,预计变动!$B:$B,$F15,预计变动!$I:$I,">="&BB$9,预计变动!$I:$I,"<="&BB$10) -> 23 | BC15: =BB15+SUMIFS(预计变动!$F:$F,预计变动!$A:$A,$E15,预计变动!$B:$B,$F15,预计变动!$I:$I,">="&BC$9,预计变动!$I:$I,"<="&BC$10) -> 23 | BD15: =BC15+SUMIFS(预计变动!$F:$F,预计变动!$A:$A,$E15,预计变动!$B:$B,$F15,预计变动!$I:$I,">="&BD$9,预计变动!$I:$I,"<="&BD$10) -> 23 | ... BG15: =BF15+SUMIFS(预计变动!$F:$F,预计变动!$A:$A,$E15,预计变动!$B:$B,$F15,预计变动!$I:$I,">="&BG$9,预计变动!$I:$I,"<="&BG$10) -> 23
C16: 创新中心 | E16: =IF(C16<>"",C16,E15) -> 创新中心 | F16: =IF(D16<>"",D16,"*") -> * | G16: =COUNTIFS(人员状况!$C:$C,$E16,人员状况!$D:$D,$F16,人员状况!$G:$G,"<="&G$10,人员状况!$H:$H,">="&G$10+1) -> 19 | H16: =COUNTIFS(人员状况!$C:$C,$E16,人员状况!$D:$D,$F16,人员状况!$G:$G,"<="&H$10,人员状况!$H:$H,">="&H$10+1) -> 19 | I16: =COUNTIFS(人员状况!$C:$C,$E16,人员状况!$D:$D,$F16,人员状况!$G:$G,"<="&I$10,人员状况!$H:$H,">="&I$10+1) -> 19 | J16: =COUNTIFS(人员状况!$C:$C,$E16,人员状况!$D:$D,$F16,人员状况!$G:$G,"<="&J$10,人员状况!$H:$H,">="&J$10+1) -> 19 | K16: =COUNTIFS(人员状况!$C:$C,$E16,人员状况!$D:$D,$F16,人员状况!$G:$G,"<="&K$10,人员状况!$H:$H,">="&K$10+1) -> 19 | L16: =COUNTIFS(人员状况!$C:$C,$E16,人员状况!$D:$D,$F16,人员状况!$G:$G,"<="&L$10,人员状况!$H:$H,">="&L$10+1) -> 19 | M16: =COUNTIFS(人员状况!$C:$C,$E16,人员状况!$D:$D,$F16,人员状况!$G:$G,"<="&M$10,人员状况!$H:$H,">="&M$10+1) -> 19 | N16: =COUNTIFS(人员状况!$C:$C,$E16,人员状况!$D:$D,$F16,人员状况!$G:$G,"<="&N$10,人员状况!$H:$H,">="&N$10+1) -> 19 | ... S16: =COUNTIFS(人员状况!$C:$C,$E16,人员状况!$D:$D,$F16,人员状况!$G:$G,"<="&S$10,人员状况!$H:$H,">="&S$10+1) -> 19 | T16: =AT16 -> 20 | U16: =COUNTIFS(人员状况!$C:$C,$E16,人员状况!$D:$D,$F16,人员状况!$G:$G,"<="&U$10,人员状况!$H:$H,">="&U$10+1) -> 20 | V16: =IF(MONTH($G$3)>=V$8,COUNTIFS(人员状况!$C:$C,$E16,人员状况!$D:$D,$F16,人员状况!$G:$G,"<="&V$10,人员状况!$H:$H,">="&V$10+1),0) -> 19 | W16: =IF(MONTH($G$3)>=W$8,COUNTIFS(人员状况!$C:$C,$E16,人员状况!$D:$D,$F16,人员状况!$G:$G,"<="&W$10,人员状况!$H:$H,">="&W$10+1),0) -> 19 | X16: =IF(MONTH($G$3)>=X$8,COUNTIFS(人员状况!$C:$C,$E16,人员状况!$D:$D,$F16,人员状况!$G:$G,"<="&X$10,人员状况!$H:$H,">="&X$10+1),0) -> 19 | Y16: =IF(MONTH($G$3)>=Y$8,COUNTIFS(人员状况!$C:$C,$E16,人员状况!$D:$D,$F16,人员状况!$G:$G,"<="&Y$10,人员状况!$H:$H,">="&Y$10+1),0) -> 19 | Z16: =IF(MONTH($G$3)>=Z$8,COUNTIFS(人员状况!$C:$C,$E16,人员状况!$D:$D,$F16,人员状况!$G:$G,"<="&Z$10,人员状况!$H:$H,">="&Z$10+1),0) -> 19 | AA16: =IF(MONTH($G$3)>=AA$8,COUNTIFS(人员状况!$C:$C,$E16,人员状况!$D:$D,$F16,人员状况!$G:$G,"<="&AA$10,人员状况!$H:$H,">="&AA$10+1),0) -> 19 | AB16: =IF(MONTH($G$3)>=AB$8,COUNTIFS(人员状况!$C:$C,$E16,人员状况!$D:$D,$F16,人员状况!$G:$G,"<="&AB$10,人员状况!$H:$H,">="&AB$10+1),0) -> 20 | AC16: =IF(MONTH($G$3)>=AC$8,COUNTIFS(人员状况!$C:$C,$E16,人员状况!$D:$D,$F16,人员状况!$G:$G,"<="&AC$10,人员状况!$H:$H,">="&AC$10+1),0) -> 20 | ... AG16: =IF(MONTH($G$3)>=AG$8,COUNTIFS(人员状况!$C:$C,$E16,人员状况!$D:$D,$F16,人员状况!$G:$G,"<="&AG$10,人员状况!$H:$H,">="&AG$10+1),0) -> 0 | AH16: =AT16 -> 20 | AI16: =IF(MONTH($G$3)>=AI$8,0,S16+SUMIFS(预计变动!$F:$F,预计变动!$A:$A,$E16,预计变动!$B:$B,$F16,预计变动!$I:$I,">="&AI$9,预计变动!$I:$I,"<="&AI$10)) -> 0 | AJ16: =IF(MONTH($G$3)>=AJ$8,0,IF(V16=0,AI16,V16)+SUMIFS(预计变动!$F:$F,预计变动!$A:$A,$E16,预计变动!$B:$B,$F16,预计变动!$I:$I,">="&AJ$9,预计变动!$I:$I,"<="&AJ$10)) -> 0 | AK16: =IF(MONTH($G$3)>=AK$8,0,IF(W16=0,AJ16,W16)+SUMIFS(预计变动!$F:$F,预计变动!$A:$A,$E16,预计变动!$B:$B,$F16,预计变动!$I:$I,">="&AK$9,预计变动!$I:$I,"<="&AK$10)) -> 0 | AL16: =IF(MONTH($G$3)>=AL$8,0,IF(X16=0,AK16,X16)+SUMIFS(预计变动!$F:$F,预计变动!$A:$A,$E16,预计变动!$B:$B,$F16,预计变动!$I:$I,">="&AL$9,预计变动!$I:$I,"<="&AL$10)) -> 0 | AM16: =IF(MONTH($G$3)>=AM$8,0,IF(Y16=0,AL16,Y16)+SUMIFS(预计变动!$F:$F,预计变动!$A:$A,$E16,预计变动!$B:$B,$F16,预计变动!$I:$I,">="&AM$9,预计变动!$I:$I,"<="&AM$10)) -> 0 | AN16: =IF(MONTH($G$3)>=AN$8,0,IF(Z16=0,AM16,Z16)+SUMIFS(预计变动!$F:$F,预计变动!$A:$A,$E16,预计变动!$B:$B,$F16,预计变动!$I:$I,">="&AN$9,预计变动!$I:$I,"<="&AN$10)) -> 0 | AO16: =IF(MONTH($G$3)>=AO$8,0,IF(AA16=0,AN16,AA16)+SUMIFS(预计变动!$F:$F,预计变动!$A:$A,$E16,预计变动!$B:$B,$F16,预计变动!$I:$I,">="&AO$9,预计变动!$I:$I,"<="&AO$10)) -> 0 | AP16: =IF(MONTH($G$3)>=AP$8,0,IF(AB16=0,AO16,AB16)+SUMIFS(预计变动!$F:$F,预计变动!$A:$A,$E16,预计变动!$B:$B,$F16,预计变动!$I:$I,">="&AP$9,预计变动!$I:$I,"<="&AP$10)) -> 0 | AQ16: =IF(MONTH($G$3)>=AQ$8,0,IF(AC16=0,AP16,AC16)+SUMIFS(预计变动!$F:$F,预计变动!$A:$A,$E16,预计变动!$B:$B,$F16,预计变动!$I:$I,">="&AQ$9,预计变动!$I:$I,"<="&AQ$10)) -> 0 | AR16: =IF(MONTH($G$3)>AR$8,0,IF(AD16=0,AQ16,AD16)+SUMIFS(预计变动!$F:$F,预计变动!$A:$A,$E16,预计变动!$B:$B,$F16,预计变动!$I:$I,">="&AR$9,预计变动!$I:$I,"<="&AR$10)) -> 20 | AS16: =IF(MONTH($G$3)>AS$8,0,IF(AE16=0,AR16,AE16)+SUMIFS(预计变动!$F:$F,预计变动!$A:$A,$E16,预计变动!$B:$B,$F16,预计变动!$I:$I,">="&AS$9,预计变动!$I:$I,"<="&AS$10)) -> 20 | AT16: =IF(MONTH($G$3)>AT$8,0,IF(AF16=0,AS16,AF16)+SUMIFS(预计变动!$F:$F,预计变动!$A:$A,$E16,预计变动!$B:$B,$F16,预计变动!$I:$I,">="&AT$9,预计变动!$I:$I,"<="&AT$10)) -> 20 | AU16: =BG16 -> 20 | AV16: =AT16+SUMIFS(预计变动!$F:$F,预计变动!$A:$A,$E16,预计变动!$B:$B,$F16,预计变动!$I:$I,">="&AV$9,预计变动!$I:$I,"<="&AV$10) -> 20 | AW16: =AV16+SUMIFS(预计变动!$F:$F,预计变动!$A:$A,$E16,预计变动!$B:$B,$F16,预计变动!$I:$I,">="&AW$9,预计变动!$I:$I,"<="&AW$10) -> 20 | AX16: =AW16+SUMIFS(预计变动!$F:$F,预计变动!$A:$A,$E16,预计变动!$B:$B,$F16,预计变动!$I:$I,">="&AX$9,预计变动!$I:$I,"<="&AX$10) -> 20 | AY16: =AX16+SUMIFS(预计变动!$F:$F,预计变动!$A:$A,$E16,预计变动!$B:$B,$F16,预计变动!$I:$I,">="&AY$9,预计变动!$I:$I,"<="&AY$10) -> 20 | AZ16: =AY16+SUMIFS(预计变动!$F:$F,预计变动!$A:$A,$E16,预计变动!$B:$B,$F16,预计变动!$I:$I,">="&AZ$9,预计变动!$I:$I,"<="&AZ$10) -> 20 | BA16: =AZ16+SUMIFS(预计变动!$F:$F,预计变动!$A:$A,$E16,预计变动!$B:$B,$F16,预计变动!$I:$I,">="&BA$9,预计变动!$I:$I,"<="&BA$10) -> 20 | BB16: =BA16+SUMIFS(预计变动!$F:$F,预计变动!$A:$A,$E16,预计变动!$B:$B,$F16,预计变动!$I:$I,">="&BB$9,预计变动!$I:$I,"<="&BB$10) -> 20 | BC16: =BB16+SUMIFS(预计变动!$F:$F,预计变动!$A:$A,$E16,预计变动!$B:$B,$F16,预计变动!$I:$I,">="&BC$9,预计变动!$I:$I,"<="&BC$10) -> 20 | BD16: =BC16+SUMIFS(预计变动!$F:$F,预计变动!$A:$A,$E16,预计变动!$B:$B,$F16,预计变动!$I:$I,">="&BD$9,预计变动!$I:$I,"<="&BD$10) -> 20 | ... BG16: =BF16+SUMIFS(预计变动!$F:$F,预计变动!$A:$A,$E16,预计变动!$B:$B,$F16,预计变动!$I:$I,">="&BG$9,预计变动!$I:$I,"<="&BG$10) -> 20
D17: 产品 研发部 | E17: =IF(C17<>"",C17,E16) -> 创新中心 | F17: =IF(D17<>"",D17,"*") -> 产品 研发部 | G17: =COUNTIFS(人员状况!$C:$C,$E17,人员状况!$D:$D,$F17,人员状况!$G:$G,"<="&G$10,人员状况!$H:$H,">="&G$10+1) -> 8 | H17: =COUNTIFS(人员状况!$C:$C,$E17,人员状况!$D:$D,$F17,人员状况!$G:$G,"<="&H$10,人员状况!$H:$H,">="&H$10+1) -> 8 | I17: =COUNTIFS(人员状况!$C:$C,$E17,人员状况!$D:$D,$F17,人员状况!$G:$G,"<="&I$10,人员状况!$H:$H,">="&I$10+1) -> 8 | J17: =COUNTIFS(人员状况!$C:$C,$E17,人员状况!$D:$D,$F17,人员状况!$G:$G,"<="&J$10,人员状况!$H:$H,">="&J$10+1) -> 8 | K17: =COUNTIFS(人员状况!$C:$C,$E17,人员状况!$D:$D,$F17,人员状况!$G:$G,"<="&K$10,人员状况!$H:$H,">="&K$10+1) -> 8 | L17: =COUNTIFS(人员状况!$C:$C,$E17,人员状况!$D:$D,$F17,人员状况!$G:$G,"<="&L$10,人员状况!$H:$H,">="&L$10+1) -> 8 | M17: =COUNTIFS(人员状况!$C:$C,$E17,人员状况!$D:$D,$F17,人员状况!$G:$G,"<="&M$10,人员状况!$H:$H,">="&M$10+1) -> 8 | N17: =COUNTIFS(人员状况!$C:$C,$E17,人员状况!$D:$D,$F17,人员状况!$G:$G,"<="&N$10,人员状况!$H:$H,">="&N$10+1) -> 8 | ... S17: =COUNTIFS(人员状况!$C:$C,$E17,人员状况!$D:$D,$F17,人员状况!$G:$G,"<="&S$10,人员状况!$H:$H,">="&S$10+1) -> 8 | T17: =AT17 -> 8 | U17: =COUNTIFS(人员状况!$C:$C,$E17,人员状况!$D:$D,$F17,人员状况!$G:$G,"<="&U$10,人员状况!$H:$H,">="&U$10+1) -> 8 | V17: =IF(MONTH($G$3)>=V$8,COUNTIFS(人员状况!$C:$C,$E17,人员状况!$D:$D,$F17,人员状况!$G:$G,"<="&V$10,人员状况!$H:$H,">="&V$10+1),0) -> 8 | W17: =IF(MONTH($G$3)>=W$8,COUNTIFS(人员状况!$C:$C,$E17,人员状况!$D:$D,$F17,人员状况!$G:$G,"<="&W$10,人员状况!$H:$H,">="&W$10+1),0) -> 8 | X17: =IF(MONTH($G$3)>=X$8,COUNTIFS(人员状况!$C:$C,$E17,人员状况!$D:$D,$F17,人员状况!$G:$G,"<="&X$10,人员状况!$H:$H,">="&X$10+1),0) -> 8 | Y17: =IF(MONTH($G$3)>=Y$8,COUNTIFS(人员状况!$C:$C,$E17,人员状况!$D:$D,$F17,人员状况!$G:$G,"<="&Y$10,人员状况!$H:$H,">="&Y$10+1),0) -> 8 | Z17: =IF(MONTH($G$3)>=Z$8,COUNTIFS(人员状况!$C:$C,$E17,人员状况!$D:$D,$F17,人员状况!$G:$G,"<="&Z$10,人员状况!$H:$H,">="&Z$10+1),0) -> 8 | AA17: =IF(MONTH($G$3)>=AA$8,COUNTIFS(人员状况!$C:$C,$E17,人员状况!$D:$D,$F17,人员状况!$G:$G,"<="&AA$10,人员状况!$H:$H,">="&AA$10+1),0) -> 8 | AB17: =IF(MONTH($G$3)>=AB$8,COUNTIFS(人员状况!$C:$C,$E17,人员状况!$D:$D,$F17,人员状况!$G:$G,"<="&AB$10,人员状况!$H:$H,">="&AB$10+1),0) -> 8 | AC17: =IF(MONTH($G$3)>=AC$8,COUNTIFS(人员状况!$C:$C,$E17,人员状况!$D:$D,$F17,人员状况!$G:$G,"<="&AC$10,人员状况!$H:$H,">="&AC$10+1),0) -> 8 | ... AG17: =IF(MONTH($G$3)>=AG$8,COUNTIFS(人员状况!$C:$C,$E17,人员状况!$D:$D,$F17,人员状况!$G:$G,"<="&AG$10,人员状况!$H:$H,">="&AG$10+1),0) -> 0 | AH17: =AT17 -> 8 | AI17: =IF(MONTH($G$3)>=AI$8,0,S17+SUMIFS(预计变动!$F:$F,预计变动!$A:$A,$E17,预计变动!$B:$B,$F17,预计变动!$I:$I,">="&AI$9,预计变动!$I:$I,"<="&AI$10)) -> 0 | AJ17: =IF(MONTH($G$3)>=AJ$8,0,IF(V17=0,AI17,V17)+SUMIFS(预计变动!$F:$F,预计变动!$A:$A,$E17,预计变动!$B:$B,$F17,预计变动!$I:$I,">="&AJ$9,预计变动!$I:$I,"<="&AJ$10)) -> 0 | AK17: =IF(MONTH($G$3)>=AK$8,0,IF(W17=0,AJ17,W17)+SUMIFS(预计变动!$F:$F,预计变动!$A:$A,$E17,预计变动!$B:$B,$F17,预计变动!$I:$I,">="&AK$9,预计变动!$I:$I,"<="&AK$10)) -> 0 | AL17: =IF(MONTH($G$3)>=AL$8,0,IF(X17=0,AK17,X17)+SUMIFS(预计变动!$F:$F,预计变动!$A:$A,$E17,预计变动!$B:$B,$F17,预计变动!$I:$I,">="&AL$9,预计变动!$I:$I,"<="&AL$10)) -> 0 | AM17: =IF(MONTH($G$3)>=AM$8,0,IF(Y17=0,AL17,Y17)+SUMIFS(预计变动!$F:$F,预计变动!$A:$A,$E17,预计变动!$B:$B,$F17,预计变动!$I:$I,">="&AM$9,预计变动!$I:$I,"<="&AM$10)) -> 0 | AN17: =IF(MONTH($G$3)>=AN$8,0,IF(Z17=0,AM17,Z17)+SUMIFS(预计变动!$F:$F,预计变动!$A:$A,$E17,预计变动!$B:$B,$F17,预计变动!$I:$I,">="&AN$9,预计变动!$I:$I,"<="&AN$10)) -> 0 | AO17: =IF(MONTH($G$3)>=AO$8,0,IF(AA17=0,AN17,AA17)+SUMIFS(预计变动!$F:$F,预计变动!$A:$A,$E17,预计变动!$B:$B,$F17,预计变动!$I:$I,">="&AO$9,预计变动!$I:$I,"<="&AO$10)) -> 0 | AP17: =IF(MONTH($G$3)>=AP$8,0,IF(AB17=0,AO17,AB17)+SUMIFS(预计变动!$F:$F,预计变动!$A:$A,$E17,预计变动!$B:$B,$F17,预计变动!$I:$I,">="&AP$9,预计变动!$I:$I,"<="&AP$10)) -> 0 | AQ17: =IF(MONTH($G$3)>=AQ$8,0,IF(AC17=0,AP17,AC17)+SUMIFS(预计变动!$F:$F,预计变动!$A:$A,$E17,预计变动!$B:$B,$F17,预计变动!$I:$I,">="&AQ$9,预计变动!$I:$I,"<="&AQ$10)) -> 0 | AR17: =IF(MONTH($G$3)>AR$8,0,IF(AD17=0,AQ17,AD17)+SUMIFS(预计变动!$F:$F,预计变动!$A:$A,$E17,预计变动!$B:$B,$F17,预计变动!$I:$I,">="&AR$9,预计变动!$I:$I,"<="&AR$10)) -> 8 | AS17: =IF(MONTH($G$3)>AS$8,0,IF(AE17=0,AR17,AE17)+SUMIFS(预计变动!$F:$F,预计变动!$A:$A,$E17,预计变动!$B:$B,$F17,预计变动!$I:$I,">="&AS$9,预计变动!$I:$I,"<="&AS$10)) -> 8 | AT17: =IF(MONTH($G$3)>AT$8,0,IF(AF17=0,AS17,AF17)+SUMIFS(预计变动!$F:$F,预计变动!$A:$A,$E17,预计变动!$B:$B,$F17,预计变动!$I:$I,">="&AT$9,预计变动!$I:$I,"<="&AT$10)) -> 8 | AU17: =BG17 -> 8 | AV17: =AT17+SUMIFS(预计变动!$F:$F,预计变动!$A:$A,$E17,预计变动!$B:$B,$F17,预计变动!$I:$I,">="&AV$9,预计变动!$I:$I,"<="&AV$10) -> 8 | AW17: =AV17+SUMIFS(预计变动!$F:$F,预计变动!$A:$A,$E17,预计变动!$B:$B,$F17,预计变动!$I:$I,">="&AW$9,预计变动!$I:$I,"<="&AW$10) -> 8 | AX17: =AW17+SUMIFS(预计变动!$F:$F,预计变动!$A:$A,$E17,预计变动!$B:$B,$F17,预计变动!$I:$I,">="&AX$9,预计变动!$I:$I,"<="&AX$10) -> 8 | AY17: =AX17+SUMIFS(预计变动!$F:$F,预计变动!$A:$A,$E17,预计变动!$B:$B,$F17,预计变动!$I:$I,">="&AY$9,预计变动!$I:$I,"<="&AY$10) -> 8 | AZ17: =AY17+SUMIFS(预计变动!$F:$F,预计变动!$A:$A,$E17,预计变动!$B:$B,$F17,预计变动!$I:$I,">="&AZ$9,预计变动!$I:$I,"<="&AZ$10) -> 8 | BA17: =AZ17+SUMIFS(预计变动!$F:$F,预计变动!$A:$A,$E17,预计变动!$B:$B,$F17,预计变动!$I:$I,">="&BA$9,预计变动!$I:$I,"<="&BA$10) -> 8 | BB17: =BA17+SUMIFS(预计变动!$F:$F,预计变动!$A:$A,$E17,预计变动!$B:$B,$F17,预计变动!$I:$I,">="&BB$9,预计变动!$I:$I,"<="&BB$10) -> 8 | BC17: =BB17+SUMIFS(预计变动!$F:$F,预计变动!$A:$A,$E17,预计变动!$B:$B,$F17,预计变动!$I:$I,">="&BC$9,预计变动!$I:$I,"<="&BC$10) -> 8 | BD17: =BC17+SUMIFS(预计变动!$F:$F,预计变动!$A:$A,$E17,预计变动!$B:$B,$F17,预计变动!$I:$I,">="&BD$9,预计变动!$I:$I,"<="&BD$10) -> 8 | ... BG17: =BF17+SUMIFS(预计变动!$F:$F,预计变动!$A:$A,$E17,预计变动!$B:$B,$F17,预计变动!$I:$I,">="&BG$9,预计变动!$I:$I,"<="&BG$10) -> 8
D18: XX 试验室 | E18: =IF(C18<>"",C18,E17) -> 创新中心 | F18: =IF(D18<>"",D18,"*") -> XX 试验室 | G18: =COUNTIFS(人员状况!$C:$C,$E18,人员状况!$D:$D,$F18,人员状况!$G:$G,"<="&G$10,人员状况!$H:$H,">="&G$10+1) -> 5 | H18: =COUNTIFS(人员状况!$C:$C,$E18,人员状况!$D:$D,$F18,人员状况!$G:$G,"<="&H$10,人员状况!$H:$H,">="&H$10+1) -> 5 | I18: =COUNTIFS(人员状况!$C:$C,$E18,人员状况!$D:$D,$F18,人员状况!$G:$G,"<="&I$10,人员状况!$H:$H,">="&I$10+1) -> 5 | J18: =COUNTIFS(人员状况!$C:$C,$E18,人员状况!$D:$D,$F18,人员状况!$G:$G,"<="&J$10,人员状况!$H:$H,">="&J$10+1) -> 5 | K18: =COUNTIFS(人员状况!$C:$C,$E18,人员状况!$D:$D,$F18,人员状况!$G:$G,"<="&K$10,人员状况!$H:$H,">="&K$10+1) -> 5 | L18: =COUNTIFS(人员状况!$C:$C,$E18,人员状况!$D:$D,$F18,人员状况!$G:$G,"<="&L$10,人员状况!$H:$H,">="&L$10+1) -> 5 | M18: =COUNTIFS(人员状况!$C:$C,$E18,人员状况!$D:$D,$F18,人员状况!$G:$G,"<="&M$10,人员状况!$H:$H,">="&M$10+1) -> 5 | N18: =COUNTIFS(人员状况!$C:$C,$E18,人员状况!$D:$D,$F18,人员状况!$G:$G,"<="&N$10,人员状况!$H:$H,">="&N$10+1) -> 5 | ... S18: =COUNTIFS(人员状况!$C:$C,$E18,人员状况!$D:$D,$F18,人员状况!$G:$G,"<="&S$10,人员状况!$H:$H,">="&S$10+1) -> 5 | T18: =AT18 -> 5 | U18: =COUNTIFS(人员状况!$C:$C,$E18,人员状况!$D:$D,$F18,人员状况!$G:$G,"<="&U$10,人员状况!$H:$H,">="&U$10+1) -> 5 | V18: =IF(MONTH($G$3)>=V$8,COUNTIFS(人员状况!$C:$C,$E18,人员状况!$D:$D,$F18,人员状况!$G:$G,"<="&V$10,人员状况!$H:$H,">="&V$10+1),0) -> 5 | W18: =IF(MONTH($G$3)>=W$8,COUNTIFS(人员状况!$C:$C,$E18,人员状况!$D:$D,$F18,人员状况!$G:$G,"<="&W$10,人员状况!$H:$H,">="&W$10+1),0) -> 5 | X18: =IF(MONTH($G$3)>=X$8,COUNTIFS(人员状况!$C:$C,$E18,人员状况!$D:$D,$F18,人员状况!$G:$G,"<="&X$10,人员状况!$H:$H,">="&X$10+1),0) -> 5 | Y18: =IF(MONTH($G$3)>=Y$8,COUNTIFS(人员状况!$C:$C,$E18,人员状况!$D:$D,$F18,人员状况!$G:$G,"<="&Y$10,人员状况!$H:$H,">="&Y$10+1),0) -> 5 | Z18: =IF(MONTH($G$3)>=Z$8,COUNTIFS(人员状况!$C:$C,$E18,人员状况!$D:$D,$F18,人员状况!$G:$G,"<="&Z$10,人员状况!$H:$H,">="&Z$10+1),0) -> 5 | AA18: =IF(MONTH($G$3)>=AA$8,COUNTIFS(人员状况!$C:$C,$E18,人员状况!$D:$D,$F18,人员状况!$G:$G,"<="&AA$10,人员状况!$H:$H,">="&AA$10+1),0) -> 5 | AB18: =IF(MONTH($G$3)>=AB$8,COUNTIFS(人员状况!$C:$C,$E18,人员状况!$D:$D,$F18,人员状况!$G:$G,"<="&AB$10,人员状况!$H:$H,">="&AB$10+1),0) -> 5 | AC18: =IF(MONTH($G$3)>=AC$8,COUNTIFS(人员状况!$C:$C,$E18,人员状况!$D:$D,$F18,人员状况!$G:$G,"<="&AC$10,人员状况!$H:$H,">="&AC$10+1),0) -> 5 | ... AG18: =IF(MONTH($G$3)>=AG$8,COUNTIFS(人员状况!$C:$C,$E18,人员状况!$D:$D,$F18,人员状况!$G:$G,"<="&AG$10,人员状况!$H:$H,">="&AG$10+1),0) -> 0 | AH18: =AT18 -> 5 | AI18: =IF(MONTH($G$3)>=AI$8,0,S18+SUMIFS(预计变动!$F:$F,预计变动!$A:$A,$E18,预计变动!$B:$B,$F18,预计变动!$I:$I,">="&AI$9,预计变动!$I:$I,"<="&AI$10)) -> 0 | AJ18: =IF(MONTH($G$3)>=AJ$8,0,IF(V18=0,AI18,V18)+SUMIFS(预计变动!$F:$F,预计变动!$A:$A,$E18,预计变动!$B:$B,$F18,预计变动!$I:$I,">="&AJ$9,预计变动!$I:$I,"<="&AJ$10)) -> 0 | AK18: =IF(MONTH($G$3)>=AK$8,0,IF(W18=0,AJ18,W18)+SUMIFS(预计变动!$F:$F,预计变动!$A:$A,$E18,预计变动!$B:$B,$F18,预计变动!$I:$I,">="&AK$9,预计变动!$I:$I,"<="&AK$10)) -> 0 | AL18: =IF(MONTH($G$3)>=AL$8,0,IF(X18=0,AK18,X18)+SUMIFS(预计变动!$F:$F,预计变动!$A:$A,$E18,预计变动!$B:$B,$F18,预计变动!$I:$I,">="&AL$9,预计变动!$I:$I,"<="&AL$10)) -> 0 | AM18: =IF(MONTH($G$3)>=AM$8,0,IF(Y18=0,AL18,Y18)+SUMIFS(预计变动!$F:$F,预计变动!$A:$A,$E18,预计变动!$B:$B,$F18,预计变动!$I:$I,">="&AM$9,预计变动!$I:$I,"<="&AM$10)) -> 0 | AN18: =IF(MONTH($G$3)>=AN$8,0,IF(Z18=0,AM18,Z18)+SUMIFS(预计变动!$F:$F,预计变动!$A:$A,$E18,预计变动!$B:$B,$F18,预计变动!$I:$I,">="&AN$9,预计变动!$I:$I,"<="&AN$10)) -> 0 | AO18: =IF(MONTH($G$3)>=AO$8,0,IF(AA18=0,AN18,AA18)+SUMIFS(预计变动!$F:$F,预计变动!$A:$A,$E18,预计变动!$B:$B,$F18,预计变动!$I:$I,">="&AO$9,预计变动!$I:$I,"<="&AO$10)) -> 0 | AP18: =IF(MONTH($G$3)>=AP$8,0,IF(AB18=0,AO18,AB18)+SUMIFS(预计变动!$F:$F,预计变动!$A:$A,$E18,预计变动!$B:$B,$F18,预计变动!$I:$I,">="&AP$9,预计变动!$I:$I,"<="&AP$10)) -> 0 | AQ18: =IF(MONTH($G$3)>=AQ$8,0,IF(AC18=0,AP18,AC18)+SUMIFS(预计变动!$F:$F,预计变动!$A:$A,$E18,预计变动!$B:$B,$F18,预计变动!$I:$I,">="&AQ$9,预计变动!$I:$I,"<="&AQ$10)) -> 0 | AR18: =IF(MONTH($G$3)>AR$8,0,IF(AD18=0,AQ18,AD18)+SUMIFS(预计变动!$F:$F,预计变动!$A:$A,$E18,预计变动!$B:$B,$F18,预计变动!$I:$I,">="&AR$9,预计变动!$I:$I,"<="&AR$10)) -> 5 | AS18: =IF(MONTH($G$3)>AS$8,0,IF(AE18=0,AR18,AE18)+SUMIFS(预计变动!$F:$F,预计变动!$A:$A,$E18,预计变动!$B:$B,$F18,预计变动!$I:$I,">="&AS$9,预计变动!$I:$I,"<="&AS$10)) -> 5 | AT18: =IF(MONTH($G$3)>AT$8,0,IF(AF18=0,AS18,AF18)+SUMIFS(预计变动!$F:$F,预计变动!$A:$A,$E18,预计变动!$B:$B,$F18,预计变动!$I:$I,">="&AT$9,预计变动!$I:$I,"<="&AT$10)) -> 5 | AU18: =BG18 -> 5 | AV18: =AT18+SUMIFS(预计变动!$F:$F,预计变动!$A:$A,$E18,预计变动!$B:$B,$F18,预计变动!$I:$I,">="&AV$9,预计变动!$I:$I,"<="&AV$10) -> 5 | AW18: =AV18+SUMIFS(预计变动!$F:$F,预计变动!$A:$A,$E18,预计变动!$B:$B,$F18,预计变动!$I:$I,">="&AW$9,预计变动!$I:$I,"<="&AW$10) -> 5 | AX18: =AW18+SUMIFS(预计变动!$F:$F,预计变动!$A:$A,$E18,预计变动!$B:$B,$F18,预计变动!$I:$I,">="&AX$9,预计变动!$I:$I,"<="&AX$10) -> 5 | AY18: =AX18+SUMIFS(预计变动!$F:$F,预计变动!$A:$A,$E18,预计变动!$B:$B,$F18,预计变动!$I:$I,">="&AY$9,预计变动!$I:$I,"<="&AY$10) -> 5 | AZ18: =AY18+SUMIFS(预计变动!$F:$F,预计变动!$A:$A,$E18,预计变动!$B:$B,$F18,预计变动!$I:$I,">="&AZ$9,预计变动!$I:$I,"<="&AZ$10) -> 5 | BA18: =AZ18+SUMIFS(预计变动!$F:$F,预计变动!$A:$A,$E18,预计变动!$B:$B,$F18,预计变动!$I:$I,">="&BA$9,预计变动!$I:$I,"<="&BA$10) -> 5 | BB18: =BA18+SUMIFS(预计变动!$F:$F,预计变动!$A:$A,$E18,预计变动!$B:$B,$F18,预计变动!$I:$I,">="&BB$9,预计变动!$I:$I,"<="&BB$10) -> 5 | BC18: =BB18+SUMIFS(预计变动!$F:$F,预计变动!$A:$A,$E18,预计变动!$B:$B,$F18,预计变动!$I:$I,">="&BC$9,预计变动!$I:$I,"<="&BC$10) -> 5 | BD18: =BC18+SUMIFS(预计变动!$F:$F,预计变动!$A:$A,$E18,预计变动!$B:$B,$F18,预计变动!$I:$I,">="&BD$9,预计变动!$I:$I,"<="&BD$10) -> 5 | ... BG18: =BF18+SUMIFS(预计变动!$F:$F,预计变动!$A:$A,$E18,预计变动!$B:$B,$F18,预计变动!$I:$I,">="&BG$9,预计变动!$I:$I,"<="&BG$10) -> 5
D19: XX 孵化业务 | E19: =IF(C19<>"",C19,E18) -> 创新中心 | F19: =IF(D19<>"",D19,"*") -> XX 孵化业务 | G19: =COUNTIFS(人员状况!$C:$C,$E19,人员状况!$D:$D,$F19,人员状况!$G:$G,"<="&G$10,人员状况!$H:$H,">="&G$10+1) -> 6 | H19: =COUNTIFS(人员状况!$C:$C,$E19,人员状况!$D:$D,$F19,人员状况!$G:$G,"<="&H$10,人员状况!$H:$H,">="&H$10+1) -> 6 | I19: =COUNTIFS(人员状况!$C:$C,$E19,人员状况!$D:$D,$F19,人员状况!$G:$G,"<="&I$10,人员状况!$H:$H,">="&I$10+1) -> 6 | J19: =COUNTIFS(人员状况!$C:$C,$E19,人员状况!$D:$D,$F19,人员状况!$G:$G,"<="&J$10,人员状况!$H:$H,">="&J$10+1) -> 6 | K19: =COUNTIFS(人员状况!$C:$C,$E19,人员状况!$D:$D,$F19,人员状况!$G:$G,"<="&K$10,人员状况!$H:$H,">="&K$10+1) -> 6 | L19: =COUNTIFS(人员状况!$C:$C,$E19,人员状况!$D:$D,$F19,人员状况!$G:$G,"<="&L$10,人员状况!$H:$H,">="&L$10+1) -> 6 | M19: =COUNTIFS(人员状况!$C:$C,$E19,人员状况!$D:$D,$F19,人员状况!$G:$G,"<="&M$10,人员状况!$H:$H,">="&M$10+1) -> 6 | N19: =COUNTIFS(人员状况!$C:$C,$E19,人员状况!$D:$D,$F19,人员状况!$G:$G,"<="&N$10,人员状况!$H:$H,">="&N$10+1) -> 6 | ... S19: =COUNTIFS(人员状况!$C:$C,$E19,人员状况!$D:$D,$F19,人员状况!$G:$G,"<="&S$10,人员状况!$H:$H,">="&S$10+1) -> 6 | T19: =AT19 -> 7 | U19: =COUNTIFS(人员状况!$C:$C,$E19,人员状况!$D:$D,$F19,人员状况!$G:$G,"<="&U$10,人员状况!$H:$H,">="&U$10+1) -> 7 | V19: =IF(MONTH($G$3)>=V$8,COUNTIFS(人员状况!$C:$C,$E19,人员状况!$D:$D,$F19,人员状况!$G:$G,"<="&V$10,人员状况!$H:$H,">="&V$10+1),0) -> 6 | W19: =IF(MONTH($G$3)>=W$8,COUNTIFS(人员状况!$C:$C,$E19,人员状况!$D:$D,$F19,人员状况!$G:$G,"<="&W$10,人员状况!$H:$H,">="&W$10+1),0) -> 6 | X19: =IF(MONTH($G$3)>=X$8,COUNTIFS(人员状况!$C:$C,$E19,人员状况!$D:$D,$F19,人员状况!$G:$G,"<="&X$10,人员状况!$H:$H,">="&X$10+1),0) -> 6 | Y19: =IF(MONTH($G$3)>=Y$8,COUNTIFS(人员状况!$C:$C,$E19,人员状况!$D:$D,$F19,人员状况!$G:$G,"<="&Y$10,人员状况!$H:$H,">="&Y$10+1),0) -> 6 | Z19: =IF(MONTH($G$3)>=Z$8,COUNTIFS(人员状况!$C:$C,$E19,人员状况!$D:$D,$F19,人员状况!$G:$G,"<="&Z$10,人员状况!$H:$H,">="&Z$10+1),0) -> 6 | AA19: =IF(MONTH($G$3)>=AA$8,COUNTIFS(人员状况!$C:$C,$E19,人员状况!$D:$D,$F19,人员状况!$G:$G,"<="&AA$10,人员状况!$H:$H,">="&AA$10+1),0) -> 6 | AB19: =IF(MONTH($G$3)>=AB$8,COUNTIFS(人员状况!$C:$C,$E19,人员状况!$D:$D,$F19,人员状况!$G:$G,"<="&AB$10,人员状况!$H:$H,">="&AB$10+1),0) -> 7 | AC19: =IF(MONTH($G$3)>=AC$8,COUNTIFS(人员状况!$C:$C,$E19,人员状况!$D:$D,$F19,人员状况!$G:$G,"<="&AC$10,人员状况!$H:$H,">="&AC$10+1),0) -> 7 | ... AG19: =IF(MONTH($G$3)>=AG$8,COUNTIFS(人员状况!$C:$C,$E19,人员状况!$D:$D,$F19,人员状况!$G:$G,"<="&AG$10,人员状况!$H:$H,">="&AG$10+1),0) -> 0 | AH19: =AT19 -> 7 | AI19: =IF(MONTH($G$3)>=AI$8,0,S19+SUMIFS(预计变动!$F:$F,预计变动!$A:$A,$E19,预计变动!$B:$B,$F19,预计变动!$I:$I,">="&AI$9,预计变动!$I:$I,"<="&AI$10)) -> 0 | AJ19: =IF(MONTH($G$3)>=AJ$8,0,IF(V19=0,AI19,V19)+SUMIFS(预计变动!$F:$F,预计变动!$A:$A,$E19,预计变动!$B:$B,$F19,预计变动!$I:$I,">="&AJ$9,预计变动!$I:$I,"<="&AJ$10)) -> 0 | AK19: =IF(MONTH($G$3)>=AK$8,0,IF(W19=0,AJ19,W19)+SUMIFS(预计变动!$F:$F,预计变动!$A:$A,$E19,预计变动!$B:$B,$F19,预计变动!$I:$I,">="&AK$9,预计变动!$I:$I,"<="&AK$10)) -> 0 | AL19: =IF(MONTH($G$3)>=AL$8,0,IF(X19=0,AK19,X19)+SUMIFS(预计变动!$F:$F,预计变动!$A:$A,$E19,预计变动!$B:$B,$F19,预计变动!$I:$I,">="&AL$9,预计变动!$I:$I,"<="&AL$10)) -> 0 | AM19: =IF(MONTH($G$3)>=AM$8,0,IF(Y19=0,AL19,Y19)+SUMIFS(预计变动!$F:$F,预计变动!$A:$A,$E19,预计变动!$B:$B,$F19,预计变动!$I:$I,">="&AM$9,预计变动!$I:$I,"<="&AM$10)) -> 0 | AN19: =IF(MONTH($G$3)>=AN$8,0,IF(Z19=0,AM19,Z19)+SUMIFS(预计变动!$F:$F,预计变动!$A:$A,$E19,预计变动!$B:$B,$F19,预计变动!$I:$I,">="&AN$9,预计变动!$I:$I,"<="&AN$10)) -> 0 | AO19: =IF(MONTH($G$3)>=AO$8,0,IF(AA19=0,AN19,AA19)+SUMIFS(预计变动!$F:$F,预计变动!$A:$A,$E19,预计变动!$B:$B,$F19,预计变动!$I:$I,">="&AO$9,预计变动!$I:$I,"<="&AO$10)) -> 0 | AP19: =IF(MONTH($G$3)>=AP$8,0,IF(AB19=0,AO19,AB19)+SUMIFS(预计变动!$F:$F,预计变动!$A:$A,$E19,预计变动!$B:$B,$F19,预计变动!$I:$I,">="&AP$9,预计变动!$I:$I,"<="&AP$10)) -> 0 | AQ19: =IF(MONTH($G$3)>=AQ$8,0,IF(AC19=0,AP19,AC19)+SUMIFS(预计变动!$F:$F,预计变动!$A:$A,$E19,预计变动!$B:$B,$F19,预计变动!$I:$I,">="&AQ$9,预计变动!$I:$I,"<="&AQ$10)) -> 0 | AR19: =IF(MONTH($G$3)>AR$8,0,IF(AD19=0,AQ19,AD19)+SUMIFS(预计变动!$F:$F,预计变动!$A:$A,$E19,预计变动!$B:$B,$F19,预计变动!$I:$I,">="&AR$9,预计变动!$I:$I,"<="&AR$10)) -> 7 | AS19: =IF(MONTH($G$3)>AS$8,0,IF(AE19=0,AR19,AE19)+SUMIFS(预计变动!$F:$F,预计变动!$A:$A,$E19,预计变动!$B:$B,$F19,预计变动!$I:$I,">="&AS$9,预计变动!$I:$I,"<="&AS$10)) -> 7 | AT19: =IF(MONTH($G$3)>AT$8,0,IF(AF19=0,AS19,AF19)+SUMIFS(预计变动!$F:$F,预计变动!$A:$A,$E19,预计变动!$B:$B,$F19,预计变动!$I:$I,">="&AT$9,预计变动!$I:$I,"<="&AT$10)) -> 7 | AU19: =BG19 -> 7 | AV19: =AT19+SUMIFS(预计变动!$F:$F,预计变动!$A:$A,$E19,预计变动!$B:$B,$F19,预计变动!$I:$I,">="&AV$9,预计变动!$I:$I,"<="&AV$10) -> 7 | AW19: =AV19+SUMIFS(预计变动!$F:$F,预计变动!$A:$A,$E19,预计变动!$B:$B,$F19,预计变动!$I:$I,">="&AW$9,预计变动!$I:$I,"<="&AW$10) -> 7 | AX19: =AW19+SUMIFS(预计变动!$F:$F,预计变动!$A:$A,$E19,预计变动!$B:$B,$F19,预计变动!$I:$I,">="&AX$9,预计变动!$I:$I,"<="&AX$10) -> 7 | AY19: =AX19+SUMIFS(预计变动!$F:$F,预计变动!$A:$A,$E19,预计变动!$B:$B,$F19,预计变动!$I:$I,">="&AY$9,预计变动!$I:$I,"<="&AY$10) -> 7 | AZ19: =AY19+SUMIFS(预计变动!$F:$F,预计变动!$A:$A,$E19,预计变动!$B:$B,$F19,预计变动!$I:$I,">="&AZ$9,预计变动!$I:$I,"<="&AZ$10) -> 7 | BA19: =AZ19+SUMIFS(预计变动!$F:$F,预计变动!$A:$A,$E19,预计变动!$B:$B,$F19,预计变动!$I:$I,">="&BA$9,预计变动!$I:$I,"<="&BA$10) -> 7 | BB19: =BA19+SUMIFS(预计变动!$F:$F,预计变动!$A:$A,$E19,预计变动!$B:$B,$F19,预计变动!$I:$I,">="&BB$9,预计变动!$I:$I,"<="&BB$10) -> 7 | BC19: =BB19+SUMIFS(预计变动!$F:$F,预计变动!$A:$A,$E19,预计变动!$B:$B,$F19,预计变动!$I:$I,">="&BC$9,预计变动!$I:$I,"<="&BC$10) -> 7 | BD19: =BC19+SUMIFS(预计变动!$F:$F,预计变动!$A:$A,$E19,预计变动!$B:$B,$F19,预计变动!$I:$I,">="&BD$9,预计变动!$I:$I,"<="&BD$10) -> 7 | ... BG19: =BF19+SUMIFS(预计变动!$F:$F,预计变动!$A:$A,$E19,预计变动!$B:$B,$F19,预计变动!$I:$I,">="&BG$9,预计变动!$I:$I,"<="&BG$10) -> 7
