Workbook

Sheet 资金预算汇总表
A1: 2018年（1）月资金预算表
A3: 项目 | B3: 集团预算合计 | C3: 集团实际发生金额 | D3: 集团差异(预算-实际） | E3: 执行率
A4: 一、账面资金余额 | B4: 24696154 | C4: 28751456
A5: 其中不可用金额 | B5: =SUM(B6:B9) -> 7122450.3 | C5: 6770493.3
A6: -银承保证金 | B6: 5881430.3 | C6: 5512314.3
A7: -支付宝不可提现余额 | B7: 240976.59 | C7: 235485.09
A8: -定期存款等其他不可使用资金 | B8: 1000000 | C8: 1000000
A9: -其他 | B9: 43.44 | C9: =C5-C6-C7-C8 -> 22693.86
A10: 期初银承敞口金额 | B10: 6588963.6 | C10: 6362339
A11: 二、期初可动用资金余额 | B11: =B4-B5 -> 17573704 | C11: 21980963 | D11: =D4-D6-D7-D8 -> 0
A12: 三、加：资金收入 | B12: =SUM(B13:B21) -> 2142397.1 | C12: =SUM(C13:C21) -> 1707699.5 | D12: =SUM(D13:D21) -> 434697.58 | E12: =C12/B12 -> 0.79709757
A13: 1、直营平台1组收款 | B13: =运营收款预算表!$I$8 -> 1647397.1 | C13: =运营收款预算表!$J$8 -> 452434.19 | D13: =B13-C13 -> 1194962.9 | E13: =C13/B13 -> 0.27463578
A14: 2、直营平台2组收款 | B14: =运营收款预算表!$I$14 -> 335000 | C14: =运营收款预算表!$J$14 -> 300647.21 | D14: =B14-C14 -> 34352.79 | E14: =C14/B14 -> 0.89745436
A15: 3、代销平台组收款 | B15: =运营收款预算表!$I$18 -> 160000 | C15: =运营收款预算表!$J$18 -> 0 | D15: =B15-C15 -> 160000 | E15: =C15/B15 -> 0
A16: 4、渠道组收款 | B16: =运营收款预算表!$I$28 -> 0 | C16: =运营收款预算表!$J$28 -> 0 | D16: =B16-C16 -> 0 | E16: =C16/B16 -> #DIV/0!
A17: 5、线下门店收款 | B17: =运营收款预算表!$I$29 -> 0 | C17: =运营收款预算表!$J$29 -> 0 | D17: =B17-C17 -> 0 | E17: =C17/B17 -> #DIV/0!
A18: 6、往来 | C18: =收款日报表!$G$151 -> 0 | E18: =C18/B18 -> #DIV/0!
A19: 7、其他 | C19: =收款日报表!$G$152+收款日报表!$G$153-12960-135534.5 -> 669083.6 | D19: =B19-C19 -> -669083.6 | E19: =C19/B19 -> #DIV/0!
A20: 8、收客户押金 | D20: =B20-C20 -> 0 | E20: =C20/B20 -> #DIV/0!
A21: 9、收各种保证金&押金(其他） | B21: =线下门店收款预算表!$F$31 -> 0 | C21: =150000+135534.5 -> 285534.5 | D21: =B21-C21 -> -285534.5 | E21: =C21/B21 -> #DIV/0!
A22: 四、可供使用资金： | B22: =B11+B12 -> 19716101 | C22: =C11+C12 -> 23688663 | D22: =D11+D12 -> 434697.58 | E22: =C22/B22 -> 1.2014882
A23: 五、减：资金支出 | B23: =B24+B28+SUM(B31:B46) -> #REF! | C23: =C24+C28+SUM(C31:C46) -> #REF! | D23: =SUM(D24:D45) -> #REF! | E23: =C23/B23 -> #REF!
A24: 1、供应商货款（采购）-电汇 | B24: =供应商货款!$J$12 -> 0 | C24: =货款付款统计表!$F$21-供应商货款!#REF! -> #REF! | D24: =B24-C24 -> #REF! | E24: =C24/B24 -> #REF!
A25: 供应商货款（采购）-票面金额 | B25: =供应商货款!$K$12 -> 0 | C25: =货款付款统计表!$G$21 -> 0 | D25: =B25-C25 -> 0 | E25: =C25/B25 -> #DIV/0!
A26: -保证金 | B26: =B25*0.5 -> 0 | C26: =应付票据明细!$C$5 -> 654098.68 | D26: =B26-C26 -> -654098.68 | E26: =C26/B26 -> #DIV/0!
A27: -敞口 | B27: =B25-B26 -> 0 | C27: =应付票据明细!$C$6 -> 654098.67 | D27: =B27-C27 -> -654098.67 | E27: =C27/B27 -> #DIV/0!
A28: 本月到期实际支付银承 | B28: =应付票据明细!$D$4 -> 712456.77 | C28: =C29+C30 -> 712456.77 | D28: =B28-C28 -> 0 | E28: =C28/B28 -> 1
A29: -保证金 | B29: =应付票据明细!$D$5 -> 284982.71 | C29: =应付票据明细!$D$5 -> 284982.71 | D29: =B29-C29 -> 0 | E29: =C29/B29 -> 1
A30: -敞口 | B30: =应付票据明细!$D$6 -> 427474.06 | C30: =应付票据明细!$D$6 -> 427474.06 | D30: =B30-C30 -> 0 | E30: =C30/B30 -> 1
A31: 2、工资、五险一金 | B31: =人力资源部!$C$27 -> 1536759.1 | C31: =人力资源部!$D$27 -> 1579373.6 | D31: =B31-C31 -> -42614.52 | E31: =C31/B31 -> 1.0277301
A32: 3、办公室租金（物业&水电） | B32: =人力资源部!$C$28 -> 221000 | C32: =人力资源部!$D$28 -> 215756.54 | D32: =B32-C32 -> 5243.46 | E32: =C32/B32 -> 0.97627394
A33: 4、站内推广 | B33: =电商!$D$13+#REF!+#REF! -> #REF! | C33: =电商!$E$13+#REF!+#REF! -> #REF! | D33: =B33-C33 -> #REF! | E33: =C33/B33 -> #REF!
A34: 5、站外推广 | B34: =电商!$D$20+#REF! -> #REF! | C34: =电商!$E$20+#REF! -> #REF! | D34: =B34-C34 -> #REF! | E34: =C34/B34 -> #REF!
A35: 6、品牌推广 | B35: =市场部!$B$3+市场部!$B$4+市场部!$B$5+市场部!$B$6 -> 1390 | C35: =市场部!$C$3+市场部!$C$4+市场部!$C$5+市场部!$C$6 -> 1390 | D35: =B35-C35 -> 0 | E35: =C35/B35 -> 1
A36: 7、平台费用（天猫&京东、聚划算、淘宝客） | B36: =电商!$D$23+#REF! -> #REF! | C36: =电商!$E$23+#REF!+85992.32 -> #REF! | D36: =B36-C36 -> #REF! | E36: =C36/B36 -> #REF!
A37: 8、外包客服费用 | B37: =财务部!C17 -> 159500 | C37: =财务部!$D$17 -> 160172 | D37: =B37-C37 -> -672 | E37: =C37/B37 -> 1.0042132
A38: 9、外包仓储费（科捷、菜鸟、唯品会） | B38: =财务部!$C$13+财务部!$C$15+财务部!$C$16 -> 111361.14 | C38: =财务部!$D$13+财务部!$D$15+财务部!$D$16 -> 126011.39 | D38: =B38-C38 -> -14650.25 | E38: =C38/B38 -> 1.1315562
A39: 10、税金 | B39: =财务部!$C$5+财务部!$C$6+财务部!$C$7+财务部!$C$8+财务部!$C$9+财务部!$C$10 -> 1552949 | C39: =财务部!$D$5+财务部!$D$6+财务部!$D$7+财务部!$D$8+财务部!$D$9+财务部!$D$10 -> 1552949 | D39: =B39-C39 -> 0 | E39: =C39/B39 -> 1 | G39: 预算 | H39: 实际 | I39: 检验
A40: 11、线下门店费用类支出 | B40: =线下销售部!$C$9 -> 262900 | C40: =线下销售部!$D$9 -> 268001.23 | D40: =B40-C40 -> -5101.23 | E40: =C40/B40 -> 1.0194037 | F40: 供应商 | G40: =供应商货款!$L$12 -> 0 | H40: =供应商货款!$M$12 -> 0 | I40: =IF(C24=H40,0,H40-C24) -> #REF!
A41: 12、线下门店保证金、押金支出 | B41: =线下销售部!$C$18 -> 20000 | C41: =线下销售部!$D$18 -> 0 | D41: =B41-C41 -> 20000 | E41: =C41/B41 -> 0 | F41: 所有费用 | G41: =人力资源部!$C$26+财务部!$C$26+电商!$D$28+#REF!+#REF!+#REF!+线下销售部!$C$31+市场部!$B$11+电商设计部!$B$8+产品设计部!$B$9+采购部!$B$7+#REF!+#REF!+行政部!$B$8 -> #REF! | H41: =C23-C28-C36-C24 -> #REF! | I41: =IF(H41=H42,0,H41-H42) -> #REF!
...

Sheet 运营整体预算执行情况
A1: 20XX年（X）月运营预算执行情况
A2: 部门 | B2: 客户/平台/店铺 | C2: 负责人 | D2: 收款 | F2: 销售额（含税） | H2: 推广费 | J2: 销售推广占比 | M2: 注：推广费仅包含钻展、直通车、品销宝和聚划算参团服务费，淘宝客等站内推广及其他站外推广金额较小，未计入核算
D3: 预算 | E3: 实际 | F3: 预算 | G3: 实际 | H3: 预算 | I3: 实际 | J3: 预算 | K3: 实际
A4: 自营平台1组 | B4: 天猫旗舰店 | C4: XXX | D4: =运营收款预算表!$I$3 -> 1344797.1 | E4: =运营收款预算表!$J$3 -> 0 | F4: 1100000 | G4: 1555733 | H4: =电商!$D$13+电商!$D$20 -> 0 | I4: 319579.62 | J4: =H4/F4 -> 0 | K4: =I4/G4 -> 0.20542061
B5: 淘宝自营店 | D5: =运营收款预算表!I4 -> 188600 | E5: =运营收款预算表!$J$4 -> 272666.15 | F5: 160000 | G5: 292668.68
B6: 天猫专卖店 | D6: =运营收款预算表!I5 -> 114000 | E6: =运营收款预算表!$J$5 -> 115053.26 | F6: 110000 | G6: 117364.61
B7: 有货 | E7: 64714.78
B8: 合 计 | D8: =SUM(D4:D7) -> 1647397.1 | E8: =SUM(E4:E7) -> 452434.19 | F8: =SUM(F4:F7) -> 1370000 | G8: =SUM(G4:G7) -> 1965766.3 | H8: =SUM(H4:H7) -> 0 | I8: =SUM(I4:I7) -> 319579.62
A9: 完成率 | D9: =E8/D8 -> 0.27463578 | F9: =G8/F8 -> 1.4348659 | H9: =I8/H8 -> #DIV/0!
A11: 部门 | B11: 客户/平台/店铺 | C11: 负责人 | D11: 收款 | F11: 销售额（含税） | H11: 推广费 | J11: 销售推广占比
D12: 预算 | E12: 实际 | F12: 预算 | G12: 实际 | H12: 预算 | I12: 实际 | J12: 预算 | K12: 实际
A13: 自营平台2组 | B13: 淘宝小店 | C13: XXX | D13: =运营收款预算表!I9 -> 120000 | E13: =运营收款预算表!$J$9 -> 116770.2 | F13: 100000 | G13: 98709.72 | H13: =#REF! -> #REF! | I13: 14113 | J13: =H13/(F13+F15) -> #REF! | K13: =I13/(G13+G15) -> 0.090818321
B14: 网易考拉 | D14: =运营收款预算表!I10 -> 150000 | E14: =运营收款预算表!$J$10 -> 121264.23 | F14: 100000 | G14: 124456.18
B15: 京东POP | D15: =运营收款预算表!I11 -> 50000 | E15: =运营收款预算表!$J$11 -> 60772.78 | F15: 30000 | G15: 56688.44
B16: 有赞 | E16: =运营收款预算表!$J$13 -> 1840 | F16: 15000 | G16: 5672.93
B17: 合 计 | D17: =SUM(D13:D16) -> 320000 | E17: =SUM(E13:E16) -> 300647.21 | F17: =SUM(F13:F16) -> 245000 | G17: =SUM(G13:G16) -> 285527.27
A18: 完成率 | D18: =E17/D17 -> 0.93952253 | F18: =G17/F17 -> 1.1654174 | H18: =I13/H13 -> #REF!
A20: 部门 | B20: 客户/平台/店铺 | C20: 负责人 | D20: 收款 | F20: 销售额 | H20: 推广费 | J20: 销售推广占比
D21: 预算 | E21: 实际 | F21: 预算 | G21: 实际 | H21: 预算 | I21: 实际 | J21: 预算 | K21: 实际
A22: 代销平台组 | B22: 京东自营 | C22: XXX | D22: =运营收款预算表!I15 -> 0 | E22: =运营收款预算表!$J$15 -> 0 | F22: 300000 | G22: 251043.42 | H22: 20000 | I22: 22827.76 | J22: =H22/F22 -> 0.066666667 | K22: =I22/G22 -> 0.090931521
B23: 唯品会 | D23: =运营收款预算表!I16 -> 160000 | E23: =运营收款预算表!$J$16 -> 0 | F23: 250000 | G23: 149165.8
B24: 合 计 | D24: =SUM(D22:D23) -> 160000 | E24: =SUM(E22:E23) -> 0 | F24: =SUM(F22:F23) -> 550000 | G24: =SUM(G22:G23) -> 400209.22 | H24: =SUM(H22:H23) -> 20000 | I24: =SUM(I22:I23) -> 22827.76
A25: 完成率 | D25: =E24/D24 -> 0 | F25: =G24/F24 -> 0.72765313 | H25: =I24/H24 -> 1.141388
A27: 部门 | B27: 客户/平台/店铺 | C27: 负责人 | D27: 收款
D28: 预算 | E28: 实际
A29: 渠道组 | B29: 分销 | C29: XXX | D29: =运营收款预算表!I28 -> 0 | E29: =运营收款预算表!$J$28 -> 0
A30: 完成率 | D30: =E29/D29 -> #DIV/0!
A32: 部门 | B32: 客户/平台/店铺 | C32: 负责人 | D32: 收款 | F32: 费用 | H32: 费用销售占比
D33: 预算 | E33: 实际 | F33: 预算 | G33: 实际 | H33: 预算 | I33: 实际
A34: 线下店铺 | B34: 线下门店 | C34: XXX | D34: =线下门店收款预算表!$G$31 -> 0 | E34: =运营收款预算表!$J$29 -> 0 | F34: =线下销售部!$C$31 -> 329665.2 | G34: =线下销售部!$D$31 -> 380050.01 | H34: =F34/D34 -> #DIV/0! | I34: =G34/E34 -> #DIV/0!
A35: 完成率 | D35: =E34/D34 -> #DIV/0! | F35: =G34/F34 -> 1.1528363

Sheet 运营收款预算表
A1: 2018年（1）月收款预算表
A2: 部门 | B2: 收款主体 | C2: 客户代码 | D2: 客户/平台/店铺 | E2: 负责人 | F2: 结算期 | G2: 结算方式 | H2: 币别 | I2: 预算收入货款 | J2: 实际 | K2: 预算-实际 | L2: 回款完成率
A3: 电商运营部 | C3: 1001 | D3: 天猫店 | E3: 81 | F3: 实时结算 | G3: 支付宝转账 | H3: 人民币 | I3: 1344797.1 | J3: =SUMIF(收款日报表!$D$3:$D$148,运营收款预算表!C3,收款日报表!$G$3:$G$148) -> 0 | K3: =I3-J3 -> 1344797.1 | L3: =IFERROR(J3/I3,"") -> 0
C4: 1002 | D4: 淘宝主店 | E4: 81 | F4: 实时结算 | G4: 支付宝转账 | H4: 人民币 | I4: 188600 | J4: =收款日报表!$G$4 -> 272666.15 | K4: =I4-J4 -> -84066.15 | L4: =IFERROR(J4/I4,"") -> 1.4457378
C5: 1003 | D5: 京东POP店 | E5: 81 | F5: 实时结算 | H5: 人民币 | I5: 114000 | J5: =收款日报表!$G$6 -> 115053.26 | K5: =I5-J5 -> -1053.26 | L5: =IFERROR(J5/I5,"") -> 1.0092391
C6: 1004 | D6: 有赞 | E6: 81 | J6: =收款日报表!G14 -> 64714.78 | K6: =I6-J6 -> -64714.78 | L6: =IFERROR(J6/I6,"")
C7: 1005 | D7: 拼多多 | E7: 81 | J7: =收款日报表!G15 -> 0 | K7: =I7-J7 -> 0 | L7: =IFERROR(J7/I7,"")
D8: 小计 | I8: =SUM(I3:I7) -> 1647397.1 | J8: =SUM(J3:J7) -> 452434.19 | K8: =SUM(K3:K7) -> 1194962.9 | L8: =IFERROR(J8/I8,"") -> 0.27463578
A9: 野球帝自媒体 | C9: 2001 | F9: 实时结算 | G9: 支付宝转账 | H9: 人民币 | I9: 120000 | J9: =收款日报表!$G$8 -> 116770.2 | K9: =I9-J9 -> 3229.8 | L9: =IFERROR(J9/I9,"") -> 0.973085
C10: 2002 | F10: 实时结算 | G10: 支付宝转账 | H10: 人民币 | I10: 150000 | J10: =收款日报表!$G$9 -> 121264.23 | K10: =I10-J10 -> 28735.77 | L10: =IFERROR(J10/I10,"") -> 0.8084282
C11: 2003 | F11: 实时结算 | G11: 支付宝转账 | H11: 人民币 | I11: 50000 | J11: =收款日报表!$G$7 -> 60772.78 | K11: =I11-J11 -> -10772.78 | L11: =IFERROR(J11/I11,"") -> 1.2154556
C12: 2004 | K12: =I12-J12 -> 0 | L12: =IFERROR(J12/I12,"")
C13: 2005 | F13: 实时结算 | G13: 支付宝转账 | H13: 人民币 | I13: 15000 | J13: =SUMIF(收款日报表!$D$3:$D$148,运营收款预算表!C13,收款日报表!$G$3:$G$148)+收款日报表!$G$10 -> 1840 | K13: =I13-J13 -> 13160 | L13: =IFERROR(J13/I13,"") -> 0.12266667
D14: 小计 | I14: =SUM(I9:I13) -> 335000 | J14: =SUM(J9:J13) -> 300647.21 | K14: =SUM(K9:K13) -> 34352.79 | L14: =IFERROR(J14/I14,"") -> 0.89745436
A15: 线下场馆 | C15: 3001 | F15: 下月初回款 | G15: 银行汇款 | H15: 人民币 | I15: 0 | J15: =SUMIF(收款日报表!$D$3:$D$148,运营收款预算表!C15,收款日报表!$G$3:$G$148) -> 0 | K15: =I15-J15 -> 0 | L15: =IFERROR(J15/I15,"")
C16: 3002 | F16: 下月初回款 | G16: 银行汇款 | H16: 人民币 | I16: 160000 | J16: =SUMIF(收款日报表!$D$3:$D$148,运营收款预算表!C16,收款日报表!$G$3:$G$148) -> 0 | K16: =I16-J16 -> 160000 | L16: =IFERROR(J16/I16,"") -> 0
C17: 3003 | L17: =IFERROR(J17/I17,"")
D18: 小计 | I18: =SUM(I15:I17) -> 160000 | J18: =SUM(J15:J17) -> 0 | K18: =SUM(K15:K17) -> 160000 | L18: =IFERROR(J18/I18,"") -> 0
A19: 渠道组 | C19: 4001 | H19: 人民币 | J19: =SUMIF(收款日报表!$D$3:$D$148,运营收款预算表!C19,收款日报表!$G$3:$G$148) -> 0 | K19: =I19-J19 -> 0 | L19: =IFERROR(J19/I19,"")
C20: 4002 | H20: 人民币 | J20: =SUMIF(收款日报表!$D$3:$D$148,运营收款预算表!C20,收款日报表!$G$3:$G$148) -> 0 | K20: =I20-J20 -> 0 | L20: =IFERROR(J20/I20,"")
C21: 4003 | H21: 人民币 | J21: =SUMIF(收款日报表!$D$3:$D$148,运营收款预算表!C21,收款日报表!$G$3:$G$148) -> 0 | K21: =I21-J21 -> 0 | L21: =IFERROR(J21/I21,"")
C22: 4004 | H22: 人民币 | J22: =SUMIF(收款日报表!$D$3:$D$148,运营收款预算表!C22,收款日报表!$G$3:$G$148) -> 0 | K22: =I22-J22 -> 0 | L22: =IFERROR(J22/I22,"")
D23: 小计 | H23: 人民币 | I23: =SUM(I19:I22) -> 0 | J23: =SUM(J19:J22) -> 0 | K23: =SUM(K19:K22) -> 0 | L23: =IFERROR(J23/I23,"")
A24: 商务组 | C24: 5001 | H24: 人民币 | J24: =SUMIF(收款日报表!$D$3:$D$148,运营收款预算表!C24,收款日报表!$G$3:$G$148) -> 0 | K24: =I24-J24 -> 0 | L24: =IFERROR(J24/I24,"")
C25: 5002 | H25: 人民币 | I25: 220000 | J25: =SUMIF(收款日报表!$D$3:$D$148,运营收款预算表!C25,收款日报表!$G$3:$G$148) -> 0 | K25: =I25-J25 -> 220000 | L25: =IFERROR(J25/I25,"") -> 0
D26: 小计 | I26: =SUM(I24:I25) -> 220000 | J26: =SUM(J24:J25) -> 0 | K26: =SUM(K24:K25) -> 220000 | L26: =IFERROR(J26/I26,"") -> 0
A27: 其他 | C27: 6001 | H27: 人民币 | J27: =SUMIF(收款日报表!$D$3:$D$148,运营收款预算表!C27,收款日报表!$G$3:$G$148) -> 0 | K27: =I27-J27 -> 0 | L27: =IFERROR(J27/I27,"")
D28: 小 计 | I28: =SUM(I27) -> 0 | J28: =SUM(J27) -> 0 | K28: =SUM(K27) -> 0 | L28: =IFERROR(J28/I28,"")
A29: 线下店铺 | C29: 8888 | D29: 线下门店 | H29: 人民币 | I29: =线下门店收款预算表!G31 -> 0 | J29: =SUMIF(收款日报表!$D$3:$D$148,运营收款预算表!C29,收款日报表!$G$3:$G$148) -> 0 | K29: =I29-J29 -> 0 | L29: =IFERROR(J29/I29,"")
A30: 合 计 | I30: =$I$8+$I$14+$I$18+$I$28+$I$29+I23+I26 -> 2362397.1 | J30: =$I$8+$I$14+$I$18+$I$28+$I$29+J23+J26 -> 2142397.1 | K30: =$I$8+$I$14+$I$18+$I$28+$I$29+K23+K26 -> 2362397.1 | L30: =IFERROR(J30/I30,"") -> 0.90687425

Sheet 供应商货款
A1: 20xx年（xx）月供应商货款支付预算
A3: 月份 | B3: 序 号 | C3: 支付 公司 | D3: 供应商编码 | E3: 供应商 简称 | F3: 采购员 | G3: 采购内容 | H3: 付款条件 | I3: 入库月份 | J3: 预算支付金额 | M3: 实际支付 | P3: 执行率 | Q3: 备注
J4: 电汇 | K4: 承兑 | L4: 小计 | M4: 电汇 | N4: 承兑 | O4: 小计
A5: 1月 | B5: 1 | M5: =SUMIF(货款付款统计表!$C$4:$C$20,供应商货款!D5,货款付款统计表!$F$4:$F$20) -> 0 | N5: =SUMIF(货款付款统计表!C4:C20,D5,货款付款统计表!G4:G20) -> 0 | O5: =M5+N5 -> 0 | P5: =O5/L5 -> #DIV/0!
B6: 2 | M6: =SUMIF(货款付款统计表!$C$4:$C$20,供应商货款!D6,货款付款统计表!$F$4:$F$20) -> 0 | N6: =SUMIF(货款付款统计表!C5:C21,D6,货款付款统计表!G5:G21) -> 0 | O6: =M6+N6 -> 0 | P6: =O6/L6 -> #DIV/0!
B7: 3 | M7: =SUMIF(货款付款统计表!$C$4:$C$20,供应商货款!D7,货款付款统计表!$F$4:$F$20) -> 0 | N7: =SUMIF(货款付款统计表!C6:C22,D7,货款付款统计表!G6:G22) -> 0 | O7: =M7+N7 -> 0 | P7: =O7/L7 -> #DIV/0!
B8: 4 | M8: =SUMIF(货款付款统计表!$C$4:$C$20,供应商货款!D8,货款付款统计表!$F$4:$F$20) -> 0 | N8: =SUMIF(货款付款统计表!C7:C23,D8,货款付款统计表!G7:G23) -> 0 | O8: =M8+N8 -> 0 | P8: =O8/L8 -> #DIV/0!
B9: 5 | M9: =SUMIF(货款付款统计表!$C$4:$C$20,供应商货款!D9,货款付款统计表!$F$4:$F$20) -> 0 | N9: =SUMIF(货款付款统计表!C8:C24,D9,货款付款统计表!G8:G24) -> 0 | O9: =M9+N9 -> 0 | P9: =O9/L9 -> #DIV/0!
L10: =J10+K10 -> 0 | M10: =SUMIF(货款付款统计表!$C$4:$C$20,供应商货款!D10,货款付款统计表!$H$4:$H$20) -> 0 | N10: =SUMIF(货款付款统计表!C21:C40,D10,货款付款统计表!G21:G40) -> 0 | O10: =M10+N10 -> 0 | P10: =O10/L10 -> #DIV/0!
L11: =J11+K11 -> 0 | M11: =SUMIF(货款付款统计表!$C$4:$C$20,供应商货款!D11,货款付款统计表!$H$4:$H$20) -> 0 | N11: =SUMIF(货款付款统计表!C21:C41,D11,货款付款统计表!G21:G41) -> 0 | O11: =M11+N11 -> 0 | P11: =O11/L11 -> #DIV/0!
B12: 合 计 | J12: =SUM(J5:J11) -> 0 | K12: =SUM(K5:K11) -> 0 | L12: =SUM(L5:L11) -> 0 | M12: =SUM(M5:M11) -> 0 | N12: =SUM(N5:N11) -> 0 | O12: =SUM(O5:O11) -> 0 | P12: =O12/L12 -> #DIV/0!
M13: =M12-货款付款统计表!F21 -> 0 | N13: =N12-货款付款统计表!G21 -> 0 | O13: =O12-货款付款统计表!H21 -> 0
M15: 电汇部分货款执行率
M16: =(M12-#REF!)/J12 -> #REF!

Sheet 应付票据明细
A1: 2018年应付票据汇总 | G1: 月份
G2: 1
B3: 期初余额 | C3: 本期增加 | D3: 本期减少（到期票据） | E3: 期末余额
A4: 票面金额 | B4: 11874653 | C4: =SUMIF(F:F,$G$2,I:I) -> 1308197.4 | D4: =SUMIF(H11:H502,G2,I11:I502) -> 712456.77 | E4: =B4+C4-D4 -> 12470394
A5: 保证金 | B5: 5512314.3 | C5: =SUMIF(F11:F502,G2,J11:J502) -> 654098.68 | D5: =SUMIF(H11:H502,G2,J11:J502) -> 284982.71 | E5: =B5+C5-D5 -> 5881430.3
A6: 敞口 | B6: 6362339 | C6: =C4-C5 -> 654098.67 | D6: =D4-D5 -> 427474.06 | E6: =E4-E5 -> 6588963.6
C7: =C4-货款付款统计表!$G$21 -> 1308197.4
A9: 应付票据明细表
A10: 序号 | B10: 开票银行 | C10: 出票单位 | D10: 票据号 | E10: 出票日期 | F10: 出票月份 | G10: 到期日期 | H10: 到期月份 | I10: 票据金额 | J10: 支付保证金 | K10: 敞口金额 | L10: 支付供应商 | M10: 支付日期 | N10: 备注
A11: 44 | B11: 兴业银行深圳中心区支行 | E11: 43020 | F11: =MONTH(E11) -> 10 | G11: 43202 | H11: =MONTH(G11) -> 4 | I11: 200000 | J11: 2711000 | K11: 2710356
A12: 45 | B12: 兴业银行深圳中心区支行 | E12: 43020 | F12: =MONTH(E12) -> 10 | G12: 43202 | H12: =MONTH(G12) -> 4 | I12: 200000
A13: 46 | B13: 兴业银行深圳中心区支行 | E13: 43020 | F13: =MONTH(E13) -> 10 | G13: 43202 | H13: =MONTH(G13) -> 4 | I13: 200000
A14: 47 | B14: 兴业银行深圳中心区支行 | E14: 43020 | F14: =MONTH(E14) -> 10 | G14: 43202 | H14: =MONTH(G14) -> 4 | I14: 200000
A15: 48 | B15: 兴业银行深圳中心区支行 | E15: 43020 | F15: =MONTH(E15) -> 10 | G15: 43202 | H15: =MONTH(G15) -> 4 | I15: 200000
A16: 49 | B16: 兴业银行深圳中心区支行 | E16: 43020 | F16: =MONTH(E16) -> 10 | G16: 43202 | H16: =MONTH(G16) -> 4 | I16: 200000
A17: 50 | B17: 兴业银行深圳中心区支行 | E17: 43020 | F17: =MONTH(E17) -> 10 | G17: 43202 | H17: =MONTH(G17) -> 4 | I17: 200000
A18: 51 | B18: 兴业银行深圳中心区支行 | E18: 43020 | F18: =MONTH(E18) -> 10 | G18: 43202 | H18: =MONTH(G18) -> 4 | I18: 200000
A19: 52 | B19: 兴业银行深圳中心区支行 | E19: 43020 | F19: =MONTH(E19) -> 10 | G19: 43202 | H19: =MONTH(G19) -> 4 | I19: 144241
A20: 53 | B20: 兴业银行深圳中心区支行 | E20: 43020 | F20: =MONTH(E20) -> 10 | G20: 43202 | H20: =MONTH(G20) -> 4 | I20: 200000
A21: 54 | B21: 兴业银行深圳中心区支行 | E21: 43020 | F21: =MONTH(E21) -> 10 | G21: 43202 | H21: =MONTH(G21) -> 4 | I21: 200000
A22: 55 | B22: 兴业银行深圳中心区支行 | E22: 43020 | F22: =MONTH(E22) -> 10 | G22: 43202 | H22: =MONTH(G22) -> 4 | I22: 200000
A23: 56 | B23: 兴业银行深圳中心区支行 | E23: 43020 | F23: =MONTH(E23) -> 10 | G23: 43202 | H23: =MONTH(G23) -> 4 | I23: 200000
... A26: 59 | B26: 兴业银行深圳中心区支行 | E26: 43020 | F26: =MONTH(E26) -> 10 | G26: 43202 | H26: =MONTH(G26) -> 4 | I26: 200000
A27: 60 | B27: 中行深圳宝安支行 | E27: 43034 | F27: =MONTH(E27) -> 10 | G27: 43123 | H27: =MONTH(G27) -> 1 | I27: 112456.77 | J27: 284982.71 | K27: 427474.06
A28: 61 | B28: 中行深圳宝安支行 | E28: 43034 | F28: =MONTH(E28) -> 10 | G28: 43123 | H28: =MONTH(G28) -> 1 | I28: 200000
A29: 62 | B29: 中行深圳宝安支行 | E29: 43034 | F29: =MONTH(E29) -> 10 | G29: 43123 | H29: =MONTH(G29) -> 1 | I29: 200000
A30: 63 | B30: 中行深圳宝安支行 | E30: 43034 | F30: =MONTH(E30) -> 10 | G30: 43123 | H30: =MONTH(G30) -> 1 | I30: 200000
A31: 64 | B31: 杭州银行深圳科技支行 | E31: 43039 | F31: =MONTH(E31) -> 10 | G31: 43220 | H31: =MONTH(G31) -> 4 | I31: 100000 | J31: 1099976.9 | K31: 1099976.9
A32: 65 | B32: 杭州银行深圳科技支行 | E32: 43039 | F32: =MONTH(E32) -> 10 | G32: 43220 | H32: =MONTH(G32) -> 4 | I32: 100000
A33: 66 | B33: 杭州银行深圳科技支行 | E33: 43039 | F33: =MONTH(E33) -> 10 | G33: 43220 | H33: =MONTH(G33) -> 4 | I33: 100000
A34: 67 | B34: 杭州银行深圳科技支行 | E34: 43039 | F34: =MONTH(E34) -> 10 | G34: 43220 | H34: =MONTH(G34) -> 4 | I34: 100000
A35: 68 | B35: 杭州银行深圳科技支行 | E35: 43039 | F35: =MONTH(E35) -> 10 | G35: 43220 | H35: =MONTH(G35) -> 4 | I35: 100000
A36: 69 | B36: 杭州银行深圳科技支行 | E36: 43039 | F36: =MONTH(E36) -> 10 | G36: 43220 | H36: =MONTH(G36) -> 4 | I36: 129434
A37: 70 | B37: 杭州银行深圳科技支行 | E37: 43039 | F37: =MONTH(E37) -> 10 | G37: 43220 | H37: =MONTH(G37) -> 4 | I37: 100000
A38: 71 | B38: 杭州银行深圳科技支行 | E38: 43039 | F38: =MONTH(E38) -> 10 | G38: 43220 | H38: =MONTH(G38) -> 4 | I38: 760661.84
A39: 72 | B39: 杭州银行深圳科技支行 | E39: 43039 | F39: =MONTH(E39) -> 10 | G39: 43220 | H39: =MONTH(G39) -> 4 | I39: 90607
A40: 73 | B40: 杭州银行深圳科技支行 | E40: 43039 | F40: =MONTH(E40) -> 10 | G40: 43220 | H40: =MONTH(G40) -> 4 | I40: 100000
A41: 74 | B41: 杭州银行深圳科技支行 | E41: 43039 | F41: =MONTH(E41) -> 10 | G41: 43220 | H41: =MONTH(G41) -> 4 | I41: 100000
A42: 75 | B42: 杭州银行深圳科技支行 | E42: 43039 | F42: =MONTH(E42) -> 10 | G42: 43220 | H42: =MONTH(G42) -> 4 | I42: 19251
A43: 76 | B43: 杭州银行深圳科技支行 | E43: 43039 | F43: =MONTH(E43) -> 10 | G43: 43220 | H43: =MONTH(G43) -> 4 | I43: 100000
...

Sheet 线下门店收款预算表
A1: 20XX年（X）月线下门店收款预算表
A3: 店铺模式 | B3: 店铺名称 | C3: 收款主体 | D3: 1月
D4: 预算数 | H4: 执行数 | L4: 执行率
D5: 销售收入金额 | E5: 收回保证金 | F5: 收到联营商押金 | G5: 小计 | H5: 销售收入金额 | I5: 收回保证金 | J5: 收到联营商押金 | K5: 小计
A6: 直营 | B6: 上海正大浦东店 | C6: 减字 | G6: =D6+E6+F6 -> 0 | K6: =H6+I6+J6 -> 0 | L6: =K6/G6 -> #DIV/0!
D7: 40000 | G7: =D7+E7+F7 -> 40000 | H7: =收款日报表!$G$135 -> 39549 | K7: =H7+I7+J7 -> 39549 | L7: =K7/G7 -> 0.988725
D8: 29000 | G8: =D8+E8+F8 -> 29000 | H8: =收款日报表!$G$130 -> 24522 | K8: =H8+I8+J8 -> 24522 | L8: =K8/G8 -> 0.84558621
D9: 22000 | G9: =D9+E9+F9 -> 22000 | H9: =收款日报表!$G$133 -> 27099 | K9: =H9+I9+J9 -> 27099 | L9: =K9/G9 -> 1.2317727
D10: 29600 | G10: =D10+E10+F10 -> 29600 | H10: =收款日报表!$G$137 -> 60955 | K10: =H10+I10+J10 -> 60955 | L10: =K10/G10 -> 2.0592905
D11: 56900 | G11: =D11+E11+F11 -> 56900 | H11: =收款日报表!$G$134 -> 46908 | K11: =H11+I11+J11 -> 46908 | L11: =K11/G11 -> 0.82439367
D12: 20000 | G12: =D12+E12+F12 -> 20000 | H12: =收款日报表!$G$132 -> 12200 | K12: =H12+I12+J12 -> 12200 | L12: =K12/G12 -> 0.61
D13: 25000 | G13: =D13+E13+F13 -> 25000 | H13: =收款日报表!$G$141 -> 23323 | K13: =H13+I13+J13 -> 23323 | L13: =K13/G13 -> 0.93292
D14: 30000 | G14: =D14+E14+F14 -> 30000 | H14: =收款日报表!$G$136 -> 36074 | K14: =H14+I14+J14 -> 36074 | L14: =K14/G14 -> 1.2024667
D15: 32700 | G15: =D15+E15+F15 -> 32700 | H15: =收款日报表!$G$140 -> 36332 | K15: =H15+I15+J15 -> 36332 | L15: =K15/G15 -> 1.1110703
D16: 30000 | G16: =D16+E16+F16 -> 30000 | H16: =收款日报表!$G$142 -> 45168 | K16: =H16+I16+J16 -> 45168 | L16: =K16/G16 -> 1.5056
D17: 20000 | G17: =D17+E17+F17 -> 20000 | H17: =收款日报表!$G$143 -> 19941.1 | K17: =H17+I17+J17 -> 19941.1 | L17: =K17/G17 -> 0.997055
D18: 20000 | G18: =D18+E18+F18 -> 20000 | H18: =收款日报表!$G$144 -> 65566 | K18: =H18+I18+J18 -> 65566 | L18: =K18/G18 -> 3.2783
B19: 小 计 | D19: =SUM(D6:D18) -> 355200 | E19: =SUM(E6:E18) -> 0 | F19: =SUM(F6:F18) -> 0 | G19: =SUM(G6:G18) -> 355200 | H19: =SUM(H6:H18) -> 437637.1 | I19: =SUM(I6:I18) -> 0 | J19: =SUM(J6:J18) -> 0 | K19: =H19+I19+J19 -> 437637.1 | L19: =K19/G19 -> 1.2320864
A20: 联营 | D20: 32888.1 | G20: =D20+E20+F20 -> 32888.1 | H20: =收款日报表!$G$127 -> 32888.1 | K20: =H20+I20+J20 -> 32888.1 | L20: =K20/G20 -> 1
D21: 25928.28 | G21: =D21+E21+F21 -> 25928.28 | H21: =收款日报表!$G$138 -> 25928.28 | K21: =H21+I21+J21 -> 25928.28 | L21: =K21/G21 -> 1
D22: 5645.64 | G22: =D22+E22+F22 -> 5645.64 | H22: =收款日报表!$G$145 -> 5645.64 | K22: =H22+I22+J22 -> 5645.64 | L22: =K22/G22 -> 1
D23: 28755.3 | G23: =D23+E23+F23 -> 28755.3 | H23: =收款日报表!$G$147 -> 28755.3 | K23: =H23+I23+J23 -> 28755.3 | L23: =K23/G23 -> 1
G24: =D24+E24+F24 -> 0 | H24: =收款日报表!$G$148 -> 0 | K24: =H24+I24+J24 -> 0 | L24: =K24/G24 -> #DIV/0!
G25: =D25+E25+F25 -> 0 | H25: =收款日报表!$G$146 -> 0 | K25: =H25+I25+J25 -> 0 | L25: =K25/G25 -> #DIV/0!
G26: =D26+E26+F26 -> 0 | H26: =收款日报表!$G$149 -> 0 | K26: =H26+I26+J26 -> 0 | L26: =K26/G26 -> #DIV/0!
G27: =D27+E27+F27 -> 0 | H27: =收款日报表!$G$150 -> 0 | K27: =H27+I27+J27 -> 0 | L27: =K27/G27 -> #DIV/0!
B28: 小 计 | D28: =SUM(D20:D27) -> 93217.32 | E28: =SUM(E20:E27) -> 0 | F28: =SUM(F20:F27) -> 0 | G28: =SUM(G20:G27) -> 93217.32 | H28: =SUM(H20:H27) -> 93217.32 | I28: =SUM(I20:I27) -> 0 | J28: =SUM(J20:J27) -> 0 | K28: =H28+I28+J28 -> 93217.32 | L28: =K28/G28 -> 1
A29: 合 计 | C29: 减字 | D29: =SUMIF($C6:C$28,$C$29,D6:D28) -> 0 | E29: =SUMIF($C6:D$28,$C$29,E6:E28) -> 0 | F29: =SUMIF($C6:E$28,$C$29,F6:F28) -> 0 | G29: =D29+E29+F29 -> 0 | H29: =SUMIF($C6:G$28,$C$29,H6:H28) -> 0 | I29: =SUMIF($C6:H$28,$C$29,I6:I28) -> 0 | J29: =SUMIF($C6:I$28,$C$29,J6:J28) -> 0 | K29: =H29+I29+J29 -> 0 | L29: =K29/G29 -> #DIV/0!
C30: 诺学 | D30: =SUMIF($C7:C$28,$C$30,D7:D29) -> 0 | E30: =SUMIF($C7:D$28,$C$30,E7:E29) -> 0 | F30: =SUMIF($C7:E$28,$C$30,F7:F29) -> 0 | G30: =D30+E30+F30 -> 0 | H30: =SUMIF($C7:G$28,$C$30,H7:H29) -> 0 | I30: =SUMIF($C7:H$28,$C$30,I7:I29) -> 0 | J30: =SUMIF($C7:I$28,$C$30,J7:J29) -> 0 | K30: =H30+I30+J30 -> 0 | L30: =K30/G30 -> #DIV/0!
C31: 合计 | D31: =SUM(D29:D30) -> 0 | E31: =SUM(E29:E30) -> 0 | F31: =SUM(F29:F30) -> 0 | G31: =SUM(G29:G30) -> 0 | H31: =SUM(H29:H30) -> 0 | I31: =SUM(I29:I30) -> 0 | J31: =SUM(J29:J30) -> 0 | K31: =SUM(K29:K30) -> 0 | L31: =K31/G31 -> #DIV/0!
H32: =H31-运营收款预算表!J29 -> 0

Sheet 人力资源部
B1: 人力资源部月资金预算
A2: 付款类型 | B2: 付款明细 | C2: 1月
C3: 预算数 | D3: 执行数 | E3: 执行率 | F3: 预算-执行
A5: 人才招聘费 | B5: 招聘费 | C5: 10000 | D5: =付款统计表!$D$4 -> 0 | E5: =D5/C5 -> 0 | F5: =C5-D5 -> 10000
A6: 工资 | B6: 实发工资 | C6: 1199402.9 | D6: =付款统计表!$D$57 -> 1224144.3 | E6: =D6/C6 -> 1.0206281 | F6: =C6-D6 -> -24741.38
B7: 社保 | C7: 151183.2 | D7: =付款统计表!$D$58 -> 170248.09 | E7: =D7/C7 -> 1.1261046 | F7: =C7-D7 -> -19064.89
B8: 公积金 | C8: 46386 | D8: =付款统计表!$D$56 -> 37918 | E8: =D8/C8 -> 0.81744492 | F8: =C8-D8 -> 8468
B9: 个税 | C9: 139787.02 | D9: =付款统计表!$D$59 -> 147063.27 | E9: =D9/C9 -> 1.0520524 | F9: =C9-D9 -> -7276.25
A10: 福利费 | B10: 周运动 | C10: 2000 | D10: =付款统计表!$D$88 -> 1414 | E10: =D10/C10 -> 0.707 | F10: =C10-D10 -> 586
B11: 其他福利费（包括管理层开会餐费） | C11: 30000 | D11: 587.5 | E11: =D11/C11 -> 0.019583333 | F11: =C11-D11 -> 29412.5
A12: 车辆费 | B12: 停车费及油费 | C12: 6000 | D12: =付款统计表!$D$77 -> 10000 | E12: =D12/C12 -> 1.6666667 | F12: =C12-D12 -> -4000
A13: 办公费 | B13: 饮用水费用 | C13: 1500 | D13: =付款统计表!$D$79 -> 1460 | E13: =D13/C13 -> 0.97333333 | F13: =C13-D13 -> 40
B14: 总经办相关费用（包括餐费、相关其他采购） | C14: 3000 | D14: =付款统计表!$D$89-D11 -> 2956.55 | E14: =D14/C14 -> 0.98551667 | F14: =C14-D14 -> 43.45
B15: 办公用品月结 | C15: 3500 | D15: =付款统计表!$D$78 -> 5068.09 | E15: =D15/C15 -> 1.4480257 | F15: =C15-D15 -> -1568.09
A16: 快递费 | B16: 月结快递费 | C16: 5000 | D16: =付款统计表!$D$70 -> 809 | E16: =D16/C16 -> 0.1618 | F16: =C16-D16 -> 4191
A17: 交通差旅费 | B17: 携程、阿里商旅月结费用 | C17: 35000 | D17: =付款统计表!$D$84 -> 59569.81 | E17: =D17/C17 -> 1.7019946 | F17: =C17-D17 -> -24569.81
A18: 办公室租金/维护费用 | B18: 租金&物业 | C18: 196000 | D18: =付款统计表!$D$5 -> 196530.32 | E18: =D18/C18 -> 1.0027057 | F18: =C18-D18 -> -530.32
B19: 办公室水电 | C19: 25000 | D19: =付款统计表!$D$6 -> 19226.22 | E19: =D19/C19 -> 0.7690488 | F19: =C19-D19 -> 5773.78
B20: 办公室清洁费 | C20: 3550 | D20: =付款统计表!$D$83 -> 3400 | E20: =D20/C20 -> 0.95774648 | F20: =C20-D20 -> 150
B21: 其他修理费 | C21: 500 | D21: =付款统计表!$D$82 -> 3700 | E21: =D21/C21 -> 7.4 | F21: =C21-D21 -> -3200
A22: 费用报销 | B22: 招待费 | C22: 0 | D22: =付款统计表!$D$90 -> 0 | E22: =D22/C22 -> #DIV/0! | F22: =C22-D22 -> 0
B23: 交通差旅费 | C23: 300 | D23: =付款统计表!$D$85+付款统计表!$D$86 -> 474.47 | E23: =D23/C23 -> 1.5815667 | F23: =C23-D23 -> -174.47
B24: 采购费用（日常办公用品采购） | C24: 1500 | D24: =付款统计表!$D$87 -> 3308.54 | E24: =D24/C24 -> 2.2056933 | F24: =C24-D24 -> -1808.54
A25: 其他 | B25: 其他 | C25: 17000 | D25: =81500+付款统计表!$D$94-SUM(人力资源部!D5:D24) -> 123234.96 | E25: =D25/C25 -> 7.2491153 | F25: =C25-D25 -> -106234.96
A26: 总 计 | C26: =SUM(C5:C25) -> 1876609.1 | D26: =SUM(D5:D25) -> 2011113.1 | E26: =D26/C26 -> 1.0716739 | F26: =SUM(F5:F25) -> -134503.98 | G26: =D26-付款统计表!D94-81500 -> 0
B27: 工资、五险一金 | C27: =SUM(C6:C9) -> 1536759.1 | D27: =SUM(D6:D9) -> 1579373.6
B28: 办公室租金水电 | C28: =C18+C19 -> 221000 | D28: =D18+D19 -> 215756.54
B29: 报销费用 | C29: =SUM(C22:C24)+C14+C10+C11 -> 36800 | D29: =SUM(D22:D24) -> 3783.01
B30: 其他运营付款 | C30: =C26-C27-C28-C29 -> 82050 | D30: =D26-D27-D28-D29 -> 212199.91

Sheet 财务部
B1: 财务部月资金预算
A2: 付款类型 | B2: 付款明细 | C2: 1月 | F2: 预算-执行
C3: 预算数 | D3: 执行数 | E3: 执行率
A4: 贷款 | B4: 还贷款 | C4: 200000 | D4: =付款统计表!$E$68 -> 200000 | E4: =D4/C4 -> 1 | F4: =C4-D4 -> 0
A5: 税金 | B5: 增值税 | C5: 286324.06 | D5: =付款统计表!$E$60 -> 286324.06 | E5: =D5/C5 -> 1 | F5: =C5-D5 -> 0
B6: 文化建设税 | C6: 0 | D6: =付款统计表!$E$66 -> 0 | E6: =D6/C6 -> #DIV/0! | F6: =C6-D6 -> 0
B7: 附加税 | C7: 34358.9 | D7: =付款统计表!$E$62+付款统计表!$E$63+付款统计表!$E$61 -> 34358.9 | E7: =D7/C7 -> 1 | F7: =C7-D7 -> 0
B8: 企业所得税 | C8: 1141385.5 | D8: =付款统计表!$E$67 -> 1141385.5 | E8: =D8/C8 -> 1 | F8: =C8-D8 -> 0
B9: 印花税 | C9: 90880.5 | D9: =付款统计表!$E$65 -> 90880.5 | E9: =D9/C9 -> 1 | F9: =C9-D9 -> 0
B10: 滞纳金 | C10: 0 | D10: =付款统计表!$E$64 -> 0 | E10: =D10/C10 -> #DIV/0! | F10: =C10-D10 -> 0
A11: 财务费用 | B11: 手续及工本费 | C11: 800 | D11: =付款统计表!$E$71 -> 1131.07 | E11: =D11/C11 -> 1.4138375 | F11: =C11-D11 -> -331.07
B12: 利息支出 | C12: 20000 | D12: =付款统计表!$E$69 -> 18912.83 | E12: =D12/C12 -> 0.9456415 | F12: =C12-D12 -> 1087.17
A13: 物流仓储费 | B13: 科捷物流 | C13: 0 | D13: =付款统计表!$E$52 -> 7628.98 | E13: =D13/C13 -> #DIV/0! | F13: =C13-D13 -> -7628.98
B14: 跨越物流 | C14: 2784.5 | D14: =付款统计表!$E$51 -> 2784.5 | E14: =D14/C14 -> 1
B15: 唯品仓储费 | C15: 16161.14 | D15: =付款统计表!$E$50 -> 16161.14 | E15: =D15/C15 -> 1 | F15: =C15-D15 -> 0
B16: 菜鸟仓储费 | C16: 95200 | D16: 102221.27 | E16: =D16/C16 -> 1.0737528 | F16: =C16-D16 -> -7021.27
A17: 客服外包服务费 | B17: 客服外包服务费 | C17: 159500 | D17: =付款统计表!$T$49 -> 160172 | E17: =D17/C17 -> 1.0042132 | F17: =C17-D17 -> -672
A18: 专业咨询服务费 | B18: 咨询费 | C18: 0 | D18: =付款统计表!$E$73 -> 0 | E18: =D18/C18 -> #DIV/0! | F18: =C18-D18 -> 0
A19: 办公室租金 | B19: 上海办公室费用 | C19: 0 | D19: =付款统计表!$E$5+付款统计表!$E$6+付款统计表!$E$80+付款统计表!$E$81+付款统计表!$E$82+付款统计表!$E$83 -> 0 | E19: =D19/C19 -> #DIV/0! | F19: =C19-D19 -> 0
A20: 支付宝退款 | B20: 售后退款 | C20: 0 | D20: =付款统计表!$E$55 -> 0 | E20: =D20/C20 -> #DIV/0! | F20: =C20-D20 -> 0
A21: 其他 | B21: 其他付款 | D21: =付款统计表!$E$94-SUM(财务部!D4:D15)-SUM(财务部!D17:D20)-SUM(财务部!D22:D25) -> 1837 | E21: =D21/C21 -> #DIV/0! | F21: =C21-D21 -> -1837
A22: 费用报销 | B22: 招待费 | C22: 0 | D22: =付款统计表!$E$90 -> 0 | E22: =D22/C22 -> #DIV/0! | F22: =C22-D22 -> 0
B23: 交通差旅费 | C23: 800 | D23: =付款统计表!$E$85+付款统计表!$E$86 -> 860.24 | E23: =D23/C23 -> 1.0753 | F23: =C23-D23 -> -60.24
B24: 采购费用 | C24: 0 | D24: =付款统计表!$E$87 -> 0 | E24: =D24/C24 -> #DIV/0! | F24: =C24-D24 -> 0
B25: 其他报销 | C25: 200 | E25: =D25/C25 -> 0 | F25: =C25-D25 -> 200
A26: 总 计 | C26: =SUM(C4:C25) -> 2048394.6 | D26: =SUM(D4:D25) -> 2064658 | E26: =D26/C26 -> 1.0079396 | F26: =SUM(F4:F25) -> -16263.39
B27: 报销费用 | C27: =C22+C23+C24+C25 -> 1000 | D27: =D22+D23+D24+D25 -> 860.24
B28: 其他运营付款 | C28: =C11+C18+C19+C20+C21 -> 800 | D28: =D26-D27-SUM(D5:D10)-SUM(D13:D16)-D17-D4-D12 -> 2968.07

Sheet 电商
A1: 月电商资金支出预算表
A2: 引用 | B2: 类别 | C2: 明细 | D2: 1月 | G2: 2月 | J2: 3月
D3: 预计支付金额 | E3: 实际支付 | F3: 执行率 | G3: 预计支付金额 | H3: 实际支付 | I3: 执行率 | J3: 预计支付金额 | K3: 实际支付 | L3: 执行率 | M3: 预算-实际
A5: 6601.016 | B5: 站内推广 | C5: 天猫-钻展 | M5: =D5-E5 -> 0
A6: 6601.016 | C6: 天猫-直通车 | M6: =D6-E6 -> 0
A7: 6601.016 | C7: 天猫-品销宝 | M7: =D7-E7 -> 0
A8: 6601.016 | C8: 天猫-如意淘 | M8: =D8-E8 -> 0
A9: 6601.016 | C9: 天猫-聚划算 | M9: =D9-E9 -> 0
A10: 6601.016 | C10: 天猫-淘抢购 | M10: =D10-E10 -> 0
A11: 6601.016 | C11: 天猫-其他 | M11: =D11-E11 -> 0
C12: 阿里V任务
C13: 小 计 | D13: =SUM(D5:D12) -> 0 | E13: =SUM(E5:E12) -> 0 | F13: =E13/D13 -> #DIV/0! | G13: =SUM(G5:G12) -> 0 | H13: =SUM(H5:H12) -> 0 | I13: =H13/G13 -> #DIV/0! | J13: =SUM(J5:J12) -> 0 | K13: =SUM(K5:K12) -> 0 | L13: =K13/J13 -> #DIV/0! | M13: =D13-E13 -> 0
A14: 6601.019 | B14: 站外推广 | C14: 360推广 | M14: =D14-E14 -> 0
A15: 6601.019 | C15: 百度推广 | M15: =D15-E15 -> 0
A16: 6601.019 | C16: 短信推广费 | M16: =D16-E16 -> 0
A17: 6601.019 | C17: 粉丝通 | M17: =D17-E17 -> 0
C18: 淘客佣金（站外） | M18: =D18-E18 -> 0
A19: 6601.019 | C19: 站外推广-其他 | M19: =D19-E19 -> 0
C20: 小 计 | D20: =SUM(D14:D19) -> 0 | E20: =SUM(E14:E19) -> 0 | F20: =E20/D20 -> #DIV/0! | G20: =SUM(G14:G19) -> 0 | H20: =SUM(H14:H19) -> 0 | I20: =H20/G20 -> #DIV/0! | J20: =SUM(J14:J19) -> 0 | K20: =SUM(K14:K19) -> 0 | L20: =K20/J20 -> #DIV/0! | M20: =D20-E20 -> 0
A21: 6601.020.001 | B21: 平台佣金 | C21: 天猫佣金 | M21: =D21-E21 -> 0
A22: 6601.020.001 | C22: 其他 | M22: =D22-E22 -> 0
C23: 小 计 | D23: =SUM(D21:D22) -> 0 | E23: =SUM(E21:E22) -> 0 | F23: =E23/D23 -> #DIV/0! | G23: =SUM(G21:G22) -> 0 | H23: =SUM(H21:H22) -> 0 | I23: =H23/G23 -> #DIV/0! | J23: =SUM(J21:J22) -> 0 | K23: =SUM(K21:K22) -> 0 | L23: =K23/J23 -> #DIV/0! | M23: =D23-E23 -> 0
A24: 6601.006 | B24: 费用报销 | C24: 交通差旅费 | M24: =D24-E24 -> 0
A25: 6601.010 | C25: 业务招待费 | M25: =D25-E25 -> 0
A26: 6601.031 | C26: 其他 | M26: =D26-E26 -> 0
C27: 小 计 | D27: =SUM(D24:D26) -> 0 | E27: =SUM(E24:E26) -> 0 | F27: =E27/D27 -> #DIV/0! | G27: =SUM(G24:G26) -> 0 | H27: =SUM(H24:H26) -> 0 | I27: =H27/G27 -> #DIV/0! | J27: =SUM(J24:J26) -> 0 | K27: =SUM(K24:K26) -> 0 | L27: =K27/J27 -> #DIV/0! | M27: =D27-E27 -> 0
A28: 合计 | D28: =SUM(D13+D20+D23+D27) -> 0 | E28: =SUM(E13+E20+E23+E27) -> 0 | F28: =E28/D28 -> #DIV/0! | G28: =SUM(G13+G20+G23+G27) -> 0 | H28: =SUM(H13+H20+H23+H27) -> 0 | I28: =H28/G28 -> #DIV/0! | J28: =SUM(J13+J20+J23+J27) -> 0 | K28: =SUM(K13+K20+K23+K27) -> 0 | L28: =K28/J28 -> #DIV/0! | M28: =D28-E28 -> 0 | N28: =E28-E23-付款统计表!$I$94 -> -409048.99
M29: =E28-付款统计表!I94-E21 -> -409048.99

Sheet 销售支持组
A1: 2017年销售支持组资金支出预算表
A2: 引用 | B2: 类别 | C2: 明细 | D2: 8月
D3: 预计支付金额 | E3: 实际支付 | F3: 执行率
A5: 6601.006 | B5: 费用报销 | C5: 交通差旅费 | D5: 0 | E5: =付款统计表!$M$85+付款统计表!$M$86 -> 130 | F5: =E5/D5 -> #DIV/0!
A6: 6601.010 | C6: 业务招待费 | D6: 0 | E6: =付款统计表!$M$90 -> 0 | F6: =E6/D6 -> #DIV/0!
A7: 6601.031 | C7: 其他 | D7: 0 | E7: =付款统计表!$M$94-销售支持组!E5-销售支持组!E6 -> 0 | F7: =E7/D7 -> #DIV/0!
C8: 合 计 | D8: =SUM(D5:D7) -> 0 | E8: =SUM(E5:E7) -> 130 | F8: =E8/D8 -> #DIV/0! | G8: =E8-付款统计表!M94 -> 0

Sheet 线下销售部
A1: 线下销售部月资金预算
A2: 付款大类 | B2: 费用明细 | C2: 1月 | F2: 备注 | G2: 预算-执行
C3: 预算数 | D3: 执行数 | E3: 执行率
A4: 线下门店费用类支出 | B4: 门店租金&物业费 | C4: 250000 | D4: =SUMIF(付款统计表!$A$4:$A$93,线下销售部!B4,付款统计表!$H$4:$H$93) -> 253114.84 | E4: =D4/C4 -> 1.0124594 | G4: =C4-D4 -> -3114.84
B5: 门店水电费 | C5: 4800 | D5: =SUMIF(付款统计表!$A$4:$A$93,线下销售部!B5,付款统计表!$H$4:$H$93) -> 6798.5 | E5: =D5/C5 -> 1.4163542 | G5: =C5-D5 -> -1998.5
B6: 门店推广费 | C6: 4500 | D6: =SUMIF(付款统计表!$A$4:$A$93,线下销售部!B6,付款统计表!$H$4:$H$93) -> 3415.55 | E6: =D6/C6 -> 0.75901111 | G6: =C6-D6 -> 1084.45
B7: 门店POS机租金 | C7: 2600 | D7: =SUMIF(付款统计表!$A$4:$A$93,线下销售部!B7,付款统计表!$H$4:$H$93) -> 3500 | E7: =D7/C7 -> 1.3461538 | G7: =C7-D7 -> -900
B8: 门店其他 | C8: 1000 | D8: =SUMIF(付款统计表!$A$4:$A$93,线下销售部!B8,付款统计表!$H$4:$H$93) -> 1172.34 | E8: =D8/C8 -> 1.17234 | G8: =C8-D8 -> -172.34
B9: 小 计 | C9: =SUM(C4:C8) -> 262900 | D9: =SUM(D4:D8) -> 268001.23 | E9: =D9/C9 -> 1.0194037 | G9: =C9-D9 -> -5101.23
A10: 线下门店保证金、押金支出 | B10: 门店租金押金 | D10: =SUMIF(付款统计表!$A$4:$A$93,线下销售部!B10,付款统计表!$H$4:$H$93) -> 0 | E10: =D10/C10 -> #DIV/0! | G10: =C10-D10 -> 0
B11: 门店装修押金 | D11: =SUMIF(付款统计表!$A$4:$A$93,线下销售部!B11,付款统计表!$H$4:$H$93) -> 0 | E11: =D11/C11 -> #DIV/0! | G11: =C11-D11 -> 0
B12: 门店质保金 | D12: =SUMIF(付款统计表!$A$4:$A$93,线下销售部!B12,付款统计表!$H$4:$H$93) -> 0 | E12: =D12/C12 -> #DIV/0! | G12: =C12-D12 -> 0
B13: 门店物业保证金 | D13: =SUMIF(付款统计表!$A$4:$A$93,线下销售部!B13,付款统计表!$H$4:$H$93) -> 0 | E13: =D13/C13 -> #DIV/0! | G13: =C13-D13 -> 0
B14: 门店装修保证金 | D14: =SUMIF(付款统计表!$A$4:$A$93,线下销售部!B14,付款统计表!$H$4:$H$93) -> 0 | E14: =D14/C14 -> #DIV/0! | G14: =C14-D14 -> 0
B15: 门店收银系统押金 | C15: 20000 | D15: =SUMIF(付款统计表!$A$4:$A$93,线下销售部!B15,付款统计表!$H$4:$H$93) -> 0 | E15: =D15/C15 -> 0 | G15: =C15-D15 -> 20000
B16: 门店履约保证金 | D16: =SUMIF(付款统计表!$A$4:$A$93,线下销售部!B16,付款统计表!$H$4:$H$93) -> 0 | E16: =D16/C16 -> #DIV/0! | G16: =C16-D16 -> 0
B17: 门店其他保证金 | D17: =SUMIF(付款统计表!$A$4:$A$93,线下销售部!B17,付款统计表!$H$4:$H$93) -> 0 | E17: =D17/C17 -> #DIV/0! | G17: =C17-D17 -> 0
B18: 小 计 | C18: =SUM(C10:C17) -> 20000 | D18: =SUM(D10:D17) -> 0 | E18: =D18/C18 -> 0 | G18: =C18-D18 -> 20000
A19: 线下门店投资性支出 | B19: 门店入场费 | D19: =SUMIF(付款统计表!$A$4:$A$93,线下销售部!B19,付款统计表!$H$4:$H$93) -> 0 | E19: =D19/C19 -> #DIV/0! | G19: =C19-D19 -> 0
B20: 门店装修费 | C20: 10000 | D20: =SUMIF(付款统计表!$A$4:$A$93,线下销售部!B20,付款统计表!$H$4:$H$93) -> 0 | E20: =D20/C20 -> 0 | G20: =C20-D20 -> 10000
B21: 门店道具费 | C21: 26165.2 | D21: =SUMIF(付款统计表!$A$4:$A$93,线下销售部!B21,付款统计表!$H$4:$H$93) -> 26165 | E21: =D21/C21 -> 0.99999236 | G21: =C21-D21 -> 0.2
B22: 门店灯具费 | D22: =SUMIF(付款统计表!$A$4:$A$93,线下销售部!B22,付款统计表!$H$4:$H$93) -> 0 | E22: =D22/C22 -> #DIV/0! | G22: =C22-D22 -> 0
B23: 门店收银系统、设备 | D23: =SUMIF(付款统计表!$A$4:$A$93,线下销售部!B23,付款统计表!$H$4:$H$93) -> 0 | E23: =D23/C23 -> #DIV/0! | G23: =C23-D23 -> 0
B24: 门店其他支出 | D24: =SUMIF(付款统计表!$A$4:$A$93,线下销售部!B24,付款统计表!$H$4:$H$93) -> 14420 | E24: =D24/C24 -> #DIV/0! | G24: =C24-D24 -> -14420
B25: 小 计 | C25: =SUM(C19:C24) -> 36165.2 | D25: =SUM(D19:D24) -> 40585 | E25: =D25/C25 -> 1.1222114 | G25: =C25-D25 -> -4419.8
A26: 费用报销 | B26: 备用金报销 | C26: 5600 | D26: =SUMIF(付款统计表!$A$4:$A$93,线下销售部!B26,付款统计表!$H$4:$H$93) -> 5402.58 | E26: =D26/C26 -> 0.96474643 | G26: =C26-D26 -> 197.42
B27: 招待费 | C27: 0 | D27: =SUMIF(付款统计表!$A$4:$A$93,线下销售部!B27,付款统计表!$H$4:$H$93) -> 2141 | E27: =D27/C27 -> #DIV/0! | G27: =C27-D27 -> -2141
B28: 交通差旅费 | C28: 5000 | D28: =SUMIF(付款统计表!$A$4:$A$93,线下销售部!B28,付款统计表!$H$4:$H$93)+付款统计表!$H$86 -> 5555.2 | E28: =D28/C28 -> 1.11104 | G28: =C28-D28 -> -555.2
B29: 其他报销 | D29: =付款统计表!$H$94-线下销售部!D9-线下销售部!D18-线下销售部!D25-线下销售部!D26-线下销售部!D27-线下销售部!D28+20000 -> 58365 | E29: =D29/C29 -> #DIV/0! | G29: =C29-D29 -> -58365
B30: 小 计 | C30: =SUM(C26:C29) -> 10600 | D30: =SUM(D26:D29) -> 71463.78 | E30: =D30/C30 -> 6.741866 | G30: =C30-D30 -> -60863.78
A31: 总 计 | C31: =C9+C18+C25+C30 -> 329665.2 | D31: =D9+D18+D25+D30 -> 380050.01 | E31: =D31/C31 -> 1.1528363 | G31: =C31-D31 -> -50384.81 | H31: =D31-付款统计表!H94-20000 -> 0

Sheet 市场部
A1: 市场部（1）月资金预算
A2: 项目 | B2: 预算数 | C2: 执行数 | D2: 执行率
A3: 品牌推广——红人 | C3: =SUMIF(付款统计表!$A$4:$A$93,市场部!A3,付款统计表!$G$4:$G$93) -> 0 | D3: =C3/B3 -> #DIV/0! | F3: =B3-C3 -> 0
A4: 品牌推广——明星 | C4: =SUMIF(付款统计表!$A$4:$A$93,市场部!A4,付款统计表!$G$4:$G$93) -> 0 | D4: =C4/B4 -> #DIV/0! | F4: =B4-C4 -> 0
A5: 品牌推广——微信 | C5: =SUMIF(付款统计表!$A$4:$A$93,市场部!A5,付款统计表!$G$4:$G$93) -> 0 | D5: =C5/B5 -> #DIV/0! | F5: =B5-C5 -> 0
A6: 品牌推广——其他 | B6: 1390 | C6: =SUMIF(付款统计表!$A$4:$A$93,市场部!A6,付款统计表!$G$4:$G$93) -> 1390 | D6: =C6/B6 -> 1 | F6: =B6-C6 -> 0
A7: 招待费 | C7: =SUMIF(付款统计表!$A$4:$A$93,市场部!A7,付款统计表!$G$4:$G$93) -> 0 | D7: =C7/B7 -> #DIV/0! | F7: =B7-C7 -> 0
A8: 交通差旅费 | C8: =SUMIF(付款统计表!$A$4:$A$93,市场部!A8,付款统计表!$G$4:$G$93)+付款统计表!$G$86 -> 0 | D8: =C8/B8 -> #DIV/0! | F8: =B8-C8 -> 0
A9: 采购费用 | C9: =SUMIF(付款统计表!$A$4:$A$93,市场部!A9,付款统计表!$G$4:$G$93) -> 0 | D9: =C9/B9 -> #DIV/0! | F9: =B9-C9 -> 0
A10: 其他报销 | C10: =付款统计表!$G$94-SUM(市场部!C3:C9) -> 0 | D10: =C10/B10 -> #DIV/0! | F10: =B10-C10 -> 0
A11: 总 计 | B11: =SUM(B3:B10) -> 1390 | C11: =SUM(C3:C10) -> 1390 | D11: =C11/B11 -> 1 | F11: =C11-付款统计表!G94 -> 0
A17: 1月品牌推广预算明细表
A19: 明细 | B19: 对方单位 | C19: 经办人 | D19: 预算 | E19: 备注
A21: 品牌推广——其他 | D21: 1390 | E21: 11月份新闻稿发布费用
B23: 小 计 | D23: =SUM(D21:D22) -> 1390
A24: 报销
B27: 小 计 | D27: =SUM(D24:D26) -> 0
A28: 合 计 | D28: =D23+D27 -> 1390

Sheet 电商设计部
A1: 电商设计部月资金预算
A2: 项目 | B2: 预算数 | C2: 执行数 | D2: 执行率 | F2: 备注
A3: 设计——拍摄费 | B3: 250000 | C3: =付款统计表!$F$48 -> 136935 | D3: =C3/B3 -> 0.54774 | E3: =B3-C3 -> 113065 | F3: 18大片拍摄，18产品图拍摄外包
A4: 业务招待费 | B4: 0 | C4: =付款统计表!$F$90 -> 0 | D4: =C4/B4 -> #DIV/0! | E4: =B4-C4 -> 0
A5: 交通差旅费 | B5: 6000 | C5: =付款统计表!$F$85+付款统计表!$F$86 -> 3582.66 | D5: =C5/B5 -> 0.59711 | E5: =B5-C5 -> 2417.34 | F5: 上海拍摄来回住宿，新产品开发外出
A6: 采购费用 | B6: 20000 | C6: =付款统计表!$F$87 -> 0 | D6: =C6/B6 -> 0 | E6: =B6-C6 -> 20000 | F6: 拍摄道具采购，产品开发样品采购
A7: 其他报销 | C7: =付款统计表!$F$94-SUM(电商设计部!C3:C6) -> 0 | D7: =C7/B7 -> #DIV/0! | E7: =B7-C7 -> 0
A8: 总 计 | B8: =SUM(B3:B7) -> 276000 | C8: =SUM(C3:C7) -> 140517.66 | D8: =C8/B8 -> 0.50912196 | E8: =B8-C8 -> 135482.34 | F8: =C8-付款统计表!F94 -> 0

Sheet 产品设计部
A1: 产品设计部月资金预算
A2: 项目 | B2: 1月 | E2: 预算-实际 | F2: 备注
B3: 预算数 | C3: 执行数 | D3: 执行率
A4: 交通差旅费 | B4: 10000 | C4: =付款统计表!$O$85+付款统计表!$O$86 -> 8689.46 | D4: =C4/B4 -> 0.868946 | E4: =B4-C4 -> 1310.54
A5: 采购费用 | C5: =付款统计表!$O$87 -> 0 | D5: =C5/B5 -> #DIV/0! | E5: =B5-C5 -> 0
A6: 备用金报销 | B6: 9000 | C6: =付款统计表!$O$91 -> 8306.18 | D6: =C6/B6 -> 0.92290889 | E6: =B6-C6 -> 693.82
A7: 打样费 | B7: 12000 | C7: 2945 | D7: =C7/B7 -> 0.24541667 | E7: =B7-C7 -> 9055 | F7: 手表、鞋子
A8: 其他 | B8: 25000 | C8: =付款统计表!$O$94-SUM(产品设计部!C4:C7) -> 12600 | D8: =C8/B8 -> 0.504 | E8: =B8-C8 -> 12400 | F8: 测试、表测试、箱子、鞋子测试
A9: 总 计 | B9: =SUM(B4:B8) -> 56000 | C9: =SUM(C4:C8) -> 32540.64 | D9: =C9/B9 -> 0.58108286 | E9: =B9-C9 -> 23459.36 | F9: =C9-付款统计表!O94 -> 0

Sheet 采购部
A1: 采购部资金预算
A2: 项目 | B2: 预算数 | C2: 执行数 | D2: 执行率
A3: 交通差旅费 | B3: 3800 | C3: =付款统计表!$P$85+付款统计表!$Q$85+付款统计表!$P$86+付款统计表!$Q$86 -> 6733.76 | D3: =C3/B3 -> 1.7720421 | E3: =B3-C3 -> -2933.76
A4: 采购费用 | B4: 1000 | C4: =付款统计表!$P$87+付款统计表!$Q$87 -> 1595 | D4: =C4/B4 -> 1.595 | E4: =B4-C4 -> -595
A5: 仓库备用金报销 | B5: 2000 | C5: =付款统计表!$P$91+付款统计表!$Q$91 -> 1580.59 | D5: =C5/B5 -> 0.790295 | E5: =B5-C5 -> 419.41
A6: 其他报销 | B6: 1600 | C6: =付款统计表!$P$94+付款统计表!$Q$94-SUM(C3:C5) -> 1551 | D6: =C6/B6 -> 0.969375 | E6: =B6-C6 -> 49
A7: 总计： | B7: =SUM(B3:B6) -> 8400 | C7: =SUM(C3:C6) -> 11460.35 | D7: =C7/B7 -> 1.3643274 | E7: =B7-C7 -> -3060.35 | F7: =C7-付款统计表!P94-付款统计表!Q94 -> 0

Sheet 行政部
A1: 行政部月资金预算
A2: 项目 | B2: 预算数 | C2: 执行数 | D2: 执行率 | F2: 备注
A3: 专利费 | B3: 60000 | D3: =C3/B3 -> 0 | E3: =B3-C3 -> 60000
A4: 专业服务费 | B4: 15000 | C4: =付款统计表!$C$75+付款统计表!$C$76+付款统计表!$C$73+3620 -> 6742.5 | D4: =C4/B4 -> 0.4495 | E4: =B4-C4 -> 8257.5
A5: 业务招待费 | B5: 40000 | C5: =付款统计表!$C$90 -> 32401.77 | D5: =C5/B5 -> 0.81004425 | E5: =B5-C5 -> 7598.23
A6: 交通差旅费 | C6: 42.5 | D6: =C6/B6 -> #DIV/0! | E6: =B6-C6 -> -42.5
A7: 其他报销 | B7: 50000 | C7: 27249.64 | D7: =C7/B7 -> 0.5449928 | E7: =B7-C7 -> 22750.36
A8: 总计： | B8: =SUM(B3:B7) -> 165000 | C8: =SUM(C3:C7) -> 66436.41 | D8: =C8/B8 -> 0.40264491 | E8: =B8-C8 -> 98563.59

Sheet 差异明细
A1: 各项资金预算执行项目及部门差异明细
B2: 运营-自营一组 | C2: 运营-自营二组 | D2: 运营-代销平台组 | E2: 运营-渠道组 | F2: 线下销售 | G2: 市场部 | H2: CEO办公室 | I2: 总裁办 | J2: 财务部 | K2: 组织部 | L2: 设计部 | M2: IT部 | N2: 供应链部&品质部 | O2: 研发部 | P2: 合计
A3: 招聘费 | K3: =人力资源部!$F$5 -> 10000 | P3: =SUM(B3:O3) -> 10000
A4: 租金水电 | J4: =财务部!$F$19 -> 0 | K4: =人力资源部!$F$18+人力资源部!$F$19 -> 5243.46 | P4: =SUM(B4:O4) -> 5243.46
A5: 线下门店费用类支出 | F5: =线下销售部!$G$9 -> -5101.23 | P5: =SUM(B5:O5) -> -5101.23
A6: 线下门店保证金、押金支出 | F6: =线下销售部!$G$18 -> 20000 | P6: =SUM(B6:O6) -> 20000
A7: 线下门店投资性支出 | F7: =线下销售部!$G$25 -> -4419.8 | P7: =SUM(B7:O7) -> -4419.8
A8: 运营站内推广费 | B8: =电商!$M$13 -> 0 | P8: =SUM(B8:O8) -> 0
A9: 运营站外推广费 | B9: =电商!$M$20 -> 0 | P9: =SUM(B9:O9) -> 0
A10: 平台佣金 | B10: =电商!$M$23 -> 0 | P10: =SUM(B10:O10) -> 0
A11: 品牌推广——红人 | G11: =市场部!$F$3 -> 0 | P11: =SUM(B11:O11) -> 0
A12: 品牌推广——明星 | G12: =市场部!$F$4 -> 0 | P12: =SUM(B12:O12) -> 0
A13: 品牌推广——微信 | G13: =市场部!$F$5 -> 0 | P13: =SUM(B13:O13) -> 0
A14: 品牌推广——其他 | G14: =市场部!$F$6 -> 0 | P14: =SUM(B14:O14) -> 0
A15: 客服服务费 | J15: =财务部!$F$17 -> -672 | P15: =SUM(B15:O15) -> -672
A16: 仓储物流费 | J16: =财务部!$F$13+财务部!$F$15+财务部!$F$16 -> -14650.25 | K16: =人力资源部!$F$16 -> 4191 | P16: =SUM(B16:O16) -> -10459.25
A17: 专利费 | I17: =行政部!$E$3 -> 60000 | P17: =SUM(B17:O17) -> 60000
A18: 专业服务费 | I18: =行政部!$E$4 -> 8257.5 | J18: =财务部!$F$18 -> 0 | K18: =人力资源部!$F$17 -> -24569.81 | P18: =SUM(B18:O18) -> -16312.31
A19: 工资薪金 | K19: =人力资源部!$F$6+人力资源部!$F$7+人力资源部!$F$8+人力资源部!$F$9 -> -42614.52 | P19: =SUM(B19:O19) -> -42614.52
A20: 税金 | J20: =财务部!$F$5+财务部!$F$6+财务部!$F$7+财务部!$F$8+财务部!$F$9+财务部!$F$10 -> 0 | P20: =SUM(B20:O20) -> 0
A21: 贷款及利息 | J21: =财务部!$F$4+财务部!$F$12 -> 1087.17 | P21: =SUM(B21:O21) -> 1087.17
A22: 招待费 | F22: =线下销售部!$G$27 -> -2141 | G22: =市场部!$F$7 -> 0 | I22: =行政部!$E$5 -> 7598.23 | J22: =财务部!$F$22 -> 0 | P22: =SUM(B22:O22) -> 5457.23
A23: 交通差旅费 | B23: =电商!$M$24 -> 0 | F23: =线下销售部!$G$28 -> -555.2 | G23: =市场部!$F$8 -> 0 | I23: =行政部!$E$6 -> -42.5 | J23: =财务部!$F$23 -> -60.24 | L23: =电商设计部!$E$5 -> 2417.34 | N23: =采购部!$E$3 -> -2933.76 | O23: =产品设计部!E4 -> 1310.54 | P23: =SUM(B23:O23) -> 136.18
A24: 备用金报销 | F24: =线下销售部!$G$26 -> 197.42 | N24: =采购部!$E$5 -> 419.41 | O24: =产品设计部!E6 -> 693.82 | P24: =SUM(B24:O24) -> 1310.65
A25: 网络电话费 | P25: =SUM(B25:O25) -> 0
A26: 采购费用 | G26: =市场部!$F$9 -> 0 | J26: =财务部!$F$24 -> 0 | K26: =人力资源部!$F$13+人力资源部!$F$15+人力资源部!$F$24 -> -3336.63 | L26: =电商设计部!$E$6 -> 20000 | N26: =采购部!$E$4 -> -595 | O26: =产品设计部!E5 -> 0 | P26: =SUM(B26:O26) -> 16068.37
A27: 其他 | B27: =电商!$M$28-SUM(B3:B26) -> 0 | F27: =线下销售部!$G$31-SUM(差异明细!F3:F26) -> -58365 | G27: =市场部!$F$11-SUM(差异明细!G3:G26) -> 0 | I27: =行政部!$E$7 -> 22750.36 | J27: =财务部!$F$26-SUM(差异明细!J3:J26) -> -1968.07 | K27: =人力资源部!$F$26-SUM(差异明细!K3:K26) -> -83417.48 | L27: =电商设计部!$E$8-SUM(差异明细!L3:L26) -> 113065 | N27: =采购部!$E$7-SUM(差异明细!N3:N26) -> 49 | O27: =产品设计部!E7+产品设计部!E8 -> 21455 | P27: =SUM(B27:O27) -> 13568.81
A28: 总计： | B28: =SUM(B3:B27) -> 0 | C28: =SUM(C3:C27) -> 0 | D28: =SUM(D3:D27) -> 0 | E28: =SUM(E3:E27) -> 0 | F28: =SUM(F3:F27) -> -50384.81 | G28: =SUM(G3:G27) -> 0 | H28: =SUM(H3:H27) -> 0 | I28: =SUM(I3:I27) -> 98563.59 | ... O28: =SUM(O3:O27) -> 23459.36 | P28: =SUM(B28:O28) -> 53292.76
A31: 负数为超出预算部分

Sheet 付款统计表
A1: 月付款汇总表
A2: 部门 | B2: CEO办公室 | C2: 总裁办 | D2: 组织部 | E2: 财务部 | F2: 设计部 | G2: 市场部 | H2: 线下销售 | I2: 线上运营部-运营一组 | J2: 线上运营部-运营二组 | K2: 线上运营部-代销平台组 | L2: 线上运营部-渠道组 | M2: 线上运营部-销售支持组 | N2: 线上运营部-其他 | O2: 研发部 | P2: 品质部 | Q2: 供应链部 | R2: IT部 | S2: 其他 | T2: 合计
A3: 费用明细
A4: 招聘费 | B4: 0 | C4: 0 | D4: 0 | E4: 0 | F4: 0 | G4: 0 | H4: 0 | I4: 0 | J4: 0 | K4: 0 | L4: 0 | M4: 0 | N4: 0 | O4: 0 | P4: 0 | Q4: 0 | R4: 0 | S4: 0 | T4: =SUM(B4:S4) -> 0
A5: 租金、物业费（非线下门店） | B5: 0 | C5: 0 | D5: 196530.32 | E5: 0 | F5: 0 | G5: 0 | H5: 0 | I5: 0 | J5: 0 | K5: 0 | L5: 0 | M5: 0 | N5: 0 | O5: 0 | P5: 0 | Q5: 0 | R5: 0 | S5: 0 | T5: =SUM(B5:S5) -> 196530.32
A6: 水电费（非线下门店） | B6: 0 | C6: 0 | D6: 19226.22 | E6: 0 | F6: 0 | G6: 0 | H6: 0 | I6: 0 | J6: 0 | K6: 0 | L6: 0 | M6: 0 | N6: 0 | O6: 0 | P6: 0 | Q6: 0 | R6: 0 | S6: 0 | T6: =SUM(B6:S6) -> 19226.22
A7: 门店租金&物业费 | B7: 0 | C7: 0 | D7: 0 | E7: 0 | F7: 0 | G7: 0 | H7: 253114.84 | I7: 0 | J7: 0 | K7: 0 | L7: 0 | M7: 0 | N7: 0 | O7: 0 | P7: 0 | Q7: 0 | R7: 0 | S7: 0 | T7: =SUM(B7:S7) -> 253114.84
A8: 门店水电费 | B8: 0 | C8: 0 | D8: 0 | E8: 0 | F8: 0 | G8: 0 | H8: 6798.5 | I8: 0 | J8: 0 | K8: 0 | L8: 0 | M8: 0 | N8: 0 | O8: 0 | P8: 0 | Q8: 0 | R8: 0 | S8: 0 | T8: =SUM(B8:S8) -> 6798.5
A9: 门店推广费 | B9: 0 | C9: 0 | D9: 0 | E9: 0 | F9: 0 | G9: 0 | H9: 3415.55 | I9: 0 | J9: 0 | K9: 0 | L9: 0 | M9: 0 | N9: 0 | O9: 0 | P9: 0 | Q9: 0 | R9: 0 | S9: 0 | T9: =SUM(B9:S9) -> 3415.55
A10: 门店POS机租金 | B10: 0 | C10: 0 | D10: 0 | E10: 0 | F10: 0 | G10: 0 | H10: 3500 | I10: 0 | J10: 0 | K10: 0 | L10: 0 | M10: 0 | N10: 0 | O10: 0 | P10: 0 | Q10: 0 | R10: 0 | S10: 0 | T10: =SUM(B10:S10) -> 3500
A11: 门店其他 | B11: 0 | C11: 0 | D11: 0 | E11: 0 | F11: 0 | G11: 0 | H11: 1172.34 | I11: 0 | J11: 0 | K11: 0 | L11: 0 | M11: 0 | N11: 0 | O11: 0 | P11: 0 | Q11: 0 | R11: 0 | S11: 0 | T11: =SUM(B11:S11) -> 1172.34
A12: 门店租金押金 | B12: 0 | C12: 0 | D12: 0 | E12: 0 | F12: 0 | G12: 0 | H12: 0 | I12: 0 | J12: 0 | K12: 0 | L12: 0 | M12: 0 | N12: 0 | O12: 0 | P12: 0 | Q12: 0 | R12: 0 | S12: 0 | T12: =SUM(B12:S12) -> 0
A13: 门店装修押金 | B13: 0 | C13: 0 | D13: 0 | E13: 0 | F13: 0 | G13: 0 | H13: 0 | I13: 0 | J13: 0 | K13: 0 | L13: 0 | M13: 0 | N13: 0 | O13: 0 | P13: 0 | Q13: 0 | R13: 0 | S13: 0 | T13: =SUM(B13:S13) -> 0
A14: 门店质保金 | B14: 0 | C14: 0 | D14: 0 | E14: 0 | F14: 0 | G14: 0 | H14: 0 | I14: 0 | J14: 0 | K14: 0 | L14: 0 | M14: 0 | N14: 0 | O14: 0 | P14: 0 | Q14: 0 | R14: 0 | S14: 0 | T14: =SUM(B14:S14) -> 0
A15: 门店物业保证金 | B15: 0 | C15: 0 | D15: 0 | E15: 0 | F15: 0 | G15: 0 | H15: 0 | I15: 0 | J15: 0 | K15: 0 | L15: 0 | M15: 0 | N15: 0 | O15: 0 | P15: 0 | Q15: 0 | R15: 0 | S15: 0 | T15: =SUM(B15:S15) -> 0
... A93: 其他 | B93: 27056 | C93: 12895.52 | D93: 41734.96 | E93: 17 | F93: 0 | G93: 0 | H93: 38365 | I93: 725 | J93: 0 | K93: 0 | L93: 2000 | M93: 0 | N93: 0 | O93: 15545 | P93: 0 | Q93: 345 | R93: 150 | S93: 0 | T93: =SUM(B93:S93) -> 138833.48
A94: 合计 | B94: =SUM(B4:B93) -> 28746.7 | C94: =SUM(C4:C93) -> 66436.41 | D94: =SUM(D4:D93) -> 1929613.1 | E94: =SUM(E4:E93) -> 1962436.7 | F94: =SUM(F4:F93) -> 140517.66 | G94: =SUM(G4:G93) -> 1390 | H94: =SUM(H4:H93) -> 360050.01 | I94: =SUM(I4:I93) -> 409048.99 | ... T94: =SUM(T4:T93) -> 5604188.6
A98: 2017年（7）月付款统计表-付款
A99: 部门 | B99: CEO办公室 | C99: 总裁办 | D99: 组织部 | E99: 财务部 | F99: 设计部 | G99: 市场部 | H99: 线下销售 | I99: 线上运营部-运营一组 | J99: 线上运营部-运营二组 | K99: 线上运营部-代销平台组 | L99: 线上运营部-渠道组 | M99: 线上运营部-销售支持组 | N99: 线上运营部-其他 | O99: 研发部 | P99: 品质部 | Q99: 供应链部 | R99: IT部 | S99: 其他 | T99: 合计
A100: 费用明细
A101: 招聘费 | B101: 0 | C101: 0 | D101: 0 | E101: 0 | F101: 0 | G101: 0 | H101: 0 | I101: 0 | J101: 0 | K101: 0 | L101: 0 | M101: 0 | N101: 0 | O101: 0 | P101: 0 | Q101: 0 | R101: 0 | S101: 0 | T101: =SUM(B101:S101) -> 0
A102: 租金、物业费（非线下门店） | B102: 0 | C102: 0 | D102: 0 | E102: 0 | F102: 0 | G102: 0 | H102: 0 | I102: 0 | J102: 0 | K102: 0 | L102: 0 | M102: 0 | N102: 0 | O102: 0 | P102: 0 | Q102: 0 | R102: 0 | S102: 0 | T102: =SUM(B102:S102) -> 0
A103: 水电费（非线下门店） | B103: 0 | C103: 0 | D103: 0 | E103: 0 | F103: 0 | G103: 0 | H103: 0 | I103: 0 | J103: 0 | K103: 0 | L103: 0 | M103: 0 | N103: 0 | O103: 0 | P103: 0 | Q103: 0 | R103: 0 | S103: 0 | T103: =SUM(B103:S103) -> 0
A104: 门店租金&物业费 | B104: 0 | C104: 0 | D104: 0 | E104: 0 | F104: 0 | G104: 0 | H104: 22146.04 | I104: 0 | J104: 0 | K104: 0 | L104: 0 | M104: 0 | N104: 0 | O104: 0 | P104: 0 | Q104: 0 | R104: 0 | S104: 0 | T104: =SUM(B104:S104) -> 22146.04
A105: 门店水电费 | B105: 0 | C105: 0 | D105: 0 | E105: 0 | F105: 0 | G105: 0 | H105: 496.8 | I105: 0 | J105: 0 | K105: 0 | L105: 0 | M105: 0 | N105: 0 | O105: 0 | P105: 0 | Q105: 0 | R105: 0 | S105: 0 | T105: =SUM(B105:S105) -> 496.8
A106: 门店推广费 | B106: 0 | C106: 0 | D106: 0 | E106: 0 | F106: 0 | G106: 0 | H106: 441 | I106: 0 | J106: 0 | K106: 0 | L106: 0 | M106: 0 | N106: 0 | O106: 0 | P106: 0 | Q106: 0 | R106: 0 | S106: 0 | T106: =SUM(B106:S106) -> 441
A107: 门店POS机租金 | B107: 0 | C107: 0 | D107: 0 | E107: 0 | F107: 0 | G107: 0 | H107: 0 | I107: 0 | J107: 0 | K107: 0 | L107: 0 | M107: 0 | N107: 0 | O107: 0 | P107: 0 | Q107: 0 | R107: 0 | S107: 0 | T107: =SUM(B107:S107) -> 0
A108: 门店其他 | B108: 0 | C108: 0 | D108: 0 | E108: 0 | F108: 0 | G108: 0 | H108: 3200 | I108: 0 | J108: 0 | K108: 0 | L108: 0 | M108: 0 | N108: 0 | O108: 0 | P108: 0 | Q108: 0 | R108: 0 | S108: 0 | T108: =SUM(B108:S108) -> 3200
A109: 门店租金押金 | B109: 0 | C109: 0 | D109: 0 | E109: 0 | F109: 0 | G109: 0 | H109: 0 | I109: 0 | J109: 0 | K109: 0 | L109: 0 | M109: 0 | N109: 0 | O109: 0 | P109: 0 | Q109: 0 | R109: 0 | S109: 0 | T109: =SUM(B109:S109) -> 0
A110: 门店装修押金 | B110: 0 | C110: 0 | D110: 0 | E110: 0 | F110: 0 | G110: 0 | H110: 0 | I110: 0 | J110: 0 | K110: 0 | L110: 0 | M110: 0 | N110: 0 | O110: 0 | P110: 0 | Q110: 0 | R110: 0 | S110: 0 | T110: =SUM(B110:S110) -> 0
A111: 门店质保金 | B111: 0 | C111: 0 | D111: 0 | E111: 0 | F111: 0 | G111: 0 | H111: 0 | I111: 0 | J111: 0 | K111: 0 | L111: 0 | M111: 0 | N111: 0 | O111: 0 | P111: 0 | Q111: 0 | R111: 0 | S111: 0 | T111: =SUM(B111:S111) -> 0
A112: 门店物业保证金 | B112: 0 | C112: 0 | D112: 0 | E112: 0 | F112: 0 | G112: 0 | H112: 0 | I112: 0 | J112: 0 | K112: 0 | L112: 0 | M112: 0 | N112: 0 | O112: 0 | P112: 0 | Q112: 0 | R112: 0 | S112: 0 | T112: =SUM(B112:S112) -> 0
... A188: 其他 | B188: 0 | C188: 0 | D188: 0 | E188: 0 | F188: 50000 | G188: 0 | H188: 0 | I188: 0 | J188: 0 | K188: 0 | L188: 0 | M188: 0 | N188: 0 | O188: 0 | P188: 0 | Q188: 0 | R188: 0 | S188: 59197.75 | T188: =SUM(B188:S188) -> 109197.75
A189: 合计 | B189: =SUM(B101:B188) -> 0 | C189: =SUM(C101:C188) -> 0 | D189: =SUM(D101:D188) -> 6457.3 | E189: =SUM(E101:E188) -> 0 | F189: =SUM(F101:F188) -> 50000 | G189: =SUM(G101:G188) -> 0 | H189: =SUM(H101:H188) -> 31500.84 | I189: =SUM(I101:I188) -> 156148 | ... T189: =SUM(T101:T188) -> 570518.89
A194: 2017年（7）月付款统计表-报销
A195: 部门 | B195: CEO办公室 | C195: 总裁办 | D195: 组织部 | E195: 财务部 | F195: 设计部 | G195: 市场部 | H195: 线下销售 | I195: 线上运营部-运营一组 | J195: 线上运营部-运营二组 | K195: 线上运营部-代销平台组 | L195: 线上运营部-渠道组 | M195: 线上运营部-销售支持组 | N195: 线上运营部-其他 | O195: 研发部 | P195: 品质部 | Q195: 供应链部 | R195: IT部 | S195: 其他 | T195: 合计
A196: 费用明细
A197: 招聘费 | B197: 0 | C197: 0 | D197: 0 | E197: 0 | F197: 0 | G197: 0 | H197: 0 | I197: 0 | J197: 0 | K197: 0 | L197: 0 | M197: 0 | N197: 0 | O197: 0 | P197: 0 | Q197: 0 | R197: 0 | S197: 0 | T197: =SUM(B197:S197) -> 0
A198: 租金、物业费（非线下门店） | B198: 0 | C198: 0 | D198: 0 | E198: 0 | F198: 0 | G198: 0 | H198: 0 | I198: 0 | J198: 0 | K198: 0 | L198: 0 | M198: 0 | N198: 0 | O198: 0 | P198: 0 | Q198: 0 | R198: 0 | S198: 0 | T198: =SUM(B198:S198) -> 0
A199: 水电费（非线下门店） | B199: 0 | C199: 0 | D199: 0 | E199: 0 | F199: 0 | G199: 0 | H199: 0 | I199: 0 | J199: 0 | K199: 0 | L199: 0 | M199: 0 | N199: 0 | O199: 0 | P199: 121 | Q199: 0 | R199: 0 | S199: 0 | T199: =SUM(B199:S199) -> 121
...

Sheet 收款日报表
A1: 月收款日报表
A2: 序号 | B2: 部门 | C2: 公司 | D2: 客户代码 | E2: 匹配收款预算 | F2: 客户/平台 | G2: 本月累计 | H2: 1 | I2: 2 | J2: 3 | K2: 4 | L2: 5 | M2: 6 | N2: 7 | O2: 8 | P2: 9 | Q2: 10 | R2: 11 | S2: 12 | T2: 13 | U2: 14 | V2: 15 | W2: 16 | X2: 17 | Y2: 18 | Z2: 19 | AA2: 20 | AB2: 21 | AC2: 22 | AD2: 23 | AE2: 24 | AF2: 25 | AG2: 26 | AH2: 27 | AI2: 28 | AJ2: 29 | AK2: 30 | AL2: 31
A3: 1 | B3: 直营平台1组 | C3: 深圳兜满 | D3: 00053 | E3: 天猫BU蕉下旗舰店 | F3: bananaumbrella蕉下旗舰店 | G3: =SUM(H3:AL3) -> 1266179.6 | H3: -157713.99 | I3: 228594.22 | J3: 29178.05 | K3: 15263.97 | L3: 28394.89 | O3: 185070.11 | P3: 29093.59 | Q3: 22479.13 | R3: =22163-864.7 -> 21298.3 | S3: 33448.57 | V3: 227567.7 | W3: 27654.3 | X3: 23483.05 | Y3: 13767.97 | Z3: 19446 | AC3: 186441.3 | AD3: 26194 | AE3: 17080.5 | AF3: 12238.2 | AG3: 27043.68 | AJ3: 169174.05 | AK3: 39406.83 | AL3: 41575.14
A4: 2 | B4: 直营平台1组 | D4: 00104 | E4: 淘宝BU蕉下自营店 | F4: bananaumbrella自营店 | G4: =SUM(H4:AL4) -> 272666.15 | H4: -18354.05 | I4: 31232.42 | J4: 8417.18 | K4: 8125.12 | L4: 5395.46 | O4: 19380.19 | P4: 5186 | Q4: 4563.01 | R4: =6763-179 -> 6584 | S4: 6228 | V4: 33556.12 | W4: 8187 | X4: 8280 | Y4: 7512 | Z4: 9353 | AC4: 44024.53 | AD4: 8479.1 | AE4: 20885.74 | AF4: 5516.74 | AG4: 5733 | AJ4: 27040.51 | AK4: 6147.08 | AL4: 11194
A5: 3 | B5: 渠道组 | D5: 00062 | G5: =SUM(H5:AL5) -> 0
A6: 4 | B6: 直营平台1组 | C6: 减字 | D6: 00055 | E6: 天猫BU减字专卖店 | F6: bananaumbrella减字专卖店 | G6: =SUM(H6:AL6) -> 115053.26 | H6: -14595.38 | I6: 23251.06 | J6: =4140.54 -> 4140.54 | K6: 2152.9 | L6: 3276.9 | O6: 12335.54 | P6: 4838 | Q6: 4594 | R6: 5401 | S6: 3679 | V6: =12984 -> 12984 | W6: 12483 | X6: 3310.04 | Y6: 3741 | Z6: 2712 | AC6: =9356-50 -> 9306 | AD6: =3667 -> 3667 | AE6: 1001 | AF6: 2131 | AG6: 2450.11 | AJ6: 7664.01 | AK6: 1903.52 | AL6: 2627.02
A7: 5 | B7: 直营平台2组 | D7: 00054 | E7: 京东POP | F7: 京东钱包bu旗舰店 | G7: =SUM(H7:AL7) -> 60772.78 | I7: 2462.89 | J7: 8168.86 | K7: 2958.24 | L7: 906.74 | O7: 63.95 | P7: 4967.11 | Q7: 2415.57 | R7: 1147.23 | S7: 1045.09 | V7: 4590.14 | W7: 1748.35 | X7: 2813.88 | Y7: 1142.53 | Z7: 6578.97 | AC7: 2107.46 | AD7: 3066.76 | AE7: 230.91 | AF7: 771.45 | AG7: -48.83 | AJ7: 7803.38 | AK7: 3616.85 | AL7: 2215.25
A8: 6 | B8: 直营平台2组 | D8: 00052 | E8: 淘宝kiki小店 | F8: kiki美伞淘宝店 | G8: =SUM(H8:AL8) -> 116770.2 | H8: =9918.87+-27462 -> -17543.13 | I8: 27462 | J8: 3635.4 | K8: 3633 | L8: 2621 | O8: 12026 | P8: 7281 | Q8: 4960 | R8: 3526.5 | S8: 4036 | V8: 17442.43 | W8: 3557 | X8: 4229 | Y8: 2697 | Z8: 4649 | AC8: 9330 | AD8: 2564 | AE8: 2481 | AF8: 2196 | AG8: 2314 | AJ8: 6820 | AK8: =2791 -> 2791 | AL8: 4062
A9: 7 | B9: 直营平台2组 | D9: 00103 | E9: 网易考拉 | F9: 杭州网易印象科技有限公司 | G9: =SUM(H9:AL9) -> 121264.23 | J9: 30339.53 | V9: 26895.27 | AL9: 64029.43
A10: 8 | B10: 直营平台2组 | E10: 稀饭好物 | G10: =SUM(H10:AL10) -> 1840 | K10: 1040 | Y10: 480 | Z10: 320
A11: 9 | B11: 直营平台2组 | D11: 00054 | E11: 京东POP | F11: 深圳科捷物流有限公司 | G11: =SUM(H11:AL11) -> 0
A12: 10 | B12: 代销平台 | C12: 减字 | D12: 00024 | F12: 蜜芽宝贝（天津）信息技术有限公司 | G12: =SUM(H12:AL12) -> 0
A13: 11 | B13: 代销平台 | D13: 00036 | E13: 魅惠所 | F13: 上海魅力惠 | G13: =SUM(H13:AL13) -> 0
A14: 12 | B14: 直营平台1组 | D14: 00034 | E14: 有货 | F14: 有货（江苏）商贸服务有限公司 | G14: =SUM(H14:AL14) -> 64714.78 | L14: 64714.78
A15: 13 | B15: 代销平台 | D15: 00030 | F15: 上海达令网/北京普缇客科技有限公司 | G15: =SUM(H15:AL15) -> 0
A16: 14 | B16: 代销平台 | D16: 00038 | E16: 唯品会 | F16: 唯品会(中国)有限公司 | G16: =SUM(H16:AL16) -> 309931 | Y16: 49043.95 | AC16: 90835.71 | AL16: 170051.34
A17: 15 | B17: 代销平台 | D17: 00027 | E17: 京东自营 | F17: 北京京东世纪贸易有限公司-BU | G17: =SUM(H17:AL17) -> 0
A18: 16 | B18: 代销平台 | D18: 00027 | E18: 京东自营 | F18: 北京京东世纪贸易有限公司-WB | G18: =SUM(H18:AL18) -> 0
A19: 17 | B19: 代销平台 | D19: 00004 | F19: 亚马逊（中国）投资有限公司 | G19: =SUM(H19:AL19) -> 0
A20: 18 | B20: 代销平台 | D20: 00045 | E20: 苏宁 | F20: 苏宁易付宝网络科技有限公司 | G20: =SUM(H20:AL20) -> 0
A21: 19 | B21: 渠道组 | D21: 00251 | G21: =SUM(H21:AL21) -> 16004 | H21: -198564.22 | I21: 1766.92 | J21: 5.9 | K21: 1199.73 | L21: 82.69 | O21: 2399.94 | P21: 1545.67 | Q21: 5.67 | R21: 5.66 | S21: 5.64 | V21: 893.58 | W21: -1809.93 | X21: 1.12 | Y21: 100955.12 | Z21: 102540.11 | AC21: 1156.23 | AD21: 1.1 | AE21: 1.08 | AF21: 3.18 | AG21: 170.23 | AJ21: 3231.65 | AK21: 147.38 | AL21: 259.55
A22: 20 | B22: 渠道组 | D22: 00064 | G22: =SUM(H22:AL22) -> 0
A23: 21 | B23: 渠道组 | G23: =SUM(H23:AL23) -> 0
A24: 22 | B24: 直营平台2组 | D24: 00058 | E24: 有赞 | F24: 有赞 | G24: =SUM(H24:AL24) -> 4869.23 | H24: 57.19 | I24: 136.78 | K24: 95.75 | L24: 267.39 | P24: 728.61 | R24: -169 | S24: 228.62 | V24: 161.72 | W24: 277.33 | X24: 323.44 | Y24: 467.57 | Z24: 986.53 | AC24: 437.02 | AD24: 224.99 | AF24: 89.46 | AK24: 501.97 | AL24: 53.86
A25: 23 | B25: 渠道组 | D25: 00095 | G25: =SUM(H25:AL25) -> 0
A26: 24 | B26: 渠道组 | D26: 00109 | G26: =SUM(H26:AL26) -> 0
A27: 25 | B27: 渠道组 | D27: 00016 | G27: =SUM(H27:AL27) -> 295000 | AE27: 145000 | AF27: 150000
A28: 26 | B28: 渠道组 | D28: 00111 | G28: =SUM(H28:AL28) -> 0
A29: 27 | B29: 渠道组 | D29: 00010 | G29: =SUM(H29:AL29) -> 0
A30: 28 | B30: 渠道组 | D30: 00023 | G30: =SUM(H30:AL30) -> 0
A31: 29 | B31: 渠道组 | D31: 00041 | G31: =SUM(H31:AL31) -> 0
A32: 30 | B32: 渠道组 | D32: 00112 | G32: =SUM(H32:AL32) -> 46610 | AJ32: 46610
A33: 31 | B33: 渠道组 | D33: 00110 | G33: =SUM(H33:AL33) -> 0
A34: 32 | B34: 渠道组 | D34: 00113 | G34: =SUM(H34:AL34) -> 0
A35: 33 | B35: 渠道组 | D35: 00114 | G35: =SUM(H35:AL35) -> 45 | Z35: 45
A36: 34 | B36: 渠道组 | D36: 00000 | G36: =SUM(H36:AL36) -> 35237.19 | I36: 3000 | J36: 33 | L36: 89 | O36: 300 | P36: 1295.17 | Q36: 120 | R36: 0 | S36: 0 | V36: 103.4 | W36: 5.1 | X36: 125 | Y36: 60 | Z36: 59.24 | AD36: 60 | AE36: 5092 | AF36: 31.16 | AG36: -1034.42 | AJ36: 28613.18 | AK36: -1624.16 | AL36: -1090.48
A37: 35 | B37: 渠道组 | D37: 77777 | G37: =SUM(H37:AL37) -> 0
A38: 36 | B38: 渠道组 | D38: 00000 | G38: =SUM(H38:AL38) -> 0
A39: 37 | B39: 渠道组 | D39: 99999 | G39: =SUM(H39:AL39) -> 0
A40: 38 | B40: 渠道组 | D40: 00000 | G40: =SUM(H40:AL40) -> 14952.57 | AF40: =10550.57+4402 -> 14952.57
...

Sheet 货款付款统计表
A1: 月供应商货款支付明细
A2: 支付公司 | B2: 日期 | C2: 供应商代码 | D2: 供应商名称 | E2: 支付内容 | F2: 支付金额
F3: 电汇 | G3: 承兑 | H3: 小计
H4: =F4+G4 -> 0
H5: =F5+G5 -> 0
H6: =F6+G6 -> 0
H7: =F7+G7 -> 0
H8: =F8+G8 -> 0
H9: =F9+G9 -> 0
H10: =F10+G10 -> 0
H11: =F11+G11 -> 0
H12: =F12+G12 -> 0
H13: =F13+G13 -> 0
H14: =F14+G14 -> 0
H15: =F15+G15 -> 0
... H20: =F20+G20 -> 0
F21: =SUM(F4:F20) -> 0 | G21: =SUM(G4:G20) -> 0 | H21: =SUM(H4:H20) -> 0
