Workbook
Name aa: [1]XL4Poppy!$C$39
Name hgf: '[2]#REF'!$A$2:$D$39
Name hhgg: #REF!
Name mydata: OFFSET([3]平台数据汇总!$A$1,1,,COUNTA([3]平台数据汇总!$A:$A),COUNTA([3]平台数据汇总!$2:$2))
Name Print_Area_MI: #REF!
Name 大多数: [4]XL4Poppy!$A$15
Name 飞过海: [5]XL4Poppy!$C$4
Name 费用代码: #REF!
Name 费用项目: #REF!
Name 分析区域: [6]数据源!$B:$F
Name 金额: [6]数据源!$F:$F
Name 明细分类账: [7]明细分类账!$A$1:$Q$261
Name 期初余额: [8]总账!$D$2:$D$25
Name 期末余额: [8]总账!$G$2:$G$25
Name 应收: #REF!
Name 主数据: #REF!
Name 主数据代码: #REF!
Name 主数据项目: #REF!
Name 总账科目: [8]总账!$A$2:$A$25
Name 전: #REF!
Name 주택사업본부: #REF!
Name 철구사업본부: #REF!

Sheet 基础资料
A1: 日期： | B1: 44228
A3: 平台sku | B3: 规格型号 | C3: 亚马逊ASIN | D3: erp sku | E3: sku名称
A4: 6B3008
A5: 6B3009
A6: AHH-01-001
A7: AHJ01005
A8: AHJ01006
A9: AHJ01007
A10: AJH05
A11: TOP01
A12: TOP2001
A13: TOP2002
A14: TOP2003
A15: UINM01
... A21: XXS6B006

Sheet 本地仓-出入库明细
B1: 日期： | C1: =基础资料!B1 -> 44228
B2: 注：灰色部分为公式，不可填数字！ | F2: 本地仓出入库明细表
B3: 日期 | C3: sku | D3: 名称 | E3: 规格型号 | F3: 摘要 | G3: 入库 | J3: 发出物流单号 | K3: 出库数量 | L3: 结存数量
G4: 数量 | H4: 单价 | I4: 金额
B5: 43864 | C5: 6B3008 | F5: 购入 | G5: 2000 | H5: 113.3 | I5: =IF(ISERROR(G5*H5),0,G5*H5) -> 226600 | L5: =VLOOKUP(C5,本地仓!$A:$D,4,0)+SUMIFS(G5,F5,"购入",C5,C5)-SUMIFS(K5,C5,C5,F5,"发出") -> 2000
B6: 43864 | C6: 6B3009 | F6: 购入 | G6: 50 | H6: 351.23 | I6: =IF(ISERROR(G6*H6),0,G6*H6) -> 17561.5 | L6: =VLOOKUP(C6,本地仓!$A:$D,4,0)+SUMIFS(G$5:G6,F$5:F6,"购入",C$5:C6,C6)-SUMIFS(K$5:K6,C$5:C6,C6,F$5:F6,"发出") -> 50
B7: 43864 | C7: AHH-01-001 | F7: 购入 | G7: 268 | H7: 62.445878 | I7: =IF(ISERROR(G7*H7),0,G7*H7) -> 16735.495 | L7: =VLOOKUP(C7,本地仓!$A:$D,4,0)+SUMIFS(G$5:G7,F$5:F7,"购入",C$5:C7,C7)-SUMIFS(K$5:K7,C$5:C7,C7,F$5:F7,"发出") -> 268
B8: 43864 | C8: AHJ01006 | F8: 购入 | G8: 90 | H8: 89.552295 | I8: =IF(ISERROR(G8*H8),0,G8*H8) -> 8059.7065 | L8: =VLOOKUP(C8,本地仓!$A:$D,4,0)+SUMIFS(G$5:G8,F$5:F8,"购入",C$5:C8,C8)-SUMIFS(K$5:K8,C$5:C8,C8,F$5:F8,"发出") -> 390
B9: 43864 | C9: AHJ01007 | F9: 购入 | G9: 480 | H9: 101.47724 | I9: =IF(ISERROR(G9*H9),0,G9*H9) -> 48709.076 | L9: =VLOOKUP(C9,本地仓!$A:$D,4,0)+SUMIFS(G$5:G9,F$5:F9,"购入",C$5:C9,C9)-SUMIFS(K$5:K9,C$5:C9,C9,F$5:F9,"发出") -> 490
B10: 43864 | C10: TOP01 | F10: 购入 | G10: 100 | H10: 227.4586 | I10: =IF(ISERROR(G10*H10),0,G10*H10) -> 22745.86 | L10: =VLOOKUP(C10,本地仓!$A:$D,4,0)+SUMIFS(G$5:G10,F$5:F10,"购入",C$5:C10,C10)-SUMIFS(K$5:K10,C$5:C10,C10,F$5:F10,"发出") -> 110
B11: 43864 | C11: TOP2001 | F11: 购入 | G11: 51 | H11: 103.05169 | I11: =IF(ISERROR(G11*H11),0,G11*H11) -> 5255.6362 | L11: =VLOOKUP(C11,本地仓!$A:$D,4,0)+SUMIFS(G$5:G11,F$5:F11,"购入",C$5:C11,C11)-SUMIFS(K$5:K11,C$5:C11,C11,F$5:F11,"发出") -> 90
B12: 43864 | C12: TOP2002 | F12: 购入 | G12: 140 | H12: 200.74692 | I12: =IF(ISERROR(G12*H12),0,G12*H12) -> 28104.568 | L12: =VLOOKUP(C12,本地仓!$A:$D,4,0)+SUMIFS(G$5:G12,F$5:F12,"购入",C$5:C12,C12)-SUMIFS(K$5:K12,C$5:C12,C12,F$5:F12,"发出") -> 160
B13: 43864 | C13: TOP2003 | F13: 购入 | G13: 290 | H13: 114.19907 | I13: =IF(ISERROR(G13*H13),0,G13*H13) -> 33117.73 | L13: =VLOOKUP(C13,本地仓!$A:$D,4,0)+SUMIFS(G$5:G13,F$5:F13,"购入",C$5:C13,C13)-SUMIFS(K$5:K13,C$5:C13,C13,F$5:F13,"发出") -> 291
B14: 43864 | C14: UINM01 | F14: 购入 | G14: 70 | H14: 139.80612 | I14: =IF(ISERROR(G14*H14),0,G14*H14) -> 9786.4286 | L14: =VLOOKUP(C14,本地仓!$A:$D,4,0)+SUMIFS(G$5:G14,F$5:F14,"购入",C$5:C14,C14)-SUMIFS(K$5:K14,C$5:C14,C14,F$5:F14,"发出") -> 70
B15: 43864 | C15: XXS6B001 | F15: 购入 | G15: 140 | H15: 180.05002 | I15: =IF(ISERROR(G15*H15),0,G15*H15) -> 25207.003 | L15: =VLOOKUP(C15,本地仓!$A:$D,4,0)+SUMIFS(G$5:G15,F$5:F15,"购入",C$5:C15,C15)-SUMIFS(K$5:K15,C$5:C15,C15,F$5:F15,"发出") -> 190
B16: 43864 | C16: XXS6B002 | F16: 购入 | G16: 45 | H16: 115.90529 | I16: =IF(ISERROR(G16*H16),0,G16*H16) -> 5215.7382 | L16: =VLOOKUP(C16,本地仓!$A:$D,4,0)+SUMIFS(G$5:G16,F$5:F16,"购入",C$5:C16,C16)-SUMIFS(K$5:K16,C$5:C16,C16,F$5:F16,"发出") -> 45
B17: 43864 | C17: XXS6B003 | F17: 购入 | G17: 140 | H17: 76.177893 | I17: =IF(ISERROR(G17*H17),0,G17*H17) -> 10664.905 | L17: =VLOOKUP(C17,本地仓!$A:$D,4,0)+SUMIFS(G$5:G17,F$5:F17,"购入",C$5:C17,C17)-SUMIFS(K$5:K17,C$5:C17,C17,F$5:F17,"发出") -> 140
B18: 43864 | C18: XXS6B004 | F18: 购入 | G18: 150 | H18: 71.194425 | I18: =IF(ISERROR(G18*H18),0,G18*H18) -> 10679.164
B19: 43866 | C19: 6B3008 | F19: 发出（发出到海外仓） | I19: =IF(ISERROR(G19*H19),0,G19*H19) -> 0 | J19: A20210215001 | K19: =SUMIFS(物流信息跟踪!$J:$J,物流信息跟踪!$I:$I,$J19,物流信息跟踪!$C:$C,$C19) -> 2500 | L19: =VLOOKUP(C19,本地仓!$A:$D,4,0)+SUMIFS(G$5:G19,F$5:F19,"购入",C$5:C19,C19)-SUMIFS(K$5:K19,C$5:C19,C19,F$5:F19,"发出") -> 2000
B20: 43866 | C20: 6B3009 | F20: 发出（发出到海外仓） | I20: =IF(ISERROR(G20*H20),0,G20*H20) -> 0 | J20: A20210215001 | K20: =SUMIFS(物流信息跟踪!$J:$J,物流信息跟踪!$I:$I,$J20,物流信息跟踪!$C:$C,$C20) -> 417 | L20: =VLOOKUP(C20,本地仓!$A:$D,4,0)+SUMIFS(G$5:G20,F$5:F20,"购入",C$5:C20,C20)-SUMIFS(K$5:K20,C$5:C20,C20,F$5:F20,"发出") -> 50
B21: 43866 | C21: AHH-01-001 | F21: 发出（发出到海外仓） | I21: =IF(ISERROR(G21*H21),0,G21*H21) -> 0 | J21: A20210215001 | K21: =SUMIFS(物流信息跟踪!$J:$J,物流信息跟踪!$I:$I,$J21,物流信息跟踪!$C:$C,$C21) -> 0 | L21: =VLOOKUP(C21,本地仓!$A:$D,4,0)+SUMIFS(G$5:G21,F$5:F21,"购入",C$5:C21,C21)-SUMIFS(K$5:K21,C$5:C21,C21,F$5:F21,"发出") -> 268
B22: 43866 | C22: AHJ01006 | F22: 发出（发出到海外仓） | I22: =IF(ISERROR(G22*H22),0,G22*H22) -> 0 | J22: A20210215001 | K22: =SUMIFS(物流信息跟踪!$J:$J,物流信息跟踪!$I:$I,$J22,物流信息跟踪!$C:$C,$C22) -> 415 | L22: =VLOOKUP(C22,本地仓!$A:$D,4,0)+SUMIFS(G$5:G22,F$5:F22,"购入",C$5:C22,C22)-SUMIFS(K$5:K22,C$5:C22,C22,F$5:F22,"发出") -> 390
B23: 43866 | C23: AHJ01007 | F23: 发出（发出到海外仓） | I23: =IF(ISERROR(G23*H23),0,G23*H23) -> 0 | J23: A20210215001 | K23: =SUMIFS(物流信息跟踪!$J:$J,物流信息跟踪!$I:$I,$J23,物流信息跟踪!$C:$C,$C23) -> 490 | L23: =VLOOKUP(C23,本地仓!$A:$D,4,0)+SUMIFS(G$5:G23,F$5:F23,"购入",C$5:C23,C23)-SUMIFS(K$5:K23,C$5:C23,C23,F$5:F23,"发出") -> 490
B24: 43866 | C24: TOP01 | F24: 发出（发出到海外仓） | I24: =IF(ISERROR(G24*H24),0,G24*H24) -> 0 | J24: A20210215001 | K24: =SUMIFS(物流信息跟踪!$J:$J,物流信息跟踪!$I:$I,$J24,物流信息跟踪!$C:$C,$C24) -> 0 | L24: =VLOOKUP(C24,本地仓!$A:$D,4,0)+SUMIFS(G$5:G24,F$5:F24,"购入",C$5:C24,C24)-SUMIFS(K$5:K24,C$5:C24,C24,F$5:F24,"发出") -> 110
B25: 43866 | C25: TOP2001 | F25: 发出（发出到海外仓） | I25: =IF(ISERROR(G25*H25),0,G25*H25) -> 0 | J25: A20210215001 | K25: =SUMIFS(物流信息跟踪!$J:$J,物流信息跟踪!$I:$I,$J25,物流信息跟踪!$C:$C,$C25) -> 90 | L25: =VLOOKUP(C25,本地仓!$A:$D,4,0)+SUMIFS(G$5:G25,F$5:F25,"购入",C$5:C25,C25)-SUMIFS(K$5:K25,C$5:C25,C25,F$5:F25,"发出") -> 90
B26: 43866 | C26: TOP2002 | F26: 发出（发出到海外仓） | I26: =IF(ISERROR(G26*H26),0,G26*H26) -> 0 | J26: A20210215001 | K26: =SUMIFS(物流信息跟踪!$J:$J,物流信息跟踪!$I:$I,$J26,物流信息跟踪!$C:$C,$C26) -> 140 | L26: =VLOOKUP(C26,本地仓!$A:$D,4,0)+SUMIFS(G$5:G26,F$5:F26,"购入",C$5:C26,C26)-SUMIFS(K$5:K26,C$5:C26,C26,F$5:F26,"发出") -> 160
B27: 43866 | C27: TOP2003 | F27: 发出（发出到海外仓） | I27: =IF(ISERROR(G27*H27),0,G27*H27) -> 0 | J27: A20210215001 | K27: =SUMIFS(物流信息跟踪!$J:$J,物流信息跟踪!$I:$I,$J27,物流信息跟踪!$C:$C,$C27) -> 290 | L27: =VLOOKUP(C27,本地仓!$A:$D,4,0)+SUMIFS(G$5:G27,F$5:F27,"购入",C$5:C27,C27)-SUMIFS(K$5:K27,C$5:C27,C27,F$5:F27,"发出") -> 291
B28: 43866 | C28: UINM01 | F28: 发出（发出到海外仓） | I28: =IF(ISERROR(G28*H28),0,G28*H28) -> 0 | J28: A20210215001 | K28: =SUMIFS(物流信息跟踪!$J:$J,物流信息跟踪!$I:$I,$J28,物流信息跟踪!$C:$C,$C28) -> 0 | L28: =VLOOKUP(C28,本地仓!$A:$D,4,0)+SUMIFS(G$5:G28,F$5:F28,"购入",C$5:C28,C28)-SUMIFS(K$5:K28,C$5:C28,C28,F$5:F28,"发出") -> 70
B29: 43866 | C29: XXS6B001 | F29: 发出（发出到海外仓） | I29: =IF(ISERROR(G29*H29),0,G29*H29) -> 0 | J29: A20210215001 | K29: =SUMIFS(物流信息跟踪!$J:$J,物流信息跟踪!$I:$I,$J29,物流信息跟踪!$C:$C,$C29) -> 0 | L29: =VLOOKUP(C29,本地仓!$A:$D,4,0)+SUMIFS(G$5:G29,F$5:F29,"购入",C$5:C29,C29)-SUMIFS(K$5:K29,C$5:C29,C29,F$5:F29,"发出") -> 190
B30: 43866 | C30: XXS6B002 | F30: 发出（发出到海外仓） | I30: =IF(ISERROR(G30*H30),0,G30*H30) -> 0 | J30: A20210215001 | K30: =SUMIFS(物流信息跟踪!$J:$J,物流信息跟踪!$I:$I,$J30,物流信息跟踪!$C:$C,$C30) -> 45 | L30: =VLOOKUP(C30,本地仓!$A:$D,4,0)+SUMIFS(G$5:G30,F$5:F30,"购入",C$5:C30,C30)-SUMIFS(K$5:K30,C$5:C30,C30,F$5:F30,"发出") -> 45
... B32: 43866 | C32: XXS6B004 | F32: 发出（发出到海外仓） | I32: =IF(ISERROR(G32*H32),0,G32*H32) -> 0 | J32: A20210215001 | K32: =SUMIFS(物流信息跟踪!$J:$J,物流信息跟踪!$I:$I,$J32,物流信息跟踪!$C:$C,$C32) -> 0 | L32: =VLOOKUP(C32,本地仓!$A:$D,4,0)+SUMIFS(G$5:G32,F$5:F32,"购入",C$5:C32,C32)-SUMIFS(K$5:K32,C$5:C32,C32,F$5:F32,"发出") -> 150
B33: 合计 | G33: =SUM(G5:G32) -> 4014 | I33: =SUM(I5:I32) -> 468442.81 | K33: =SUM(K5:K32) -> 4527

Sheet 本地仓
A1: 日期： | B1: ='本地仓-出入库明细'!C1 -> 44228
A2: 注：灰色部分为公式，不可填数字！ | G2: 本地仓进销存报表 单位：元
A3: sku | B3: 名称 | C3: 规格型号 | D3: 期初 | G3: 入库（供应商采购） | J3: 出库（发出到海外仓） | M3: 出库（退回给供应商） | P3: 结存
D4: 数量 | E4: 单价 | F4: 金额 | G4: 数量 | H4: 单价 | I4: 金额 | J4: 数量 | K4: 单价 | L4: 金额 | M4: 数量 | N4: 单价 | O4: 金额 | P4: 数量 | Q4: 单价 | R4: 金额
A5: 6B3008 | D5: 0 | E5: 110 | F5: =D5*E5 -> 0 | G5: =SUMIFS('本地仓-出入库明细'!$G:$G,'本地仓-出入库明细'!$C:$C,$A5,'本地仓-出入库明细'!$F:$F,"购入") -> 2000 | H5: =IF(ISERROR(I5/G5),0,I5/G5) -> 113.3 | I5: =SUMIFS('本地仓-出入库明细'!$I:$I,'本地仓-出入库明细'!$C:$C,$A5,'本地仓-出入库明细'!$F:$F,"购入") -> 226600 | J5: -1800 | K5: =IFERROR((F5+I5)/(D5+G5),0) -> 113.3 | L5: =IFERROR(J5*K5,0) -> -203940 | M5: =-SUMIFS('本地仓-出入库明细'!$K:$K,'本地仓-出入库明细'!$C:$C,$A5,'本地仓-出入库明细'!$F:$F,"发出（退回给供应商）") -> 0 | N5: =IFERROR((I5+L5)/(G5+J5),"") -> 113.3 | O5: =IFERROR(M5*N5,0) -> 0 | P5: =D5+G5+J5+M5 -> 200 | Q5: =IF(ISERROR(R5/P5),0,R5/P5) -> 113.3 | R5: =F5+I5+L5+O5 -> 22660
A6: 6B3009 | D6: 0 | E6: 341 | F6: =D6*E6 -> 0 | G6: =SUMIFS('本地仓-出入库明细'!$G:$G,'本地仓-出入库明细'!$C:$C,$A6,'本地仓-出入库明细'!$F:$F,"购入") -> 50 | H6: =IF(ISERROR(I6/G6),0,I6/G6) -> 351.23 | I6: =SUMIFS('本地仓-出入库明细'!$I:$I,'本地仓-出入库明细'!$C:$C,$A6,'本地仓-出入库明细'!$F:$F,"购入") -> 17561.5 | J6: -20 | K6: =IFERROR((F6+I6)/(D6+G6),0) -> 351.23 | L6: =IFERROR(J6*K6,0) -> -7024.6 | M6: =-SUMIFS('本地仓-出入库明细'!$K:$K,'本地仓-出入库明细'!$C:$C,$A6,'本地仓-出入库明细'!$F:$F,"发出（退回给供应商）") -> 0 | N6: =IFERROR((I6+L6)/(G6+J6),"") -> 351.23 | O6: =IFERROR(M6*N6,0) -> 0 | P6: =D6+G6+J6+M6 -> 30 | Q6: =IF(ISERROR(R6/P6),0,R6/P6) -> 351.23 | R6: =F6+I6+L6+O6 -> 10536.9
A7: AHH-01-001 | D7: 0 | E7: 60.627066 | F7: =D7*E7 -> 0 | G7: =SUMIFS('本地仓-出入库明细'!$G:$G,'本地仓-出入库明细'!$C:$C,$A7,'本地仓-出入库明细'!$F:$F,"购入") -> 268 | H7: =IF(ISERROR(I7/G7),0,I7/G7) -> 62.445878 | I7: =SUMIFS('本地仓-出入库明细'!$I:$I,'本地仓-出入库明细'!$C:$C,$A7,'本地仓-出入库明细'!$F:$F,"购入") -> 16735.495 | J7: =-SUMIFS('本地仓-出入库明细'!$K:$K,'本地仓-出入库明细'!$C:$C,$A7,'本地仓-出入库明细'!$F:$F,"发出（发出到海外仓）") -> 0 | K7: =IFERROR((F7+I7)/(D7+G7),0) -> 62.445878 | L7: =IFERROR(J7*K7,0) -> 0 | M7: =-SUMIFS('本地仓-出入库明细'!$K:$K,'本地仓-出入库明细'!$C:$C,$A7,'本地仓-出入库明细'!$F:$F,"发出（退回给供应商）") -> 0 | N7: =IFERROR((I7+L7)/(G7+J7),"") -> 62.445878 | O7: =IFERROR(M7*N7,0) -> 0 | P7: =D7+G7+J7+M7 -> 268 | Q7: =IF(ISERROR(R7/P7),0,R7/P7) -> 62.445878 | R7: =F7+I7+L7+O7 -> 16735.495
A8: AHJ01005 | D8: 0 | E8: 78.048026 | F8: =D8*E8 -> 0 | G8: =SUMIFS('本地仓-出入库明细'!$G:$G,'本地仓-出入库明细'!$C:$C,$A8,'本地仓-出入库明细'!$F:$F,"购入") -> 0 | H8: =IF(ISERROR(I8/G8),0,I8/G8) -> 0 | I8: =SUMIFS('本地仓-出入库明细'!$I:$I,'本地仓-出入库明细'!$C:$C,$A8,'本地仓-出入库明细'!$F:$F,"购入") -> 0 | J8: =-SUMIFS('本地仓-出入库明细'!$K:$K,'本地仓-出入库明细'!$C:$C,$A8,'本地仓-出入库明细'!$F:$F,"发出（发出到海外仓）") -> 0 | K8: =IFERROR((F8+I8)/(D8+G8),0) -> 0 | L8: =IFERROR(J8*K8,0) -> 0 | M8: =-SUMIFS('本地仓-出入库明细'!$K:$K,'本地仓-出入库明细'!$C:$C,$A8,'本地仓-出入库明细'!$F:$F,"发出（退回给供应商）") -> 0 | N8: =IFERROR((I8+L8)/(G8+J8),"") | O8: =IFERROR(M8*N8,0) -> 0 | P8: =D8+G8+J8+M8 -> 0 | Q8: =IF(ISERROR(R8/P8),0,R8/P8) -> 0 | R8: =F8+I8+L8+O8 -> 0
A9: AHJ01006 | D9: 300 | E9: 86.943976 | F9: =D9*E9 -> 26083.193 | G9: =SUMIFS('本地仓-出入库明细'!$G:$G,'本地仓-出入库明细'!$C:$C,$A9,'本地仓-出入库明细'!$F:$F,"购入") -> 90 | H9: =IF(ISERROR(I9/G9),0,I9/G9) -> 89.552295 | I9: =SUMIFS('本地仓-出入库明细'!$I:$I,'本地仓-出入库明细'!$C:$C,$A9,'本地仓-出入库明细'!$F:$F,"购入") -> 8059.7065 | J9: -60 | K9: =IFERROR((F9+I9)/(D9+G9),0) -> 87.545895 | L9: =IFERROR(J9*K9,0) -> -5252.7537 | M9: =-SUMIFS('本地仓-出入库明细'!$K:$K,'本地仓-出入库明细'!$C:$C,$A9,'本地仓-出入库明细'!$F:$F,"发出（退回给供应商）") -> 0 | N9: =IFERROR((I9+L9)/(G9+J9),"") -> 93.565094 | O9: =IFERROR(M9*N9,0) -> 0 | P9: =D9+G9+J9+M9 -> 330 | Q9: =IF(ISERROR(R9/P9),0,R9/P9) -> 87.545895 | R9: =F9+I9+L9+O9 -> 28890.145
A10: AHJ01007 | D10: 10 | E10: 101.47724 | F10: =D10*E10 -> 1014.7724 | G10: =SUMIFS('本地仓-出入库明细'!$G:$G,'本地仓-出入库明细'!$C:$C,$A10,'本地仓-出入库明细'!$F:$F,"购入") -> 480 | H10: =IF(ISERROR(I10/G10),0,I10/G10) -> 101.47724 | I10: =SUMIFS('本地仓-出入库明细'!$I:$I,'本地仓-出入库明细'!$C:$C,$A10,'本地仓-出入库明细'!$F:$F,"购入") -> 48709.076 | J10: =-SUMIFS('本地仓-出入库明细'!$K:$K,'本地仓-出入库明细'!$C:$C,$A10,'本地仓-出入库明细'!$F:$F,"发出（发出到海外仓）") -> -490 | K10: =IFERROR((F10+I10)/(D10+G10),0) -> 101.47724 | L10: =IFERROR(J10*K10,0) -> -49723.848 | M10: =-SUMIFS('本地仓-出入库明细'!$K:$K,'本地仓-出入库明细'!$C:$C,$A10,'本地仓-出入库明细'!$F:$F,"发出（退回给供应商）") -> 0 | N10: =IFERROR((I10+L10)/(G10+J10),"") -> 101.47724 | O10: =IFERROR(M10*N10,0) -> 0 | P10: =D10+G10+J10+M10 -> 0 | Q10: =IF(ISERROR(R10/P10),0,R10/P10) -> 0 | R10: =F10+I10+L10+O10 -> 5.0931703e-11
A11: AJH05 | D11: 33 | E11: 107.40351 | F11: =D11*E11 -> 3544.3159 | G11: =SUMIFS('本地仓-出入库明细'!$G:$G,'本地仓-出入库明细'!$C:$C,$A11,'本地仓-出入库明细'!$F:$F,"购入") -> 0 | H11: =IF(ISERROR(I11/G11),0,I11/G11) -> 0 | I11: =SUMIFS('本地仓-出入库明细'!$I:$I,'本地仓-出入库明细'!$C:$C,$A11,'本地仓-出入库明细'!$F:$F,"购入") -> 0 | J11: =-SUMIFS('本地仓-出入库明细'!$K:$K,'本地仓-出入库明细'!$C:$C,$A11,'本地仓-出入库明细'!$F:$F,"发出（发出到海外仓）") -> 0 | K11: =IFERROR((F11+I11)/(D11+G11),0) -> 107.40351 | L11: =IFERROR(J11*K11,0) -> 0 | M11: =-SUMIFS('本地仓-出入库明细'!$K:$K,'本地仓-出入库明细'!$C:$C,$A11,'本地仓-出入库明细'!$F:$F,"发出（退回给供应商）") -> 0 | N11: =IFERROR((I11+L11)/(G11+J11),"") | O11: =IFERROR(M11*N11,0) -> 0 | P11: =D11+G11+J11+M11 -> 33 | Q11: =IF(ISERROR(R11/P11),0,R11/P11) -> 107.40351 | R11: =F11+I11+L11+O11 -> 3544.3159
A12: TOP01 | D12: 10 | E12: 227.4586 | F12: =D12*E12 -> 2274.586 | G12: =SUMIFS('本地仓-出入库明细'!$G:$G,'本地仓-出入库明细'!$C:$C,$A12,'本地仓-出入库明细'!$F:$F,"购入") -> 100 | H12: =IF(ISERROR(I12/G12),0,I12/G12) -> 227.4586 | I12: =SUMIFS('本地仓-出入库明细'!$I:$I,'本地仓-出入库明细'!$C:$C,$A12,'本地仓-出入库明细'!$F:$F,"购入") -> 22745.86 | J12: =-SUMIFS('本地仓-出入库明细'!$K:$K,'本地仓-出入库明细'!$C:$C,$A12,'本地仓-出入库明细'!$F:$F,"发出（发出到海外仓）") -> 0 | K12: =IFERROR((F12+I12)/(D12+G12),0) -> 227.4586 | L12: =IFERROR(J12*K12,0) -> 0 | M12: =-SUMIFS('本地仓-出入库明细'!$K:$K,'本地仓-出入库明细'!$C:$C,$A12,'本地仓-出入库明细'!$F:$F,"发出（退回给供应商）") -> 0 | N12: =IFERROR((I12+L12)/(G12+J12),"") -> 227.4586 | O12: =IFERROR(M12*N12,0) -> 0 | P12: =D12+G12+J12+M12 -> 110 | Q12: =IF(ISERROR(R12/P12),0,R12/P12) -> 227.4586 | R12: =F12+I12+L12+O12 -> 25020.446
A13: TOP2001 | D13: 39 | E13: 103.05169 | F13: =D13*E13 -> 4019.0159 | G13: =SUMIFS('本地仓-出入库明细'!$G:$G,'本地仓-出入库明细'!$C:$C,$A13,'本地仓-出入库明细'!$F:$F,"购入") -> 51 | H13: =IF(ISERROR(I13/G13),0,I13/G13) -> 103.05169 | I13: =SUMIFS('本地仓-出入库明细'!$I:$I,'本地仓-出入库明细'!$C:$C,$A13,'本地仓-出入库明细'!$F:$F,"购入") -> 5255.6362 | J13: =-SUMIFS('本地仓-出入库明细'!$K:$K,'本地仓-出入库明细'!$C:$C,$A13,'本地仓-出入库明细'!$F:$F,"发出（发出到海外仓）") -> -90 | K13: =IFERROR((F13+I13)/(D13+G13),0) -> 103.05169 | L13: =IFERROR(J13*K13,0) -> -9274.6521 | M13: =-SUMIFS('本地仓-出入库明细'!$K:$K,'本地仓-出入库明细'!$C:$C,$A13,'本地仓-出入库明细'!$F:$F,"发出（退回给供应商）") -> 0 | N13: =IFERROR((I13+L13)/(G13+J13),"") -> 103.05169 | O13: =IFERROR(M13*N13,0) -> 0 | P13: =D13+G13+J13+M13 -> 0 | Q13: =IF(ISERROR(R13/P13),0,R13/P13) -> 0 | R13: =F13+I13+L13+O13 -> 0
A14: TOP2002 | D14: 20 | E14: 200.74692 | F14: =D14*E14 -> 4014.9383 | G14: =SUMIFS('本地仓-出入库明细'!$G:$G,'本地仓-出入库明细'!$C:$C,$A14,'本地仓-出入库明细'!$F:$F,"购入") -> 140 | H14: =IF(ISERROR(I14/G14),0,I14/G14) -> 200.74692 | I14: =SUMIFS('本地仓-出入库明细'!$I:$I,'本地仓-出入库明细'!$C:$C,$A14,'本地仓-出入库明细'!$F:$F,"购入") -> 28104.568 | J14: =-SUMIFS('本地仓-出入库明细'!$K:$K,'本地仓-出入库明细'!$C:$C,$A14,'本地仓-出入库明细'!$F:$F,"发出（发出到海外仓）") -> -140 | K14: =IFERROR((F14+I14)/(D14+G14),0) -> 200.74692 | L14: =IFERROR(J14*K14,0) -> -28104.568 | M14: =-SUMIFS('本地仓-出入库明细'!$K:$K,'本地仓-出入库明细'!$C:$C,$A14,'本地仓-出入库明细'!$F:$F,"发出（退回给供应商）") -> 0 | N14: =IFERROR((I14+L14)/(G14+J14),"") | O14: =IFERROR(M14*N14,0) -> 0 | P14: =D14+G14+J14+M14 -> 20 | Q14: =IF(ISERROR(R14/P14),0,R14/P14) -> 200.74692 | R14: =F14+I14+L14+O14 -> 4014.9383
A15: TOP2003 | D15: 1 | E15: 110.87288 | F15: =D15*E15 -> 110.87288 | G15: =SUMIFS('本地仓-出入库明细'!$G:$G,'本地仓-出入库明细'!$C:$C,$A15,'本地仓-出入库明细'!$F:$F,"购入") -> 290 | H15: =IF(ISERROR(I15/G15),0,I15/G15) -> 114.19907 | I15: =SUMIFS('本地仓-出入库明细'!$I:$I,'本地仓-出入库明细'!$C:$C,$A15,'本地仓-出入库明细'!$F:$F,"购入") -> 33117.73 | J15: =-SUMIFS('本地仓-出入库明细'!$K:$K,'本地仓-出入库明细'!$C:$C,$A15,'本地仓-出入库明细'!$F:$F,"发出（发出到海外仓）") -> -290 | K15: =IFERROR((F15+I15)/(D15+G15),0) -> 114.18764 | L15: =IFERROR(J15*K15,0) -> -33114.415 | M15: =-SUMIFS('本地仓-出入库明细'!$K:$K,'本地仓-出入库明细'!$C:$C,$A15,'本地仓-出入库明细'!$F:$F,"发出（退回给供应商）") -> 0 | N15: =IFERROR((I15+L15)/(G15+J15),"") | O15: =IFERROR(M15*N15,0) -> 0 | P15: =D15+G15+J15+M15 -> 1 | Q15: =IF(ISERROR(R15/P15),0,R15/P15) -> 114.18764 | R15: =F15+I15+L15+O15 -> 114.18764
A16: UINM01 | D16: 0 | E16: 135.7341 | F16: =D16*E16 -> 0 | G16: =SUMIFS('本地仓-出入库明细'!$G:$G,'本地仓-出入库明细'!$C:$C,$A16,'本地仓-出入库明细'!$F:$F,"购入") -> 70 | H16: =IF(ISERROR(I16/G16),0,I16/G16) -> 139.80612 | I16: =SUMIFS('本地仓-出入库明细'!$I:$I,'本地仓-出入库明细'!$C:$C,$A16,'本地仓-出入库明细'!$F:$F,"购入") -> 9786.4286 | J16: =-SUMIFS('本地仓-出入库明细'!$K:$K,'本地仓-出入库明细'!$C:$C,$A16,'本地仓-出入库明细'!$F:$F,"发出（发出到海外仓）") -> 0 | K16: =IFERROR((F16+I16)/(D16+G16),0) -> 139.80612 | L16: =IFERROR(J16*K16,0) -> 0 | M16: =-SUMIFS('本地仓-出入库明细'!$K:$K,'本地仓-出入库明细'!$C:$C,$A16,'本地仓-出入库明细'!$F:$F,"发出（退回给供应商）") -> 0 | N16: =IFERROR((I16+L16)/(G16+J16),"") -> 139.80612 | O16: =IFERROR(M16*N16,0) -> 0 | P16: =D16+G16+J16+M16 -> 70 | Q16: =IF(ISERROR(R16/P16),0,R16/P16) -> 139.80612 | R16: =F16+I16+L16+O16 -> 9786.4286
A17: XXS6B001 | D17: 50 | E17: 178.26735 | F17: =D17*E17 -> 8913.3674 | G17: =SUMIFS('本地仓-出入库明细'!$G:$G,'本地仓-出入库明细'!$C:$C,$A17,'本地仓-出入库明细'!$F:$F,"购入") -> 140 | H17: =IF(ISERROR(I17/G17),0,I17/G17) -> 180.05002 | I17: =SUMIFS('本地仓-出入库明细'!$I:$I,'本地仓-出入库明细'!$C:$C,$A17,'本地仓-出入库明细'!$F:$F,"购入") -> 25207.003 | J17: =-SUMIFS('本地仓-出入库明细'!$K:$K,'本地仓-出入库明细'!$C:$C,$A17,'本地仓-出入库明细'!$F:$F,"发出（发出到海外仓）") -> 0 | K17: =IFERROR((F17+I17)/(D17+G17),0) -> 179.5809 | L17: =IFERROR(J17*K17,0) -> 0 | M17: =-SUMIFS('本地仓-出入库明细'!$K:$K,'本地仓-出入库明细'!$C:$C,$A17,'本地仓-出入库明细'!$F:$F,"发出（退回给供应商）") -> 0 | N17: =IFERROR((I17+L17)/(G17+J17),"") -> 180.05002 | O17: =IFERROR(M17*N17,0) -> 0 | P17: =D17+G17+J17+M17 -> 190 | Q17: =IF(ISERROR(R17/P17),0,R17/P17) -> 179.5809 | R17: =F17+I17+L17+O17 -> 34120.37
A18: XXS6B002 | D18: 0 | E18: 114.75772 | F18: =D18*E18 -> 0 | G18: =SUMIFS('本地仓-出入库明细'!$G:$G,'本地仓-出入库明细'!$C:$C,$A18,'本地仓-出入库明细'!$F:$F,"购入") -> 45 | H18: =IF(ISERROR(I18/G18),0,I18/G18) -> 115.90529 | I18: =SUMIFS('本地仓-出入库明细'!$I:$I,'本地仓-出入库明细'!$C:$C,$A18,'本地仓-出入库明细'!$F:$F,"购入") -> 5215.7382 | J18: =-SUMIFS('本地仓-出入库明细'!$K:$K,'本地仓-出入库明细'!$C:$C,$A18,'本地仓-出入库明细'!$F:$F,"发出（发出到海外仓）") -> -45 | K18: =IFERROR((F18+I18)/(D18+G18),0) -> 115.90529 | L18: =IFERROR(J18*K18,0) -> -5215.7382 | M18: =-SUMIFS('本地仓-出入库明细'!$K:$K,'本地仓-出入库明细'!$C:$C,$A18,'本地仓-出入库明细'!$F:$F,"发出（退回给供应商）") -> 0 | N18: =IFERROR((I18+L18)/(G18+J18),"") | O18: =IFERROR(M18*N18,0) -> 0 | P18: =D18+G18+J18+M18 -> 0 | Q18: =IF(ISERROR(R18/P18),0,R18/P18) -> 0 | R18: =F18+I18+L18+O18 -> -4.5474735e-12
A19: XXS6B003 | D19: 0 | E19: 75.423657 | F19: =D19*E19 -> 0 | G19: =SUMIFS('本地仓-出入库明细'!$G:$G,'本地仓-出入库明细'!$C:$C,$A19,'本地仓-出入库明细'!$F:$F,"购入") -> 140 | H19: =IF(ISERROR(I19/G19),0,I19/G19) -> 76.177893 | I19: =SUMIFS('本地仓-出入库明细'!$I:$I,'本地仓-出入库明细'!$C:$C,$A19,'本地仓-出入库明细'!$F:$F,"购入") -> 10664.905 | J19: =-SUMIFS('本地仓-出入库明细'!$K:$K,'本地仓-出入库明细'!$C:$C,$A19,'本地仓-出入库明细'!$F:$F,"发出（发出到海外仓）") -> -140 | K19: =IFERROR((F19+I19)/(D19+G19),0) -> 76.177893 | L19: =IFERROR(J19*K19,0) -> -10664.905 | M19: =-SUMIFS('本地仓-出入库明细'!$K:$K,'本地仓-出入库明细'!$C:$C,$A19,'本地仓-出入库明细'!$F:$F,"发出（退回给供应商）") -> 0 | N19: =IFERROR((I19+L19)/(G19+J19),"") | O19: =IFERROR(M19*N19,0) -> 0 | P19: =D19+G19+J19+M19 -> 0 | Q19: =IF(ISERROR(R19/P19),0,R19/P19) -> 0 | R19: =F19+I19+L19+O19 -> 0
A20: XXS6B004 | D20: 0 | E20: 70.48953 | F20: =D20*E20 -> 0 | G20: =SUMIFS('本地仓-出入库明细'!$G:$G,'本地仓-出入库明细'!$C:$C,$A20,'本地仓-出入库明细'!$F:$F,"购入") -> 150 | H20: =IF(ISERROR(I20/G20),0,I20/G20) -> 71.194425 | I20: =SUMIFS('本地仓-出入库明细'!$I:$I,'本地仓-出入库明细'!$C:$C,$A20,'本地仓-出入库明细'!$F:$F,"购入") -> 10679.164 | J20: =-SUMIFS('本地仓-出入库明细'!$K:$K,'本地仓-出入库明细'!$C:$C,$A20,'本地仓-出入库明细'!$F:$F,"发出（发出到海外仓）") -> 0 | K20: =IFERROR((F20+I20)/(D20+G20),0) -> 71.194425 | L20: =IFERROR(J20*K20,0) -> 0 | M20: =-SUMIFS('本地仓-出入库明细'!$K:$K,'本地仓-出入库明细'!$C:$C,$A20,'本地仓-出入库明细'!$F:$F,"发出（退回给供应商）") -> 0 | N20: =IFERROR((I20+L20)/(G20+J20),"") -> 71.194425 | O20: =IFERROR(M20*N20,0) -> 0 | P20: =D20+G20+J20+M20 -> 150 | Q20: =IF(ISERROR(R20/P20),0,R20/P20) -> 71.194425 | R20: =F20+I20+L20+O20 -> 10679.164
A21: XXS6B005 | D21: 0 | E21: 104.02491 | F21: =D21*E21 -> 0 | G21: =SUMIFS('本地仓-出入库明细'!$G:$G,'本地仓-出入库明细'!$C:$C,$A21,'本地仓-出入库明细'!$F:$F,"购入") -> 0 | H21: =IF(ISERROR(I21/G21),0,I21/G21) -> 0 | I21: =SUMIFS('本地仓-出入库明细'!$I:$I,'本地仓-出入库明细'!$C:$C,$A21,'本地仓-出入库明细'!$F:$F,"购入") -> 0 | J21: =-SUMIFS('本地仓-出入库明细'!$K:$K,'本地仓-出入库明细'!$C:$C,$A21,'本地仓-出入库明细'!$F:$F,"发出（发出到海外仓）") -> 0 | K21: =IFERROR((F21+I21)/(D21+G21),0) -> 0 | L21: =IFERROR(J21*K21,0) -> 0 | M21: =-SUMIFS('本地仓-出入库明细'!$K:$K,'本地仓-出入库明细'!$C:$C,$A21,'本地仓-出入库明细'!$F:$F,"发出（退回给供应商）") -> 0 | N21: =IFERROR((I21+L21)/(G21+J21),"") | O21: =IFERROR(M21*N21,0) -> 0 | P21: =D21+G21+J21+M21 -> 0 | Q21: =IF(ISERROR(R21/P21),0,R21/P21) -> 0 | R21: =F21+I21+L21+O21 -> 0
A22: XXS6B006 | D22: 10 | E22: 101.36272 | F22: =D22*E22 -> 1013.6272 | G22: =SUMIFS('本地仓-出入库明细'!$G:$G,'本地仓-出入库明细'!$C:$C,$A22,'本地仓-出入库明细'!$F:$F,"购入") -> 0 | H22: =IF(ISERROR(I22/G22),0,I22/G22) -> 0 | I22: =SUMIFS('本地仓-出入库明细'!$I:$I,'本地仓-出入库明细'!$C:$C,$A22,'本地仓-出入库明细'!$F:$F,"购入") -> 0 | J22: =-SUMIFS('本地仓-出入库明细'!$K:$K,'本地仓-出入库明细'!$C:$C,$A22,'本地仓-出入库明细'!$F:$F,"发出（发出到海外仓）") -> 0 | K22: =IFERROR((F22+I22)/(D22+G22),0) -> 101.36272 | L22: =IFERROR(J22*K22,0) -> 0 | M22: =-SUMIFS('本地仓-出入库明细'!$K:$K,'本地仓-出入库明细'!$C:$C,$A22,'本地仓-出入库明细'!$F:$F,"发出（退回给供应商）") -> 0 | N22: =IFERROR((I22+L22)/(G22+J22),"") | O22: =IFERROR(M22*N22,0) -> 0 | P22: =D22+G22+J22+M22 -> 10 | Q22: =IF(ISERROR(R22/P22),0,R22/P22) -> 101.36272 | R22: =F22+I22+L22+O22 -> 1013.6272
A23: 合计 | D23: =SUM(D5:D22) -> 473 | F23: =SUM(F5:F22) -> 50988.689 | G23: =SUM(G5:G22) -> 4014 | I23: =SUM(I5:I22) -> 468442.81 | J23: =SUM(J5:J22) -> -3075 | L23: =SUM(L5:L22) -> -352315.48 | M23: =SUM(M5:M22) -> 0 | O23: =SUM(O5:O22) -> 0 | P23: =SUM(P5:P22) -> 1412 | R23: =SUM(R5:R22) -> 167116.02
A24: check(should be 0) | G24: =G23-'本地仓-出入库明细'!G33 -> 0 | J24: =J23+'本地仓-出入库明细'!K33 -> 1452

Sheet 物流信息跟踪
A1: 日期： | B1: =[9]基础资料!C1 -> 44228
A2: 在途仓物流信息更跟踪表
A3: 注：灰色部分为公式，不可填数字！
A4: 发货日期 | B4: shipment ID | C4: sku | D4: 产品名称 | E4: 承运商 | F4: 运输方式 | G4: 目的地 | H4: 产品名称 | I4: 物流单号 | J4: 发往FBA | P4: FBA接收 | R4: 尚在途数量 | S4: 原因说明
J5: 数量 | K5: 各sku总重量KG | L5: 单个sku重量KG | M5: 批次总运费 | N5: 各sku总头程 | O5: 单个sku头程 | P5: 实际签收数量 | Q5: 签收时间
A6: 合计 | J6: =SUMIF($A$7:$A$996,"*合计",J$7:J$996) -> 0 | K6: =SUMIF($A$7:$A$996,"*合计",K$7:K$996) -> 0 | M6: =SUMIF($A$7:$A$996,"*合计",M$7:M$996) -> 0 | N6: =SUMIF($A$7:$A$996,"*合计",N$7:N$996) -> 0 | P6: =SUMIF($A$7:$A$996,"*合计",P$7:P$996) -> 0 | R6: =SUMIF($A$7:$A$996,"*合计",R$7:R$996) -> 0 | U6: 月份 | V6: 接收数量合计 | W6: check
A7: 44208 | B7: UPS | C7: AHJ01005 | E7: UPS | F7: 海运 | G7: 美国 | I7: A20210112001 | J7: 2687 | K7: =J7*L7 -> 11258.53 | L7: =VLOOKUP(C7,[9]基础资料!$B:$G,6,0) -> 4.19 | M7: =N14 -> 69626.59 | N7: =O7*J7 -> 56292.65 | O7: =VLOOKUP(C7,[9]基础资料!$B:$H,7,0) -> 20.95 | P7: =J7 -> 2687 | Q7: 43874 | R7: =J7-P7 -> 0 | T7: =J7-P7 -> 0 | U7: 44197 | V7: =SUMPRODUCT((MONTH($Q$7:$Q$99)=MONTH($U7))*($P$7:$P$99)*($Q$7:$Q$99<>"")) -> 0
A8: 44208 | B8: UPS | C8: 6B3009 | E8: UPS | F8: 海运 | G8: 美国 | I8: A20210112001 | J8: 1458 | K8: =J8*L8 -> 933.12 | L8: =VLOOKUP(C8,[9]基础资料!$B:$G,6,0) -> 0.64 | N8: =O8*J8 -> 4199.04 | O8: =VLOOKUP(C8,[9]基础资料!$B:$H,7,0) -> 2.88 | P8: =J8 -> 1458 | Q8: 43874 | R8: =J8-P8 -> 0 | S8: 待查 | T8: =J8-P8 -> 0 | U8: 44228 | V8: =SUMPRODUCT((MONTH($Q$7:$Q$99)=MONTH(U8))*($P$7:$P$99)*($Q$7:$Q$99<>"")) -> 8477 | W8: =V8-[9]库存调整表US!H1 -> 0
A9: 44208 | B9: UPS | C9: AHJ01006 | E9: UPS | F9: 海运 | G9: 美国 | I9: A20210112001 | J9: 200 | K9: =J9*L9 -> 460 | L9: =VLOOKUP(C9,[9]基础资料!$B:$G,6,0) -> 2.3 | N9: =O9*J9 -> 2300 | O9: =VLOOKUP(C9,[9]基础资料!$B:$H,7,0) -> 11.5 | P9: =J9 -> 200 | Q9: 43874 | R9: =J9-P9 -> 0 | T9: =J9-P9 -> 0 | U9: 44256 | V9: =SUMPRODUCT((MONTH($Q$7:$Q$99)=MONTH(U9))*($P$7:$P$99)*($Q$7:$Q$99<>"")) -> 0
A10: 44208 | B10: UPS | C10: AHJ01007 | E10: UPS | F10: 海运 | G10: 美国 | I10: A20210112001 | J10: 500 | K10: =J10*L10 -> 1050 | L10: =VLOOKUP(C10,[9]基础资料!$B:$G,6,0) -> 2.1 | N10: =O10*J10 -> 5250 | O10: =VLOOKUP(C10,[9]基础资料!$B:$H,7,0) -> 10.5 | P10: 500 | Q10: 43874 | R10: =J10-P10 -> 0 | S10: 原因待查 | T10: =J10-P10 -> 0 | U10: 44287 | V10: =SUMPRODUCT((MONTH($Q$7:$Q$99)=MONTH(U10))*($P$7:$P$99)*($Q$7:$Q$99<>"")) -> 0
A11: 44208 | B11: UPS | C11: TOP01 | E11: UPS | F11: 海运 | G11: 美国 | I11: A20210112001 | J11: 47 | K11: =J11*L11 -> 155.1 | L11: =VLOOKUP(C11,[9]基础资料!$B:$G,6,0) -> 3.3 | N11: =O11*J11 -> 930.6 | O11: =VLOOKUP(C11,[9]基础资料!$B:$H,7,0) -> 19.8 | P11: =J11 -> 47 | Q11: 43874 | R11: =J11-P11 -> 0 | T11: =J11-P11 -> 0 | U11: 44317 | V11: =SUMPRODUCT((MONTH($Q$7:$Q$99)=MONTH(U11))*($P$7:$P$99)*($Q$7:$Q$99<>"")) -> 0
A12: 44208 | B12: UPS | C12: AJH05 | E12: UPS | F12: 海运 | G12: 美国 | I12: A20210112001 | J12: 178 | K12: =J12*L12 -> 142.4 | L12: =VLOOKUP(C12,[9]基础资料!$B:$G,6,0) -> 0.8 | N12: =O12*J12 -> 640.8 | O12: =VLOOKUP(C12,[9]基础资料!$B:$H,7,0) -> 3.6 | P12: =J12 -> 178 | Q12: 43874 | R12: =J12-P12 -> 0 | T12: =J12-P12 -> 0 | U12: 44348 | V12: =SUMPRODUCT((MONTH($Q$7:$Q$99)=MONTH(U12))*($P$7:$P$99)*($Q$7:$Q$99<>"")) -> 0
A13: 44208 | B13: UPS | C13: AHH-01-001 | E13: UPS | F13: 海运 | G13: 美国 | I13: A20210112001 | J13: 3 | K13: =J13*L13 -> 3 | L13: =VLOOKUP(C13,[9]基础资料!$B:$G,6,0) -> 1 | N13: =O13*J13 -> 13.5 | O13: =VLOOKUP(C13,[9]基础资料!$B:$H,7,0) -> 4.5 | P13: =J13 -> 3 | Q13: 43874 | R13: =J13-P13 -> 0 | T13: =J13-P13 -> 0 | U13: 44378 | V13: =SUMPRODUCT((MONTH($Q$7:$Q$99)=MONTH(U13))*($P$7:$P$99)*($Q$7:$Q$99<>"")) -> 0
B14: 批次小计 | J14: =SUM(J7:J13) -> 5073 | K14: =SUM(K7:K13) -> 14002.15 | M14: =M7 -> 69626.59 | N14: =SUM(N7:N13) -> 69626.59 | P14: =SUM(P7:P13) -> 5073 | R14: =SUM(R7:R12) -> 0 | T14: =J14-P14 -> 0
A15: 44211 | B15: UPS | C15: 6B3008 | E15: UPS | F15: 海运 | G15: 美国 | I15: A20210120001 | J15: 580 | K15: =J15*L15 -> 904.8 | L15: =VLOOKUP(C15,[9]基础资料!$B:$G,6,0) -> 1.56 | M15: =N21 -> 28385.4 | N15: =O15*J15 -> 4524 | O15: =VLOOKUP(C15,[9]基础资料!$B:$H,7,0) -> 7.8 | P15: =J15 -> 580 | Q15: 43882 | R15: =J15-P15 -> 0 | T15: =J15-P15 -> 0
A16: 44211 | B16: UPS | C16: AHJ01005 | E16: UPS | F16: 海运 | G16: 美国 | I16: A20210120001 | J16: 744 | K16: =J16*L16 -> 3117.36 | L16: =VLOOKUP(C16,[9]基础资料!$B:$G,6,0) -> 4.19 | N16: =O16*J16 -> 15586.8 | O16: =VLOOKUP(C16,[9]基础资料!$B:$H,7,0) -> 20.95 | P16: =J16 -> 744 | Q16: 43882 | R16: =J16-P16 -> 0 | T16: =J16-P16 -> 0
A17: 44211 | B17: UPS | C17: AHJ01006 | E17: UPS | F17: 海运 | G17: 美国 | I17: A20210120001 | J17: 354 | K17: =J17*L17 -> 814.2 | L17: =VLOOKUP(C17,[9]基础资料!$B:$G,6,0) -> 2.3 | N17: =O17*J17 -> 4071 | O17: =VLOOKUP(C17,[9]基础资料!$B:$H,7,0) -> 11.5 | P17: =J17 -> 354 | Q17: 43882 | R17: =J17-P17 -> 0 | T17: =J17-P17 -> 0
A18: 44211 | B18: UPS | C18: TOP2001 | E18: UPS | F18: 海运 | G18: 美国 | I18: A20210120001 | J18: 24 | K18: =J18*L18 -> 81.6 | L18: =VLOOKUP(C18,[9]基础资料!$B:$G,6,0) -> 3.4 | N18: =O18*J18 -> 489.6 | O18: =VLOOKUP(C18,[9]基础资料!$B:$H,7,0) -> 20.4 | P18: =J18 -> 24 | Q18: 43882 | R18: =J18-P18 -> 0 | T18: =J18-P18 -> 0
A19: 44211 | B19: UPS | C19: AHJ01006 | E19: UPS | F19: 海运 | G19: 美国 | I19: A20210120001 | J19: 300 | K19: =J19*L19 -> 690 | L19: =VLOOKUP(C19,[9]基础资料!$B:$G,6,0) -> 2.3 | N19: =O19*J19 -> 3450 | O19: =VLOOKUP(C19,[9]基础资料!$B:$H,7,0) -> 11.5 | P19: 200 | Q19: 43882 | R19: =J19-P19 -> 100 | T19: =J19-P19 -> 100
A20: 44211 | B20: UPS | C20: TOP2003 | E20: UPS | F20: 海运 | G20: 美国 | I20: A20210120001 | J20: 48 | K20: =J20*L20 -> 52.8 | L20: =VLOOKUP(C20,[9]基础资料!$B:$G,6,0) -> 1.1 | N20: =O20*J20 -> 264 | O20: =VLOOKUP(C20,[9]基础资料!$B:$H,7,0) -> 5.5 | P20: =J20 -> 48 | Q20: 43882 | R20: =J20-P20 -> 0 | T20: =J20-P20 -> 0
B21: 批次小计 | J21: =SUM(J15:J20) -> 2050 | K21: =SUM(K15:K20) -> 5660.76 | M21: =M15 -> 28385.4 | N21: =SUM(N15:N20) -> 28385.4 | P21: =SUM(P15:P20) -> 1950 | R21: =SUM(R15:R20) -> 100 | T21: =J21-P21 -> 100
A22: 44216 | B22: UPS | C22: UINM01 | E22: UPS | F22: 海运 | G22: 美国 | I22: A20210120001 | J22: 31 | K22: =J22*L22 -> 62 | L22: =VLOOKUP(C22,[9]基础资料!$B:$G,6,0) -> 2 | M22: =N28 -> 9504.42 | N22: =O22*J22 -> 310 | O22: =VLOOKUP(C22,[9]基础资料!$B:$H,7,0) -> 10 | P22: =J22 -> 31 | Q22: 43882 | R22: =J22-P22 -> 0 | T22: =J22-P22 -> 0
A23: 44216 | B23: UPS | C23: AHJ01006 | E23: UPS | F23: 海运 | G23: 美国 | I23: A20210120001 | J23: 190 | K23: =J23*L23 -> 437 | L23: =VLOOKUP(C23,[9]基础资料!$B:$G,6,0) -> 2.3 | N23: =O23*J23 -> 2185 | O23: =VLOOKUP(C23,[9]基础资料!$B:$H,7,0) -> 11.5 | P23: 190 | Q23: 43882 | R23: =J23-P23 -> 0 | T23: =J23-P23 -> 0
A24: 44216 | B24: UPS | C24: TOP2002 | E24: UPS | F24: 海运 | G24: 美国 | I24: A20210120001 | J24: 19 | K24: =J24*L24 -> 47.5 | L24: =VLOOKUP(C24,[9]基础资料!$B:$G,6,0) -> 2.5 | N24: =O24*J24 -> 237.5 | O24: =VLOOKUP(C24,[9]基础资料!$B:$H,7,0) -> 12.5 | P24: =J24 -> 19 | Q24: 43874 | R24: =J24-P24 -> 0 | T24: =J24-P24 -> 0
A25: 44216 | B25: UPS | C25: AHJ01006 | E25: UPS | F25: 海运 | G25: 美国 | I25: A20210120001 | J25: 380 | K25: =J25*L25 -> 874 | L25: =VLOOKUP(C25,[9]基础资料!$B:$G,6,0) -> 2.3 | N25: =O25*J25 -> 4370 | O25: =VLOOKUP(C25,[9]基础资料!$B:$H,7,0) -> 11.5 | P25: =J25 -> 380 | Q25: 43874 | R25: =J25-P25 -> 0 | T25: =J25-P25 -> 0
A26: 44216 | B26: UPS | C26: 6B3009 | E26: UPS | F26: 海运 | G26: 美国 | I26: A20210120001 | J26: 109 | K26: =J26*L26 -> 69.76 | L26: =VLOOKUP(C26,[9]基础资料!$B:$G,6,0) -> 0.64 | N26: =O26*J26 -> 313.92 | O26: =VLOOKUP(C26,[9]基础资料!$B:$H,7,0) -> 2.88 | P26: 109 | Q26: 43874 | R26: =J26-P26 -> 0 | T26: =J26-P26 -> 0
A27: 44216 | B27: UPS | C27: 6B3009 | E27: UPS | F27: 海运 | G27: 美国 | I27: A20210120001 | J27: 725 | K27: =J27*L27 -> 464 | L27: =VLOOKUP(C27,[9]基础资料!$B:$G,6,0) -> 0.64 | N27: =O27*J27 -> 2088 | O27: =VLOOKUP(C27,[9]基础资料!$B:$H,7,0) -> 2.88 | P27: =J27 -> 725 | Q27: 43874 | R27: =J27-P27 -> 0 | S27: 原因待查 | T27: =J27-P27 -> 0
B28: 批次小计 | J28: =SUM(J22:J27) -> 1454 | K28: =SUM(K22:K27) -> 1954.26 | M28: =SUM(M22:M27) -> 9504.42 | N28: =SUM(N22:N27) -> 9504.42 | P28: =SUM(P22:P27) -> 1454 | R28: =SUM(R15:R23) -> 200 | T28: =J28-P28 -> 0
B29: 1月合计 | J29: =SUMIF($B$7:$B$28,"批次小计",J$7:J$28) -> 8577 | K29: =SUMIF($B$7:$B$28,"批次小计",K$7:K$28) -> 21617.17 | M29: =M28+M21+M14 -> 107516.41 | N29: =SUMIF($B$7:$B$28,"批次小计",N$7:N$28) -> 107516.41 | P29: =SUMIF($B$7:$B$28,"批次小计",P$7:P$28) -> 8477 | R29: =SUMIF($A$7:$A$28,"批次小计",R$7:R$28) -> 0 | T29: =J29-P29 -> 100
A30: 44232 | B30: UPS | C30: 6B3008 | E30: UPS | F30: 海运 | G30: 美国 | I30: A20210215001 | J30: 2500 | K30: =J30*L30 -> 3900 | L30: =VLOOKUP(C30,[9]基础资料!$B:$G,6,0) -> 1.56 | M30: =N35 -> 27343.34 | N30: =O30*J30 -> 19500 | O30: =VLOOKUP(C30,[9]基础资料!$B:$H,7,0) -> 7.8 | R30: =J30-P30 -> 2500 | S30: 2月份发出，本月尚在途 | T30: =J30-P30 -> 2500
A31: 44232 | B31: UPS | C31: 6B3009 | E31: UPS | F31: 海运 | G31: 美国 | I31: A20210215001 | J31: 50 | K31: =J31*L31 -> 32 | L31: =VLOOKUP(C31,[9]基础资料!$B:$G,6,0) -> 0.64 | N31: =O31*J31 -> 144 | O31: =VLOOKUP(C31,[9]基础资料!$B:$H,7,0) -> 2.88 | R31: =J31-P31 -> 50 | S31: 2月份发出，本月尚在途 | T31: =J31-P31 -> 50
A32: 44232 | B32: UPS | C32: 6B3009 | E32: UPS | F32: 海运 | G32: 美国 | I32: A20210215001 | J32: 268 | K32: =J32*L32 -> 171.52 | L32: =VLOOKUP(C32,[9]基础资料!$B:$G,6,0) -> 0.64 | N32: =O32*J32 -> 771.84 | O32: =VLOOKUP(C32,[9]基础资料!$B:$H,7,0) -> 2.88 | R32: =J32-P32 -> 268 | S32: 2月份发出，本月尚在途 | T32: =J32-P32 -> 268
A33: 44232 | B33: UPS | C33: AHJ01006 | E33: UPS | F33: 海运 | G33: 美国 | I33: A20210215001 | J33: 155 | K33: =J33*L33 -> 356.5 | L33: =VLOOKUP(C33,[9]基础资料!$B:$G,6,0) -> 2.3 | N33: =O33*J33 -> 1782.5 | O33: =VLOOKUP(C33,[9]基础资料!$B:$H,7,0) -> 11.5 | R33: =J33-P33 -> 155 | S33: 2月份发出，本月尚在途 | T33: =J33-P33 -> 155
A34: 44232 | B34: UPS | C34: AHJ01007 | E34: UPS | F34: 海运 | G34: 美国 | I34: A20210215001 | J34: 490 | K34: =J34*L34 -> 1029 | L34: =VLOOKUP(C34,[9]基础资料!$B:$G,6,0) -> 2.1 | N34: =O34*J34 -> 5145 | O34: =VLOOKUP(C34,[9]基础资料!$B:$H,7,0) -> 10.5 | R34: =J34-P34 -> 490 | S34: 2月份发出，本月尚在途 | T34: =J34-P34 -> 490
B35: 批次小计 | J35: =SUM(J30:J34) -> 3463 | K35: =SUM(K30:K34) -> 5489.02 | M35: =M30 -> 27343.34 | N35: =SUM(N30:N34) -> 27343.34 | P35: =SUM(P30:P34) -> 0 | R35: =SUM(R30:R34) -> 3463 | T35: =J35-P35 -> 3463
A36: 44242 | B36: UPS | C36: TOP2001 | E36: UPS | F36: 海运 | G36: 美国 | I36: A20210215001 | J36: 90 | K36: =J36*L36 -> 306 | L36: =VLOOKUP(C36,[9]基础资料!$B:$G,6,0) -> 3.4 | M36: =N43 -> 9697.62 | N36: =O36*J36 -> 1836 | O36: =VLOOKUP(C36,[9]基础资料!$B:$H,7,0) -> 20.4 | R36: =J36-P36 -> 90 | S36: 2月份发出，本月尚在途 | T36: =J36-P36 -> 90
A37: 44242 | B37: UPS | C37: TOP2002 | E37: UPS | F37: 海运 | G37: 美国 | I37: A20210215001 | J37: 140 | K37: =J37*L37 -> 350 | L37: =VLOOKUP(C37,[9]基础资料!$B:$G,6,0) -> 2.5 | N37: =O37*J37 -> 1750 | O37: =VLOOKUP(C37,[9]基础资料!$B:$H,7,0) -> 12.5 | R37: =J37-P37 -> 140 | S37: 2月份发出，本月尚在途 | T37: =J37-P37 -> 140
A38: 44242 | B38: UPS | C38: TOP2003 | E38: UPS | F38: 海运 | G38: 美国 | I38: A20210215001 | J38: 290 | K38: =J38*L38 -> 319 | L38: =VLOOKUP(C38,[9]基础资料!$B:$G,6,0) -> 1.1 | N38: =O38*J38 -> 1595 | O38: =VLOOKUP(C38,[9]基础资料!$B:$H,7,0) -> 5.5 | R38: =J38-P38 -> 290 | S38: 2月份发出，本月尚在途 | T38: =J38-P38 -> 290
A39: 44242 | B39: UPS | C39: AHJ01006 | E39: UPS | F39: 海运 | G39: 美国 | I39: A20210215001 | J39: 260 | K39: =J39*L39 -> 598 | L39: =VLOOKUP(C39,[9]基础资料!$B:$G,6,0) -> 2.3 | N39: =O39*J39 -> 2990 | O39: =VLOOKUP(C39,[9]基础资料!$B:$H,7,0) -> 11.5 | R39: =J39-P39 -> 260 | S39: 2月份发出，本月尚在途 | T39: =J39-P39 -> 260
A40: 44242 | B40: UPS | C40: XXS6B002 | E40: UPS | F40: 海运 | G40: 美国 | I40: A20210215001 | J40: 45 | K40: =J40*L40 -> 27 | L40: =VLOOKUP(C40,[9]基础资料!$B:$G,6,0) -> 0.6 | N40: =O40*J40 -> 121.5 | O40: =VLOOKUP(C40,[9]基础资料!$B:$H,7,0) -> 2.7 | R40: =J40-P40 -> 45 | S40: 2月份发出，本月尚在途 | T40: =J40-P40 -> 45
...

Sheet 在途仓
A1: 日期： | B1: =基础资料!B1 -> 44228
A2: 注：灰色部分为公式，不可填数字！ | I2: 在途仓进销存报表 单位：元
A4: sku | B4: 名称 | C4: 规格型号 | D4: 期初 | I4: 入库（本地仓发出） | N4: 出库（海外仓签收） | S4: 结存（尚在途）
D5: 数量 | E5: 采购单价 | F5: 头程单价 | G5: 采购金额 | H5: 头程金额 | I5: 数量 | J5: 采购单价 | K5: 头程单价 | L5: 采购金额 | M5: 头程金额 | N5: 数量 | O5: 采购单价 | P5: 头程单价 | Q5: 采购金额 | R5: 头程金额 | S5: 数量 | T5: 采购单价 | U5: 头程单价 | V5: 采购金额 | W5: 头程金额
A6: 6B3008 | D6: 580 | E6: 110 | F6: 7.3 | G6: =D6*E6 -> 63800 | H6: =D6*F6 -> 4234 | I6: =SUMIF(物流信息跟踪!$C$30:$C$44,$A6,物流信息跟踪!$J$30:$J$44) -> 2500 | J6: =-VLOOKUP($A6,本地仓!$A$5:$L$22,11,0) -> -113.3 | K6: =IFERROR(M6/I6,0) -> 7.8 | L6: =-VLOOKUP($A6,本地仓!$A$5:$L$22,12,0) -> 203940 | M6: =SUMPRODUCT((MONTH(物流信息跟踪!$A$7:$A$1000)=MONTH($B$1))*(物流信息跟踪!$N$7:$N$1000)*(物流信息跟踪!$C$7:$C$1000=$A6)) -> 19500 | N6: =SUMPRODUCT((MONTH(物流信息跟踪!$Q$7:$Q$1000)=MONTH($B$1))*(物流信息跟踪!$P$7:$P$1000)*(物流信息跟踪!$C$7:$C$1000=$A6)) -> 580 | O6: =IFERROR((G6+L6)/($D6+$I6),0) -> 86.928571 | P6: =IFERROR((H6+M6)/($D6+$I6),0) -> 7.7058442 | Q6: =-IFERROR($N6*O6,0) -> -50418.571 | R6: =-IFERROR($N6*P6,0) -> -4469.3896 | S6: =D6+I6+N6 -> 3660 | T6: =IFERROR(V6/S6,0) -> 59.37744 | U6: =W6/S6 -> 5.2635548 | V6: =G6+L6+Q6 -> 217321.43 | W6: =H6+M6+R6 -> 19264.61
A7: 6B3009 | D7: 2292 | E7: 350 | F7: 2.38 | G7: =D7*E7 -> 802200 | H7: =D7*F7 -> 5454.96 | I7: =SUMIF(物流信息跟踪!$C$30:$C$44,$A7,物流信息跟踪!$J$30:$J$44) -> 417 | J7: =-VLOOKUP($A7,本地仓!$A$5:$L$22,11,0) -> -351.23 | K7: =IFERROR(M7/I7,0) -> 2.88 | L7: =-VLOOKUP($A7,本地仓!$A$5:$L$22,12,0) -> 7024.6 | M7: =SUMPRODUCT((MONTH(物流信息跟踪!$A$7:$A$1000)=MONTH($B$1))*(物流信息跟踪!$N$7:$N$1000)*(物流信息跟踪!$C$7:$C$1000=$A7)) -> 1200.96 | N7: =SUMPRODUCT((MONTH(物流信息跟踪!$Q$7:$Q$1000)=MONTH($B$1))*(物流信息跟踪!$P$7:$P$1000)*(物流信息跟踪!$C$7:$C$1000=$A7)) -> 2292 | O7: =IFERROR((G7+L7)/(D7+I7),0) -> 298.71709 | P7: =IFERROR((H7+M7)/($D7+$I7),0) -> 2.4569657 | Q7: =-IFERROR($N7*O7,0) -> -684659.57 | R7: =-IFERROR($N7*P7,0) -> -5631.3653 | S7: =D7+I7+N7 -> 5001 | T7: =IFERROR(V7/S7,0) -> 24.908024 | U7: =W7/S7 -> 0.20486996 | V7: =G7+L7+Q7 -> 124565.03 | W7: =H7+M7+R7 -> 1024.5547
A8: AHH-01-001 | D8: 3 | E8: 62.445878 | F8: 4 | G8: =D8*E8 -> 187.33763 | H8: =D8*F8 -> 12 | I8: =SUMIF(物流信息跟踪!$C$30:$C$44,$A8,物流信息跟踪!$J$30:$J$44) -> 0 | J8: =-VLOOKUP($A8,本地仓!$A$5:$L$22,11,0) -> -62.445878 | K8: =IFERROR(M8/I8,0) -> 0 | L8: =-VLOOKUP($A8,本地仓!$A$5:$L$22,12,0) -> 0 | M8: =SUMPRODUCT((MONTH(物流信息跟踪!$A$7:$A$1000)=MONTH($B$1))*(物流信息跟踪!$N$7:$N$1000)*(物流信息跟踪!$C$7:$C$1000=$A8)) -> 0 | N8: =SUMPRODUCT((MONTH(物流信息跟踪!$Q$7:$Q$1000)=MONTH($B$1))*(物流信息跟踪!$P$7:$P$1000)*(物流信息跟踪!$C$7:$C$1000=$A8)) -> 3 | O8: =IFERROR((G8+L8)/(D8+I8),0) -> 62.445878 | P8: =IFERROR((H8+M8)/($D8+$I8),0) -> 4 | Q8: =-IFERROR($N8*O8,0) -> -187.33763 | R8: =-IFERROR($N8*P8,0) -> -12 | S8: =D8+I8+N8 -> 6 | T8: =IFERROR(V8/S8,0) -> 0 | U8: =W8/S8 -> 0 | V8: =G8+L8+Q8 -> 0 | W8: =H8+M8+R8 -> 0
A9: AHJ01005 | D9: 3431 | E9: 0 | F9: 20.45 | G9: =D9*E9 -> 0 | H9: =D9*F9 -> 70163.95 | I9: =SUMIF(物流信息跟踪!$C$30:$C$44,$A9,物流信息跟踪!$J$30:$J$44) -> 0 | J9: =-VLOOKUP($A9,本地仓!$A$5:$L$22,11,0) -> 0 | K9: =IFERROR(M9/I9,0) -> 0 | L9: =-VLOOKUP($A9,本地仓!$A$5:$L$22,12,0) -> 0 | M9: =SUMPRODUCT((MONTH(物流信息跟踪!$A$7:$A$1000)=MONTH($B$1))*(物流信息跟踪!$N$7:$N$1000)*(物流信息跟踪!$C$7:$C$1000=$A9)) -> 0 | N9: =SUMPRODUCT((MONTH(物流信息跟踪!$Q$7:$Q$1000)=MONTH($B$1))*(物流信息跟踪!$P$7:$P$1000)*(物流信息跟踪!$C$7:$C$1000=$A9)) -> 3431 | O9: =IFERROR((G9+L9)/(D9+I9),0) -> 0 | P9: =IFERROR((H9+M9)/($D9+$I9),0) -> 20.45 | Q9: =-IFERROR($N9*O9,0) -> 0 | R9: =-IFERROR($N9*P9,0) -> -70163.95 | S9: =D9+I9+N9 -> 6862 | T9: =IFERROR(V9/S9,0) -> 0 | U9: =W9/S9 -> 0 | V9: =G9+L9+Q9 -> 0 | W9: =H9+M9+R9 -> 0
A10: AHJ01006 | D10: 1424 | E10: 90 | F10: 11 | G10: =D10*E10 -> 128160 | H10: =D10*F10 -> 15664 | I10: =SUMIF(物流信息跟踪!$C$30:$C$44,$A10,物流信息跟踪!$J$30:$J$44) -> 415 | J10: =-VLOOKUP($A10,本地仓!$A$5:$L$22,11,0) -> -87.545895 | K10: =IFERROR(M10/I10,0) -> 11.5 | L10: =-VLOOKUP($A10,本地仓!$A$5:$L$22,12,0) -> 5252.7537 | M10: =SUMPRODUCT((MONTH(物流信息跟踪!$A$7:$A$1000)=MONTH($B$1))*(物流信息跟踪!$N$7:$N$1000)*(物流信息跟踪!$C$7:$C$1000=$A10)) -> 4772.5 | N10: =SUMPRODUCT((MONTH(物流信息跟踪!$Q$7:$Q$1000)=MONTH($B$1))*(物流信息跟踪!$P$7:$P$1000)*(物流信息跟踪!$C$7:$C$1000=$A10)) -> 1324 | O10: =IFERROR((G10+L10)/(D10+I10),0) -> 72.546359 | P10: =IFERROR((H10+M10)/($D10+$I10),0) -> 11.112833 | Q10: =-IFERROR($N10*O10,0) -> -96051.379 | R10: =-IFERROR($N10*P10,0) -> -14713.391 | S10: =D10+I10+N10 -> 3163 | T10: =IFERROR(V10/S10,0) -> 11.812006 | U10: =W10/S10 -> 1.8093927 | V10: =G10+L10+Q10 -> 37361.375 | W10: =H10+M10+R10 -> 5723.109
A11: AHJ01007 | D11: 500 | E11: 101 | F11: 10 | G11: =D11*E11 -> 50500 | H11: =D11*F11 -> 5000 | I11: =SUMIF(物流信息跟踪!$C$30:$C$44,$A11,物流信息跟踪!$J$30:$J$44) -> 490 | J11: =-VLOOKUP($A11,本地仓!$A$5:$L$22,11,0) -> -101.47724 | K11: =IFERROR(M11/I11,0) -> 10.5 | L11: =-VLOOKUP($A11,本地仓!$A$5:$L$22,12,0) -> 49723.848 | M11: =SUMPRODUCT((MONTH(物流信息跟踪!$A$7:$A$1000)=MONTH($B$1))*(物流信息跟踪!$N$7:$N$1000)*(物流信息跟踪!$C$7:$C$1000=$A11)) -> 5145 | N11: =SUMPRODUCT((MONTH(物流信息跟踪!$Q$7:$Q$1000)=MONTH($B$1))*(物流信息跟踪!$P$7:$P$1000)*(物流信息跟踪!$C$7:$C$1000=$A11)) -> 500 | O11: =IFERROR((G11+L11)/(D11+I11),0) -> 101.23621 | P11: =IFERROR((H11+M11)/($D11+$I11),0) -> 10.247475 | Q11: =-IFERROR($N11*O11,0) -> -50618.105 | R11: =-IFERROR($N11*P11,0) -> -5123.7374 | S11: =D11+I11+N11 -> 1490 | T11: =IFERROR(V11/S11,0) -> 33.292445 | U11: =W11/S11 -> 3.3699749 | V11: =G11+L11+Q11 -> 49605.743 | W11: =H11+M11+R11 -> 5021.2626
A12: AJH05 | D12: 178 | E12: 107 | F12: 3.1 | G12: =D12*E12 -> 19046 | H12: =D12*F12 -> 551.8 | I12: =SUMIF(物流信息跟踪!$C$30:$C$44,$A12,物流信息跟踪!$J$30:$J$44) -> 0 | J12: =-VLOOKUP($A12,本地仓!$A$5:$L$22,11,0) -> -107.40351 | K12: =IFERROR(M12/I12,0) -> 0 | L12: =-VLOOKUP($A12,本地仓!$A$5:$L$22,12,0) -> 0 | M12: =SUMPRODUCT((MONTH(物流信息跟踪!$A$7:$A$1000)=MONTH($B$1))*(物流信息跟踪!$N$7:$N$1000)*(物流信息跟踪!$C$7:$C$1000=$A12)) -> 0 | N12: =SUMPRODUCT((MONTH(物流信息跟踪!$Q$7:$Q$1000)=MONTH($B$1))*(物流信息跟踪!$P$7:$P$1000)*(物流信息跟踪!$C$7:$C$1000=$A12)) -> 178 | O12: =IFERROR((G12+L12)/(D12+I12),0) -> 107 | P12: =IFERROR((H12+M12)/($D12+$I12),0) -> 3.1 | Q12: =-IFERROR($N12*O12,0) -> -19046 | R12: =-IFERROR($N12*P12,0) -> -551.8 | S12: =D12+I12+N12 -> 356 | T12: =IFERROR(V12/S12,0) -> 0 | U12: =W12/S12 -> 0 | V12: =G12+L12+Q12 -> 0 | W12: =H12+M12+R12 -> 0
A13: TOP01 | D13: 47 | E13: 227.4586 | F13: 19.3 | G13: =D13*E13 -> 10690.554 | H13: =D13*F13 -> 907.1 | I13: =SUMIF(物流信息跟踪!$C$30:$C$44,$A13,物流信息跟踪!$J$30:$J$44) -> 0 | J13: =-VLOOKUP($A13,本地仓!$A$5:$L$22,11,0) -> -227.4586 | K13: =IFERROR(M13/I13,0) -> 0 | L13: =-VLOOKUP($A13,本地仓!$A$5:$L$22,12,0) -> 0 | M13: =SUMPRODUCT((MONTH(物流信息跟踪!$A$7:$A$1000)=MONTH($B$1))*(物流信息跟踪!$N$7:$N$1000)*(物流信息跟踪!$C$7:$C$1000=$A13)) -> 0 | N13: =SUMPRODUCT((MONTH(物流信息跟踪!$Q$7:$Q$1000)=MONTH($B$1))*(物流信息跟踪!$P$7:$P$1000)*(物流信息跟踪!$C$7:$C$1000=$A13)) -> 47 | O13: =IFERROR((G13+L13)/(D13+I13),0) -> 227.4586 | P13: =IFERROR((H13+M13)/($D13+$I13),0) -> 19.3 | Q13: =-IFERROR($N13*O13,0) -> -10690.554 | R13: =-IFERROR($N13*P13,0) -> -907.1 | S13: =D13+I13+N13 -> 94 | T13: =IFERROR(V13/S13,0) -> 0 | U13: =W13/S13 -> 0 | V13: =G13+L13+Q13 -> 0 | W13: =H13+M13+R13 -> 0
A14: TOP2001 | D14: 24 | E14: 104 | F14: 19.9 | G14: =D14*E14 -> 2496 | H14: =D14*F14 -> 477.6 | I14: =SUMIF(物流信息跟踪!$C$30:$C$44,$A14,物流信息跟踪!$J$30:$J$44) -> 90 | J14: =-VLOOKUP($A14,本地仓!$A$5:$L$22,11,0) -> -103.05169 | K14: =IFERROR(M14/I14,0) -> 20.4 | L14: =-VLOOKUP($A14,本地仓!$A$5:$L$22,12,0) -> 9274.6521 | M14: =SUMPRODUCT((MONTH(物流信息跟踪!$A$7:$A$1000)=MONTH($B$1))*(物流信息跟踪!$N$7:$N$1000)*(物流信息跟踪!$C$7:$C$1000=$A14)) -> 1836 | N14: =SUMPRODUCT((MONTH(物流信息跟踪!$Q$7:$Q$1000)=MONTH($B$1))*(物流信息跟踪!$P$7:$P$1000)*(物流信息跟踪!$C$7:$C$1000=$A14)) -> 24 | O14: =IFERROR((G14+L14)/(D14+I14),0) -> 103.25133 | P14: =IFERROR((H14+M14)/($D14+$I14),0) -> 20.294737 | Q14: =-IFERROR($N14*O14,0) -> -2478.032 | R14: =-IFERROR($N14*P14,0) -> -487.07368 | S14: =D14+I14+N14 -> 138 | T14: =IFERROR(V14/S14,0) -> 67.337826 | U14: =W14/S14 -> 13.235698 | V14: =G14+L14+Q14 -> 9292.62 | W14: =H14+M14+R14 -> 1826.5263
A15: TOP2002 | D15: 19 | E15: 200 | F15: 12 | G15: =D15*E15 -> 3800 | H15: =D15*F15 -> 228 | I15: =SUMIF(物流信息跟踪!$C$30:$C$44,$A15,物流信息跟踪!$J$30:$J$44) -> 140 | J15: =-VLOOKUP($A15,本地仓!$A$5:$L$22,11,0) -> -200.74692 | K15: =IFERROR(M15/I15,0) -> 12.5 | L15: =-VLOOKUP($A15,本地仓!$A$5:$L$22,12,0) -> 28104.568 | M15: =SUMPRODUCT((MONTH(物流信息跟踪!$A$7:$A$1000)=MONTH($B$1))*(物流信息跟踪!$N$7:$N$1000)*(物流信息跟踪!$C$7:$C$1000=$A15)) -> 1750 | N15: =SUMPRODUCT((MONTH(物流信息跟踪!$Q$7:$Q$1000)=MONTH($B$1))*(物流信息跟踪!$P$7:$P$1000)*(物流信息跟踪!$C$7:$C$1000=$A15)) -> 19 | O15: =IFERROR((G15+L15)/(D15+I15),0) -> 200.65766 | P15: =IFERROR((H15+M15)/($D15+$I15),0) -> 12.440252 | Q15: =-IFERROR($N15*O15,0) -> -3812.4956 | R15: =-IFERROR($N15*P15,0) -> -236.36478 | S15: =D15+I15+N15 -> 178 | T15: =IFERROR(V15/S15,0) -> 157.82063 | U15: =W15/S15 -> 9.7844675 | V15: =G15+L15+Q15 -> 28092.073 | W15: =H15+M15+R15 -> 1741.6352
A16: TOP2003 | D16: 48 | E16: 114.18764 | F16: 5 | G16: =D16*E16 -> 5481.0066 | H16: =D16*F16 -> 240 | I16: =SUMIF(物流信息跟踪!$C$30:$C$44,$A16,物流信息跟踪!$J$30:$J$44) -> 290 | J16: =-VLOOKUP($A16,本地仓!$A$5:$L$22,11,0) -> -114.18764 | K16: =IFERROR(M16/I16,0) -> 5.5 | L16: =-VLOOKUP($A16,本地仓!$A$5:$L$22,12,0) -> 33114.415 | M16: =SUMPRODUCT((MONTH(物流信息跟踪!$A$7:$A$1000)=MONTH($B$1))*(物流信息跟踪!$N$7:$N$1000)*(物流信息跟踪!$C$7:$C$1000=$A16)) -> 1595 | N16: =SUMPRODUCT((MONTH(物流信息跟踪!$Q$7:$Q$1000)=MONTH($B$1))*(物流信息跟踪!$P$7:$P$1000)*(物流信息跟踪!$C$7:$C$1000=$A16)) -> 48 | O16: =IFERROR((G16+L16)/(D16+I16),0) -> 114.18764 | P16: =IFERROR((H16+M16)/($D16+$I16),0) -> 5.4289941 | Q16: =-IFERROR($N16*O16,0) -> -5481.0066 | R16: =-IFERROR($N16*P16,0) -> -260.59172 | S16: =D16+I16+N16 -> 386 | T16: =IFERROR(V16/S16,0) -> 85.78864 | U16: =W16/S16 -> 4.0787779 | V16: =G16+L16+Q16 -> 33114.415 | W16: =H16+M16+R16 -> 1574.4083
A17: UINM01 | D17: 31 | E17: 139.80612 | F17: 9.5 | G17: =D17*E17 -> 4333.9898 | H17: =D17*F17 -> 294.5 | I17: =SUMIF(物流信息跟踪!$C$30:$C$44,$A17,物流信息跟踪!$J$30:$J$44) -> 0 | J17: =-VLOOKUP($A17,本地仓!$A$5:$L$22,11,0) -> -139.80612 | K17: =IFERROR(M17/I17,0) -> 0 | L17: =-VLOOKUP($A17,本地仓!$A$5:$L$22,12,0) -> 0 | M17: =SUMPRODUCT((MONTH(物流信息跟踪!$A$7:$A$1000)=MONTH($B$1))*(物流信息跟踪!$N$7:$N$1000)*(物流信息跟踪!$C$7:$C$1000=$A17)) -> 0 | N17: =SUMPRODUCT((MONTH(物流信息跟踪!$Q$7:$Q$1000)=MONTH($B$1))*(物流信息跟踪!$P$7:$P$1000)*(物流信息跟踪!$C$7:$C$1000=$A17)) -> 31 | O17: =IFERROR((G17+L17)/(D17+I17),0) -> 139.80612 | P17: =IFERROR((H17+M17)/($D17+$I17),0) -> 9.5 | Q17: =-IFERROR($N17*O17,0) -> -4333.9898 | R17: =-IFERROR($N17*P17,0) -> -294.5 | S17: =D17+I17+N17 -> 62 | T17: =IFERROR(V17/S17,0) -> 0 | U17: =W17/S17 -> 0 | V17: =G17+L17+Q17 -> 0 | W17: =H17+M17+R17 -> 0
A18: XXS6B001 | D18: 0 | E18: 179.5809 | F18: 3.5 | G18: =D18*E18 -> 0 | H18: =D18*F18 -> 0 | I18: =SUMIF(物流信息跟踪!$C$30:$C$44,$A18,物流信息跟踪!$J$30:$J$44) -> 0 | J18: =-VLOOKUP($A18,本地仓!$A$5:$L$22,11,0) -> -179.5809 | K18: =IFERROR(M18/I18,0) -> 0 | L18: =-VLOOKUP($A18,本地仓!$A$5:$L$22,12,0) -> 0 | M18: =SUMPRODUCT((MONTH(物流信息跟踪!$A$7:$A$1000)=MONTH($B$1))*(物流信息跟踪!$N$7:$N$1000)*(物流信息跟踪!$C$7:$C$1000=$A18)) -> 0 | N18: =SUMPRODUCT((MONTH(物流信息跟踪!$Q$7:$Q$1000)=MONTH($B$1))*(物流信息跟踪!$P$7:$P$1000)*(物流信息跟踪!$C$7:$C$1000=$A18)) -> 0 | O18: =IFERROR((G18+L18)/(D18+I18),0) -> 0 | P18: =IFERROR((H18+M18)/($D18+$I18),0) -> 0 | Q18: =-IFERROR($N18*O18,0) -> 0 | R18: =-IFERROR($N18*P18,0) -> 0 | S18: =D18+I18+N18 -> 0 | T18: =IFERROR(V18/S18,0) -> 0 | U18: =W18/S18 -> #DIV/0! | V18: =G18+L18+Q18 -> 0 | W18: =H18+M18+R18 -> 0
... A23: XXS6B006 | D23: 0 | E23: 101.36272 | F23: 3.5 | G23: =D23*E23 -> 0 | H23: =D23*F23 -> 0 | I23: =SUMIF(物流信息跟踪!$C$30:$C$44,$A23,物流信息跟踪!$J$30:$J$44) -> 0 | J23: =-VLOOKUP($A23,本地仓!$A$5:$L$22,11,0) -> -101.36272 | K23: =IFERROR(M23/I23,0) -> 0 | L23: =-VLOOKUP($A23,本地仓!$A$5:$L$22,12,0) -> 0 | M23: =SUMPRODUCT((MONTH(物流信息跟踪!$A$7:$A$1000)=MONTH($B$1))*(物流信息跟踪!$N$7:$N$1000)*(物流信息跟踪!$C$7:$C$1000=$A23)) -> 0 | N23: =SUMPRODUCT((MONTH(物流信息跟踪!$Q$7:$Q$1000)=MONTH($B$1))*(物流信息跟踪!$P$7:$P$1000)*(物流信息跟踪!$C$7:$C$1000=$A23)) -> 0 | O23: =IFERROR((G23+L23)/(D23+I23),0) -> 0 | P23: =IFERROR((H23+M23)/($D23+$I23),0) -> 0 | Q23: =-IFERROR($N23*O23,0) -> 0 | R23: =-IFERROR($N23*P23,0) -> 0 | S23: =D23+I23+N23 -> 0 | T23: =IFERROR(V23/S23,0) -> 0 | U23: =W23/S23 -> #DIV/0! | V23: =G23+L23+Q23 -> 0 | W23: =H23+M23+R23 -> 0
A24: 合计 | D24: =SUM(D6:D23) -> 8577 | G24: =SUM(G6:G23) -> 1090694.9 | H24: =SUM(H6:H23) -> 103227.91 | I24: =SUM(I6:I23) -> 4527 | K24: =SUM(K6:K23) -> 81.78 | L24: =SUM(L6:L23) -> 352315.48 | M24: =SUM(M6:M23) -> 37040.96 | N24: =SUM(N6:N23) -> 8477 | Q24: =SUM(Q6:Q23) -> -927777.04 | R24: =SUM(R6:R23) -> -102851.26 | S24: =SUM(S6:S23) -> 21581 | V24: =SUM(V6:V23) -> 515233.32 | W24: =SUM(W6:W23) -> 37417.607
A25: check(should be 0) | I25: =I24-物流信息跟踪!J44 -> 0 | L25: =L24+本地仓!L23 -> 0 | N25: =N24-库存调整表US!H1 -> 0

Sheet FBA仓
A1: 日期： | B1: =基础资料!B1 -> 44228
A2: FBA仓进销存及成本计算报表
A3: 注：灰色部分为公式，不可填数字！ | AH3: 单位：RMB
A5: sku | B5: 名称 | C5: 规格型号 | D5: 站点 | E5: 期初 | J5: 入库（在途仓接收） | O5: 销售出库 | T5: 客户退货入库 | W5: 已移除 | Z5: 盘库 | AG5: 结存
E6: 数量 | F6: 采购单价 | G6: 头程单价 | H6: 采购金额 | I6: 头程金额 | J6: 数量 | K6: 采购单价 | L6: 头程单价 | M6: 采购金额 | N6: 头程金额 | O6: 数量 | P6: 采购单价 | Q6: 头程单价 | R6: 采购金额 | S6: 头程金额 | T6: 数量 | U6: 采购金额 | V6: 头程金额 | W6: 数量 | X6: 采购金额 | Y6: 头程金额 | Z6: 已找回 | AA6: 已丢失 | AB6: 已弃置 | AC6: 已残损、其他 | AD6: 数量小计 | AE6: 采购金额 | AF6: 头程金额 | AG6: 数量 | AH6: 采购单价 | AI6: 头程单价 | AJ6: 采购金额 | AK6: 头程金额 | AL6: 库存调整表 | AN6: 入成本 | AO6: 营业外支出
A7: 6B3008 | D7: A004-US | E7: 510 | F7: =H7/E7 -> 109.5 | G7: =I7/E7 -> 7.3 | H7: 55845 | I7: 3723 | J7: =VLOOKUP($A7,在途仓!$A:$N,14,0) -> 580 | K7: =VLOOKUP($A7,在途仓!$A:$V,14,0) -> 580 | L7: =IFERROR(N7/J7,0) -> 7.7058442 | M7: =-VLOOKUP($A7,在途仓!$A:$R,17,0) -> 50418.571 | N7: =-VLOOKUP($A7,在途仓!$A:$R,18,0) -> 4469.3896 | O7: =IF(ISERROR(VLOOKUP($A7,库存调整表US!$A:$K,11,0)),0,VLOOKUP($A7,库存调整表US!$A:$K,11,0)) -> -586 | P7: =(H7+M7)/($E7+$J7) -> 97.489515 | Q7: =(I7+N7)/($E7+$J7) -> 7.5159538 | R7: =IFERROR($O7*P7,0) -> -57128.856 | S7: =IFERROR($O7*Q7,0) -> -4404.3489 | T7: =VLOOKUP($A7,库存调整表US!$A:$I,9,0) -> 77 | U7: =$T7*P7 -> 7506.6927 | V7: =$T7*Q7 -> 578.72844 | W7: =VLOOKUP($A7,库存调整表US!$A:$P,MATCH(W$5,库存调整表US!$A$2:$P$2,0),0) -> 0 | X7: =$W7*S7 -> 0 | Y7: =$W7*T7 -> 0 | Z7: =VLOOKUP($A7,库存调整表US!$A:$P,MATCH(Z$6,库存调整表US!$A$2:$P$2,0),0) -> 0 | AA7: =VLOOKUP($A7,库存调整表US!$A:$P,MATCH(AA$6,库存调整表US!$A$2:$P$2,0),0) -> 0 | AB7: =VLOOKUP($A7,库存调整表US!$A:$P,MATCH(AB$6,库存调整表US!$A$2:$P$2,0),0) -> 0 | AC7: =VLOOKUP($A7,库存调整表US!$A:$P,MATCH(AC$6,库存调整表US!$A$2:$P$2,0),0) -> 0 | AD7: =SUM(Z7:AC7) -> 0 | AE7: =$AD7*P7 -> 0 | AF7: =$AD7*Q7 -> 0 | AG7: =E7+J7+O7+T7+AD7 -> 581 | AH7: =IF(ISERROR(AJ7/$AG7),0,AJ7/$AG7) -> 97.489515 | AI7: =IF(ISERROR(AK7/$AG7),0,AK7/$AG7) -> 7.5159538 | AJ7: =H7+M7+R7+U7+AE7+X7 -> 56641.408 | AK7: =I7+N7+S7+V7+AF7+Y7 -> 4366.7691 | AL7: 581 | AM7: =AG7-AL7 -> 0 | AN7: =R7+S7+U7+V7+X7+Y7 -> -53447.784 | AO7: =AE7+AF7 -> 0
A8: 6B3009 | D8: A004-US | E8: 3054 | F8: =H8/E8 -> 340.5 | G8: =I8/E8 -> 2.38 | H8: 1039887 | I8: 7268.52 | J8: =VLOOKUP($A8,在途仓!$A:$N,14,0) -> 2292 | K8: =VLOOKUP($A8,在途仓!$A:$V,14,0) -> 2292 | L8: =IFERROR(N8/J8,0) -> 2.4569657 | M8: =-VLOOKUP($A8,在途仓!$A:$R,17,0) -> 684659.57 | N8: =-VLOOKUP($A8,在途仓!$A:$R,18,0) -> 5631.3653 | O8: =IF(ISERROR(VLOOKUP($A8,库存调整表US!$A:$K,11,0)),0,VLOOKUP($A8,库存调整表US!$A:$K,11,0)) -> -1877 | P8: =(H8+M8)/($E8+$J8) -> 322.58634 | Q8: =(I8+N8)/($E8+$J8) -> 2.4129976 | R8: =IFERROR($O8*P8,0) -> -605494.56 | S8: =IFERROR($O8*Q8,0) -> -4529.1965 | T8: =VLOOKUP($A8,库存调整表US!$A:$I,9,0) -> 182 | U8: =$T8*$P8 -> 58710.714 | V8: =$T8*Q8 -> 439.16557 | W8: =VLOOKUP($A8,库存调整表US!$A:$P,MATCH(W$5,库存调整表US!$A$2:$P$2,0),0) -> -4 | X8: =$W8*S8 -> 18116.786 | Y8: =$W8*T8 -> -728 | Z8: =VLOOKUP($A8,库存调整表US!$A:$P,MATCH(Z$6,库存调整表US!$A$2:$P$2,0),0) -> 2 | AA8: =VLOOKUP($A8,库存调整表US!$A:$P,MATCH(AA$6,库存调整表US!$A$2:$P$2,0),0) -> 0 | AB8: =VLOOKUP($A8,库存调整表US!$A:$P,MATCH(AB$6,库存调整表US!$A$2:$P$2,0),0) -> 0 | AC8: =VLOOKUP($A8,库存调整表US!$A:$P,MATCH(AC$6,库存调整表US!$A$2:$P$2,0),0) -> 0 | AD8: =SUM(Z8:AC8) -> 2 | AE8: =$AD8*P8 -> 645.17268 | AF8: =$AD8*Q8 -> 4.8259953 | AG8: =E8+J8+O8+T8+AD8 -> 3653 | AH8: =IF(ISERROR(AJ8/AG8),0,AJ8/AG8) -> 327.54577 | AI8: =IF(ISERROR(AK8/$AG8),0,AK8/$AG8) -> 2.2137094 | AJ8: =H8+M8+R8+U8+AE8+X8 -> 1196524.7 | AK8: =I8+N8+S8+V8+AF8+Y8 -> 8086.6803 | AL8: 3649 | AM8: =AG8-AL8 -> 4 | AN8: =R8+S8+U8+V8+X8+Y8 -> -533485.09 | AO8: =AE8+AF8 -> 649.99868
A9: AHH-01-001 | D9: A004-US | E9: 2 | F9: =H9/E9 -> 60.127066 | G9: =I9/E9 -> 4 | H9: 120.25413 | I9: 8 | J9: =VLOOKUP($A9,在途仓!$A:$N,14,0) -> 3 | K9: =VLOOKUP($A9,在途仓!$A:$V,14,0) -> 3 | L9: =IFERROR(N9/J9,0) -> 4 | M9: =-VLOOKUP($A9,在途仓!$A:$R,17,0) -> 187.33763 | N9: =-VLOOKUP($A9,在途仓!$A:$R,18,0) -> 12 | O9: =IF(ISERROR(VLOOKUP($A9,库存调整表US!$A:$K,11,0)),0,VLOOKUP($A9,库存调整表US!$A:$K,11,0)) -> -1 | P9: =(H9+M9)/($E9+$J9) -> 61.518353 | Q9: =(I9+N9)/($E9+$J9) -> 4 | R9: =IFERROR($O9*P9,0) -> -61.518353 | S9: =IFERROR($O9*Q9,0) -> -4 | T9: =VLOOKUP($A9,库存调整表US!$A:$I,9,0) -> 0 | U9: =$T9*$P9 -> 0 | V9: =$T9*Q9 -> 0 | W9: =VLOOKUP($A9,库存调整表US!$A:$P,MATCH(W$5,库存调整表US!$A$2:$P$2,0),0) -> 0 | X9: =$W9*S9 -> 0 | Y9: =$W9*T9 -> 0 | Z9: =VLOOKUP($A9,库存调整表US!$A:$P,MATCH(Z$6,库存调整表US!$A$2:$P$2,0),0) -> 2 | AA9: =VLOOKUP($A9,库存调整表US!$A:$P,MATCH(AA$6,库存调整表US!$A$2:$P$2,0),0) -> 0 | AB9: =VLOOKUP($A9,库存调整表US!$A:$P,MATCH(AB$6,库存调整表US!$A$2:$P$2,0),0) -> 0 | AC9: =VLOOKUP($A9,库存调整表US!$A:$P,MATCH(AC$6,库存调整表US!$A$2:$P$2,0),0) -> 0 | AD9: =SUM(Z9:AC9) -> 2 | AE9: =$AD9*P9 -> 123.03671 | AF9: =$AD9*Q9 -> 8 | AG9: =E9+J9+O9+T9+AD9 -> 6 | AH9: =IF(ISERROR(AJ9/AG9),0,AJ9/AG9) -> 61.518353 | AI9: =IF(ISERROR(AK9/$AG9),0,AK9/$AG9) -> 4 | AJ9: =H9+M9+R9+U9+AE9+X9 -> 369.11012 | AK9: =I9+N9+S9+V9+AF9+Y9 -> 24 | AL9: 6 | AM9: =AG9-AL9 -> 0 | AN9: =R9+S9+U9+V9+X9+Y9 -> -65.518353 | AO9: =AE9+AF9 -> 131.03671
A10: AHJ01005 | D10: A004-US | E10: 3138 | F10: =H10/E10 -> 77.548026 | G10: =I10/E10 -> 20.45 | H10: 243345.7 | I10: 64172.1 | J10: =VLOOKUP($A10,在途仓!$A:$N,14,0) -> 3431 | K10: =VLOOKUP($A10,在途仓!$A:$V,14,0) -> 3431 | L10: =IFERROR(N10/J10,0) -> 20.45 | M10: =-VLOOKUP($A10,在途仓!$A:$R,17,0) -> 0 | N10: =-VLOOKUP($A10,在途仓!$A:$R,18,0) -> 70163.95 | O10: =IF(ISERROR(VLOOKUP($A10,库存调整表US!$A:$K,11,0)),0,VLOOKUP($A10,库存调整表US!$A:$K,11,0)) -> -5627 | P10: =(H10+M10)/($E10+$J10) -> 37.044558 | Q10: =(I10+N10)/($E10+$J10) -> 20.45 | R10: =IFERROR($O10*P10,0) -> -208449.73 | S10: =IFERROR($O10*Q10,0) -> -115072.15 | T10: =VLOOKUP($A10,库存调整表US!$A:$I,9,0) -> 136 | U10: =$T10*$P10 -> 5038.0599 | V10: =$T10*Q10 -> 2781.2 | W10: =VLOOKUP($A10,库存调整表US!$A:$P,MATCH(W$5,库存调整表US!$A$2:$P$2,0),0) -> -2 | X10: =$W10*S10 -> 230144.3 | Y10: =$W10*T10 -> -272 | Z10: =VLOOKUP($A10,库存调整表US!$A:$P,MATCH(Z$6,库存调整表US!$A$2:$P$2,0),0) -> 8 | AA10: =VLOOKUP($A10,库存调整表US!$A:$P,MATCH(AA$6,库存调整表US!$A$2:$P$2,0),0) -> 0 | AB10: =VLOOKUP($A10,库存调整表US!$A:$P,MATCH(AB$6,库存调整表US!$A$2:$P$2,0),0) -> -3 | AC10: =VLOOKUP($A10,库存调整表US!$A:$P,MATCH(AC$6,库存调整表US!$A$2:$P$2,0),0) -> -4 | AD10: =SUM(Z10:AC10) -> 1 | AE10: =$AD10*P10 -> 37.044558 | AF10: =$AD10*Q10 -> 20.45 | AG10: =E10+J10+O10+T10+AD10 -> 1079 | AH10: =IF(ISERROR(AJ10/AG10),0,AJ10/AG10) -> 250.33863 | AI10: =IF(ISERROR(AK10/$AG10),0,AK10/$AG10) -> 20.197915 | AJ10: =H10+M10+R10+U10+AE10+X10 -> 270115.38 | AK10: =I10+N10+S10+V10+AF10+Y10 -> 21793.55 | AL10: 1077 | AM10: =AG10-AL10 -> 2 | AN10: =R10+S10+U10+V10+X10+Y10 -> -85830.32 | AO10: =AE10+AF10 -> 57.494558
A11: AHJ01006 | D11: A004-US | E11: 2055 | F11: =H11/E11 -> 86.443976 | G11: =I11/E11 -> 11 | H11: 177642.37 | I11: 22605 | J11: =VLOOKUP($A11,在途仓!$A:$N,14,0) -> 1324 | K11: =VLOOKUP($A11,在途仓!$A:$V,14,0) -> 1324 | L11: =IFERROR(N11/J11,0) -> 11.112833 | M11: =-VLOOKUP($A11,在途仓!$A:$R,17,0) -> 96051.379 | N11: =-VLOOKUP($A11,在途仓!$A:$R,18,0) -> 14713.391 | O11: =IF(ISERROR(VLOOKUP($A11,库存调整表US!$A:$K,11,0)),0,VLOOKUP($A11,库存调整表US!$A:$K,11,0)) -> -1526 | P11: =(H11+M11)/($E11+$J11) -> 80.998446 | Q11: =(I11+N11)/($E11+$J11) -> 11.044212 | R11: =IFERROR($O11*P11,0) -> -123603.63 | S11: =IFERROR($O11*Q11,0) -> -16853.467 | T11: =VLOOKUP($A11,库存调整表US!$A:$I,9,0) -> 78 | U11: =$T11*$P11 -> 6317.8788 | V11: =$T11*Q11 -> 861.4485 | W11: =VLOOKUP($A11,库存调整表US!$A:$P,MATCH(W$5,库存调整表US!$A$2:$P$2,0),0) -> -1 | X11: =$W11*S11 -> 16853.467 | Y11: =$W11*T11 -> -78 | Z11: =VLOOKUP($A11,库存调整表US!$A:$P,MATCH(Z$6,库存调整表US!$A$2:$P$2,0),0) -> 0 | AA11: =VLOOKUP($A11,库存调整表US!$A:$P,MATCH(AA$6,库存调整表US!$A$2:$P$2,0),0) -> -1 | AB11: =VLOOKUP($A11,库存调整表US!$A:$P,MATCH(AB$6,库存调整表US!$A$2:$P$2,0),0) -> 0 | AC11: =VLOOKUP($A11,库存调整表US!$A:$P,MATCH(AC$6,库存调整表US!$A$2:$P$2,0),0) -> 0 | AD11: =SUM(Z11:AC11) -> -1 | AE11: =$AD11*P11 -> -80.998446 | AF11: =$AD11*Q11 -> -11.044212 | AG11: =E11+J11+O11+T11+AD11 -> 1930 | AH11: =IF(ISERROR(AJ11/AG11),0,AJ11/AG11) -> 89.730812 | AI11: =IF(ISERROR(AK11/$AG11),0,AK11/$AG11) -> 11.003797 | AJ11: =H11+M11+R11+U11+AE11+X11 -> 173180.47 | AK11: =I11+N11+S11+V11+AF11+Y11 -> 21237.328 | AL11: 1929 | AM11: =AG11-AL11 -> 1 | AN11: =R11+S11+U11+V11+X11+Y11 -> -116502.3 | AO11: =AE11+AF11 -> -92.042657
A12: AHJ01007 | D12: A004-US | E12: 1113 | F12: =H12/E12 -> 100.97724 | G12: =I12/E12 -> 10 | H12: 112387.67 | I12: 11130 | J12: =VLOOKUP($A12,在途仓!$A:$N,14,0) -> 500 | K12: =VLOOKUP($A12,在途仓!$A:$V,14,0) -> 500 | L12: =IFERROR(N12/J12,0) -> 10.247475 | M12: =-VLOOKUP($A12,在途仓!$A:$R,17,0) -> 50618.105 | N12: =-VLOOKUP($A12,在途仓!$A:$R,18,0) -> 5123.7374 | O12: =IF(ISERROR(VLOOKUP($A12,库存调整表US!$A:$K,11,0)),0,VLOOKUP($A12,库存调整表US!$A:$K,11,0)) -> -579 | P12: =(H12+M12)/($E12+$J12) -> 101.05752 | Q12: =(I12+N12)/($E12+$J12) -> 10.076713 | R12: =IFERROR($O12*P12,0) -> -58512.302 | S12: =IFERROR($O12*Q12,0) -> -5834.4166 | T12: =VLOOKUP($A12,库存调整表US!$A:$I,9,0) -> 75 | U12: =$T12*$P12 -> 7579.3137 | V12: =$T12*Q12 -> 755.75344 | W12: =VLOOKUP($A12,库存调整表US!$A:$P,MATCH(W$5,库存调整表US!$A$2:$P$2,0),0) -> -1 | X12: =$W12*S12 -> 5834.4166 | Y12: =$W12*T12 -> -75 | Z12: =VLOOKUP($A12,库存调整表US!$A:$P,MATCH(Z$6,库存调整表US!$A$2:$P$2,0),0) -> 0 | AA12: =VLOOKUP($A12,库存调整表US!$A:$P,MATCH(AA$6,库存调整表US!$A$2:$P$2,0),0) -> -1 | AB12: =VLOOKUP($A12,库存调整表US!$A:$P,MATCH(AB$6,库存调整表US!$A$2:$P$2,0),0) -> 0 | AC12: =VLOOKUP($A12,库存调整表US!$A:$P,MATCH(AC$6,库存调整表US!$A$2:$P$2,0),0) -> 0 | AD12: =SUM(Z12:AC12) -> -1 | AE12: =$AD12*P12 -> -101.05752 | AF12: =$AD12*Q12 -> -10.076713 | AG12: =E12+J12+O12+T12+AD12 -> 1108 | AH12: =IF(ISERROR(AJ12/AG12),0,AJ12/AG12) -> 106.32324 | AI12: =IF(ISERROR(AK12/$AG12),0,AK12/$AG12) -> 10.009023 | AJ12: =H12+M12+R12+U12+AE12+X12 -> 117806.15 | AK12: =I12+N12+S12+V12+AF12+Y12 -> 11089.998 | AL12: 1107 | AM12: =AG12-AL12 -> 1 | AN12: =R12+S12+U12+V12+X12+Y12 -> -50252.235 | AO12: =AE12+AF12 -> -111.13423
A13: AJH05 | D13: A004-US | E13: 175 | F13: =H13/E13 -> 106.90351 | G13: =I13/E13 -> 3.1 | H13: 18708.115 | I13: 542.5 | J13: =VLOOKUP($A13,在途仓!$A:$N,14,0) -> 178 | K13: =VLOOKUP($A13,在途仓!$A:$V,14,0) -> 178 | L13: =IFERROR(N13/J13,0) -> 3.1 | M13: =-VLOOKUP($A13,在途仓!$A:$R,17,0) -> 19046 | N13: =-VLOOKUP($A13,在途仓!$A:$R,18,0) -> 551.8 | O13: =IF(ISERROR(VLOOKUP($A13,库存调整表US!$A:$K,11,0)),0,VLOOKUP($A13,库存调整表US!$A:$K,11,0)) -> -369 | P13: =(H13+M13)/($E13+$J13) -> 106.95217 | Q13: =(I13+N13)/($E13+$J13) -> 3.1 | R13: =IFERROR($O13*P13,0) -> -39465.349 | S13: =IFERROR($O13*Q13,0) -> -1143.9 | T13: =VLOOKUP($A13,库存调整表US!$A:$I,9,0) -> 164 | U13: =$T13*$P13 -> 17540.155 | V13: =$T13*Q13 -> 508.4 | W13: =VLOOKUP($A13,库存调整表US!$A:$P,MATCH(W$5,库存调整表US!$A$2:$P$2,0),0) -> -1 | X13: =$W13*S13 -> 1143.9 | Y13: =$W13*T13 -> -164 | Z13: =VLOOKUP($A13,库存调整表US!$A:$P,MATCH(Z$6,库存调整表US!$A$2:$P$2,0),0) -> 1 | AA13: =VLOOKUP($A13,库存调整表US!$A:$P,MATCH(AA$6,库存调整表US!$A$2:$P$2,0),0) -> -3 | AB13: =VLOOKUP($A13,库存调整表US!$A:$P,MATCH(AB$6,库存调整表US!$A$2:$P$2,0),0) -> 0 | AC13: =VLOOKUP($A13,库存调整表US!$A:$P,MATCH(AC$6,库存调整表US!$A$2:$P$2,0),0) -> 0 | AD13: =SUM(Z13:AC13) -> -2 | AE13: =$AD13*P13 -> -213.90433 | AF13: =$AD13*Q13 -> -6.2 | AG13: =E13+J13+O13+T13+AD13 -> 146 | AH13: =IF(ISERROR(AJ13/AG13),0,AJ13/AG13) -> 114.7871 | AI13: =IF(ISERROR(AK13/$AG13),0,AK13/$AG13) -> 1.9767123 | AJ13: =H13+M13+R13+U13+AE13+X13 -> 16758.916 | AK13: =I13+N13+S13+V13+AF13+Y13 -> 288.6 | AL13: 145 | AM13: =AG13-AL13 -> 1 | AN13: =R13+S13+U13+V13+X13+Y13 -> -21580.794 | AO13: =AE13+AF13 -> -220.10433
A14: TOP01 | D14: A004-US | E14: 107 | F14: =H14/E14 -> 226.9586 | G14: =I14/E14 -> 19.3 | H14: 24284.57 | I14: 2065.1 | J14: =VLOOKUP($A14,在途仓!$A:$N,14,0) -> 47 | K14: =VLOOKUP($A14,在途仓!$A:$V,14,0) -> 47 | L14: =IFERROR(N14/J14,0) -> 19.3 | M14: =-VLOOKUP($A14,在途仓!$A:$R,17,0) -> 10690.554 | N14: =-VLOOKUP($A14,在途仓!$A:$R,18,0) -> 907.1 | O14: =IF(ISERROR(VLOOKUP($A14,库存调整表US!$A:$K,11,0)),0,VLOOKUP($A14,库存调整表US!$A:$K,11,0)) -> -143 | P14: =(H14+M14)/($E14+$J14) -> 227.1112 | Q14: =(I14+N14)/($E14+$J14) -> 19.3 | R14: =IFERROR($O14*P14,0) -> -32476.901 | S14: =IFERROR($O14*Q14,0) -> -2759.9 | T14: =VLOOKUP($A14,库存调整表US!$A:$I,9,0) -> 0 | U14: =$T14*$P14 -> 0 | V14: =$T14*Q14 -> 0 | W14: =VLOOKUP($A14,库存调整表US!$A:$P,MATCH(W$5,库存调整表US!$A$2:$P$2,0),0) -> 0 | X14: =$W14*S14 -> 0 | Y14: =$W14*T14 -> 0 | Z14: =VLOOKUP($A14,库存调整表US!$A:$P,MATCH(Z$6,库存调整表US!$A$2:$P$2,0),0) -> 2 | AA14: =VLOOKUP($A14,库存调整表US!$A:$P,MATCH(AA$6,库存调整表US!$A$2:$P$2,0),0) -> 0 | AB14: =VLOOKUP($A14,库存调整表US!$A:$P,MATCH(AB$6,库存调整表US!$A$2:$P$2,0),0) -> 0 | AC14: =VLOOKUP($A14,库存调整表US!$A:$P,MATCH(AC$6,库存调整表US!$A$2:$P$2,0),0) -> 0 | AD14: =SUM(Z14:AC14) -> 2 | AE14: =$AD14*P14 -> 454.22239 | AF14: =$AD14*Q14 -> 38.6 | AG14: =E14+J14+O14+T14+AD14 -> 13 | AH14: =IF(ISERROR(AJ14/AG14),0,AJ14/AG14) -> 227.1112 | AI14: =IF(ISERROR(AK14/$AG14),0,AK14/$AG14) -> 19.3 | AJ14: =H14+M14+R14+U14+AE14+X14 -> 2952.4456 | AK14: =I14+N14+S14+V14+AF14+Y14 -> 250.9 | AL14: 13 | AM14: =AG14-AL14 -> 0 | AN14: =R14+S14+U14+V14+X14+Y14 -> -35236.801 | AO14: =AE14+AF14 -> 492.82239
