Workbook

Sheet 主页
B2: 预算编制年度实际数据截止月份 | D2: 44499
B4: 编制说明：
B5: 表格中黄色单元格中设有公式，可自动运算，不需要直接填写数据。如果数据行数超过表格预先留的行数，请注意复制每行的相应公式。
B7: 编制步骤：
B8: 步骤1：填写上年标准成本、上年的销售明细。 上年数据将用作分析当年数据的比较基数。
C9: 填写上年标准成本
C10: 注意事项：
C11: 在每份表格的同一个年度里，统一选择一套单位成本作为标准成本，进行销售成本的计算，以保证不同维度之间毛利数据的可比性。兼顾单位成本数据与实际成本水平的接近程度和数据的可得性，可以选择当年或最近一个月或最近一个季度的平均实际成本、或者标准成本。
C12: 填写上年实际销售明细数据
B14: 步骤2：填写当年标准成本、当年截止至最后一个结账月份的销售明细。 当年的实际数据加上当年剩余月份的估计数据，将用做分析下年预算数据的对比基数。
C15: 填写当年标准成本
C16: 填写当年实际
C17: 注意事项：
C18: 尽量详细到各个维度最末一级，如每个产品、每个客户、每份单据。因为进行数据汇总会比进行数据拆解容易得多。
B20: 步骤3：分别按渠道、业务员、客户、产品等维度估计当年剩余月份的销售数据
C21: 填写当年剩余月份估计数（ 渠道）
C22: 填写当年剩余月份估计数（部门 业务员）
C23: 填写当年剩余月份估计数（客户）
C24: 填写当年剩余月份估计数（ 产品）
B26: 步骤4：分别按渠道、业务员、客户、产品等维度填写下年的预算销售数据
C27: 填写下年预算销售数据（ 渠道）
C28: 填写下年预算销售数据（业务员）
C29: 填写下年预算销售数据（ 客户）
C30: 填写下年预算销售数据（产品）
C31: 填写下年预算分月销售额
B33: 步骤5：将分解到渠道、部门及业务员、客户、产品等各个维度的当年估计数和下年预算数与目标数进行核对、校准，对数据进行必要调整
C34: 查看并预算校准表格
B36: 步骤6：对下年预算、当年估计、上年实际进行对比分析，确认价格、毛利变化的合理性
C37: 查看并核对销售对比分析底稿
C38: 注意事项：注意确认表格中是否已经涵盖到了上年、当年、预算中涉及的所有产品，表格中公式完整
C39: 查看产品销售及毛利影响因素分析

Sheet 上年标准成本
A1: 产品大类 | B1: 产品子类 | C1: 产品名称 | D1: 产品来源 | E1: 外购价格 | F1: 材料成本 | G1: 外协加工费 | H1: 人工及制造费用 | I1: 单位成本 | K1: 返回主页
A2: PA | B2: PA01 | C2: A0111 | D2: 外购 | E2: 13 | I2: =SUM(E2:H2) -> 13
A3: PB | B3: PB01 | C3: B0122 | D3: 自制 | F3: 10 | G3: 1 | H3: 2 | I3: =SUM(E3:H3) -> 13
A4: PC | B4: PC01 | C4: C0122 | D4: 自制 | F4: 5 | G4: 1 | H4: 3 | I4: =SUM(E4:H4) -> 9
A5: PA | B5: PA01 | C5: A0111 | D5: 自制 | F5: 9 | G5: 2 | H5: 3 | I5: =SUM(E5:H5) -> 14
A6: PB | B6: PB01 | C6: B0122 | D6: 自制 | F6: 9 | H6: 5 | I6: =SUM(E6:H6) -> 14
A7: PC | B7: PC01 | C7: C0122 | D7: 自制 | F7: 4 | G7: 2 | H7: 1 | I7: =SUM(E7:H7) -> 7
A8: SE | B8: SE99 | C8: C0199 | D8: 服务 | F8: 80 | G8: 30 | H8: 10 | I8: =SUM(E8:H8) -> 120

Sheet 上年实际
A1: 订单日期 | B1: 订单号 | C1: 交付日期 | D1: 客户大类 | E1: 客户子类 | F1: 客户名称 | G1: 渠道分类 | H1: 渠道名称 | I1: 销售部门 | J1: 业务员 | K1: 产品名称 | L1: 产品大类 | M1: 产品子类 | N1: 产品来源 | O1: 销售数量 | P1: 不含税销售收入 | Q1: 增值税率 | R1: 不含税销售单价 | S1: 含税单价 | T1: 单位标准成本 | U1: 销售成本 | V1: 销售毛利 | W1: 毛利率 | X1: 毛利占比% | Z1: 返回主页
A2: 44211 | B2: SO0001 | C2: 43861 | D2: CA | E2: CA01 | F2: 天猫 | G2: SCA | H2: SCA01 | I2: DA | J2: 张三 | K2: A0111 | L2: PA | M2: PA01 | N2: 外购 | O2: 98 | P2: 1500 | Q2: 0.13 | R2: =IFERROR(P2/O2,"") -> 15.306122 | S2: =IFERROR(R2*(1+Q2),"") -> 17.295918 | T2: =IFERROR(INDEX(上年标准成本!$I:$I,MATCH(K2,上年标准成本!$C:$C,0),1),"") -> 13 | U2: =IFERROR(O2*T2,"") -> 1274 | V2: =IFERROR(P2-U2,"") -> 226 | W2: =IFERROR(V2/P2,"") -> 0.15066667 | X2: =IFERROR(IF(W2/SUM(W:W)=0,"",W2/SUM(W:W)),"") -> 0.16231745
A3: 44286 | B3: SO0002 | C3: 43951 | D3: CB | E3: CB01 | F3: 苏宁 | G3: SCB | H3: SCB01 | I3: DB | J3: 李四 | K3: B0122 | L3: PB | M3: PB01 | N3: 自制 | O3: 121 | P3: 1980 | Q3: 0.13 | R3: =IFERROR(P3/O3,"") -> 16.363636 | S3: =IFERROR(R3*(1+Q3),"") -> 18.490909 | T3: =IFERROR(INDEX(上年标准成本!$I:$I,MATCH(K3,上年标准成本!$C:$C,0),1),"") -> 13 | U3: =IFERROR(O3*T3,"") -> 1573 | V3: =IFERROR(P3-U3,"") -> 407 | W3: =IFERROR(V3/P3,"") -> 0.20555556 | X3: =IFERROR(IF(W3/SUM(W:W)=0,"",W3/SUM(W:W)),"") -> 0.2214508
A4: 44345 | B4: SO0003 | C4: 43981 | D4: CC | E4: CC01 | F4: 京东 | G4: SCC | H4: SCC01 | I4: DC | J4: 王二麻子 | K4: C0122 | L4: PC | M4: PC01 | N4: 自制 | O4: 88 | P4: 1000 | Q4: 0.13 | R4: =IFERROR(P4/O4,"") -> 11.363636 | S4: =IFERROR(R4*(1+Q4),"") -> 12.840909 | T4: =IFERROR(INDEX(上年标准成本!$I:$I,MATCH(K4,上年标准成本!$C:$C,0),1),"") -> 9 | U4: =IFERROR(O4*T4,"") -> 792 | V4: =IFERROR(P4-U4,"") -> 208 | W4: =IFERROR(V4/P4,"") -> 0.208 | X4: =IFERROR(IF(W4/SUM(W:W)=0,"",W4/SUM(W:W)),"") -> 0.22408427
A5: 44345 | B5: SO0003 | C5: 43981 | D5: CC | E5: CC01 | F5: 苏宁 | G5: SCC | H5: SCC01 | I5: DC | J5: 王二麻子 | K5: C0199 | L5: SE | M5: SE99 | N5: 服务 | O5: 3 | P5: 566.03774 | Q5: 0.06 | R5: =IFERROR(P5/O5,"") -> 188.67925 | S5: =IFERROR(R5*(1+Q5),"") -> 200 | T5: =IFERROR(INDEX(上年标准成本!$I:$I,MATCH(K5,上年标准成本!$C:$C,0),1),"") -> 120 | U5: =IFERROR(O5*T5,"") -> 360 | V5: =IFERROR(P5-U5,"") -> 206.03774 | W5: =IFERROR(V5/P5,"") -> 0.364 | X5: =IFERROR(IF(W5/SUM(W:W)=0,"",W5/SUM(W:W)),"") -> 0.39214747
R6: =IFERROR(P6/O6,"") | S6: =IFERROR(R6*(1+Q6),"") | T6: =IFERROR(INDEX(上年标准成本!$I:$I,MATCH(K6,上年标准成本!$C:$C,0),1),"") | U6: =IFERROR(O6*T6,"") | V6: =IFERROR(P6-U6,"") | W6: =IFERROR(V6/P6,"") | X6: =IFERROR(IF(W6/SUM(W:W)=0,"",W6/SUM(W:W)),"")
R7: =IFERROR(P7/O7,"") | S7: =IFERROR(R7*(1+Q7),"") | T7: =IFERROR(INDEX(上年标准成本!$I:$I,MATCH(K7,上年标准成本!$C:$C,0),1),"") | U7: =IFERROR(O7*T7,"") | V7: =IFERROR(P7-U7,"") | W7: =IFERROR(V7/P7,"") | X7: =IFERROR(IF(W7/SUM(W:W)=0,"",W7/SUM(W:W)),"")
R8: =IFERROR(P8/O8,"") | S8: =IFERROR(R8*(1+Q8),"") | T8: =IFERROR(INDEX(上年标准成本!$I:$I,MATCH(K8,上年标准成本!$C:$C,0),1),"") | U8: =IFERROR(O8*T8,"") | V8: =IFERROR(P8-U8,"") | W8: =IFERROR(V8/P8,"") | X8: =IFERROR(IF(W8/SUM(W:W)=0,"",W8/SUM(W:W)),"")
R9: =IFERROR(P9/O9,"") | S9: =IFERROR(R9*(1+Q9),"") | T9: =IFERROR(INDEX(上年标准成本!$I:$I,MATCH(K9,上年标准成本!$C:$C,0),1),"") | U9: =IFERROR(O9*T9,"") | V9: =IFERROR(P9-U9,"") | W9: =IFERROR(V9/P9,"") | X9: =IFERROR(IF(W9/SUM(W:W)=0,"",W9/SUM(W:W)),"")
R10: =IFERROR(P10/O10,"") | S10: =IFERROR(R10*(1+Q10),"") | T10: =IFERROR(INDEX(上年标准成本!$I:$I,MATCH(K10,上年标准成本!$C:$C,0),1),"") | U10: =IFERROR(O10*T10,"") | V10: =IFERROR(P10-U10,"") | W10: =IFERROR(V10/P10,"") | X10: =IFERROR(IF(W10/SUM(W:W)=0,"",W10/SUM(W:W)),"")
R11: =IFERROR(P11/O11,"") | S11: =IFERROR(R11*(1+Q11),"") | T11: =IFERROR(INDEX(上年标准成本!$I:$I,MATCH(K11,上年标准成本!$C:$C,0),1),"") | U11: =IFERROR(O11*T11,"") | V11: =IFERROR(P11-U11,"") | W11: =IFERROR(V11/P11,"") | X11: =IFERROR(IF(W11/SUM(W:W)=0,"",W11/SUM(W:W)),"")
R12: =IFERROR(P12/O12,"") | S12: =IFERROR(R12*(1+Q12),"") | T12: =IFERROR(INDEX(上年标准成本!$I:$I,MATCH(K12,上年标准成本!$C:$C,0),1),"") | U12: =IFERROR(O12*T12,"") | V12: =IFERROR(P12-U12,"") | W12: =IFERROR(V12/P12,"") | X12: =IFERROR(IF(W12/SUM(W:W)=0,"",W12/SUM(W:W)),"")
R13: =IFERROR(P13/O13,"") | S13: =IFERROR(R13*(1+Q13),"") | T13: =IFERROR(INDEX(上年标准成本!$I:$I,MATCH(K13,上年标准成本!$C:$C,0),1),"") | U13: =IFERROR(O13*T13,"") | V13: =IFERROR(P13-U13,"") | W13: =IFERROR(V13/P13,"") | X13: =IFERROR(IF(W13/SUM(W:W)=0,"",W13/SUM(W:W)),"")
R14: =IFERROR(P14/O14,"") | S14: =IFERROR(R14*(1+Q14),"") | T14: =IFERROR(INDEX(上年标准成本!$I:$I,MATCH(K14,上年标准成本!$C:$C,0),1),"") | U14: =IFERROR(O14*T14,"") | V14: =IFERROR(P14-U14,"") | W14: =IFERROR(V14/P14,"") | X14: =IFERROR(IF(W14/SUM(W:W)=0,"",W14/SUM(W:W)),"")
R15: =IFERROR(P15/O15,"") | S15: =IFERROR(R15*(1+Q15),"") | T15: =IFERROR(INDEX(上年标准成本!$I:$I,MATCH(K15,上年标准成本!$C:$C,0),1),"") | U15: =IFERROR(O15*T15,"") | V15: =IFERROR(P15-U15,"") | W15: =IFERROR(V15/P15,"") | X15: =IFERROR(IF(W15/SUM(W:W)=0,"",W15/SUM(W:W)),"")
R16: =IFERROR(P16/O16,"") | S16: =IFERROR(R16*(1+Q16),"") | T16: =IFERROR(INDEX(上年标准成本!$I:$I,MATCH(K16,上年标准成本!$C:$C,0),1),"") | U16: =IFERROR(O16*T16,"") | V16: =IFERROR(P16-U16,"") | W16: =IFERROR(V16/P16,"") | X16: =IFERROR(IF(W16/SUM(W:W)=0,"",W16/SUM(W:W)),"")
R17: =IFERROR(P17/O17,"") | S17: =IFERROR(R17*(1+Q17),"") | T17: =IFERROR(INDEX(上年标准成本!$I:$I,MATCH(K17,上年标准成本!$C:$C,0),1),"") | U17: =IFERROR(O17*T17,"") | V17: =IFERROR(P17-U17,"") | W17: =IFERROR(V17/P17,"") | X17: =IFERROR(IF(W17/SUM(W:W)=0,"",W17/SUM(W:W)),"")
... R999: =IFERROR(P999/O999,"") | S999: =IFERROR(R999*(1+Q999),"") | T999: =IFERROR(INDEX(上年标准成本!$I:$I,MATCH(K999,上年标准成本!$C:$C,0),1),"") | U999: =IFERROR(O999*T999,"") | V999: =IFERROR(P999-U999,"") | W999: =IFERROR(V999/P999,"") | X999: =IFERROR(IF(W999/SUM(W:W)=0,"",W999/SUM(W:W)),"")

Sheet 当年实际
A1: 订单日期 | B1: 订单号 | C1: 交付日期 | D1: 客户大类 | E1: 客户子类 | F1: 客户名称 | G1: 渠道分类 | H1: 渠道名称 | I1: 销售部门 | J1: 业务员 | K1: 产品名称 | L1: 产品大类 | M1: 产品子类 | N1: 产品来源 | O1: 销售数量 | P1: 不含税销售收入 | Q1: 增值税率 | R1: 不含税销售单价 | S1: 含税单价 | T1: 单位标准成本 | U1: 销售成本 | V1: 销售毛利 | W1: 毛利率 | X1: 毛利占比% | Z1: 返回主页
A2: 44211 | B2: SO0001 | C2: 44227 | D2: CA | E2: CA01 | F2: 天猫 | G2: SCA | H2: SCA01 | I2: DA | J2: 张三 | K2: A0111 | L2: PA | M2: PA01 | N2: 外购 | O2: 100 | P2: 1800 | Q2: 0.13 | R2: =IFERROR(P2/O2,"") -> 18 | S2: =IFERROR(R2*(1+Q2),"") -> 20.34 | T2: =IFERROR(INDEX(当年标准成本!$I:$I,MATCH(K2,当年标准成本!$C:$C,0),1),"") -> 13 | U2: =IFERROR(O2*T2,"") -> 1300 | V2: =IFERROR(P2-U2,"") -> 500 | W2: =IFERROR(V2/P2,"") -> 0.27777778 | X2: =IFERROR(IF(W2/SUM(W:W)=0,"",W2/SUM(W:W)),"") -> 0.35082795
A3: 44286 | B3: SO0002 | C3: 44316 | D3: CB | E3: CB01 | F3: 苏宁 | G3: SCB | H3: SCB01 | I3: DB | J3: 李四 | K3: B0122 | L3: PB | M3: PB01 | N3: 自制 | O3: 124 | P3: 2000 | Q3: 0.13 | R3: =IFERROR(P3/O3,"") -> 16.129032 | S3: =IFERROR(R3*(1+Q3),"") -> 18.225806 | T3: =IFERROR(INDEX(当年标准成本!$I:$I,MATCH(K3,当年标准成本!$C:$C,0),1),"") -> 13 | U3: =IFERROR(O3*T3,"") -> 1612 | V3: =IFERROR(P3-U3,"") -> 388 | W3: =IFERROR(V3/P3,"") -> 0.194 | X3: =IFERROR(IF(W3/SUM(W:W)=0,"",W3/SUM(W:W)),"") -> 0.24501824
A4: 44345 | B4: SO0003 | C4: 44346 | D4: CC | E4: CC01 | F4: 京东 | G4: SCC | H4: SCC01 | I4: DC | J4: 王二麻子 | K4: C0122 | L4: PC | M4: PC01 | N4: 自制 | O4: 112 | P4: 1200 | Q4: 0.13 | R4: =IFERROR(P4/O4,"") -> 10.714286 | S4: =IFERROR(R4*(1+Q4),"") -> 12.107143 | T4: =IFERROR(INDEX(当年标准成本!$I:$I,MATCH(K4,当年标准成本!$C:$C,0),1),"") -> 9 | U4: =IFERROR(O4*T4,"") -> 1008 | V4: =IFERROR(P4-U4,"") -> 192 | W4: =IFERROR(V4/P4,"") -> 0.16 | X4: =IFERROR(IF(W4/SUM(W:W)=0,"",W4/SUM(W:W)),"") -> 0.2020769
A5: 44345 | B5: SO0004 | C5: 44530 | D5: CC | E5: CC01 | F5: 京东 | G5: SCC | H5: SCC01 | I5: DC | J5: 王二麻子 | K5: C0122 | L5: PC | M5: PC01 | N5: 自制 | O5: 112 | P5: 1200 | Q5: 0.13 | R5: =IFERROR(P5/O5,"") -> 10.714286 | S5: =IFERROR(R5*(1+Q5),"") -> 12.107143 | T5: =IFERROR(INDEX(当年标准成本!$I:$I,MATCH(K5,当年标准成本!$C:$C,0),1),"") -> 9 | U5: =IFERROR(O5*T5,"") -> 1008 | V5: =IFERROR(P5-U5,"") -> 192 | W5: =IFERROR(V5/P5,"") -> 0.16 | X5: =IFERROR(IF(W5/SUM(W:W)=0,"",W5/SUM(W:W)),"") -> 0.2020769
R6: =IFERROR(P6/O6,"") | S6: =IFERROR(R6*(1+Q6),"") | T6: =IFERROR(INDEX(当年标准成本!$I:$I,MATCH(K6,当年标准成本!$C:$C,0),1),"") | U6: =IFERROR(O6*T6,"") | V6: =IFERROR(P6-U6,"") | W6: =IFERROR(V6/P6,"") | X6: =IFERROR(IF(W6/SUM(W:W)=0,"",W6/SUM(W:W)),"")
R7: =IFERROR(P7/O7,"") | S7: =IFERROR(R7*(1+Q7),"") | T7: =IFERROR(INDEX(当年标准成本!$I:$I,MATCH(K7,当年标准成本!$C:$C,0),1),"") | U7: =IFERROR(O7*T7,"") | V7: =IFERROR(P7-U7,"") | W7: =IFERROR(V7/P7,"") | X7: =IFERROR(IF(W7/SUM(W:W)=0,"",W7/SUM(W:W)),"")
R8: =IFERROR(P8/O8,"") | S8: =IFERROR(R8*(1+Q8),"") | T8: =IFERROR(INDEX(当年标准成本!$I:$I,MATCH(K8,当年标准成本!$C:$C,0),1),"") | U8: =IFERROR(O8*T8,"") | V8: =IFERROR(P8-U8,"") | W8: =IFERROR(V8/P8,"") | X8: =IFERROR(IF(W8/SUM(W:W)=0,"",W8/SUM(W:W)),"")
R9: =IFERROR(P9/O9,"") | S9: =IFERROR(R9*(1+Q9),"") | T9: =IFERROR(INDEX(当年标准成本!$I:$I,MATCH(K9,当年标准成本!$C:$C,0),1),"") | U9: =IFERROR(O9*T9,"") | V9: =IFERROR(P9-U9,"") | W9: =IFERROR(V9/P9,"") | X9: =IFERROR(IF(W9/SUM(W:W)=0,"",W9/SUM(W:W)),"")
R10: =IFERROR(P10/O10,"") | S10: =IFERROR(R10*(1+Q10),"") | T10: =IFERROR(INDEX(当年标准成本!$I:$I,MATCH(K10,当年标准成本!$C:$C,0),1),"") | U10: =IFERROR(O10*T10,"") | V10: =IFERROR(P10-U10,"") | W10: =IFERROR(V10/P10,"") | X10: =IFERROR(IF(W10/SUM(W:W)=0,"",W10/SUM(W:W)),"")
R11: =IFERROR(P11/O11,"") | S11: =IFERROR(R11*(1+Q11),"") | T11: =IFERROR(INDEX(当年标准成本!$I:$I,MATCH(K11,当年标准成本!$C:$C,0),1),"") | U11: =IFERROR(O11*T11,"") | V11: =IFERROR(P11-U11,"") | W11: =IFERROR(V11/P11,"") | X11: =IFERROR(IF(W11/SUM(W:W)=0,"",W11/SUM(W:W)),"")
R12: =IFERROR(P12/O12,"") | S12: =IFERROR(R12*(1+Q12),"") | T12: =IFERROR(INDEX(当年标准成本!$I:$I,MATCH(K12,当年标准成本!$C:$C,0),1),"") | U12: =IFERROR(O12*T12,"") | V12: =IFERROR(P12-U12,"") | W12: =IFERROR(V12/P12,"") | X12: =IFERROR(IF(W12/SUM(W:W)=0,"",W12/SUM(W:W)),"")
R13: =IFERROR(P13/O13,"") | S13: =IFERROR(R13*(1+Q13),"") | T13: =IFERROR(INDEX(当年标准成本!$I:$I,MATCH(K13,当年标准成本!$C:$C,0),1),"") | U13: =IFERROR(O13*T13,"") | V13: =IFERROR(P13-U13,"") | W13: =IFERROR(V13/P13,"") | X13: =IFERROR(IF(W13/SUM(W:W)=0,"",W13/SUM(W:W)),"")
R14: =IFERROR(P14/O14,"") | S14: =IFERROR(R14*(1+Q14),"") | T14: =IFERROR(INDEX(当年标准成本!$I:$I,MATCH(K14,当年标准成本!$C:$C,0),1),"") | U14: =IFERROR(O14*T14,"") | V14: =IFERROR(P14-U14,"") | W14: =IFERROR(V14/P14,"") | X14: =IFERROR(IF(W14/SUM(W:W)=0,"",W14/SUM(W:W)),"")
R15: =IFERROR(P15/O15,"") | S15: =IFERROR(R15*(1+Q15),"") | T15: =IFERROR(INDEX(当年标准成本!$I:$I,MATCH(K15,当年标准成本!$C:$C,0),1),"") | U15: =IFERROR(O15*T15,"") | V15: =IFERROR(P15-U15,"") | W15: =IFERROR(V15/P15,"") | X15: =IFERROR(IF(W15/SUM(W:W)=0,"",W15/SUM(W:W)),"")
R16: =IFERROR(P16/O16,"") | S16: =IFERROR(R16*(1+Q16),"") | T16: =IFERROR(INDEX(当年标准成本!$I:$I,MATCH(K16,当年标准成本!$C:$C,0),1),"") | U16: =IFERROR(O16*T16,"") | V16: =IFERROR(P16-U16,"") | W16: =IFERROR(V16/P16,"") | X16: =IFERROR(IF(W16/SUM(W:W)=0,"",W16/SUM(W:W)),"")
R17: =IFERROR(P17/O17,"") | S17: =IFERROR(R17*(1+Q17),"") | T17: =IFERROR(INDEX(当年标准成本!$I:$I,MATCH(K17,当年标准成本!$C:$C,0),1),"") | U17: =IFERROR(O17*T17,"") | V17: =IFERROR(P17-U17,"") | W17: =IFERROR(V17/P17,"") | X17: =IFERROR(IF(W17/SUM(W:W)=0,"",W17/SUM(W:W)),"")
... R999: =IFERROR(P999/O999,"") | S999: =IFERROR(R999*(1+Q999),"") | T999: =IFERROR(INDEX(当年标准成本!$I:$I,MATCH(K999,当年标准成本!$C:$C,0),1),"") | U999: =IFERROR(O999*T999,"") | V999: =IFERROR(P999-U999,"") | W999: =IFERROR(V999/P999,"") | X999: =IFERROR(IF(W999/SUM(W:W)=0,"",W999/SUM(W:W)),"")

Sheet 当年估计 渠道
A1: 渠道分类 | B1: 渠道名称 | C1: 覆盖客户数量 | D1: ="当年剩余月份估计 E"&TEXT(主页!$D$2,"YY")&"YTG" -> 当年剩余月份估计 E21YTG | J1: ="当年已过去月份实际 A"&TEXT(主页!$D$2,"YY")&"YTD" -> 当年已过去月份实际 A21YTD | L1: 返回主页
D2: 销售收入 | E2: 收入占比% | F2: 毛利率 | G2: 销售毛利 | H2: 毛利占比% | J2: 毛利率
A3: SCB | B3: SCB01 | C3: 1 | D3: 500 | E3: =IF(D3/SUM(D:D)=0,"",D3/SUM(D:D)) -> 0.090909091 | F3: 0.165 | G3: =D3*F3 -> 82.5 | H3: =IF(G3/SUM(G:G)=0,"",G3/SUM(G:G)) -> 0.06639839 | J3: =IFERROR(SUMIFS(当年实际!$V:$V,当年实际!$H:$H,$B3,当年实际!$C:$C,">="&DATE(YEAR(主页!$D$2),1,1),当年实际!$C:$C,"<="&EOMONTH(DATE(YEAR(主页!$D$2),MONTH(主页!$D$2),1),0))/SUMIFS(当年实际!$P:$P,当年实际!$H:$H,$B3,当年实际!$C:$C,">="&DATE(YEAR(主页!$D$2),1,1),当年实际!$C:$C,"<="&EOMONTH(DATE(YEAR(主页!$D$2),MONTH(主页!$D$2),1),0)),"") -> 0.194
A4: SCA | B4: SCA01 | C4: 2 | D4: 2000 | E4: =IF(D4/SUM(D:D)=0,"",D4/SUM(D:D)) -> 0.36363636 | F4: 0.28 | G4: =D4*F4 -> 560 | H4: =IF(G4/SUM(G:G)=0,"",G4/SUM(G:G)) -> 0.45070423 | J4: =IFERROR(SUMIFS(当年实际!$V:$V,当年实际!$H:$H,$B4,当年实际!$C:$C,">="&DATE(YEAR(主页!$D$2),1,1),当年实际!$C:$C,"<="&EOMONTH(DATE(YEAR(主页!$D$2),MONTH(主页!$D$2),1),0))/SUMIFS(当年实际!$P:$P,当年实际!$H:$H,$B4,当年实际!$C:$C,">="&DATE(YEAR(主页!$D$2),1,1),当年实际!$C:$C,"<="&EOMONTH(DATE(YEAR(主页!$D$2),MONTH(主页!$D$2),1),0)),"") -> 0.27777778
A5: SCC | B5: SCC01 | C5: 3 | D5: 3000 | E5: =IF(D5/SUM(D:D)=0,"",D5/SUM(D:D)) -> 0.54545455 | F5: 0.2 | G5: =D5*F5 -> 600 | H5: =IF(G5/SUM(G:G)=0,"",G5/SUM(G:G)) -> 0.48289738 | J5: =IFERROR(SUMIFS(当年实际!$V:$V,当年实际!$H:$H,$B5,当年实际!$C:$C,">="&DATE(YEAR(主页!$D$2),1,1),当年实际!$C:$C,"<="&EOMONTH(DATE(YEAR(主页!$D$2),MONTH(主页!$D$2),1),0))/SUMIFS(当年实际!$P:$P,当年实际!$H:$H,$B5,当年实际!$C:$C,">="&DATE(YEAR(主页!$D$2),1,1),当年实际!$C:$C,"<="&EOMONTH(DATE(YEAR(主页!$D$2),MONTH(主页!$D$2),1),0)),"") -> 0.16
E6: =IF(D6/SUM(D:D)=0,"",D6/SUM(D:D)) | G6: =D6*F6 -> 0 | H6: =IF(G6/SUM(G:G)=0,"",G6/SUM(G:G)) | J6: =IFERROR(SUMIFS(当年实际!$V:$V,当年实际!$H:$H,$B6,当年实际!$C:$C,">="&DATE(YEAR(主页!$D$2),1,1),当年实际!$C:$C,"<="&EOMONTH(DATE(YEAR(主页!$D$2),MONTH(主页!$D$2),1),0))/SUMIFS(当年实际!$P:$P,当年实际!$H:$H,$B6,当年实际!$C:$C,">="&DATE(YEAR(主页!$D$2),1,1),当年实际!$C:$C,"<="&EOMONTH(DATE(YEAR(主页!$D$2),MONTH(主页!$D$2),1),0)),"")
E7: =IF(D7/SUM(D:D)=0,"",D7/SUM(D:D)) | G7: =D7*F7 -> 0 | H7: =IF(G7/SUM(G:G)=0,"",G7/SUM(G:G)) | J7: =IFERROR(SUMIFS(当年实际!$V:$V,当年实际!$H:$H,$B7,当年实际!$C:$C,">="&DATE(YEAR(主页!$D$2),1,1),当年实际!$C:$C,"<="&EOMONTH(DATE(YEAR(主页!$D$2),MONTH(主页!$D$2),1),0))/SUMIFS(当年实际!$P:$P,当年实际!$H:$H,$B7,当年实际!$C:$C,">="&DATE(YEAR(主页!$D$2),1,1),当年实际!$C:$C,"<="&EOMONTH(DATE(YEAR(主页!$D$2),MONTH(主页!$D$2),1),0)),"")
E8: =IF(D8/SUM(D:D)=0,"",D8/SUM(D:D)) | G8: =D8*F8 -> 0 | H8: =IF(G8/SUM(G:G)=0,"",G8/SUM(G:G)) | J8: =IFERROR(SUMIFS(当年实际!$V:$V,当年实际!$H:$H,$B8,当年实际!$C:$C,">="&DATE(YEAR(主页!$D$2),1,1),当年实际!$C:$C,"<="&EOMONTH(DATE(YEAR(主页!$D$2),MONTH(主页!$D$2),1),0))/SUMIFS(当年实际!$P:$P,当年实际!$H:$H,$B8,当年实际!$C:$C,">="&DATE(YEAR(主页!$D$2),1,1),当年实际!$C:$C,"<="&EOMONTH(DATE(YEAR(主页!$D$2),MONTH(主页!$D$2),1),0)),"")
E9: =IF(D9/SUM(D:D)=0,"",D9/SUM(D:D)) | G9: =D9*F9 -> 0 | H9: =IF(G9/SUM(G:G)=0,"",G9/SUM(G:G)) | J9: =IFERROR(SUMIFS(当年实际!$V:$V,当年实际!$H:$H,$B9,当年实际!$C:$C,">="&DATE(YEAR(主页!$D$2),1,1),当年实际!$C:$C,"<="&EOMONTH(DATE(YEAR(主页!$D$2),MONTH(主页!$D$2),1),0))/SUMIFS(当年实际!$P:$P,当年实际!$H:$H,$B9,当年实际!$C:$C,">="&DATE(YEAR(主页!$D$2),1,1),当年实际!$C:$C,"<="&EOMONTH(DATE(YEAR(主页!$D$2),MONTH(主页!$D$2),1),0)),"")
E10: =IF(D10/SUM(D:D)=0,"",D10/SUM(D:D)) | G10: =D10*F10 -> 0 | H10: =IF(G10/SUM(G:G)=0,"",G10/SUM(G:G)) | J10: =IFERROR(SUMIFS(当年实际!$V:$V,当年实际!$H:$H,$B10,当年实际!$C:$C,">="&DATE(YEAR(主页!$D$2),1,1),当年实际!$C:$C,"<="&EOMONTH(DATE(YEAR(主页!$D$2),MONTH(主页!$D$2),1),0))/SUMIFS(当年实际!$P:$P,当年实际!$H:$H,$B10,当年实际!$C:$C,">="&DATE(YEAR(主页!$D$2),1,1),当年实际!$C:$C,"<="&EOMONTH(DATE(YEAR(主页!$D$2),MONTH(主页!$D$2),1),0)),"")
E11: =IF(D11/SUM(D:D)=0,"",D11/SUM(D:D)) | G11: =D11*F11 -> 0 | H11: =IF(G11/SUM(G:G)=0,"",G11/SUM(G:G)) | J11: =IFERROR(SUMIFS(当年实际!$V:$V,当年实际!$H:$H,$B11,当年实际!$C:$C,">="&DATE(YEAR(主页!$D$2),1,1),当年实际!$C:$C,"<="&EOMONTH(DATE(YEAR(主页!$D$2),MONTH(主页!$D$2),1),0))/SUMIFS(当年实际!$P:$P,当年实际!$H:$H,$B11,当年实际!$C:$C,">="&DATE(YEAR(主页!$D$2),1,1),当年实际!$C:$C,"<="&EOMONTH(DATE(YEAR(主页!$D$2),MONTH(主页!$D$2),1),0)),"")
E12: =IF(D12/SUM(D:D)=0,"",D12/SUM(D:D)) | G12: =D12*F12 -> 0 | H12: =IF(G12/SUM(G:G)=0,"",G12/SUM(G:G)) | J12: =IFERROR(SUMIFS(当年实际!$V:$V,当年实际!$H:$H,$B12,当年实际!$C:$C,">="&DATE(YEAR(主页!$D$2),1,1),当年实际!$C:$C,"<="&EOMONTH(DATE(YEAR(主页!$D$2),MONTH(主页!$D$2),1),0))/SUMIFS(当年实际!$P:$P,当年实际!$H:$H,$B12,当年实际!$C:$C,">="&DATE(YEAR(主页!$D$2),1,1),当年实际!$C:$C,"<="&EOMONTH(DATE(YEAR(主页!$D$2),MONTH(主页!$D$2),1),0)),"")
E13: =IF(D13/SUM(D:D)=0,"",D13/SUM(D:D)) | G13: =D13*F13 -> 0 | H13: =IF(G13/SUM(G:G)=0,"",G13/SUM(G:G)) | J13: =IFERROR(SUMIFS(当年实际!$V:$V,当年实际!$H:$H,$B13,当年实际!$C:$C,">="&DATE(YEAR(主页!$D$2),1,1),当年实际!$C:$C,"<="&EOMONTH(DATE(YEAR(主页!$D$2),MONTH(主页!$D$2),1),0))/SUMIFS(当年实际!$P:$P,当年实际!$H:$H,$B13,当年实际!$C:$C,">="&DATE(YEAR(主页!$D$2),1,1),当年实际!$C:$C,"<="&EOMONTH(DATE(YEAR(主页!$D$2),MONTH(主页!$D$2),1),0)),"")
E14: =IF(D14/SUM(D:D)=0,"",D14/SUM(D:D)) | G14: =D14*F14 -> 0 | H14: =IF(G14/SUM(G:G)=0,"",G14/SUM(G:G)) | J14: =IFERROR(SUMIFS(当年实际!$V:$V,当年实际!$H:$H,$B14,当年实际!$C:$C,">="&DATE(YEAR(主页!$D$2),1,1),当年实际!$C:$C,"<="&EOMONTH(DATE(YEAR(主页!$D$2),MONTH(主页!$D$2),1),0))/SUMIFS(当年实际!$P:$P,当年实际!$H:$H,$B14,当年实际!$C:$C,">="&DATE(YEAR(主页!$D$2),1,1),当年实际!$C:$C,"<="&EOMONTH(DATE(YEAR(主页!$D$2),MONTH(主页!$D$2),1),0)),"")
E15: =IF(D15/SUM(D:D)=0,"",D15/SUM(D:D)) | G15: =D15*F15 -> 0 | H15: =IF(G15/SUM(G:G)=0,"",G15/SUM(G:G)) | J15: =IFERROR(SUMIFS(当年实际!$V:$V,当年实际!$H:$H,$B15,当年实际!$C:$C,">="&DATE(YEAR(主页!$D$2),1,1),当年实际!$C:$C,"<="&EOMONTH(DATE(YEAR(主页!$D$2),MONTH(主页!$D$2),1),0))/SUMIFS(当年实际!$P:$P,当年实际!$H:$H,$B15,当年实际!$C:$C,">="&DATE(YEAR(主页!$D$2),1,1),当年实际!$C:$C,"<="&EOMONTH(DATE(YEAR(主页!$D$2),MONTH(主页!$D$2),1),0)),"")
E16: =IF(D16/SUM(D:D)=0,"",D16/SUM(D:D)) | G16: =D16*F16 -> 0 | H16: =IF(G16/SUM(G:G)=0,"",G16/SUM(G:G)) | J16: =IFERROR(SUMIFS(当年实际!$V:$V,当年实际!$H:$H,$B16,当年实际!$C:$C,">="&DATE(YEAR(主页!$D$2),1,1),当年实际!$C:$C,"<="&EOMONTH(DATE(YEAR(主页!$D$2),MONTH(主页!$D$2),1),0))/SUMIFS(当年实际!$P:$P,当年实际!$H:$H,$B16,当年实际!$C:$C,">="&DATE(YEAR(主页!$D$2),1,1),当年实际!$C:$C,"<="&EOMONTH(DATE(YEAR(主页!$D$2),MONTH(主页!$D$2),1),0)),"")
E17: =IF(D17/SUM(D:D)=0,"",D17/SUM(D:D)) | G17: =D17*F17 -> 0 | H17: =IF(G17/SUM(G:G)=0,"",G17/SUM(G:G)) | J17: =IFERROR(SUMIFS(当年实际!$V:$V,当年实际!$H:$H,$B17,当年实际!$C:$C,">="&DATE(YEAR(主页!$D$2),1,1),当年实际!$C:$C,"<="&EOMONTH(DATE(YEAR(主页!$D$2),MONTH(主页!$D$2),1),0))/SUMIFS(当年实际!$P:$P,当年实际!$H:$H,$B17,当年实际!$C:$C,">="&DATE(YEAR(主页!$D$2),1,1),当年实际!$C:$C,"<="&EOMONTH(DATE(YEAR(主页!$D$2),MONTH(主页!$D$2),1),0)),"")
... E1201: =IF(D1201/SUM(D:D)=0,"",D1201/SUM(D:D)) | G1201: =D1201*F1201 -> 0 | H1201: =IF(G1201/SUM(G:G)=0,"",G1201/SUM(G:G)) | J1201: =IFERROR(SUMIFS(当年实际!$V:$V,当年实际!$H:$H,$B1201,当年实际!$C:$C,">="&DATE(YEAR(主页!$D$2),1,1),当年实际!$C:$C,"<="&EOMONTH(DATE(YEAR(主页!$D$2),MONTH(主页!$D$2),1),0))/SUMIFS(当年实际!$P:$P,当年实际!$H:$H,$B1201,当年实际!$C:$C,">="&DATE(YEAR(主页!$D$2),1,1),当年实际!$C:$C,"<="&EOMONTH(DATE(YEAR(主页!$D$2),MONTH(主页!$D$2),1),0)),"")

Sheet 当年估计 业务员
A1: 销售大区 | B1: 办事处 | C1: 业务员 | D1: ="当年剩余月份估计 E"&TEXT(主页!$D$2,"YY")&"YTG" -> 当年剩余月份估计 E21YTG | J1: ="当年已过去月份实际 A"&TEXT(主页!$D$2,"YY")&"YTD" -> 当年已过去月份实际 A21YTD | M1: 返回主页
A2: 销售大区 | B2: 办事处 | C2: 业务员 | D2: 销售收入 | E2: 收入占比% | F2: 毛利率 | G2: 销售毛利 | H2: 毛利占比% | J2: 毛利率
A3: 东区 | B3: 北京 | C3: 张三 | D3: 1200 | E3: =IF(D3/SUM(D:D)=0,"",D3/SUM(D:D)) -> 0.19354839 | F3: 0.17 | G3: =D3*F3 -> 204 | H3: =IF(G3/SUM(G:G)=0,"",G3/SUM(G:G)) -> 0.1347424 | J3: =IFERROR(SUMIFS(当年实际!$V:$V,当年实际!$J:$J,$C3,当年实际!$C:$C,">="&DATE(YEAR(主页!$D$2),1,1),当年实际!$C:$C,"<="&EOMONTH(DATE(YEAR(主页!$D$2),MONTH(主页!$D$2),1),0))/SUMIFS(当年实际!$P:$P,当年实际!$J:$J,$C3,当年实际!$C:$C,">="&DATE(YEAR(主页!$D$2),1,1),当年实际!$C:$C,"<="&EOMONTH(DATE(YEAR(主页!$D$2),MONTH(主页!$D$2),1),0)),"") -> 0.27777778
A4: 南区 | B4: 上海 | C4: 李四 | D4: 2000 | E4: =IF(D4/SUM(D:D)=0,"",D4/SUM(D:D)) -> 0.32258065 | F4: 0.13 | G4: =D4*F4 -> 260 | H4: =IF(G4/SUM(G:G)=0,"",G4/SUM(G:G)) -> 0.17173052 | J4: =IFERROR(SUMIFS(当年实际!$V:$V,当年实际!$J:$J,$C4,当年实际!$C:$C,">="&DATE(YEAR(主页!$D$2),1,1),当年实际!$C:$C,"<="&EOMONTH(DATE(YEAR(主页!$D$2),MONTH(主页!$D$2),1),0))/SUMIFS(当年实际!$P:$P,当年实际!$J:$J,$C4,当年实际!$C:$C,">="&DATE(YEAR(主页!$D$2),1,1),当年实际!$C:$C,"<="&EOMONTH(DATE(YEAR(主页!$D$2),MONTH(主页!$D$2),1),0)),"") -> 0.194
A5: 北区 | B5: 广州 | C5: 王二麻子 | D5: 3000 | E5: =IF(D5/SUM(D:D)=0,"",D5/SUM(D:D)) -> 0.48387097 | F5: 0.35 | G5: =D5*F5 -> 1050 | H5: =IF(G5/SUM(G:G)=0,"",G5/SUM(G:G)) -> 0.69352708 | J5: =IFERROR(SUMIFS(当年实际!$V:$V,当年实际!$J:$J,$C5,当年实际!$C:$C,">="&DATE(YEAR(主页!$D$2),1,1),当年实际!$C:$C,"<="&EOMONTH(DATE(YEAR(主页!$D$2),MONTH(主页!$D$2),1),0))/SUMIFS(当年实际!$P:$P,当年实际!$J:$J,$C5,当年实际!$C:$C,">="&DATE(YEAR(主页!$D$2),1,1),当年实际!$C:$C,"<="&EOMONTH(DATE(YEAR(主页!$D$2),MONTH(主页!$D$2),1),0)),"") -> 0.16
E6: =IF(D6/SUM(D:D)=0,"",D6/SUM(D:D)) | G6: =D6*F6 -> 0 | H6: =IF(G6/SUM(G:G)=0,"",G6/SUM(G:G)) | J6: =IFERROR(SUMIFS(当年实际!$V:$V,当年实际!$J:$J,$C6,当年实际!$C:$C,">="&DATE(YEAR(主页!$D$2),1,1),当年实际!$C:$C,"<="&EOMONTH(DATE(YEAR(主页!$D$2),MONTH(主页!$D$2),1),0))/SUMIFS(当年实际!$P:$P,当年实际!$J:$J,$C6,当年实际!$C:$C,">="&DATE(YEAR(主页!$D$2),1,1),当年实际!$C:$C,"<="&EOMONTH(DATE(YEAR(主页!$D$2),MONTH(主页!$D$2),1),0)),"")
E7: =IF(D7/SUM(D:D)=0,"",D7/SUM(D:D)) | G7: =D7*F7 -> 0 | H7: =IF(G7/SUM(G:G)=0,"",G7/SUM(G:G)) | J7: =IFERROR(SUMIFS(当年实际!$V:$V,当年实际!$J:$J,$C7,当年实际!$C:$C,">="&DATE(YEAR(主页!$D$2),1,1),当年实际!$C:$C,"<="&EOMONTH(DATE(YEAR(主页!$D$2),MONTH(主页!$D$2),1),0))/SUMIFS(当年实际!$P:$P,当年实际!$J:$J,$C7,当年实际!$C:$C,">="&DATE(YEAR(主页!$D$2),1,1),当年实际!$C:$C,"<="&EOMONTH(DATE(YEAR(主页!$D$2),MONTH(主页!$D$2),1),0)),"")
E8: =IF(D8/SUM(D:D)=0,"",D8/SUM(D:D)) | G8: =D8*F8 -> 0 | H8: =IF(G8/SUM(G:G)=0,"",G8/SUM(G:G)) | J8: =IFERROR(SUMIFS(当年实际!$V:$V,当年实际!$J:$J,$C8,当年实际!$C:$C,">="&DATE(YEAR(主页!$D$2),1,1),当年实际!$C:$C,"<="&EOMONTH(DATE(YEAR(主页!$D$2),MONTH(主页!$D$2),1),0))/SUMIFS(当年实际!$P:$P,当年实际!$J:$J,$C8,当年实际!$C:$C,">="&DATE(YEAR(主页!$D$2),1,1),当年实际!$C:$C,"<="&EOMONTH(DATE(YEAR(主页!$D$2),MONTH(主页!$D$2),1),0)),"")
E9: =IF(D9/SUM(D:D)=0,"",D9/SUM(D:D)) | G9: =D9*F9 -> 0 | H9: =IF(G9/SUM(G:G)=0,"",G9/SUM(G:G)) | J9: =IFERROR(SUMIFS(当年实际!$V:$V,当年实际!$J:$J,$C9,当年实际!$C:$C,">="&DATE(YEAR(主页!$D$2),1,1),当年实际!$C:$C,"<="&EOMONTH(DATE(YEAR(主页!$D$2),MONTH(主页!$D$2),1),0))/SUMIFS(当年实际!$P:$P,当年实际!$J:$J,$C9,当年实际!$C:$C,">="&DATE(YEAR(主页!$D$2),1,1),当年实际!$C:$C,"<="&EOMONTH(DATE(YEAR(主页!$D$2),MONTH(主页!$D$2),1),0)),"")
E10: =IF(D10/SUM(D:D)=0,"",D10/SUM(D:D)) | G10: =D10*F10 -> 0 | H10: =IF(G10/SUM(G:G)=0,"",G10/SUM(G:G)) | J10: =IFERROR(SUMIFS(当年实际!$V:$V,当年实际!$J:$J,$C10,当年实际!$C:$C,">="&DATE(YEAR(主页!$D$2),1,1),当年实际!$C:$C,"<="&EOMONTH(DATE(YEAR(主页!$D$2),MONTH(主页!$D$2),1),0))/SUMIFS(当年实际!$P:$P,当年实际!$J:$J,$C10,当年实际!$C:$C,">="&DATE(YEAR(主页!$D$2),1,1),当年实际!$C:$C,"<="&EOMONTH(DATE(YEAR(主页!$D$2),MONTH(主页!$D$2),1),0)),"")
E11: =IF(D11/SUM(D:D)=0,"",D11/SUM(D:D)) | G11: =D11*F11 -> 0 | H11: =IF(G11/SUM(G:G)=0,"",G11/SUM(G:G)) | J11: =IFERROR(SUMIFS(当年实际!$V:$V,当年实际!$J:$J,$C11,当年实际!$C:$C,">="&DATE(YEAR(主页!$D$2),1,1),当年实际!$C:$C,"<="&EOMONTH(DATE(YEAR(主页!$D$2),MONTH(主页!$D$2),1),0))/SUMIFS(当年实际!$P:$P,当年实际!$J:$J,$C11,当年实际!$C:$C,">="&DATE(YEAR(主页!$D$2),1,1),当年实际!$C:$C,"<="&EOMONTH(DATE(YEAR(主页!$D$2),MONTH(主页!$D$2),1),0)),"")
E12: =IF(D12/SUM(D:D)=0,"",D12/SUM(D:D)) | G12: =D12*F12 -> 0 | H12: =IF(G12/SUM(G:G)=0,"",G12/SUM(G:G)) | J12: =IFERROR(SUMIFS(当年实际!$V:$V,当年实际!$J:$J,$C12,当年实际!$C:$C,">="&DATE(YEAR(主页!$D$2),1,1),当年实际!$C:$C,"<="&EOMONTH(DATE(YEAR(主页!$D$2),MONTH(主页!$D$2),1),0))/SUMIFS(当年实际!$P:$P,当年实际!$J:$J,$C12,当年实际!$C:$C,">="&DATE(YEAR(主页!$D$2),1,1),当年实际!$C:$C,"<="&EOMONTH(DATE(YEAR(主页!$D$2),MONTH(主页!$D$2),1),0)),"")
E13: =IF(D13/SUM(D:D)=0,"",D13/SUM(D:D)) | G13: =D13*F13 -> 0 | H13: =IF(G13/SUM(G:G)=0,"",G13/SUM(G:G)) | J13: =IFERROR(SUMIFS(当年实际!$V:$V,当年实际!$J:$J,$C13,当年实际!$C:$C,">="&DATE(YEAR(主页!$D$2),1,1),当年实际!$C:$C,"<="&EOMONTH(DATE(YEAR(主页!$D$2),MONTH(主页!$D$2),1),0))/SUMIFS(当年实际!$P:$P,当年实际!$J:$J,$C13,当年实际!$C:$C,">="&DATE(YEAR(主页!$D$2),1,1),当年实际!$C:$C,"<="&EOMONTH(DATE(YEAR(主页!$D$2),MONTH(主页!$D$2),1),0)),"")
E14: =IF(D14/SUM(D:D)=0,"",D14/SUM(D:D)) | G14: =D14*F14 -> 0 | H14: =IF(G14/SUM(G:G)=0,"",G14/SUM(G:G)) | J14: =IFERROR(SUMIFS(当年实际!$V:$V,当年实际!$J:$J,$C14,当年实际!$C:$C,">="&DATE(YEAR(主页!$D$2),1,1),当年实际!$C:$C,"<="&EOMONTH(DATE(YEAR(主页!$D$2),MONTH(主页!$D$2),1),0))/SUMIFS(当年实际!$P:$P,当年实际!$J:$J,$C14,当年实际!$C:$C,">="&DATE(YEAR(主页!$D$2),1,1),当年实际!$C:$C,"<="&EOMONTH(DATE(YEAR(主页!$D$2),MONTH(主页!$D$2),1),0)),"")
E15: =IF(D15/SUM(D:D)=0,"",D15/SUM(D:D)) | G15: =D15*F15 -> 0 | H15: =IF(G15/SUM(G:G)=0,"",G15/SUM(G:G)) | J15: =IFERROR(SUMIFS(当年实际!$V:$V,当年实际!$J:$J,$C15,当年实际!$C:$C,">="&DATE(YEAR(主页!$D$2),1,1),当年实际!$C:$C,"<="&EOMONTH(DATE(YEAR(主页!$D$2),MONTH(主页!$D$2),1),0))/SUMIFS(当年实际!$P:$P,当年实际!$J:$J,$C15,当年实际!$C:$C,">="&DATE(YEAR(主页!$D$2),1,1),当年实际!$C:$C,"<="&EOMONTH(DATE(YEAR(主页!$D$2),MONTH(主页!$D$2),1),0)),"")
E16: =IF(D16/SUM(D:D)=0,"",D16/SUM(D:D)) | G16: =D16*F16 -> 0 | H16: =IF(G16/SUM(G:G)=0,"",G16/SUM(G:G)) | J16: =IFERROR(SUMIFS(当年实际!$V:$V,当年实际!$J:$J,$C16,当年实际!$C:$C,">="&DATE(YEAR(主页!$D$2),1,1),当年实际!$C:$C,"<="&EOMONTH(DATE(YEAR(主页!$D$2),MONTH(主页!$D$2),1),0))/SUMIFS(当年实际!$P:$P,当年实际!$J:$J,$C16,当年实际!$C:$C,">="&DATE(YEAR(主页!$D$2),1,1),当年实际!$C:$C,"<="&EOMONTH(DATE(YEAR(主页!$D$2),MONTH(主页!$D$2),1),0)),"")
E17: =IF(D17/SUM(D:D)=0,"",D17/SUM(D:D)) | G17: =D17*F17 -> 0 | H17: =IF(G17/SUM(G:G)=0,"",G17/SUM(G:G)) | J17: =IFERROR(SUMIFS(当年实际!$V:$V,当年实际!$J:$J,$C17,当年实际!$C:$C,">="&DATE(YEAR(主页!$D$2),1,1),当年实际!$C:$C,"<="&EOMONTH(DATE(YEAR(主页!$D$2),MONTH(主页!$D$2),1),0))/SUMIFS(当年实际!$P:$P,当年实际!$J:$J,$C17,当年实际!$C:$C,">="&DATE(YEAR(主页!$D$2),1,1),当年实际!$C:$C,"<="&EOMONTH(DATE(YEAR(主页!$D$2),MONTH(主页!$D$2),1),0)),"")
... E1200: =IF(D1200/SUM(D:D)=0,"",D1200/SUM(D:D)) | G1200: =D1200*F1200 -> 0 | H1200: =IF(G1200/SUM(G:G)=0,"",G1200/SUM(G:G)) | J1200: =IFERROR(SUMIFS(当年实际!$V:$V,当年实际!$J:$J,$C1200,当年实际!$C:$C,">="&DATE(YEAR(主页!$D$2),1,1),当年实际!$C:$C,"<="&EOMONTH(DATE(YEAR(主页!$D$2),MONTH(主页!$D$2),1),0))/SUMIFS(当年实际!$P:$P,当年实际!$J:$J,$C1200,当年实际!$C:$C,">="&DATE(YEAR(主页!$D$2),1,1),当年实际!$C:$C,"<="&EOMONTH(DATE(YEAR(主页!$D$2),MONTH(主页!$D$2),1),0)),"")

Sheet 当年估计 客户
A1: 客户大类 | B1: 客户子类 | C1: 客户名称 | D1: ="当年剩余月份估计 E"&TEXT(主页!$D$2,"YY")&"YTG" -> 当年剩余月份估计 E21YTG | J1: ="当年已过去月份实际 A"&TEXT(主页!$D$2,"YY")&"YTD" -> 当年已过去月份实际 A21YTD | L1: 返回主页
A2: 客户大类 | B2: 客户子类 | C2: 客户名称 | D2: 销售收入 | E2: 收入占比% | F2: 毛利率 | G2: 销售毛利 | H2: 毛利占比% | J2: 毛利率
A3: A | B3: A01 | C3: 京东 | D3: 1200 | E3: =IF(D3/SUM(D:D)=0,"",D3/SUM(D:D)) -> 0.19354839 | F3: 0.35 | G3: =D3*F3 -> 420 | H3: =IF(G3/SUM(G:G)=0,"",G3/SUM(G:G)) -> 0.36238136 | J3: =IFERROR(SUMIFS(当年实际!$V:$V,当年实际!$F:$F,$C3,当年实际!$C:$C,">="&DATE(YEAR(主页!$D$2),1,1),当年实际!$C:$C,"<="&EOMONTH(DATE(YEAR(主页!$D$2),MONTH(主页!$D$2),1),0))/SUMIFS(当年实际!$P:$P,当年实际!$F:$F,$C3,当年实际!$C:$C,">="&DATE(YEAR(主页!$D$2),1,1),当年实际!$C:$C,"<="&EOMONTH(DATE(YEAR(主页!$D$2),MONTH(主页!$D$2),1),0)),"") -> 0.16
A4: B | B4: B01 | C4: 天猫 | D4: 2000 | E4: =IF(D4/SUM(D:D)=0,"",D4/SUM(D:D)) -> 0.32258065 | F4: 0.17 | G4: =D4*F4 -> 340 | H4: =IF(G4/SUM(G:G)=0,"",G4/SUM(G:G)) -> 0.29335634 | J4: =IFERROR(SUMIFS(当年实际!$V:$V,当年实际!$F:$F,$C4,当年实际!$C:$C,">="&DATE(YEAR(主页!$D$2),1,1),当年实际!$C:$C,"<="&EOMONTH(DATE(YEAR(主页!$D$2),MONTH(主页!$D$2),1),0))/SUMIFS(当年实际!$P:$P,当年实际!$F:$F,$C4,当年实际!$C:$C,">="&DATE(YEAR(主页!$D$2),1,1),当年实际!$C:$C,"<="&EOMONTH(DATE(YEAR(主页!$D$2),MONTH(主页!$D$2),1),0)),"") -> 0.27777778
A5: C | B5: C01 | C5: 苏宁 | D5: 3000 | E5: =IF(D5/SUM(D:D)=0,"",D5/SUM(D:D)) -> 0.48387097 | F5: 0.133 | G5: =D5*F5 -> 399 | H5: =IF(G5/SUM(G:G)=0,"",G5/SUM(G:G)) -> 0.3442623 | J5: =IFERROR(SUMIFS(当年实际!$V:$V,当年实际!$F:$F,$C5,当年实际!$C:$C,">="&DATE(YEAR(主页!$D$2),1,1),当年实际!$C:$C,"<="&EOMONTH(DATE(YEAR(主页!$D$2),MONTH(主页!$D$2),1),0))/SUMIFS(当年实际!$P:$P,当年实际!$F:$F,$C5,当年实际!$C:$C,">="&DATE(YEAR(主页!$D$2),1,1),当年实际!$C:$C,"<="&EOMONTH(DATE(YEAR(主页!$D$2),MONTH(主页!$D$2),1),0)),"") -> 0.194
E6: =IF(D6/SUM(D:D)=0,"",D6/SUM(D:D)) | G6: =D6*F6 -> 0 | H6: =IF(G6/SUM(G:G)=0,"",G6/SUM(G:G)) | J6: =IFERROR(SUMIFS(当年实际!$V:$V,当年实际!$F:$F,$C6,当年实际!$C:$C,">="&DATE(YEAR(主页!$D$2),1,1),当年实际!$C:$C,"<="&EOMONTH(DATE(YEAR(主页!$D$2),MONTH(主页!$D$2),1),0))/SUMIFS(当年实际!$P:$P,当年实际!$F:$F,$C6,当年实际!$C:$C,">="&DATE(YEAR(主页!$D$2),1,1),当年实际!$C:$C,"<="&EOMONTH(DATE(YEAR(主页!$D$2),MONTH(主页!$D$2),1),0)),"")
E7: =IF(D7/SUM(D:D)=0,"",D7/SUM(D:D)) | G7: =D7*F7 -> 0 | H7: =IF(G7/SUM(G:G)=0,"",G7/SUM(G:G)) | J7: =IFERROR(SUMIFS(当年实际!$V:$V,当年实际!$F:$F,$C7,当年实际!$C:$C,">="&DATE(YEAR(主页!$D$2),1,1),当年实际!$C:$C,"<="&EOMONTH(DATE(YEAR(主页!$D$2),MONTH(主页!$D$2),1),0))/SUMIFS(当年实际!$P:$P,当年实际!$F:$F,$C7,当年实际!$C:$C,">="&DATE(YEAR(主页!$D$2),1,1),当年实际!$C:$C,"<="&EOMONTH(DATE(YEAR(主页!$D$2),MONTH(主页!$D$2),1),0)),"")
E8: =IF(D8/SUM(D:D)=0,"",D8/SUM(D:D)) | G8: =D8*F8 -> 0 | H8: =IF(G8/SUM(G:G)=0,"",G8/SUM(G:G)) | J8: =IFERROR(SUMIFS(当年实际!$V:$V,当年实际!$F:$F,$C8,当年实际!$C:$C,">="&DATE(YEAR(主页!$D$2),1,1),当年实际!$C:$C,"<="&EOMONTH(DATE(YEAR(主页!$D$2),MONTH(主页!$D$2),1),0))/SUMIFS(当年实际!$P:$P,当年实际!$F:$F,$C8,当年实际!$C:$C,">="&DATE(YEAR(主页!$D$2),1,1),当年实际!$C:$C,"<="&EOMONTH(DATE(YEAR(主页!$D$2),MONTH(主页!$D$2),1),0)),"")
E9: =IF(D9/SUM(D:D)=0,"",D9/SUM(D:D)) | G9: =D9*F9 -> 0 | H9: =IF(G9/SUM(G:G)=0,"",G9/SUM(G:G)) | J9: =IFERROR(SUMIFS(当年实际!$V:$V,当年实际!$F:$F,$C9,当年实际!$C:$C,">="&DATE(YEAR(主页!$D$2),1,1),当年实际!$C:$C,"<="&EOMONTH(DATE(YEAR(主页!$D$2),MONTH(主页!$D$2),1),0))/SUMIFS(当年实际!$P:$P,当年实际!$F:$F,$C9,当年实际!$C:$C,">="&DATE(YEAR(主页!$D$2),1,1),当年实际!$C:$C,"<="&EOMONTH(DATE(YEAR(主页!$D$2),MONTH(主页!$D$2),1),0)),"")
E10: =IF(D10/SUM(D:D)=0,"",D10/SUM(D:D)) | G10: =D10*F10 -> 0 | H10: =IF(G10/SUM(G:G)=0,"",G10/SUM(G:G)) | J10: =IFERROR(SUMIFS(当年实际!$V:$V,当年实际!$F:$F,$C10,当年实际!$C:$C,">="&DATE(YEAR(主页!$D$2),1,1),当年实际!$C:$C,"<="&EOMONTH(DATE(YEAR(主页!$D$2),MONTH(主页!$D$2),1),0))/SUMIFS(当年实际!$P:$P,当年实际!$F:$F,$C10,当年实际!$C:$C,">="&DATE(YEAR(主页!$D$2),1,1),当年实际!$C:$C,"<="&EOMONTH(DATE(YEAR(主页!$D$2),MONTH(主页!$D$2),1),0)),"")
E11: =IF(D11/SUM(D:D)=0,"",D11/SUM(D:D)) | G11: =D11*F11 -> 0 | H11: =IF(G11/SUM(G:G)=0,"",G11/SUM(G:G)) | J11: =IFERROR(SUMIFS(当年实际!$V:$V,当年实际!$F:$F,$C11,当年实际!$C:$C,">="&DATE(YEAR(主页!$D$2),1,1),当年实际!$C:$C,"<="&EOMONTH(DATE(YEAR(主页!$D$2),MONTH(主页!$D$2),1),0))/SUMIFS(当年实际!$P:$P,当年实际!$F:$F,$C11,当年实际!$C:$C,">="&DATE(YEAR(主页!$D$2),1,1),当年实际!$C:$C,"<="&EOMONTH(DATE(YEAR(主页!$D$2),MONTH(主页!$D$2),1),0)),"")
E12: =IF(D12/SUM(D:D)=0,"",D12/SUM(D:D)) | G12: =D12*F12 -> 0 | H12: =IF(G12/SUM(G:G)=0,"",G12/SUM(G:G)) | J12: =IFERROR(SUMIFS(当年实际!$V:$V,当年实际!$F:$F,$C12,当年实际!$C:$C,">="&DATE(YEAR(主页!$D$2),1,1),当年实际!$C:$C,"<="&EOMONTH(DATE(YEAR(主页!$D$2),MONTH(主页!$D$2),1),0))/SUMIFS(当年实际!$P:$P,当年实际!$F:$F,$C12,当年实际!$C:$C,">="&DATE(YEAR(主页!$D$2),1,1),当年实际!$C:$C,"<="&EOMONTH(DATE(YEAR(主页!$D$2),MONTH(主页!$D$2),1),0)),"")
E13: =IF(D13/SUM(D:D)=0,"",D13/SUM(D:D)) | G13: =D13*F13 -> 0 | H13: =IF(G13/SUM(G:G)=0,"",G13/SUM(G:G)) | J13: =IFERROR(SUMIFS(当年实际!$V:$V,当年实际!$F:$F,$C13,当年实际!$C:$C,">="&DATE(YEAR(主页!$D$2),1,1),当年实际!$C:$C,"<="&EOMONTH(DATE(YEAR(主页!$D$2),MONTH(主页!$D$2),1),0))/SUMIFS(当年实际!$P:$P,当年实际!$F:$F,$C13,当年实际!$C:$C,">="&DATE(YEAR(主页!$D$2),1,1),当年实际!$C:$C,"<="&EOMONTH(DATE(YEAR(主页!$D$2),MONTH(主页!$D$2),1),0)),"")
E14: =IF(D14/SUM(D:D)=0,"",D14/SUM(D:D)) | G14: =D14*F14 -> 0 | H14: =IF(G14/SUM(G:G)=0,"",G14/SUM(G:G)) | J14: =IFERROR(SUMIFS(当年实际!$V:$V,当年实际!$F:$F,$C14,当年实际!$C:$C,">="&DATE(YEAR(主页!$D$2),1,1),当年实际!$C:$C,"<="&EOMONTH(DATE(YEAR(主页!$D$2),MONTH(主页!$D$2),1),0))/SUMIFS(当年实际!$P:$P,当年实际!$F:$F,$C14,当年实际!$C:$C,">="&DATE(YEAR(主页!$D$2),1,1),当年实际!$C:$C,"<="&EOMONTH(DATE(YEAR(主页!$D$2),MONTH(主页!$D$2),1),0)),"")
E15: =IF(D15/SUM(D:D)=0,"",D15/SUM(D:D)) | G15: =D15*F15 -> 0 | H15: =IF(G15/SUM(G:G)=0,"",G15/SUM(G:G)) | J15: =IFERROR(SUMIFS(当年实际!$V:$V,当年实际!$F:$F,$C15,当年实际!$C:$C,">="&DATE(YEAR(主页!$D$2),1,1),当年实际!$C:$C,"<="&EOMONTH(DATE(YEAR(主页!$D$2),MONTH(主页!$D$2),1),0))/SUMIFS(当年实际!$P:$P,当年实际!$F:$F,$C15,当年实际!$C:$C,">="&DATE(YEAR(主页!$D$2),1,1),当年实际!$C:$C,"<="&EOMONTH(DATE(YEAR(主页!$D$2),MONTH(主页!$D$2),1),0)),"")
E16: =IF(D16/SUM(D:D)=0,"",D16/SUM(D:D)) | G16: =D16*F16 -> 0 | H16: =IF(G16/SUM(G:G)=0,"",G16/SUM(G:G)) | J16: =IFERROR(SUMIFS(当年实际!$V:$V,当年实际!$F:$F,$C16,当年实际!$C:$C,">="&DATE(YEAR(主页!$D$2),1,1),当年实际!$C:$C,"<="&EOMONTH(DATE(YEAR(主页!$D$2),MONTH(主页!$D$2),1),0))/SUMIFS(当年实际!$P:$P,当年实际!$F:$F,$C16,当年实际!$C:$C,">="&DATE(YEAR(主页!$D$2),1,1),当年实际!$C:$C,"<="&EOMONTH(DATE(YEAR(主页!$D$2),MONTH(主页!$D$2),1),0)),"")
E17: =IF(D17/SUM(D:D)=0,"",D17/SUM(D:D)) | G17: =D17*F17 -> 0 | H17: =IF(G17/SUM(G:G)=0,"",G17/SUM(G:G)) | J17: =IFERROR(SUMIFS(当年实际!$V:$V,当年实际!$F:$F,$C17,当年实际!$C:$C,">="&DATE(YEAR(主页!$D$2),1,1),当年实际!$C:$C,"<="&EOMONTH(DATE(YEAR(主页!$D$2),MONTH(主页!$D$2),1),0))/SUMIFS(当年实际!$P:$P,当年实际!$F:$F,$C17,当年实际!$C:$C,">="&DATE(YEAR(主页!$D$2),1,1),当年实际!$C:$C,"<="&EOMONTH(DATE(YEAR(主页!$D$2),MONTH(主页!$D$2),1),0)),"")
... E1200: =IF(D1200/SUM(D:D)=0,"",D1200/SUM(D:D)) | G1200: =D1200*F1200 -> 0 | H1200: =IF(G1200/SUM(G:G)=0,"",G1200/SUM(G:G)) | J1200: =IFERROR(SUMIFS(当年实际!$V:$V,当年实际!$F:$F,$C1200,当年实际!$C:$C,">="&DATE(YEAR(主页!$D$2),1,1),当年实际!$C:$C,"<="&EOMONTH(DATE(YEAR(主页!$D$2),MONTH(主页!$D$2),1),0))/SUMIFS(当年实际!$P:$P,当年实际!$F:$F,$C1200,当年实际!$C:$C,">="&DATE(YEAR(主页!$D$2),1,1),当年实际!$C:$C,"<="&EOMONTH(DATE(YEAR(主页!$D$2),MONTH(主页!$D$2),1),0)),"")

Sheet 当年标准成本
A1: 产品大类 | B1: 产品子类 | C1: 产品名称 | D1: 产品来源 | E1: 外购价格 | F1: 材料成本 | G1: 外协加工费 | H1: 人工及制造费用 | I1: 单位成本 | K1: 返回主页
A2: PA | B2: PA01 | C2: A0111 | D2: 外购 | E2: 13 | I2: =SUM(E2:H2) -> 13
A3: PB | B3: PB01 | C3: B0122 | D3: 自制 | F3: 10 | G3: 1 | H3: 2 | I3: =SUM(E3:H3) -> 13
A4: PC | B4: PC01 | C4: C0122 | D4: 自制 | F4: 5 | G4: 1 | H4: 3 | I4: =SUM(E4:H4) -> 9
A5: PA | B5: PA01 | C5: A0111 | D5: 自制 | F5: 9 | G5: 2 | H5: 3 | I5: =SUM(E5:H5) -> 14
A6: PB | B6: PB01 | C6: B0122 | D6: 自制 | F6: 9 | H6: 5 | I6: =SUM(E6:H6) -> 14
A7: PC | B7: PC01 | C7: C0122 | D7: 自制 | F7: 4 | G7: 2 | H7: 1 | I7: =SUM(E7:H7) -> 7
A8: SE | B8: SE99 | C8: C0199 | D8: 服务 | F8: 80 | G8: 30 | H8: 10 | I8: =SUM(E8:H8) -> 120

Sheet 当年估计 产品
A1: 产品大类 | B1: 产品子类 | C1: 产品名称 | D1: 产品来源 | E1: 销售数量 | F1: 销售收入 | G1: 增值税率 | H1: 不含税销售单价 | I1: 含税单价 | J1: 单位标准成本 | K1: 销售成本 | L1: 销售毛利 | M1: 毛利率 | O1: 返回主页
A2: PA | B2: PA01 | C2: A0111 | D2: 外购 | E2: 70 | F2: 1800 | G2: 0.13 | H2: =IFERROR(F2/E2,"") -> 25.714286 | I2: =IFERROR(H2*(1+G2),"") -> 29.057143 | J2: =IFERROR(INDEX(当年标准成本!I:I,MATCH(C2,当年标准成本!C:C,0),1),"") -> 13 | K2: =IFERROR(E2*J2,"") -> 910 | L2: =IFERROR(F2-K2,"") -> 890 | M2: =IFERROR(L2/F2,"") -> 0.49444444
A3: PB | B3: PB01 | C3: B0122 | D3: 自制 | E3: 89 | F3: 2000 | G3: 0.13 | H3: =IFERROR(F3/E3,"") -> 22.47191 | I3: =IFERROR(H3*(1+G3),"") -> 25.393258 | J3: =IFERROR(INDEX(当年标准成本!I:I,MATCH(C3,当年标准成本!C:C,0),1),"") -> 13 | K3: =IFERROR(E3*J3,"") -> 1157 | L3: =IFERROR(F3-K3,"") -> 843 | M3: =IFERROR(L3/F3,"") -> 0.4215
A4: PC | B4: PC01 | C4: C0122 | D4: 自制 | E4: 77 | F4: 1200 | G4: 0.13 | H4: =IFERROR(F4/E4,"") -> 15.584416 | I4: =IFERROR(H4*(1+G4),"") -> 17.61039 | J4: =IFERROR(INDEX(当年标准成本!I:I,MATCH(C4,当年标准成本!C:C,0),1),"") -> 9 | K4: =IFERROR(E4*J4,"") -> 693 | L4: =IFERROR(F4-K4,"") -> 507 | M4: =IFERROR(L4/F4,"") -> 0.4225
A5: PA | B5: PA01 | C5: A0111 | D5: 自制 | E5: 65 | F5: 1500 | G5: 0.13 | H5: =IFERROR(F5/E5,"") -> 23.076923 | I5: =IFERROR(H5*(1+G5),"") -> 26.076923 | J5: =IFERROR(INDEX(当年标准成本!I:I,MATCH(C5,当年标准成本!C:C,0),1),"") -> 13 | K5: =IFERROR(E5*J5,"") -> 845 | L5: =IFERROR(F5-K5,"") -> 655 | M5: =IFERROR(L5/F5,"") -> 0.43666667
A6: PB | B6: PB01 | C6: B0122 | D6: 自制 | E6: 89 | F6: 1980 | G6: 0.13 | H6: =IFERROR(F6/E6,"") -> 22.247191 | I6: =IFERROR(H6*(1+G6),"") -> 25.139326 | J6: =IFERROR(INDEX(当年标准成本!I:I,MATCH(C6,当年标准成本!C:C,0),1),"") -> 13 | K6: =IFERROR(E6*J6,"") -> 1157 | L6: =IFERROR(F6-K6,"") -> 823 | M6: =IFERROR(L6/F6,"") -> 0.41565657
A7: PC | B7: PC01 | C7: C0122 | D7: 自制 | E7: 65 | F7: 1000 | G7: 0.13 | H7: =IFERROR(F7/E7,"") -> 15.384615 | I7: =IFERROR(H7*(1+G7),"") -> 17.384615 | J7: =IFERROR(INDEX(当年标准成本!I:I,MATCH(C7,当年标准成本!C:C,0),1),"") -> 9 | K7: =IFERROR(E7*J7,"") -> 585 | L7: =IFERROR(F7-K7,"") -> 415 | M7: =IFERROR(L7/F7,"") -> 0.415
A8: SE | B8: SE99 | C8: C0199 | D8: 服务 | E8: 2 | F8: 378 | G8: 0.06 | H8: =IFERROR(F8/E8,"") -> 189 | I8: =IFERROR(H8*(1+G8),"") -> 200.34 | J8: =IFERROR(INDEX(当年标准成本!I:I,MATCH(C8,当年标准成本!C:C,0),1),"") -> 120 | K8: =IFERROR(E8*J8,"") -> 240 | L8: =IFERROR(F8-K8,"") -> 138 | M8: =IFERROR(L8/F8,"") -> 0.36507937
H9: =IFERROR(F9/E9,"") | I9: =IFERROR(H9*(1+G9),"") | J9: =IFERROR(INDEX(当年标准成本!I:I,MATCH(C9,当年标准成本!C:C,0),1),"") | K9: =IFERROR(E9*J9,"") | L9: =IFERROR(F9-K9,"") | M9: =IFERROR(L9/F9,"")
H10: =IFERROR(F10/E10,"") | I10: =IFERROR(H10*(1+G10),"") | J10: =IFERROR(INDEX(当年标准成本!I:I,MATCH(C10,当年标准成本!C:C,0),1),"") | K10: =IFERROR(E10*J10,"") | L10: =IFERROR(F10-K10,"") | M10: =IFERROR(L10/F10,"")
H11: =IFERROR(F11/E11,"") | I11: =IFERROR(H11*(1+G11),"") | J11: =IFERROR(INDEX(当年标准成本!I:I,MATCH(C11,当年标准成本!C:C,0),1),"") | K11: =IFERROR(E11*J11,"") | L11: =IFERROR(F11-K11,"") | M11: =IFERROR(L11/F11,"")
H12: =IFERROR(F12/E12,"") | I12: =IFERROR(H12*(1+G12),"") | J12: =IFERROR(INDEX(当年标准成本!I:I,MATCH(C12,当年标准成本!C:C,0),1),"") | K12: =IFERROR(E12*J12,"") | L12: =IFERROR(F12-K12,"") | M12: =IFERROR(L12/F12,"")
H13: =IFERROR(F13/E13,"") | I13: =IFERROR(H13*(1+G13),"") | J13: =IFERROR(INDEX(当年标准成本!I:I,MATCH(C13,当年标准成本!C:C,0),1),"") | K13: =IFERROR(E13*J13,"") | L13: =IFERROR(F13-K13,"") | M13: =IFERROR(L13/F13,"")
H14: =IFERROR(F14/E14,"") | I14: =IFERROR(H14*(1+G14),"") | J14: =IFERROR(INDEX(当年标准成本!I:I,MATCH(C14,当年标准成本!C:C,0),1),"") | K14: =IFERROR(E14*J14,"") | L14: =IFERROR(F14-K14,"") | M14: =IFERROR(L14/F14,"")
H15: =IFERROR(F15/E15,"") | I15: =IFERROR(H15*(1+G15),"") | J15: =IFERROR(INDEX(当年标准成本!I:I,MATCH(C15,当年标准成本!C:C,0),1),"") | K15: =IFERROR(E15*J15,"") | L15: =IFERROR(F15-K15,"") | M15: =IFERROR(L15/F15,"")
H16: =IFERROR(F16/E16,"") | I16: =IFERROR(H16*(1+G16),"") | J16: =IFERROR(INDEX(当年标准成本!I:I,MATCH(C16,当年标准成本!C:C,0),1),"") | K16: =IFERROR(E16*J16,"") | L16: =IFERROR(F16-K16,"") | M16: =IFERROR(L16/F16,"")
H17: =IFERROR(F17/E17,"") | I17: =IFERROR(H17*(1+G17),"") | J17: =IFERROR(INDEX(当年标准成本!I:I,MATCH(C17,当年标准成本!C:C,0),1),"") | K17: =IFERROR(E17*J17,"") | L17: =IFERROR(F17-K17,"") | M17: =IFERROR(L17/F17,"")
H18: =IFERROR(F18/E18,"") | I18: =IFERROR(H18*(1+G18),"") | J18: =IFERROR(INDEX(当年标准成本!I:I,MATCH(C18,当年标准成本!C:C,0),1),"") | K18: =IFERROR(E18*J18,"") | L18: =IFERROR(F18-K18,"") | M18: =IFERROR(L18/F18,"")
H19: =IFERROR(F19/E19,"") | I19: =IFERROR(H19*(1+G19),"") | J19: =IFERROR(INDEX(当年标准成本!I:I,MATCH(C19,当年标准成本!C:C,0),1),"") | K19: =IFERROR(E19*J19,"") | L19: =IFERROR(F19-K19,"") | M19: =IFERROR(L19/F19,"")
H20: =IFERROR(F20/E20,"") | I20: =IFERROR(H20*(1+G20),"") | J20: =IFERROR(INDEX(当年标准成本!I:I,MATCH(C20,当年标准成本!C:C,0),1),"") | K20: =IFERROR(E20*J20,"") | L20: =IFERROR(F20-K20,"") | M20: =IFERROR(L20/F20,"")
... H1200: =IFERROR(F1200/E1200,"") | I1200: =IFERROR(H1200*(1+G1200),"") | J1200: =IFERROR(INDEX(当年标准成本!I:I,MATCH(C1200,当年标准成本!C:C,0),1),"") | K1200: =IFERROR(E1200*J1200,"") | L1200: =IFERROR(F1200-K1200,"") | M1200: =IFERROR(L1200/F1200,"")

Sheet 下年预算 渠道
A1: 渠道分类 | B1: 渠道名称 | C1: 覆盖客户数量 | D1: ="下年预算 B"&TEXT(主页!$D$2,"YY")+1&"FY" -> 下年预算 B22FY | J1: ="当年已过去月份实际 A"&TEXT(主页!$D$2,"YY")&"YTD" -> 当年已过去月份实际 A21YTD | L1: 返回主页
D2: 销售收入 | E2: 收入占比% | F2: 毛利率 | G2: 销售毛利 | H2: 毛利占比% | J2: 毛利率
A3: SCA | B3: SCA01 | C3: 1 | D3: 1200 | E3: =IF(D3/SUM(D:D)=0,"",D3/SUM(D:D)) -> 0.19354839 | F3: 0.28 | G3: =D3*F3 -> 336 | H3: =IF(G3/SUM(G:G)=0,"",G3/SUM(G:G)) -> 0.28093645 | J3: =IFERROR(SUMIFS(当年实际!$V:$V,当年实际!$H:$H,$B3,当年实际!$C:$C,">="&DATE(YEAR(主页!$D$2),1,1),当年实际!$C:$C,"<="&EOMONTH(DATE(YEAR(主页!$D$2),MONTH(主页!$D$2),1),0))/SUMIFS(当年实际!$P:$P,当年实际!$H:$H,$B3,当年实际!$C:$C,">="&DATE(YEAR(主页!$D$2),1,1),当年实际!$C:$C,"<="&EOMONTH(DATE(YEAR(主页!$D$2),MONTH(主页!$D$2),1),0)),"") -> 0.27777778
A4: SCB | B4: SCB01 | C4: 2 | D4: 2000 | E4: =IF(D4/SUM(D:D)=0,"",D4/SUM(D:D)) -> 0.32258065 | F4: 0.19 | G4: =D4*F4 -> 380 | H4: =IF(G4/SUM(G:G)=0,"",G4/SUM(G:G)) -> 0.31772575 | J4: =IFERROR(SUMIFS(当年实际!$V:$V,当年实际!$H:$H,$B4,当年实际!$C:$C,">="&DATE(YEAR(主页!$D$2),1,1),当年实际!$C:$C,"<="&EOMONTH(DATE(YEAR(主页!$D$2),MONTH(主页!$D$2),1),0))/SUMIFS(当年实际!$P:$P,当年实际!$H:$H,$B4,当年实际!$C:$C,">="&DATE(YEAR(主页!$D$2),1,1),当年实际!$C:$C,"<="&EOMONTH(DATE(YEAR(主页!$D$2),MONTH(主页!$D$2),1),0)),"") -> 0.194
A5: SCC | B5: SCC01 | C5: 3 | D5: 3000 | E5: =IF(D5/SUM(D:D)=0,"",D5/SUM(D:D)) -> 0.48387097 | F5: 0.16 | G5: =D5*F5 -> 480 | H5: =IF(G5/SUM(G:G)=0,"",G5/SUM(G:G)) -> 0.40133779 | J5: =IFERROR(SUMIFS(当年实际!$V:$V,当年实际!$H:$H,$B5,当年实际!$C:$C,">="&DATE(YEAR(主页!$D$2),1,1),当年实际!$C:$C,"<="&EOMONTH(DATE(YEAR(主页!$D$2),MONTH(主页!$D$2),1),0))/SUMIFS(当年实际!$P:$P,当年实际!$H:$H,$B5,当年实际!$C:$C,">="&DATE(YEAR(主页!$D$2),1,1),当年实际!$C:$C,"<="&EOMONTH(DATE(YEAR(主页!$D$2),MONTH(主页!$D$2),1),0)),"") -> 0.16
E6: =IF(D6/SUM(D:D)=0,"",D6/SUM(D:D)) | G6: =D6*F6 -> 0 | H6: =IF(G6/SUM(G:G)=0,"",G6/SUM(G:G)) | J6: =IFERROR(SUMIFS(当年实际!$V:$V,当年实际!$H:$H,$B6,当年实际!$C:$C,">="&DATE(YEAR(主页!$D$2),1,1),当年实际!$C:$C,"<="&EOMONTH(DATE(YEAR(主页!$D$2),MONTH(主页!$D$2),1),0))/SUMIFS(当年实际!$P:$P,当年实际!$H:$H,$B6,当年实际!$C:$C,">="&DATE(YEAR(主页!$D$2),1,1),当年实际!$C:$C,"<="&EOMONTH(DATE(YEAR(主页!$D$2),MONTH(主页!$D$2),1),0)),"")
E7: =IF(D7/SUM(D:D)=0,"",D7/SUM(D:D)) | G7: =D7*F7 -> 0 | H7: =IF(G7/SUM(G:G)=0,"",G7/SUM(G:G)) | J7: =IFERROR(SUMIFS(当年实际!$V:$V,当年实际!$H:$H,$B7,当年实际!$C:$C,">="&DATE(YEAR(主页!$D$2),1,1),当年实际!$C:$C,"<="&EOMONTH(DATE(YEAR(主页!$D$2),MONTH(主页!$D$2),1),0))/SUMIFS(当年实际!$P:$P,当年实际!$H:$H,$B7,当年实际!$C:$C,">="&DATE(YEAR(主页!$D$2),1,1),当年实际!$C:$C,"<="&EOMONTH(DATE(YEAR(主页!$D$2),MONTH(主页!$D$2),1),0)),"")
E8: =IF(D8/SUM(D:D)=0,"",D8/SUM(D:D)) | G8: =D8*F8 -> 0 | H8: =IF(G8/SUM(G:G)=0,"",G8/SUM(G:G)) | J8: =IFERROR(SUMIFS(当年实际!$V:$V,当年实际!$H:$H,$B8,当年实际!$C:$C,">="&DATE(YEAR(主页!$D$2),1,1),当年实际!$C:$C,"<="&EOMONTH(DATE(YEAR(主页!$D$2),MONTH(主页!$D$2),1),0))/SUMIFS(当年实际!$P:$P,当年实际!$H:$H,$B8,当年实际!$C:$C,">="&DATE(YEAR(主页!$D$2),1,1),当年实际!$C:$C,"<="&EOMONTH(DATE(YEAR(主页!$D$2),MONTH(主页!$D$2),1),0)),"")
E9: =IF(D9/SUM(D:D)=0,"",D9/SUM(D:D)) | G9: =D9*F9 -> 0 | H9: =IF(G9/SUM(G:G)=0,"",G9/SUM(G:G)) | J9: =IFERROR(SUMIFS(当年实际!$V:$V,当年实际!$H:$H,$B9,当年实际!$C:$C,">="&DATE(YEAR(主页!$D$2),1,1),当年实际!$C:$C,"<="&EOMONTH(DATE(YEAR(主页!$D$2),MONTH(主页!$D$2),1),0))/SUMIFS(当年实际!$P:$P,当年实际!$H:$H,$B9,当年实际!$C:$C,">="&DATE(YEAR(主页!$D$2),1,1),当年实际!$C:$C,"<="&EOMONTH(DATE(YEAR(主页!$D$2),MONTH(主页!$D$2),1),0)),"")
E10: =IF(D10/SUM(D:D)=0,"",D10/SUM(D:D)) | G10: =D10*F10 -> 0 | H10: =IF(G10/SUM(G:G)=0,"",G10/SUM(G:G)) | J10: =IFERROR(SUMIFS(当年实际!$V:$V,当年实际!$H:$H,$B10,当年实际!$C:$C,">="&DATE(YEAR(主页!$D$2),1,1),当年实际!$C:$C,"<="&EOMONTH(DATE(YEAR(主页!$D$2),MONTH(主页!$D$2),1),0))/SUMIFS(当年实际!$P:$P,当年实际!$H:$H,$B10,当年实际!$C:$C,">="&DATE(YEAR(主页!$D$2),1,1),当年实际!$C:$C,"<="&EOMONTH(DATE(YEAR(主页!$D$2),MONTH(主页!$D$2),1),0)),"")
E11: =IF(D11/SUM(D:D)=0,"",D11/SUM(D:D)) | G11: =D11*F11 -> 0 | H11: =IF(G11/SUM(G:G)=0,"",G11/SUM(G:G)) | J11: =IFERROR(SUMIFS(当年实际!$V:$V,当年实际!$H:$H,$B11,当年实际!$C:$C,">="&DATE(YEAR(主页!$D$2),1,1),当年实际!$C:$C,"<="&EOMONTH(DATE(YEAR(主页!$D$2),MONTH(主页!$D$2),1),0))/SUMIFS(当年实际!$P:$P,当年实际!$H:$H,$B11,当年实际!$C:$C,">="&DATE(YEAR(主页!$D$2),1,1),当年实际!$C:$C,"<="&EOMONTH(DATE(YEAR(主页!$D$2),MONTH(主页!$D$2),1),0)),"")
E12: =IF(D12/SUM(D:D)=0,"",D12/SUM(D:D)) | G12: =D12*F12 -> 0 | H12: =IF(G12/SUM(G:G)=0,"",G12/SUM(G:G)) | J12: =IFERROR(SUMIFS(当年实际!$V:$V,当年实际!$H:$H,$B12,当年实际!$C:$C,">="&DATE(YEAR(主页!$D$2),1,1),当年实际!$C:$C,"<="&EOMONTH(DATE(YEAR(主页!$D$2),MONTH(主页!$D$2),1),0))/SUMIFS(当年实际!$P:$P,当年实际!$H:$H,$B12,当年实际!$C:$C,">="&DATE(YEAR(主页!$D$2),1,1),当年实际!$C:$C,"<="&EOMONTH(DATE(YEAR(主页!$D$2),MONTH(主页!$D$2),1),0)),"")
E13: =IF(D13/SUM(D:D)=0,"",D13/SUM(D:D)) | G13: =D13*F13 -> 0 | H13: =IF(G13/SUM(G:G)=0,"",G13/SUM(G:G)) | J13: =IFERROR(SUMIFS(当年实际!$V:$V,当年实际!$H:$H,$B13,当年实际!$C:$C,">="&DATE(YEAR(主页!$D$2),1,1),当年实际!$C:$C,"<="&EOMONTH(DATE(YEAR(主页!$D$2),MONTH(主页!$D$2),1),0))/SUMIFS(当年实际!$P:$P,当年实际!$H:$H,$B13,当年实际!$C:$C,">="&DATE(YEAR(主页!$D$2),1,1),当年实际!$C:$C,"<="&EOMONTH(DATE(YEAR(主页!$D$2),MONTH(主页!$D$2),1),0)),"")
E14: =IF(D14/SUM(D:D)=0,"",D14/SUM(D:D)) | G14: =D14*F14 -> 0 | H14: =IF(G14/SUM(G:G)=0,"",G14/SUM(G:G)) | J14: =IFERROR(SUMIFS(当年实际!$V:$V,当年实际!$H:$H,$B14,当年实际!$C:$C,">="&DATE(YEAR(主页!$D$2),1,1),当年实际!$C:$C,"<="&EOMONTH(DATE(YEAR(主页!$D$2),MONTH(主页!$D$2),1),0))/SUMIFS(当年实际!$P:$P,当年实际!$H:$H,$B14,当年实际!$C:$C,">="&DATE(YEAR(主页!$D$2),1,1),当年实际!$C:$C,"<="&EOMONTH(DATE(YEAR(主页!$D$2),MONTH(主页!$D$2),1),0)),"")
E15: =IF(D15/SUM(D:D)=0,"",D15/SUM(D:D)) | G15: =D15*F15 -> 0 | H15: =IF(G15/SUM(G:G)=0,"",G15/SUM(G:G)) | J15: =IFERROR(SUMIFS(当年实际!$V:$V,当年实际!$H:$H,$B15,当年实际!$C:$C,">="&DATE(YEAR(主页!$D$2),1,1),当年实际!$C:$C,"<="&EOMONTH(DATE(YEAR(主页!$D$2),MONTH(主页!$D$2),1),0))/SUMIFS(当年实际!$P:$P,当年实际!$H:$H,$B15,当年实际!$C:$C,">="&DATE(YEAR(主页!$D$2),1,1),当年实际!$C:$C,"<="&EOMONTH(DATE(YEAR(主页!$D$2),MONTH(主页!$D$2),1),0)),"")
E16: =IF(D16/SUM(D:D)=0,"",D16/SUM(D:D)) | G16: =D16*F16 -> 0 | H16: =IF(G16/SUM(G:G)=0,"",G16/SUM(G:G)) | J16: =IFERROR(SUMIFS(当年实际!$V:$V,当年实际!$H:$H,$B16,当年实际!$C:$C,">="&DATE(YEAR(主页!$D$2),1,1),当年实际!$C:$C,"<="&EOMONTH(DATE(YEAR(主页!$D$2),MONTH(主页!$D$2),1),0))/SUMIFS(当年实际!$P:$P,当年实际!$H:$H,$B16,当年实际!$C:$C,">="&DATE(YEAR(主页!$D$2),1,1),当年实际!$C:$C,"<="&EOMONTH(DATE(YEAR(主页!$D$2),MONTH(主页!$D$2),1),0)),"")
E17: =IF(D17/SUM(D:D)=0,"",D17/SUM(D:D)) | G17: =D17*F17 -> 0 | H17: =IF(G17/SUM(G:G)=0,"",G17/SUM(G:G)) | J17: =IFERROR(SUMIFS(当年实际!$V:$V,当年实际!$H:$H,$B17,当年实际!$C:$C,">="&DATE(YEAR(主页!$D$2),1,1),当年实际!$C:$C,"<="&EOMONTH(DATE(YEAR(主页!$D$2),MONTH(主页!$D$2),1),0))/SUMIFS(当年实际!$P:$P,当年实际!$H:$H,$B17,当年实际!$C:$C,">="&DATE(YEAR(主页!$D$2),1,1),当年实际!$C:$C,"<="&EOMONTH(DATE(YEAR(主页!$D$2),MONTH(主页!$D$2),1),0)),"")
... E333: =IF(D333/SUM(D:D)=0,"",D333/SUM(D:D)) | G333: =D333*F333 -> 0 | H333: =IF(G333/SUM(G:G)=0,"",G333/SUM(G:G)) | J333: =IFERROR(SUMIFS(当年实际!$V:$V,当年实际!$H:$H,$B333,当年实际!$C:$C,">="&DATE(YEAR(主页!$D$2),1,1),当年实际!$C:$C,"<="&EOMONTH(DATE(YEAR(主页!$D$2),MONTH(主页!$D$2),1),0))/SUMIFS(当年实际!$P:$P,当年实际!$H:$H,$B333,当年实际!$C:$C,">="&DATE(YEAR(主页!$D$2),1,1),当年实际!$C:$C,"<="&EOMONTH(DATE(YEAR(主页!$D$2),MONTH(主页!$D$2),1),0)),"")

Sheet 下年预算 业务员
A1: 销售大区 | B1: 办事处 | C1: 业务员 | D1: ="下年预算 B"&TEXT(主页!$D$2,"YY")+1&"FY" -> 下年预算 B22FY | J1: ="当年已过去月份实际 A"&TEXT(主页!$D$2,"YY")&"YTD" -> 当年已过去月份实际 A21YTD | L1: 返回主页
A2: 销售大区 | B2: 办事处 | C2: 业务员 | D2: 销售收入 | E2: 收入占比% | F2: 毛利率 | G2: 销售毛利 | H2: 毛利占比% | J2: 毛利率
A3: 东区 | B3: 北京 | C3: 张三 | D3: 1300 | E3: =IF(D3/SUM(D:D)=0,"",D3/SUM(D:D)) -> 0.21311475 | F3: 0.28 | G3: =D3*F3 -> 364 | H3: =IF(G3/SUM(G:G)=0,"",G3/SUM(G:G)) -> 0.28482003 | J3: =IFERROR(SUMIFS(当年实际!$V:$V,当年实际!$J:$J,$C3,当年实际!$C:$C,">="&DATE(YEAR(主页!$D$2),1,1),当年实际!$C:$C,"<="&EOMONTH(DATE(YEAR(主页!$D$2),MONTH(主页!$D$2),1),0))/SUMIFS(当年实际!$P:$P,当年实际!$J:$J,$C3,当年实际!$C:$C,">="&DATE(YEAR(主页!$D$2),1,1),当年实际!$C:$C,"<="&EOMONTH(DATE(YEAR(主页!$D$2),MONTH(主页!$D$2),1),0)),"") -> 0.27777778
A4: 南区 | B4: 上海 | C4: 李四 | D4: 2500 | E4: =IF(D4/SUM(D:D)=0,"",D4/SUM(D:D)) -> 0.40983607 | F4: 0.2 | G4: =D4*F4 -> 500 | H4: =IF(G4/SUM(G:G)=0,"",G4/SUM(G:G)) -> 0.39123631 | J4: =IFERROR(SUMIFS(当年实际!$V:$V,当年实际!$J:$J,$C4,当年实际!$C:$C,">="&DATE(YEAR(主页!$D$2),1,1),当年实际!$C:$C,"<="&EOMONTH(DATE(YEAR(主页!$D$2),MONTH(主页!$D$2),1),0))/SUMIFS(当年实际!$P:$P,当年实际!$J:$J,$C4,当年实际!$C:$C,">="&DATE(YEAR(主页!$D$2),1,1),当年实际!$C:$C,"<="&EOMONTH(DATE(YEAR(主页!$D$2),MONTH(主页!$D$2),1),0)),"") -> 0.194
A5: 北区 | B5: 广州 | C5: 王二麻子 | D5: 2300 | E5: =IF(D5/SUM(D:D)=0,"",D5/SUM(D:D)) -> 0.37704918 | F5: 0.18 | G5: =D5*F5 -> 414 | H5: =IF(G5/SUM(G:G)=0,"",G5/SUM(G:G)) -> 0.32394366 | J5: =IFERROR(SUMIFS(当年实际!$V:$V,当年实际!$J:$J,$C5,当年实际!$C:$C,">="&DATE(YEAR(主页!$D$2),1,1),当年实际!$C:$C,"<="&EOMONTH(DATE(YEAR(主页!$D$2),MONTH(主页!$D$2),1),0))/SUMIFS(当年实际!$P:$P,当年实际!$J:$J,$C5,当年实际!$C:$C,">="&DATE(YEAR(主页!$D$2),1,1),当年实际!$C:$C,"<="&EOMONTH(DATE(YEAR(主页!$D$2),MONTH(主页!$D$2),1),0)),"") -> 0.16
E6: =IF(D6/SUM(D:D)=0,"",D6/SUM(D:D)) | G6: =D6*F6 -> 0 | H6: =IF(G6/SUM(G:G)=0,"",G6/SUM(G:G)) | J6: =IFERROR(SUMIFS(当年实际!$V:$V,当年实际!$J:$J,$C6,当年实际!$C:$C,">="&DATE(YEAR(主页!$D$2),1,1),当年实际!$C:$C,"<="&EOMONTH(DATE(YEAR(主页!$D$2),MONTH(主页!$D$2),1),0))/SUMIFS(当年实际!$P:$P,当年实际!$J:$J,$C6,当年实际!$C:$C,">="&DATE(YEAR(主页!$D$2),1,1),当年实际!$C:$C,"<="&EOMONTH(DATE(YEAR(主页!$D$2),MONTH(主页!$D$2),1),0)),"")
E7: =IF(D7/SUM(D:D)=0,"",D7/SUM(D:D)) | G7: =D7*F7 -> 0 | H7: =IF(G7/SUM(G:G)=0,"",G7/SUM(G:G)) | J7: =IFERROR(SUMIFS(当年实际!$V:$V,当年实际!$J:$J,$C7,当年实际!$C:$C,">="&DATE(YEAR(主页!$D$2),1,1),当年实际!$C:$C,"<="&EOMONTH(DATE(YEAR(主页!$D$2),MONTH(主页!$D$2),1),0))/SUMIFS(当年实际!$P:$P,当年实际!$J:$J,$C7,当年实际!$C:$C,">="&DATE(YEAR(主页!$D$2),1,1),当年实际!$C:$C,"<="&EOMONTH(DATE(YEAR(主页!$D$2),MONTH(主页!$D$2),1),0)),"")
E8: =IF(D8/SUM(D:D)=0,"",D8/SUM(D:D)) | G8: =D8*F8 -> 0 | H8: =IF(G8/SUM(G:G)=0,"",G8/SUM(G:G)) | J8: =IFERROR(SUMIFS(当年实际!$V:$V,当年实际!$J:$J,$C8,当年实际!$C:$C,">="&DATE(YEAR(主页!$D$2),1,1),当年实际!$C:$C,"<="&EOMONTH(DATE(YEAR(主页!$D$2),MONTH(主页!$D$2),1),0))/SUMIFS(当年实际!$P:$P,当年实际!$J:$J,$C8,当年实际!$C:$C,">="&DATE(YEAR(主页!$D$2),1,1),当年实际!$C:$C,"<="&EOMONTH(DATE(YEAR(主页!$D$2),MONTH(主页!$D$2),1),0)),"")
E9: =IF(D9/SUM(D:D)=0,"",D9/SUM(D:D)) | G9: =D9*F9 -> 0 | H9: =IF(G9/SUM(G:G)=0,"",G9/SUM(G:G)) | J9: =IFERROR(SUMIFS(当年实际!$V:$V,当年实际!$J:$J,$C9,当年实际!$C:$C,">="&DATE(YEAR(主页!$D$2),1,1),当年实际!$C:$C,"<="&EOMONTH(DATE(YEAR(主页!$D$2),MONTH(主页!$D$2),1),0))/SUMIFS(当年实际!$P:$P,当年实际!$J:$J,$C9,当年实际!$C:$C,">="&DATE(YEAR(主页!$D$2),1,1),当年实际!$C:$C,"<="&EOMONTH(DATE(YEAR(主页!$D$2),MONTH(主页!$D$2),1),0)),"")
E10: =IF(D10/SUM(D:D)=0,"",D10/SUM(D:D)) | G10: =D10*F10 -> 0 | H10: =IF(G10/SUM(G:G)=0,"",G10/SUM(G:G)) | J10: =IFERROR(SUMIFS(当年实际!$V:$V,当年实际!$J:$J,$C10,当年实际!$C:$C,">="&DATE(YEAR(主页!$D$2),1,1),当年实际!$C:$C,"<="&EOMONTH(DATE(YEAR(主页!$D$2),MONTH(主页!$D$2),1),0))/SUMIFS(当年实际!$P:$P,当年实际!$J:$J,$C10,当年实际!$C:$C,">="&DATE(YEAR(主页!$D$2),1,1),当年实际!$C:$C,"<="&EOMONTH(DATE(YEAR(主页!$D$2),MONTH(主页!$D$2),1),0)),"")
E11: =IF(D11/SUM(D:D)=0,"",D11/SUM(D:D)) | G11: =D11*F11 -> 0 | H11: =IF(G11/SUM(G:G)=0,"",G11/SUM(G:G)) | J11: =IFERROR(SUMIFS(当年实际!$V:$V,当年实际!$J:$J,$C11,当年实际!$C:$C,">="&DATE(YEAR(主页!$D$2),1,1),当年实际!$C:$C,"<="&EOMONTH(DATE(YEAR(主页!$D$2),MONTH(主页!$D$2),1),0))/SUMIFS(当年实际!$P:$P,当年实际!$J:$J,$C11,当年实际!$C:$C,">="&DATE(YEAR(主页!$D$2),1,1),当年实际!$C:$C,"<="&EOMONTH(DATE(YEAR(主页!$D$2),MONTH(主页!$D$2),1),0)),"")
E12: =IF(D12/SUM(D:D)=0,"",D12/SUM(D:D)) | G12: =D12*F12 -> 0 | H12: =IF(G12/SUM(G:G)=0,"",G12/SUM(G:G)) | J12: =IFERROR(SUMIFS(当年实际!$V:$V,当年实际!$J:$J,$C12,当年实际!$C:$C,">="&DATE(YEAR(主页!$D$2),1,1),当年实际!$C:$C,"<="&EOMONTH(DATE(YEAR(主页!$D$2),MONTH(主页!$D$2),1),0))/SUMIFS(当年实际!$P:$P,当年实际!$J:$J,$C12,当年实际!$C:$C,">="&DATE(YEAR(主页!$D$2),1,1),当年实际!$C:$C,"<="&EOMONTH(DATE(YEAR(主页!$D$2),MONTH(主页!$D$2),1),0)),"")
E13: =IF(D13/SUM(D:D)=0,"",D13/SUM(D:D)) | G13: =D13*F13 -> 0 | H13: =IF(G13/SUM(G:G)=0,"",G13/SUM(G:G)) | J13: =IFERROR(SUMIFS(当年实际!$V:$V,当年实际!$J:$J,$C13,当年实际!$C:$C,">="&DATE(YEAR(主页!$D$2),1,1),当年实际!$C:$C,"<="&EOMONTH(DATE(YEAR(主页!$D$2),MONTH(主页!$D$2),1),0))/SUMIFS(当年实际!$P:$P,当年实际!$J:$J,$C13,当年实际!$C:$C,">="&DATE(YEAR(主页!$D$2),1,1),当年实际!$C:$C,"<="&EOMONTH(DATE(YEAR(主页!$D$2),MONTH(主页!$D$2),1),0)),"")
E14: =IF(D14/SUM(D:D)=0,"",D14/SUM(D:D)) | G14: =D14*F14 -> 0 | H14: =IF(G14/SUM(G:G)=0,"",G14/SUM(G:G)) | J14: =IFERROR(SUMIFS(当年实际!$V:$V,当年实际!$J:$J,$C14,当年实际!$C:$C,">="&DATE(YEAR(主页!$D$2),1,1),当年实际!$C:$C,"<="&EOMONTH(DATE(YEAR(主页!$D$2),MONTH(主页!$D$2),1),0))/SUMIFS(当年实际!$P:$P,当年实际!$J:$J,$C14,当年实际!$C:$C,">="&DATE(YEAR(主页!$D$2),1,1),当年实际!$C:$C,"<="&EOMONTH(DATE(YEAR(主页!$D$2),MONTH(主页!$D$2),1),0)),"")
E15: =IF(D15/SUM(D:D)=0,"",D15/SUM(D:D)) | G15: =D15*F15 -> 0 | H15: =IF(G15/SUM(G:G)=0,"",G15/SUM(G:G)) | J15: =IFERROR(SUMIFS(当年实际!$V:$V,当年实际!$J:$J,$C15,当年实际!$C:$C,">="&DATE(YEAR(主页!$D$2),1,1),当年实际!$C:$C,"<="&EOMONTH(DATE(YEAR(主页!$D$2),MONTH(主页!$D$2),1),0))/SUMIFS(当年实际!$P:$P,当年实际!$J:$J,$C15,当年实际!$C:$C,">="&DATE(YEAR(主页!$D$2),1,1),当年实际!$C:$C,"<="&EOMONTH(DATE(YEAR(主页!$D$2),MONTH(主页!$D$2),1),0)),"")
E16: =IF(D16/SUM(D:D)=0,"",D16/SUM(D:D)) | G16: =D16*F16 -> 0 | H16: =IF(G16/SUM(G:G)=0,"",G16/SUM(G:G)) | J16: =IFERROR(SUMIFS(当年实际!$V:$V,当年实际!$J:$J,$C16,当年实际!$C:$C,">="&DATE(YEAR(主页!$D$2),1,1),当年实际!$C:$C,"<="&EOMONTH(DATE(YEAR(主页!$D$2),MONTH(主页!$D$2),1),0))/SUMIFS(当年实际!$P:$P,当年实际!$J:$J,$C16,当年实际!$C:$C,">="&DATE(YEAR(主页!$D$2),1,1),当年实际!$C:$C,"<="&EOMONTH(DATE(YEAR(主页!$D$2),MONTH(主页!$D$2),1),0)),"")
E17: =IF(D17/SUM(D:D)=0,"",D17/SUM(D:D)) | G17: =D17*F17 -> 0 | H17: =IF(G17/SUM(G:G)=0,"",G17/SUM(G:G)) | J17: =IFERROR(SUMIFS(当年实际!$V:$V,当年实际!$J:$J,$C17,当年实际!$C:$C,">="&DATE(YEAR(主页!$D$2),1,1),当年实际!$C:$C,"<="&EOMONTH(DATE(YEAR(主页!$D$2),MONTH(主页!$D$2),1),0))/SUMIFS(当年实际!$P:$P,当年实际!$J:$J,$C17,当年实际!$C:$C,">="&DATE(YEAR(主页!$D$2),1,1),当年实际!$C:$C,"<="&EOMONTH(DATE(YEAR(主页!$D$2),MONTH(主页!$D$2),1),0)),"")
... E150: =IF(D150/SUM(D:D)=0,"",D150/SUM(D:D)) | G150: =D150*F150 -> 0 | H150: =IF(G150/SUM(G:G)=0,"",G150/SUM(G:G)) | J150: =IFERROR(SUMIFS(当年实际!$V:$V,当年实际!$J:$J,$C150,当年实际!$C:$C,">="&DATE(YEAR(主页!$D$2),1,1),当年实际!$C:$C,"<="&EOMONTH(DATE(YEAR(主页!$D$2),MONTH(主页!$D$2),1),0))/SUMIFS(当年实际!$P:$P,当年实际!$J:$J,$C150,当年实际!$C:$C,">="&DATE(YEAR(主页!$D$2),1,1),当年实际!$C:$C,"<="&EOMONTH(DATE(YEAR(主页!$D$2),MONTH(主页!$D$2),1),0)),"")

Sheet 下年预算 客户
A1: 客户大类 | B1: 客户子类 | C1: 客户名称 | D1: ="当年剩余月份估计 E"&TEXT(主页!$D$2,"YY")&"YTG" -> 当年剩余月份估计 E21YTG | J1: ="当年已过去月份实际 A"&TEXT(主页!$D$2,"YY")&"YTD" -> 当年已过去月份实际 A21YTD | L1: 返回主页
A2: 客户大类 | B2: 客户子类 | C2: 客户名称 | D2: 销售收入 | E2: 收入占比% | F2: 毛利率 | G2: 销售毛利 | H2: 毛利占比% | J2: 毛利率
A3: A | B3: A01 | C3: 京东 | D3: 1200 | E3: =IF(D3/SUM(D:D)=0,"",D3/SUM(D:D)) -> 0.19354839 | F3: 0.16 | G3: =D3*F3 -> 192 | H3: =IF(G3/SUM(G:G)=0,"",G3/SUM(G:G)) -> 0.14201183 | J3: =IFERROR(SUMIFS(当年实际!$V:$V,当年实际!$F:$F,$C3,当年实际!$C:$C,">="&DATE(YEAR(主页!$D$2),1,1),当年实际!$C:$C,"<="&EOMONTH(DATE(YEAR(主页!$D$2),MONTH(主页!$D$2),1),0))/SUMIFS(当年实际!$P:$P,当年实际!$F:$F,$C3,当年实际!$C:$C,">="&DATE(YEAR(主页!$D$2),1,1),当年实际!$C:$C,"<="&EOMONTH(DATE(YEAR(主页!$D$2),MONTH(主页!$D$2),1),0)),"") -> 0.16
A4: B | B4: B01 | C4: 天猫 | D4: 2000 | E4: =IF(D4/SUM(D:D)=0,"",D4/SUM(D:D)) -> 0.32258065 | F4: 0.28 | G4: =D4*F4 -> 560 | H4: =IF(G4/SUM(G:G)=0,"",G4/SUM(G:G)) -> 0.41420118 | J4: =IFERROR(SUMIFS(当年实际!$V:$V,当年实际!$F:$F,$C4,当年实际!$C:$C,">="&DATE(YEAR(主页!$D$2),1,1),当年实际!$C:$C,"<="&EOMONTH(DATE(YEAR(主页!$D$2),MONTH(主页!$D$2),1),0))/SUMIFS(当年实际!$P:$P,当年实际!$F:$F,$C4,当年实际!$C:$C,">="&DATE(YEAR(主页!$D$2),1,1),当年实际!$C:$C,"<="&EOMONTH(DATE(YEAR(主页!$D$2),MONTH(主页!$D$2),1),0)),"") -> 0.27777778
A5: C | B5: C01 | C5: 苏宁 | D5: 3000 | E5: =IF(D5/SUM(D:D)=0,"",D5/SUM(D:D)) -> 0.48387097 | F5: 0.2 | G5: =D5*F5 -> 600 | H5: =IF(G5/SUM(G:G)=0,"",G5/SUM(G:G)) -> 0.44378698 | J5: =IFERROR(SUMIFS(当年实际!$V:$V,当年实际!$F:$F,$C5,当年实际!$C:$C,">="&DATE(YEAR(主页!$D$2),1,1),当年实际!$C:$C,"<="&EOMONTH(DATE(YEAR(主页!$D$2),MONTH(主页!$D$2),1),0))/SUMIFS(当年实际!$P:$P,当年实际!$F:$F,$C5,当年实际!$C:$C,">="&DATE(YEAR(主页!$D$2),1,1),当年实际!$C:$C,"<="&EOMONTH(DATE(YEAR(主页!$D$2),MONTH(主页!$D$2),1),0)),"") -> 0.194
E6: =IF(D6/SUM(D:D)=0,"",D6/SUM(D:D)) | G6: =D6*F6 -> 0 | H6: =IF(G6/SUM(G:G)=0,"",G6/SUM(G:G)) | J6: =IFERROR(SUMIFS(当年实际!$V:$V,当年实际!$F:$F,$C6,当年实际!$C:$C,">="&DATE(YEAR(主页!$D$2),1,1),当年实际!$C:$C,"<="&EOMONTH(DATE(YEAR(主页!$D$2),MONTH(主页!$D$2),1),0))/SUMIFS(当年实际!$P:$P,当年实际!$F:$F,$C6,当年实际!$C:$C,">="&DATE(YEAR(主页!$D$2),1,1),当年实际!$C:$C,"<="&EOMONTH(DATE(YEAR(主页!$D$2),MONTH(主页!$D$2),1),0)),"")
E7: =IF(D7/SUM(D:D)=0,"",D7/SUM(D:D)) | G7: =D7*F7 -> 0 | H7: =IF(G7/SUM(G:G)=0,"",G7/SUM(G:G)) | J7: =IFERROR(SUMIFS(当年实际!$V:$V,当年实际!$F:$F,$C7,当年实际!$C:$C,">="&DATE(YEAR(主页!$D$2),1,1),当年实际!$C:$C,"<="&EOMONTH(DATE(YEAR(主页!$D$2),MONTH(主页!$D$2),1),0))/SUMIFS(当年实际!$P:$P,当年实际!$F:$F,$C7,当年实际!$C:$C,">="&DATE(YEAR(主页!$D$2),1,1),当年实际!$C:$C,"<="&EOMONTH(DATE(YEAR(主页!$D$2),MONTH(主页!$D$2),1),0)),"")
E8: =IF(D8/SUM(D:D)=0,"",D8/SUM(D:D)) | G8: =D8*F8 -> 0 | H8: =IF(G8/SUM(G:G)=0,"",G8/SUM(G:G)) | J8: =IFERROR(SUMIFS(当年实际!$V:$V,当年实际!$F:$F,$C8,当年实际!$C:$C,">="&DATE(YEAR(主页!$D$2),1,1),当年实际!$C:$C,"<="&EOMONTH(DATE(YEAR(主页!$D$2),MONTH(主页!$D$2),1),0))/SUMIFS(当年实际!$P:$P,当年实际!$F:$F,$C8,当年实际!$C:$C,">="&DATE(YEAR(主页!$D$2),1,1),当年实际!$C:$C,"<="&EOMONTH(DATE(YEAR(主页!$D$2),MONTH(主页!$D$2),1),0)),"")
E9: =IF(D9/SUM(D:D)=0,"",D9/SUM(D:D)) | G9: =D9*F9 -> 0 | H9: =IF(G9/SUM(G:G)=0,"",G9/SUM(G:G)) | J9: =IFERROR(SUMIFS(当年实际!$V:$V,当年实际!$F:$F,$C9,当年实际!$C:$C,">="&DATE(YEAR(主页!$D$2),1,1),当年实际!$C:$C,"<="&EOMONTH(DATE(YEAR(主页!$D$2),MONTH(主页!$D$2),1),0))/SUMIFS(当年实际!$P:$P,当年实际!$F:$F,$C9,当年实际!$C:$C,">="&DATE(YEAR(主页!$D$2),1,1),当年实际!$C:$C,"<="&EOMONTH(DATE(YEAR(主页!$D$2),MONTH(主页!$D$2),1),0)),"")
E10: =IF(D10/SUM(D:D)=0,"",D10/SUM(D:D)) | G10: =D10*F10 -> 0 | H10: =IF(G10/SUM(G:G)=0,"",G10/SUM(G:G)) | J10: =IFERROR(SUMIFS(当年实际!$V:$V,当年实际!$F:$F,$C10,当年实际!$C:$C,">="&DATE(YEAR(主页!$D$2),1,1),当年实际!$C:$C,"<="&EOMONTH(DATE(YEAR(主页!$D$2),MONTH(主页!$D$2),1),0))/SUMIFS(当年实际!$P:$P,当年实际!$F:$F,$C10,当年实际!$C:$C,">="&DATE(YEAR(主页!$D$2),1,1),当年实际!$C:$C,"<="&EOMONTH(DATE(YEAR(主页!$D$2),MONTH(主页!$D$2),1),0)),"")
E11: =IF(D11/SUM(D:D)=0,"",D11/SUM(D:D)) | G11: =D11*F11 -> 0 | H11: =IF(G11/SUM(G:G)=0,"",G11/SUM(G:G)) | J11: =IFERROR(SUMIFS(当年实际!$V:$V,当年实际!$F:$F,$C11,当年实际!$C:$C,">="&DATE(YEAR(主页!$D$2),1,1),当年实际!$C:$C,"<="&EOMONTH(DATE(YEAR(主页!$D$2),MONTH(主页!$D$2),1),0))/SUMIFS(当年实际!$P:$P,当年实际!$F:$F,$C11,当年实际!$C:$C,">="&DATE(YEAR(主页!$D$2),1,1),当年实际!$C:$C,"<="&EOMONTH(DATE(YEAR(主页!$D$2),MONTH(主页!$D$2),1),0)),"")
E12: =IF(D12/SUM(D:D)=0,"",D12/SUM(D:D)) | G12: =D12*F12 -> 0 | H12: =IF(G12/SUM(G:G)=0,"",G12/SUM(G:G)) | J12: =IFERROR(SUMIFS(当年实际!$V:$V,当年实际!$F:$F,$C12,当年实际!$C:$C,">="&DATE(YEAR(主页!$D$2),1,1),当年实际!$C:$C,"<="&EOMONTH(DATE(YEAR(主页!$D$2),MONTH(主页!$D$2),1),0))/SUMIFS(当年实际!$P:$P,当年实际!$F:$F,$C12,当年实际!$C:$C,">="&DATE(YEAR(主页!$D$2),1,1),当年实际!$C:$C,"<="&EOMONTH(DATE(YEAR(主页!$D$2),MONTH(主页!$D$2),1),0)),"")
E13: =IF(D13/SUM(D:D)=0,"",D13/SUM(D:D)) | G13: =D13*F13 -> 0 | H13: =IF(G13/SUM(G:G)=0,"",G13/SUM(G:G)) | J13: =IFERROR(SUMIFS(当年实际!$V:$V,当年实际!$F:$F,$C13,当年实际!$C:$C,">="&DATE(YEAR(主页!$D$2),1,1),当年实际!$C:$C,"<="&EOMONTH(DATE(YEAR(主页!$D$2),MONTH(主页!$D$2),1),0))/SUMIFS(当年实际!$P:$P,当年实际!$F:$F,$C13,当年实际!$C:$C,">="&DATE(YEAR(主页!$D$2),1,1),当年实际!$C:$C,"<="&EOMONTH(DATE(YEAR(主页!$D$2),MONTH(主页!$D$2),1),0)),"")
E14: =IF(D14/SUM(D:D)=0,"",D14/SUM(D:D)) | G14: =D14*F14 -> 0 | H14: =IF(G14/SUM(G:G)=0,"",G14/SUM(G:G)) | J14: =IFERROR(SUMIFS(当年实际!$V:$V,当年实际!$F:$F,$C14,当年实际!$C:$C,">="&DATE(YEAR(主页!$D$2),1,1),当年实际!$C:$C,"<="&EOMONTH(DATE(YEAR(主页!$D$2),MONTH(主页!$D$2),1),0))/SUMIFS(当年实际!$P:$P,当年实际!$F:$F,$C14,当年实际!$C:$C,">="&DATE(YEAR(主页!$D$2),1,1),当年实际!$C:$C,"<="&EOMONTH(DATE(YEAR(主页!$D$2),MONTH(主页!$D$2),1),0)),"")
E15: =IF(D15/SUM(D:D)=0,"",D15/SUM(D:D)) | G15: =D15*F15 -> 0 | H15: =IF(G15/SUM(G:G)=0,"",G15/SUM(G:G)) | J15: =IFERROR(SUMIFS(当年实际!$V:$V,当年实际!$F:$F,$C15,当年实际!$C:$C,">="&DATE(YEAR(主页!$D$2),1,1),当年实际!$C:$C,"<="&EOMONTH(DATE(YEAR(主页!$D$2),MONTH(主页!$D$2),1),0))/SUMIFS(当年实际!$P:$P,当年实际!$F:$F,$C15,当年实际!$C:$C,">="&DATE(YEAR(主页!$D$2),1,1),当年实际!$C:$C,"<="&EOMONTH(DATE(YEAR(主页!$D$2),MONTH(主页!$D$2),1),0)),"")
E16: =IF(D16/SUM(D:D)=0,"",D16/SUM(D:D)) | G16: =D16*F16 -> 0 | H16: =IF(G16/SUM(G:G)=0,"",G16/SUM(G:G)) | J16: =IFERROR(SUMIFS(当年实际!$V:$V,当年实际!$F:$F,$C16,当年实际!$C:$C,">="&DATE(YEAR(主页!$D$2),1,1),当年实际!$C:$C,"<="&EOMONTH(DATE(YEAR(主页!$D$2),MONTH(主页!$D$2),1),0))/SUMIFS(当年实际!$P:$P,当年实际!$F:$F,$C16,当年实际!$C:$C,">="&DATE(YEAR(主页!$D$2),1,1),当年实际!$C:$C,"<="&EOMONTH(DATE(YEAR(主页!$D$2),MONTH(主页!$D$2),1),0)),"")
E17: =IF(D17/SUM(D:D)=0,"",D17/SUM(D:D)) | G17: =D17*F17 -> 0 | H17: =IF(G17/SUM(G:G)=0,"",G17/SUM(G:G)) | J17: =IFERROR(SUMIFS(当年实际!$V:$V,当年实际!$F:$F,$C17,当年实际!$C:$C,">="&DATE(YEAR(主页!$D$2),1,1),当年实际!$C:$C,"<="&EOMONTH(DATE(YEAR(主页!$D$2),MONTH(主页!$D$2),1),0))/SUMIFS(当年实际!$P:$P,当年实际!$F:$F,$C17,当年实际!$C:$C,">="&DATE(YEAR(主页!$D$2),1,1),当年实际!$C:$C,"<="&EOMONTH(DATE(YEAR(主页!$D$2),MONTH(主页!$D$2),1),0)),"")
