Workbook
Name BM: #REF!
Name Database: #REF!
Name GL_accvouch: #REF!
Name UFPrn20091118105414: #REF!
Name UFPrn20091118105431: #REF!
Name UFPrn20091118112339: #REF!
Name UFPrn20091118135707: #REF!
Name UFPrn20091119090711: #REF!
Name UFPrn20091119093632: #REF!
Name 销售: 'F:\金财\课程研发\财务军团\财务军团D3练习资料\2.0 销售数据（原始数据）.xlsx'!sales[#Data]

Sheet 主页
C5: 预算编制年度实际数截止日期 | D5: 44469
C6: 注意检查表格之间数据取数期间是否一致！
B8: 编制说明：
B9: 1. 利润表预算：
C10: 1.1 利润表的源数据全部取自于其他表格。
C11: 1.2 注意检查数据源是否正确，取数公式是否正确。
B12: 2.现金流预算
C13: 2.1 先做销售及收现预算，根据应收账款管理策略的变化和销售数据预计期末的应收账款余额，反推当期收现金额
C14: 2.2 再做采购及付现预算，根据应付账款管理策略的变化和采购数据预计期末的应付账款余额，反推当期付现金额
C15: 2.3 员工薪酬和日常费用假设产生当期即付现，则可简化为付现额=费用额
C16: 2.4 税金根据销售、采购、利润数据推算。为了简化，如果年度之间变化幅度不大，可以忽略实际发生、申报和实缴的时间差对现金流的影响。反之，则需要考虑。
C17: 2.5 购置资产对现金流的影响一般比较大，需要根据资产预算数据尽量准确估计发生时间和金额。
C18: 2.6 缺口如何补？富余的资金如何用？资金的缺口和结余在预算时就要有计划。
B19: 3.资产负债表预算
C20: 3.1 所有资产科目都可以用公式 期末=期初+变动额 推算出来。
C21: 3.2 一般企业，资产负债表不是特别必要做。
C22: 3.3 企业可根据实际需要，决定是否做资产负债表或是否做完整的预算资产负债表

Sheet  利润表
E2: ="实际"&YEAR(主页!$D$5)-1&"全年" -> 实际2020全年 | H2: ="实际"&"截止"&YEAR(主页!$D$5)-1&"年"&MONTH(主页!$D$5)&"月" -> 实际截止2020年9月 | K2: ="估计"&"从"&YEAR(主页!$D$5)-1&"年"&MONTH(主页!$D$5)+1&"月到年底" -> 估计从2020年10月到年底 | N2: ="估计"&YEAR(主页!$D$5)&"全年" -> 估计2021全年 | Q2: ="预算"&YEAR(主页!$D$5)+1&"全年" -> 预算2022全年
B3: 金额单位：万元 | E3: ="A"&YEAR(主页!$D$5)-1&"FY" -> A2020FY | H3: ="A"&YEAR(主页!$D$5)&TEXT(MONTH(主页!$D$5),"00")&"YTD" -> A202109YTD | K3: ="E"&YEAR(主页!$D$5)&TEXT(MONTH(主页!$D$5),"00")&"YTG" -> E202109YTG | N3: ="E"&YEAR(主页!$D$5)&"FY" -> E2021FY | Q3: ="B"&YEAR(主页!$D$5)+1&"FY" -> B2022FY
E4: 金额 | F4: 占营收% | H4: 金额 | I4: 占营收% | K4: 金额 | L4: 占营收% | N4: 金额 | O4: 占营收% | Q4: 金额 | R4: 占营收%
B5: 主营业务收入 | E5: =INDEX(销售收入及毛利!$1:$1048576,MATCH($B5,销售收入及毛利!$A:$A,0),MATCH(E$3,销售收入及毛利!$4:$4,0)) -> 10046.038 | F5: =E5/E$5 -> 1 | H5: =INDEX(销售收入及毛利!$1:$1048576,MATCH($B5,销售收入及毛利!$A:$A,0),MATCH(H$3,销售收入及毛利!$4:$4,0)) -> 5000 | I5: =H5/H$5 -> 1 | K5: =INDEX(销售收入及毛利!$1:$1048576,MATCH($B5,销售收入及毛利!$A:$A,0),MATCH(K$3,销售收入及毛利!$4:$4,0)) -> 9857.3585 | L5: =K5/K$5 -> 1 | N5: =INDEX(销售收入及毛利!$1:$1048576,MATCH($B5,销售收入及毛利!$A:$A,0),MATCH(N$3,销售收入及毛利!$4:$4,0)) -> 14857.358 | O5: =N5/N$5 -> 1 | Q5: =INDEX(销售收入及毛利!$1:$1048576,MATCH($B5,销售收入及毛利!$A:$A,0),MATCH(Q$3,销售收入及毛利!$4:$4,0)) -> 26600 | R5: =Q5/Q$5 -> 1 | S5: 数据来自于销售及毛利预算表
B6: 主营业务成本 | E6: =INDEX(销售收入及毛利!$1:$1048576,MATCH($B6,销售收入及毛利!$A:$A,0),MATCH(E$3,销售收入及毛利!$4:$4,0)) -> 8160 | F6: =E6/E$5 -> 0.81226054 | H6: =INDEX(销售收入及毛利!$1:$1048576,MATCH($B6,销售收入及毛利!$A:$A,0),MATCH(H$3,销售收入及毛利!$4:$4,0)) -> 4020 | I6: =H6/H$5 -> 0.804 | K6: =INDEX(销售收入及毛利!$1:$1048576,MATCH($B6,销售收入及毛利!$A:$A,0),MATCH(K$3,销售收入及毛利!$4:$4,0)) -> 5751 | L6: =K6/K$5 -> 0.58342202 | N6: =INDEX(销售收入及毛利!$1:$1048576,MATCH($B6,销售收入及毛利!$A:$A,0),MATCH(N$3,销售收入及毛利!$4:$4,0)) -> 9771 | O6: =N6/N$5 -> 0.65765392 | Q6: =INDEX(销售收入及毛利!$1:$1048576,MATCH($B6,销售收入及毛利!$A:$A,0),MATCH(Q$3,销售收入及毛利!$4:$4,0)) -> 21809 | R6: =Q6/Q$5 -> 0.81988722 | S6: 数据来自于销售及毛利预算表
B7: 毛利 | E7: =E5-E6 -> 1886.0377 | F7: =E7/E$5 -> 0.18773946 | H7: =H5-H6 -> 980 | I7: =H7/H$5 -> 0.196 | K7: =K5-K6 -> 4106.3585 | L7: =K7/K$5 -> 0.41657798 | N7: =N5-N6 -> 5086.3585 | O7: =N7/N$5 -> 0.34234608 | Q7: =Q5-Q6 -> 4791 | R7: =Q7/Q$5 -> 0.18011278
B8: 销售及管理费用 | E8: =SUM(E9:E11) -> 2005.3404 | F8: =E8/E$5 -> 0.19961506 | H8: =SUM(H9:H11) -> 1472.7682 | I8: =H8/H$5 -> 0.29455364 | K8: =SUM(K9:K11) -> 570.61471 | L8: =K8/K$5 -> 0.057887182 | N8: =SUM(N9:N11) -> 2043.3829 | O8: =N8/N$5 -> 0.13753339 | Q8: =SUM(Q9:Q11) -> 2767.8811 | R8: =Q8/Q$5 -> 0.10405568
C9: 人力资源费用 | E9: =SUMIFS(人力资源!$G:$G,人力资源!$A:$A,$B$8) -> 1333.7749 | F9: =E9/E$5 -> 0.13276627 | H9: =SUMIFS(人力资源!U:U,人力资源!$A:$A,$B$8) -> 1008.9299 | I9: =H9/H$5 -> 0.20178598 | K9: =SUMIFS(人力资源!AH:AH,人力资源!$A:$A,$B$8) -> 340.40547 | L9: =K9/K$5 -> 0.034533133 | N9: =SUMIFS(人力资源!T:T,人力资源!$A:$A,$B$8) -> 1349.3354 | O9: =N9/N$5 -> 0.090819333 | Q9: =SUMIFS(人力资源!AU:AU,人力资源!$A:$A,$B$8) -> 1361.248 | R9: =Q9/Q$5 -> 0.051174738 | S9: 数据来自于人力资源预算表
C10: 折旧摊销 | E10: =SUMIFS(财务折旧!G:G,财务折旧!$A:$A,$B$8) -> 1.96 | F10: =E10/E$5 -> 0.0001951018 | H10: =SUMIFS(财务折旧!I:I,财务折旧!$A:$A,$B$8) -> 2.3 | I10: =H10/H$5 -> 0.00046 | K10: =SUMIFS(财务折旧!K:K,财务折旧!$A:$A,$B$8) -> 0.49 | L10: =K10/K$5 -> 4.9709057e-05 | N10: =SUMIFS(财务折旧!M:M,财务折旧!$A:$A,$B$8) -> 2.79 | O10: =N10/N$5 -> 0.00018778574 | Q10: =SUMIFS(财务折旧!O:O,财务折旧!$A:$A,$B$8) -> 3.77 | R10: =Q10/Q$5 -> 0.00014172932 | S10: 数据来自于长期资产折旧摊销预算表
C11: 其他费用 | E11: =SUMIFS(日常费用!L:L,日常费用!$A:$A,$B$8) -> 669.60551 | F11: =E11/E$5 -> 0.066653692 | H11: =SUMIFS(日常费用!O:O,日常费用!$A:$A,$B$8) -> 461.53831 | I11: =H11/H$5 -> 0.092307663 | K11: =SUMIFS(日常费用!Q:Q,日常费用!$A:$A,$B$8) -> 229.71923 | L11: =K11/K$5 -> 0.02330434 | N11: =SUMIFS(日常费用!S:S,日常费用!$A:$A,$B$8) -> 691.25755 | O11: =N11/N$5 -> 0.046526275 | Q11: =SUMIFS(日常费用!Y:Y,日常费用!$A:$A,$B$8) -> 1402.8631 | R11: =Q11/Q$5 -> 0.052739213 | S11: 数据来自于日常经营费用预算表
B12: 其他收支 | E12: =其他!G14 -> 1 | F12: =E12/E$5 -> 9.9541732e-05 | H12: =其他!I14 -> 1 | I12: =H12/H$5 -> 0.0002 | K12: =其他!K14 -> 0.5 | L12: =K12/K$5 -> 5.0723528e-05 | N12: =其他!M14 -> 1.5 | O12: =N12/N$5 -> 0.00010096007 | Q12: =其他!O14 -> 1 | R12: =Q12/Q$5 -> 3.7593985e-05 | S12: 数据来自于其他损益科目预算表
B13: 经营利润 | E13: =E7-E8-E12 -> -120.30271 | F13: =E13/E$5 -> -0.01197514 | H13: =H7-H8-H12 -> -493.76822 | I13: =H13/H$5 -> -0.098753644 | K13: =K7-K8-K12 -> 3535.2438 | L13: =K13/K$5 -> 0.35864007 | N13: =N7-N8-N12 -> 3041.4756 | O13: =N13/N$5 -> 0.20471173 | Q13: =Q7-Q8-Q12 -> 2022.1189 | R13: =Q13/Q$5 -> 0.076019508
B14: 财务费用 | E14: =其他!G17 -> 1.9 | F14: =E14/E$5 -> 0.00018912929 | H14: =其他!I17 -> 1.5 | I14: =H14/H$5 -> 0.0003 | K14: =其他!K17 -> 2.4 | L14: =K14/K$5 -> 0.00024347293 | N14: =其他!M17 -> 3.9 | O14: =N14/N$5 -> 0.00026249619 | Q14: =其他!O17 -> -0.5 | R14: =Q14/Q$5 -> -1.8796992e-05 | S14: 数据来自于其他损益科目预算表
B15: 投资收益 | F15: =E15/E$5 -> 0 | I15: =H15/H$5 -> 0 | L15: =K15/K$5 -> 0 | O15: =N15/N$5 -> 0 | R15: =Q15/Q$5 -> 0 | S15: 数据来自于其他损益科目预算表
B16: 补贴收入 | F16: =E16/E$5 -> 0 | I16: =H16/H$5 -> 0 | L16: =K16/K$5 -> 0 | O16: =N16/N$5 -> 0 | R16: =Q16/Q$5 -> 0 | S16: 数据来自于其他损益科目预算表
B17: 税前利润 | E17: =E13-E14+E15+E16 -> -122.20271 | F17: =E17/E$5 -> -0.01216427 | H17: =H13-H14+H15+H16 -> -495.26822 | I17: =H17/H$5 -> -0.099053644 | K17: =K13-K14+K15+K16 -> 3532.8438 | L17: =K17/K$5 -> 0.3583966 | N17: =N13-N14+N15+N16 -> 3037.5756 | O17: =N17/N$5 -> 0.20444923 | Q17: =Q13-Q14+Q15+Q16 -> 2022.6189 | R17: =Q17/Q$5 -> 0.076038305
B18: 税金 | E18: =E19+E20 -> 38.543336 | F18: =E18/E$5 -> 0.0038366704 | H18: =H19+H20 -> 17.602013 | I18: =H18/H$5 -> 0.0035204026 | K18: =K19+K20 -> 801.40118 | L18: =K18/K$5 -> 0.08129979 | N18: =N19+N20 -> 819.00319 | O18: =N18/N$5 -> 0.055124415 | Q18: =Q19+Q20 -> 587.2914 | R18: =Q18/Q$5 -> 0.022078624
C19: 所得税 | E19: =INDEX(税金!$1:$1048576,MATCH($C19,税金!$A:$A,0),MATCH(E$3,税金!$4:$4,0)) -> 0 | F19: =E19/E$5 -> 0 | H19: =INDEX(税金!$1:$1048576,MATCH($C19,税金!$A:$A,0),MATCH(H$3,税金!$4:$4,0)) -> 0 | I19: =H19/H$5 -> 0 | K19: =INDEX(税金!$1:$1048576,MATCH($C19,税金!$A:$A,0),MATCH(K$3,税金!$4:$4,0)) -> 738.59321 | L19: =K19/K$5 -> 0.074928107 | N19: =INDEX(税金!$1:$1048576,MATCH($C19,税金!$A:$A,0),MATCH(N$3,税金!$4:$4,0)) -> 738.59321 | O19: =N19/N$5 -> 0.049712283 | Q19: =INDEX(税金!$1:$1048576,MATCH($C19,税金!$A:$A,0),MATCH(Q$3,税金!$4:$4,0)) -> 511.40473 | R19: =Q19/Q$5 -> 0.019225742 | S19: 数据来自与税金预算
C20: 其他税金 | E20: =INDEX(税金!$1:$1048576,MATCH($C20,税金!$A:$A,0),MATCH(E$3,税金!$4:$4,0)) -> 38.543336 | F20: =E20/E$5 -> 0.0038366704 | H20: =INDEX(税金!$1:$1048576,MATCH($C20,税金!$A:$A,0),MATCH(H$3,税金!$4:$4,0)) -> 17.602013 | I20: =H20/H$5 -> 0.0035204026 | K20: =INDEX(税金!$1:$1048576,MATCH($C20,税金!$A:$A,0),MATCH(K$3,税金!$4:$4,0)) -> 62.807966 | L20: =K20/K$5 -> 0.0063716833 | N20: =INDEX(税金!$1:$1048576,MATCH($C20,税金!$A:$A,0),MATCH(N$3,税金!$4:$4,0)) -> 80.409979 | O20: =N20/N$5 -> 0.0054121316 | Q20: =INDEX(税金!$1:$1048576,MATCH($C20,税金!$A:$A,0),MATCH(Q$3,税金!$4:$4,0)) -> 75.886668 | R20: =Q20/Q$5 -> 0.0028528823 | S20: 数据来自与税金预算
B21: 净利润 | E21: =E17-E18 -> -160.74605 | F21: =E21/E$5 -> -0.01600094 | H21: =H17-H18 -> -512.87023 | I21: =H21/H$5 -> -0.10257405 | K21: =K17-K18 -> 2731.4426 | L21: =K21/K$5 -> 0.27709681 | N21: =N17-N18 -> 2218.5724 | O21: =N21/N$5 -> 0.14932482 | Q21: =Q17-Q18 -> 1435.3275 | R21: =Q21/Q$5 -> 0.053959681

Sheet 现金流
E2: ="实际"&YEAR(主页!$D$5)-1&"全年" -> 实际2020全年 | G2: ="估计"&YEAR(主页!$D$5)&"全年" -> 估计2021全年 | I2: ="预算"&YEAR(主页!$D$5)+1&"全年" -> 预算2022全年 | K2: 现金流除了做预算之外，也有必要每个月做预测，及时规划。
B3: 金额单位：万元 | E3: ="A"&YEAR(主页!$D$5)-1&"FY" -> A2020FY | G3: ="E"&YEAR(主页!$D$5)&"FY" -> E2021FY | I3: ="B"&YEAR(主页!$D$5)+1&"FY" -> B2022FY
E4: 金额 | G4: 金额 | I4: 金额
B5: 上期资金结余 | E5: 23 | G5: =E29 -> 5876.4123 | I5: =G29 -> 2220.7463
B7: 预计资金流入 | E7: =SUM(E8:E10) -> 11264.4 | G7: =SUM(G8:G10) -> 17491.4 | I7: =SUM(I8:I10) -> 30636
C8: 销售回款 | E8: =销售及收现!H15 -> 10964.4 | G8: =销售及收现!T15 -> 17291.4 | I8: =销售及收现!X15 -> 30536 | J8: 数据来自于销售收入及收现预算
C9: 其他资金流入 | E9: 300 | G9: 200 | I9: 100 | J9: 手工填列
C10: …
B12: 预计资金消耗 | E12: =SUM(E13:E18) -> 5410.9877 | G12: =SUM(G13:G18) -> 13147.066 | I12: =SUM(I13:I18) -> 15361.129
C13: 付到期货款 | E13: =生产、采购及付现!F28 -> 3011.11 | G13: =生产、采购及付现!L28 -> 6053.19 | I13: =生产、采购及付现!N28 -> 11318.868 | J13: 数据来自于采购及付现预算
C14: 付员工薪酬 | E14: =人力资源!G87+人力资源!G102+人力资源!G117+人力资源!G132+人力资源!G147 -> 1333.7749 | G14: =人力资源!T87+人力资源!T102+人力资源!T117+人力资源!T132+人力资源!T147 -> 1349.3354 | I14: =人力资源!AU87+人力资源!AU102+人力资源!AU117+人力资源!AU132+人力资源!AU147 -> 1361.248 | J14: 数据来自于人力资源预算
C15: 日常费用 | E15: =日常费用!L14 -> 675.20551 | G15: =日常费用!S14 -> 691.25755 | I15: =日常费用!Y14 -> 1402.8631 | J15: 数据来自于日常费用预算
C16: 支付税金 | E16: =税金!F28 -> 388.9373 | G16: =税金!L28 -> 1550.003 | I16: =税金!N28 -> 1277.1702 | J16: 数据来自于税金预算。为了简便，忽略了纳税申报期和实缴期之间的时间差。
C17: 购置资产付款 | E17: =长期资产!E7 -> 1.96 | G17: =长期资产!G7 -> 3503.28 | I17: =长期资产!I7 -> 0.98 | J17: 数据来自于资产预算
C18: …
B20: 资金盈余或缺口 | E20: =E5+E7-E12 -> 5876.4123 | G20: =G5+G7-G12 -> 10220.746 | I20: =I5+I7-I12 -> 17495.617
B22: 资金补充计划 | E22: =SUM(E23:E27) -> 0 | G22: =SUM(G23:G27) -> -8000 | I22: =SUM(I23:I27) -> -10000
C23: 供应链融资
C24: 向员工及合作伙伴融资
C25: 向金融机构融资 | G25: -8000 | J25: 负数表示还款
C26: 股东投入 | I26: -10000 | J26: 负数表示股东抽出资金
C27: …
B29: 本期资金结余 | E29: =E20+E22 -> 5876.4123 | G29: =G20+G22 -> 2220.7463 | I29: =I20+I22 -> 7495.617

Sheet 资产
E2: ="实际"&YEAR(主页!$D$5)-1&"全年" -> 实际2020全年 | I2: ="估计"&YEAR(主页!$D$5)&"全年" -> 估计2021全年 | M2: ="预算"&YEAR(主页!$D$5)+1&"全年" -> 预算2022全年
E3: ="A"&YEAR(主页!$D$5)-1&"FY" -> A2020FY | I3: ="E"&YEAR(主页!$D$5)&"FY" -> E2021FY | M3: ="B"&YEAR(主页!$D$5)+1&"FY" -> B2022FY
E4: 期初 | F4: 期末 | G4: 变动 | I4: 期初 | J4: 期末 | K4: 变动 | M4: 期初 | N4: 期末 | O4: 变动
B5: 货币资金 | E5: =现金流!E5 -> 23 | F5: =现金流!E29 -> 5876.4123 | G5: =F5-E5 -> 5853.4123 | I5: =现金流!G5 -> 5876.4123 | J5: =现金流!G29 -> 2220.7463 | K5: =J5-I5 -> -3655.6659 | M5: =现金流!I5 -> 2220.7463 | N5: =现金流!I29 -> 7495.617 | O5: =N5-M5 -> 5274.8707
B7: 应收账款 | E7: =销售及收现!H17 -> 3245 | F7: =销售及收现!H18 -> 3593 | G7: =F7-E7 -> 348 | I7: =销售及收现!T17 -> 3593 | J7: =销售及收现!T18 -> 3064 | K7: =J7-I7 -> -529 | M7: =销售及收现!X17 -> 3064 | N7: =销售及收现!X18 -> 4599 | O7: =N7-M7 -> 1535
B9: 存货 | E9: =生产、采购及付现!F5+生产、采购及付现!F12+生产、采购及付现!F22 -> 3423 | F9: =生产、采购及付现!F8+生产、采购及付现!F15+生产、采购及付现!F25 -> 3125.91 | G9: =F9-E9 -> -297.09 | I9: =生产、采购及付现!L5+生产、采购及付现!L12+生产、采购及付现!L22 -> 3125.91 | J9: =生产、采购及付现!L8+生产、采购及付现!L15+生产、采购及付现!L25 -> 3064 | K9: =J9-I9 -> -61.91 | M9: =生产、采购及付现!N5+生产、采购及付现!N12+生产、采购及付现!N22 -> 3064 | N9: =生产、采购及付现!N8+生产、采购及付现!N15+生产、采购及付现!N25 -> 3495.24 | O9: =N9-M9 -> 431.24
B11: 长期资产 | E11: =长期资产!E6-长期资产!E12 -> 1099.3563 | F11: =长期资产!E9-长期资产!E15 -> 968.2875 | G11: =F11-E11 -> -131.06875 | I11: =长期资产!G6-长期资产!G12 -> 968.2875 | J11: =长期资产!G9-长期资产!G15 -> 4256.615 | K11: =J11-I11 -> 3288.3275 | M11: =长期资产!I6-长期资产!G15 -> 4256.615 | N11: =长期资产!I9-长期资产!I15 -> 3970.875 | O11: =N11-M11 -> -285.74
B13: 应付账款 | E13: =生产、采购及付现!F30 -> 2044 | F13: =生产、采购及付现!F31 -> 2155.8 | G13: =F13-E13 -> 111.8 | I13: =生产、采购及付现!L30 -> 2155.8 | J13: =生产、采购及付现!L31 -> 1838.4 | K13: =J13-I13 -> -317.4 | M13: =生产、采购及付现!N30 -> 1838.4 | N13: =生产、采购及付现!N31 -> 2759.4 | O13: =N13-M13 -> 921
B15: 本年利润 | F15: =' 利润表'!E21 -> -160.74605 | G15: =F15-E15 -> -160.74605 | J15: =' 利润表'!N21 -> 2218.5724 | K15: =J15-I15 -> 2218.5724 | N15: =' 利润表'!Q21 -> 1435.3275 | O15: =N15-M15 -> 1435.3275
B17: 所有资产科目都可以用公式 期末=期初+变动额 推算出来。
B18: 一般企业，资产负债表不是特别必要做。
B19: 企业，根据实际需要，决定是否做资产负债表或是否做完整的预算资产负债表

Sheet 税金
F3: ="实际"&YEAR(主页!$D$5)-1&"全年" -> 实际2020全年 | H3: ="实际"&"截止"&YEAR(主页!$D$5)-1&"年"&MONTH(主页!$D$5)&"月" -> 实际截止2020年9月 | J3: ="估计"&"从"&YEAR(主页!$D$5)-1&"年"&MONTH(主页!$D$5)+1&"月到年底" -> 估计从2020年10月到年底 | L3: ="估计"&YEAR(主页!$D$5)&"全年" -> 估计2021全年 | N3: ="预算"&YEAR(主页!$D$5)+1&"全年" -> 预算2022全年
B4: 金额单位：万元 | F4: ="A"&YEAR(主页!$D$5)-1&"FY" -> A2020FY | H4: ="A"&YEAR(主页!$D$5)&TEXT(MONTH(主页!$D$5),"00")&"YTD" -> A202109YTD | J4: ="E"&YEAR(主页!$D$5)&TEXT(MONTH(主页!$D$5),"00")&"YTG" -> E202109YTG | L4: ="E"&YEAR(主页!$D$5)&"FY" -> E2021FY | N4: ="B"&YEAR(主页!$D$5)+1&"FY" -> B2022FY
F5: 金额 | H5: 金额 | J5: 金额 | L5: 金额 | N5: 金额
B6: 增值税 | F6: =IF(F7-F10-F14>0,F7-F10-F14,0) -> 350.39396 | H6: =IF(H7-H10-H14>0,H7-H10-H14,0) -> 160.0183 | J6: =IF(J7-J10-J14>0,J7-J10-J14,0) -> 570.98151 | L6: =IF(L7-L10-L14>0,L7-L10-L14,0) -> 730.99981 | N6: =IF(N7-N10-N14>0,N7-N10-N14,0) -> 689.8788
C7: 销项税额 | F7: =SUM(F8:F9) -> 1266.3623 | H7: =SUM(H8:H9) -> 650 | J7: =SUM(J8:J9) -> 1255.0415 | L7: =SUM(L8:L9) -> 1905.0415 | N7: =SUM(N8:N9) -> 3276
C8: 其中： | D8: 正常销售的销项 | F8: =销售及收现!H14-销售及收现!F14 -> 1266.3623 | H8: =销售及收现!L14-销售及收现!J14 -> 650 | J8: =销售及收现!P14-销售及收现!N14 -> 1255.0415 | L8: =销售及收现!T14-销售及收现!R14 -> 1905.0415 | N8: =销售及收现!X14-销售及收现!V14 -> 3276
D9: 视同销售或其他销售的销项
C10: 进项税额 | F10: =F11-F12+F13 -> 915.9683 | H10: =H11-H12+H13 -> 489.9817 | J10: =J11-J12+J13 -> 684.06 | L10: =L11-L12+L13 -> 1174.0417 | N10: =N11-N12+N13 -> 2586.1212
C11: 其中： | D11: 有专票采购的进项 | F11: =(生产、采购及付现!F9+生产、采购及付现!F18+生产、采购及付现!F26)*0.13 -> 915.9683 | H11: =(生产、采购及付现!H9+生产、采购及付现!H18+生产、采购及付现!H26)*0.13 -> 489.9817 | J11: =(生产、采购及付现!J9+生产、采购及付现!J18+生产、采购及付现!J26)*0.13 -> 684.06 | L11: =(生产、采购及付现!L9+生产、采购及付现!L18+生产、采购及付现!L26)*0.13 -> 1174.0417 | N11: =(生产、采购及付现!N9+生产、采购及付现!N18+生产、采购及付现!N26)*0.13 -> 2586.1212
D12: 减：无票采购的进项
D13: 加：费用中的可抵扣进项
C14: 上期留抵的进项 | H14: =F15 -> 0 | J14: =H15 -> 0 | L14: =F15 -> 0 | N14: =L15 -> 0
C15: 期末留抵的进项 | F15: =IF(F7-F10-F14<=0,-(F7-F10-F14),0) -> 0 | H15: =IF(H7-H10-H14<=0,-(H7-H10-H14),0) -> 0 | J15: =IF(J7-J10-J14<=0,-(J7-J10-J14),0) -> 0 | L15: =IF(L7-L10-L14<=0,-(L7-L10-L14),0) -> 0 | N15: =IF(N7-N10-N14<=0,-(N7-N10-N14),0) -> 0
A16: 所得税 | B16: 所得税 | F16: =F21*$E$17 -> 0 | H16: =H21*$E$17 -> 0 | J16: =L16-H16 -> 738.59321 | L16: =L21*$E$17 -> 738.59321 | N16: =N21*$E$17 -> 511.40473
C17: 所得税率= | E17: 0.25
D18: 税前利润 | F18: =' 利润表'!E7-' 利润表'!E8-' 利润表'!E12-' 利润表'!E14+' 利润表'!E15+' 利润表'!E16 -> -122.20271 | H18: =' 利润表'!H7-' 利润表'!H8-' 利润表'!H12-' 利润表'!H14+' 利润表'!H15+' 利润表'!H16 -> -495.26822 | J18: =' 利润表'!K7-' 利润表'!K8-' 利润表'!K12-' 利润表'!K14+' 利润表'!K15+' 利润表'!K16 -> 3532.8438 | L18: =' 利润表'!N7-' 利润表'!N8-' 利润表'!N12-' 利润表'!N14+' 利润表'!N15+' 利润表'!N16 -> 3037.5756 | N18: =' 利润表'!Q7-' 利润表'!Q8-' 利润表'!Q12-' 利润表'!Q14+' 利润表'!Q15+' 利润表'!Q16 -> 2022.6189
D19: 不能在税前列支的费用 | F19: 20 | H19: 18 | J19: 3 | L19: =H19+J19 -> 21 | N19: 23
D20: 以前年底可弥补亏损 | F20: 2 | L20: =F22 -> 104.20271 | N20: =L22 -> 0
D21: 应纳税所得 | F21: =IF(F18+F19-F20>0,F18+F19-F20,0) -> 0 | H21: =IF(H18+H19-H20>0,H18+H19-H20,0) -> 0 | J21: =IF(J18+J19-J20>0,J18+J19-J20,0) -> 3535.8438 | L21: =IF(L18+L19-L20>0,L18+L19-L20,0) -> 2954.3728 | N21: =IF(N18+N19-N20>0,N18+N19-N20,0) -> 2045.6189
D22: 以后年度可弥补亏损 | F22: =-IF(F18+F19-F20<0,F18+F19-F20,0) -> 104.20271 | H22: =-IF(H18+H19-H20<0,H18+H19-H20,0) -> 477.26822 | J22: =-IF(J18+J19-J20<0,J18+J19-J20,0) -> 0 | L22: =-IF(L18+L19-L20<0,L18+L19-L20,0) -> 0 | N22: =-IF(N18+N19-N20<0,N18+N19-N20,0) -> 0
A23: 其他税金 | B23: 其他税金 | F23: =SUM(F24:F26) -> 38.543336 | H23: =SUM(H24:H26) -> 17.602013 | J23: =SUM(J24:J26) -> 62.807966 | L23: =SUM(L24:L26) -> 80.409979 | N23: =SUM(N24:N26) -> 75.886668
C24: 城建税及教育附加， 税率 | E24: 0.11 | F24: =F6*$E$24 -> 38.543336 | H24: =H6*$E$24 -> 17.602013 | J24: =J6*$E$24 -> 62.807966 | L24: =L6*$E$24 -> 80.409979 | N24: =N6*$E$24 -> 75.886668
C25: 印花税
C26: …
B28: 税金合计 | F28: =SUM(F6,F16,F24:F26) -> 388.9373 | H28: =SUM(H6,H16,H24:H26) -> 177.62031 | J28: =SUM(J6,J16,J24:J26) -> 1372.3827 | L28: =SUM(L6,L16,L24:L26) -> 1550.003 | N28: =SUM(N6,N16,N24:N26) -> 1277.1702

Sheet 其他
G2: 实际2020全年 | I2: 实际截止2020年10月 | K2: 估计从2020年11月到年底 | M2: 估计2021全年 | O2: 预算2022全年
C3: 金额单位：万元 | G3: A2020FY | I3: A202110YTD | K3: E202110YTG | M3: E2021FY | O3: B2022FY
G4: 金额 | I4: 金额 | K4: 金额 | M4: 金额 | O4: 金额
C6: 其他业务收入 | G6: =SUM(G7:G8) -> 3 | I6: =SUM(I7:I8) -> 2 | K6: =SUM(K7:K8) -> 1 | M6: =SUM(M7:M8) -> 3 | O6: =SUM(O7:O8) -> 4
D7: 废料销售 | G7: 3 | I7: 2 | K7: 1 | M7: =I7+K7 -> 3 | O7: 4
D8: …
C10: 其他业务支出 | G10: =SUM(G11:G12) -> 2 | I10: =SUM(I11:I12) -> 1 | K10: =SUM(K11:K12) -> 0.5 | M10: =SUM(M11:M12) -> 1.5 | O10: =SUM(O11:O12) -> 3
D11: 其他材料消耗 | G11: 2 | I11: 1 | K11: 0.5 | M11: =I11+K11 -> 1.5 | O11: 3
D12: …
C14: 收支净额 | G14: =G6-G10 -> 1 | I14: =I6-I10 -> 1 | K14: =K6-K10 -> 0.5 | M14: =M6-M10 -> 1.5 | O14: =O6-O10 -> 1
C17: 财务费用 | G17: =-G18+G19+G20 -> 1.9 | I17: =-I18+I19+I20 -> 1.5 | K17: =-K18+K19+K20 -> 2.4 | M17: =-M18+M19+M20 -> 3.9 | O17: =-O18+O19+O20 -> -0.5
D18: 利息收入 | G18: 2 | I18: 1 | K18: 1 | M18: =I18+K18 -> 2 | O18: 3
D19: 利息支出 | G19: 3 | I19: 2 | K19: 3 | M19: =I19+K19 -> 5 | O19: 2
D20: 银行手续费及其他 | G20: 0.9 | I20: 0.5 | K20: 0.4 | M20: =I20+K20 -> 0.9 | O20: 0.5
C22: 投资收益

Sheet 销售收入及毛利
B2: 销售数据来源：销售收入及毛利预算
B3: 金额单位：万元 | E3: ="实际"&YEAR(主页!$D$5)-1&"全年" -> 实际2020全年 | G3: ="实际"&"截止"&YEAR(主页!$D$5)-1&"年"&MONTH(主页!$D$5)&"月" -> 实际截止2020年9月 | I3: ="估计"&"从"&YEAR(主页!$D$5)-1&"年"&MONTH(主页!$D$5)+1&"月到年底" -> 估计从2020年10月到年底 | K3: ="估计"&YEAR(主页!$D$5)&"全年" -> 估计2021全年 | M3: ="预算"&YEAR(主页!$D$5)+1&"全年" -> 预算2022全年
E4: ="A"&YEAR(主页!$D$5)-1&"FY" -> A2020FY | G4: ="A"&YEAR(主页!$D$5)&TEXT(MONTH(主页!$D$5),"00")&"YTD" -> A202109YTD | I4: ="E"&YEAR(主页!$D$5)&TEXT(MONTH(主页!$D$5),"00")&"YTG" -> E202109YTG | K4: ="E"&YEAR(主页!$D$5)&"FY" -> E2021FY | M4: ="B"&YEAR(主页!$D$5)+1&"FY" -> B2022FY
B5: 外购成品
C6: 销售收入 | E6: =SUMIFS(销售差异分析底稿!$G:$G,销售差异分析底稿!$E:$E,LEFT($B$5,2)) -> 3300 | G6: =SUMIFS(销售差异分析底稿!J:J,销售差异分析底稿!$E:$E,LEFT($B$5,2)) -> 1800 | I6: =SUMIFS(销售差异分析底稿!M:M,销售差异分析底稿!$E:$E,LEFT($B$5,2)) -> 1800 | K6: =SUMIFS(销售差异分析底稿!P:P,销售差异分析底稿!$E:$E,LEFT($B$5,2)) -> 3600 | M6: =SUMIFS(销售差异分析底稿!AF:AF,销售差异分析底稿!$E:$E,LEFT($B$5,2)) -> 4800
C7: 销售成本 | E7: =E6-E8 -> 2970 | G7: =G6-G8 -> 1500 | I7: =I6-I8 -> 1050 | K7: =K6-K8 -> 2550 | M7: =M6-M8 -> 3920
C8: 毛利 | E8: =SUMIFS(销售差异分析底稿!$H:$H,销售差异分析底稿!$E:$E,LEFT($B$5,2)) -> 330 | G8: =SUMIFS(销售差异分析底稿!K:K,销售差异分析底稿!$E:$E,LEFT($B$5,2)) -> 300 | I8: =SUMIFS(销售差异分析底稿!N:N,销售差异分析底稿!$E:$E,LEFT($B$5,2)) -> 750 | K8: =SUMIFS(销售差异分析底稿!Q:Q,销售差异分析底稿!$E:$E,LEFT($B$5,2)) -> 1050 | M8: =SUMIFS(销售差异分析底稿!AG:AG,销售差异分析底稿!$E:$E,LEFT($B$5,2)) -> 880
C9: 毛利率 | E9: =IFERROR(E8/E6,0) -> 0.1 | G9: =IFERROR(G8/G6,0) -> 0.16666667 | I9: =IFERROR(I8/I6,0) -> 0.41666667 | K9: =IFERROR(K8/K6,0) -> 0.29166667 | M9: =IFERROR(M8/M6,0) -> 0.18333333
B11: 自制成品
C12: 销售收入 | E12: =SUMIFS(销售差异分析底稿!$G:$G,销售差异分析底稿!$E:$E,LEFT($B$11,2)) -> 6180 | G12: =SUMIFS(销售差异分析底稿!J:J,销售差异分析底稿!$E:$E,LEFT($B$11,2)) -> 3200 | I12: =SUMIFS(销售差异分析底稿!M:M,销售差异分析底稿!$E:$E,LEFT($B$11,2)) -> 7680 | K12: =SUMIFS(销售差异分析底稿!P:P,销售差异分析底稿!$E:$E,LEFT($B$11,2)) -> 10880 | M12: =SUMIFS(销售差异分析底稿!AF:AF,销售差异分析底稿!$E:$E,LEFT($B$11,2)) -> 19200
C13: 销售成本 | E13: =E12-E14 -> 4830 | G13: =G12-G14 -> 2520 | I13: =I12-I14 -> 4461 | K13: =K12-K14 -> 6981 | M13: =M12-M14 -> 16827
C14: 毛利 | E14: =SUMIFS(销售差异分析底稿!$H:$H,销售差异分析底稿!$E:$E,LEFT($B$11,2)) -> 1350 | G14: =SUMIFS(销售差异分析底稿!K:K,销售差异分析底稿!$E:$E,LEFT($B$11,2)) -> 680 | I14: =SUMIFS(销售差异分析底稿!N:N,销售差异分析底稿!$E:$E,LEFT($B$11,2)) -> 3219 | K14: =SUMIFS(销售差异分析底稿!Q:Q,销售差异分析底稿!$E:$E,LEFT($B$11,2)) -> 3899 | M14: =SUMIFS(销售差异分析底稿!AG:AG,销售差异分析底稿!$E:$E,LEFT($B$11,2)) -> 2373
C15: 毛利率 | E15: =IFERROR(E14/E12,0) -> 0.2184466 | G15: =IFERROR(G14/G12,0) -> 0.2125 | I15: =IFERROR(I14/I12,0) -> 0.41914062 | K15: =IFERROR(K14/K12,0) -> 0.35836397 | M15: =IFERROR(M14/M12,0) -> 0.12359375
B17: 设计服务
C18: 销售收入 | E18: =SUMIFS(销售差异分析底稿!$G:$G,销售差异分析底稿!$E:$E,$B$17) -> 566.03774 | G18: =SUMIFS(销售差异分析底稿!J:J,销售差异分析底稿!$E:$E,$B$17) -> 0 | I18: =SUMIFS(销售差异分析底稿!M:M,销售差异分析底稿!$E:$E,$B$17) -> 377.35849 | K18: =SUMIFS(销售差异分析底稿!P:P,销售差异分析底稿!$E:$E,$B$17) -> 377.35849 | M18: =SUMIFS(销售差异分析底稿!AF:AF,销售差异分析底稿!$E:$E,$B$17) -> 2600
C19: 销售成本 | E19: =E18-E20 -> 360 | G19: =G18-G20 -> 0 | I19: =I18-I20 -> 240 | K19: =K18-K20 -> 240 | M19: =M18-M20 -> 1062
C20: 毛利 | E20: =SUMIFS(销售差异分析底稿!$H:$H,销售差异分析底稿!$E:$E,$B$17) -> 206.03774 | G20: =SUMIFS(销售差异分析底稿!K:K,销售差异分析底稿!$E:$E,$B$17) -> 0 | I20: =SUMIFS(销售差异分析底稿!N:N,销售差异分析底稿!$E:$E,$B$17) -> 137.35849 | K20: =SUMIFS(销售差异分析底稿!Q:Q,销售差异分析底稿!$E:$E,$B$17) -> 137.35849 | M20: =SUMIFS(销售差异分析底稿!AG:AG,销售差异分析底稿!$E:$E,$B$17) -> 1538
C21: 毛利率 | E21: =IFERROR(E20/E18,0) -> 0.364 | G21: =IFERROR(G20/G18,0) -> 0 | I21: =IFERROR(I20/I18,0) -> 0.364 | K21: =IFERROR(K20/K18,0) -> 0.364 | M21: =IFERROR(M20/M18,0) -> 0.59153846
B23: 合计
A24: 主营业务收入 | C24: 销售收入 | E24: =SUMIFS(销售差异分析底稿!$G:$G,销售差异分析底稿!$E:$E,"*") -> 10046.038 | G24: =SUMIFS(销售差异分析底稿!J:J,销售差异分析底稿!$E:$E,"*") -> 5000 | I24: =SUMIFS(销售差异分析底稿!M:M,销售差异分析底稿!$E:$E,"*") -> 9857.3585 | K24: =SUMIFS(销售差异分析底稿!P:P,销售差异分析底稿!$E:$E,"*") -> 14857.358 | M24: =SUMIFS(销售差异分析底稿!AF:AF,销售差异分析底稿!$E:$E,"*") -> 26600 | N24: =ROUND(M24-SUM(M6,M12,M18),0) -> 0
A25: 主营业务成本 | C25: 销售成本 | E25: =E24-E26 -> 8160 | G25: =G24-G26 -> 4020 | I25: =I24-I26 -> 5751 | K25: =K24-K26 -> 9771 | M25: =M24-M26 -> 21809 | N25: =ROUND(M25-SUM(M7,M13,M19),0) -> 0
C26: 毛利 | E26: =SUMIFS(销售差异分析底稿!$H:$H,销售差异分析底稿!$E:$E,"*") -> 1886.0377 | G26: =SUMIFS(销售差异分析底稿!K:K,销售差异分析底稿!$E:$E,"*") -> 980 | I26: =SUMIFS(销售差异分析底稿!N:N,销售差异分析底稿!$E:$E,"*") -> 4106.3585 | K26: =SUMIFS(销售差异分析底稿!Q:Q,销售差异分析底稿!$E:$E,"*") -> 5086.3585 | M26: =SUMIFS(销售差异分析底稿!AG:AG,销售差异分析底稿!$E:$E,"*") -> 4791 | N26: =ROUND(M26-SUM(M8,M14,M20),0) -> 0
C27: 毛利率 | E27: =IFERROR(E26/E24,0) -> 0.18773946 | G27: =IFERROR(G26/G24,0) -> 0.196 | I27: =IFERROR(I26/I24,0) -> 0.41657798 | K27: =IFERROR(K26/K24,0) -> 0.34234608 | M27: =IFERROR(M26/M24,0) -> 0.18011278

Sheet 销售及收现
B2: 销售数据来源：销售收入及毛利预算
B3: 产品分类 （按不同增值税率） | F3: ="实际"&YEAR(主页!$D$5)-1&"全年" -> 实际2020全年 | J3: ="实际"&"截止"&YEAR(主页!$D$5)-1&"年"&MONTH(主页!$D$5)&"月" -> 实际截止2020年9月 | N3: ="估计"&"从"&YEAR(主页!$D$5)-1&"年"&MONTH(主页!$D$5)+1&"月到年底" -> 估计从2020年10月到年底 | R3: ="估计"&YEAR(主页!$D$5)&"全年" -> 估计2021全年 | V3: ="预算"&YEAR(主页!$D$5)+1&"全年" -> 预算2022全年
F4: ="A"&YEAR(主页!$D$5)-1&"FY" -> A2020FY | J4: ="A"&YEAR(主页!$D$5)&TEXT(MONTH(主页!$D$5),"00")&"YTD" -> A202109YTD | N4: ="E"&YEAR(主页!$D$5)&TEXT(MONTH(主页!$D$5),"00")&"YTG" -> E202109YTG | R4: ="E"&YEAR(主页!$D$5)&"FY" -> E2021FY | V4: ="B"&YEAR(主页!$D$5)+1&"FY" -> B2022FY
F5: 不含税销售额 | G5: 税率 | H5: 含税销售额 | J5: 不含税销售额 | K5: 税率 | L5: 含税销售额 | N5: 不含税销售额 | O5: 税率 | P5: 含税销售额 | R5: 不含税销售额 | S5: 税率 | T5: 含税销售额 | V5: 不含税销售额 | W5: 税率 | X5: 含税销售额
B6: 自制 | C6: xx产品 | F6: =SUMIFS(销售差异分析底稿!$G:$G,销售差异分析底稿!$E:$E,$B6&"*") -> 6180 | G6: 0.13 | H6: =F6*(1+G6) -> 6983.4 | J6: =SUMIFS(销售差异分析底稿!$J:$J,销售差异分析底稿!$E:$E,$B6&"*") -> 3200 | K6: 0.13 | L6: =J6*(1+K6) -> 3616 | N6: =SUMIFS(销售差异分析底稿!M:M,销售差异分析底稿!$E:$E,$B6&"*") -> 7680 | O6: 0.13 | P6: =N6*(1+O6) -> 8678.4 | R6: =J6+N6 -> 10880 | S6: =IFERROR(T6/R6-1,"-") -> 0.13 | T6: =L6+P6 -> 12294.4 | V6: =SUMIFS(销售差异分析底稿!AF:AF,销售差异分析底稿!$E:$E,$B6&"*") -> 19200 | W6: 0.13 | X6: =V6*(1+W6) -> 21696
B7: 外购 | C7: xx产品 | F7: =SUMIFS(销售差异分析底稿!$G:$G,销售差异分析底稿!$E:$E,$B7&"*") -> 3300 | G7: 0.13 | H7: =F7*(1+G7) -> 3729 | J7: =SUMIFS(销售差异分析底稿!$J:$J,销售差异分析底稿!$E:$E,$B7&"*") -> 1800 | K7: 0.13 | L7: =J7*(1+K7) -> 2034 | N7: =SUMIFS(销售差异分析底稿!M:M,销售差异分析底稿!$E:$E,$B7&"*") -> 1800 | O7: 0.13 | P7: =N7*(1+O7) -> 2034 | R7: =J7+N7 -> 3600 | S7: =IFERROR(T7/R7-1,"-") -> 0.13 | T7: =L7+P7 -> 4068 | V7: =SUMIFS(销售差异分析底稿!AF:AF,销售差异分析底稿!$E:$E,$B7&"*") -> 4800 | W7: 0.13 | X7: =V7*(1+W7) -> 5424
B8: 安装服务 | C8: xx工程安装 | F8: =SUMIFS(销售差异分析底稿!$G:$G,销售差异分析底稿!$E:$E,$B8&"*") -> 0 | G8: 0.09 | H8: =F8*(1+G8) -> 0 | J8: =SUMIFS(销售差异分析底稿!$J:$J,销售差异分析底稿!$E:$E,$B8&"*") -> 0 | K8: 0.09 | L8: =J8*(1+K8) -> 0 | N8: =SUMIFS(销售差异分析底稿!M:M,销售差异分析底稿!$E:$E,$B8&"*") -> 0 | O8: 0.09 | P8: =N8*(1+O8) -> 0 | R8: =J8+N8 -> 0 | S8: =IFERROR(T8/R8-1,"-") -> - | T8: =L8+P8 -> 0 | V8: =SUMIFS(销售差异分析底稿!AF:AF,销售差异分析底稿!$E:$E,$B8&"*") -> 0 | W8: 0.09 | X8: =V8*(1+W8) -> 0
B9: 设计服务 | C9: xx设计 | F9: =SUMIFS(销售差异分析底稿!$G:$G,销售差异分析底稿!$E:$E,$B9&"*") -> 566.03774 | G9: 0.06 | H9: =F9*(1+G9) -> 600 | J9: =SUMIFS(销售差异分析底稿!$J:$J,销售差异分析底稿!$E:$E,$B9&"*") -> 0 | K9: 0.06 | L9: =J9*(1+K9) -> 0 | N9: =SUMIFS(销售差异分析底稿!M:M,销售差异分析底稿!$E:$E,$B9&"*") -> 377.35849 | O9: 0.06 | P9: =N9*(1+O9) -> 400 | R9: =J9+N9 -> 377.35849 | S9: =IFERROR(T9/R9-1,"-") -> 0.06 | T9: =L9+P9 -> 400 | V9: =SUMIFS(销售差异分析底稿!AF:AF,销售差异分析底稿!$E:$E,$B9&"*") -> 2600 | W9: 0.06 | X9: =V9*(1+W9) -> 2756
G10: 0.05 | H10: =F10*(1+G10) -> 0 | K10: 0.05 | L10: =J10*(1+K10) -> 0 | O10: 0.05 | P10: =N10*(1+O10) -> 0 | R10: =J10+N10 -> 0 | S10: =IFERROR(T10/R10-1,"-") -> - | T10: =L10+P10 -> 0 | W10: 0.05 | X10: =V10*(1+W10) -> 0
G11: 0.03 | H11: =F11*(1+G11) -> 0 | K11: 0.03 | L11: =J11*(1+K11) -> 0 | O11: 0.03 | P11: =N11*(1+O11) -> 0 | R11: =J11+N11 -> 0 | S11: =IFERROR(T11/R11-1,"-") -> - | T11: =L11+P11 -> 0 | W11: 0.03 | X11: =V11*(1+W11) -> 0
G12: 0.01 | H12: =F12*(1+G12) -> 0 | K12: 0.01 | L12: =J12*(1+K12) -> 0 | O12: 0.01 | P12: =N12*(1+O12) -> 0 | R12: =J12+N12 -> 0 | S12: =IFERROR(T12/R12-1,"-") -> - | T12: =L12+P12 -> 0 | W12: 0.01 | X12: =V12*(1+W12) -> 0
G13: 0 | H13: =F13*(1+G13) -> 0 | K13: 0 | L13: =J13*(1+K13) -> 0 | O13: 0 | P13: =N13*(1+O13) -> 0 | R13: =J13+N13 -> 0 | S13: =IFERROR(T13/R13-1,"-") -> - | T13: =L13+P13 -> 0 | W13: 0 | X13: =V13*(1+W13) -> 0
B14: 合计 | F14: =SUM(F6:F12) -> 10046.038 | H14: =SUM(H6:H13) -> 11312.4 | J14: =SUM(J6:J12) -> 5000 | L14: =SUM(L6:L13) -> 5650 | N14: =SUM(N6:N12) -> 9857.3585 | P14: =SUM(P6:P13) -> 11112.4 | R14: =SUM(R6:R12) -> 14857.358 | T14: =SUM(T6:T13) -> 16762.4 | V14: =SUM(V6:V12) -> 26600 | X14: =SUM(X6:X13) -> 29876
B15: 其中：销售回款收现 | H15: =H14-H19 -> 10964.4 | L15: =L14-L19 -> 6048 | P15: =P14-P19 -> 11243.4 | T15: =T14-T19 -> 17291.4 | X15: =X14-X19 -> 30536
B17: 期初应收账款 | F17: 数据取于营运资金预算表-> | H17: =[1]应收账款!$E$7 -> 3245 | J17: 数据取于营运资金预算表-> | L17: =H18 -> 3593 | N17: 数据取于营运资金预算表-> | P17: =L18 -> 3195 | R17: 数据取于营运资金预算表-> | T17: =H18 -> 3593 | V17: 数据取于营运资金预算表-> | X17: =T18 -> 3064
B18: 期末应收账款 | F18: 数据取于营运资金预算表-> | H18: =[1]应收账款!$Q$7 -> 3593 | J18: 数据取于营运资金预算表-> | L18: =INDEX([1]应收账款!$12:$12,1,MATCH(MONTH(主页!$D$5),[1]应收账款!$3:$3,0)) -> 3195 | N18: 数据取于营运资金预算表-> | P18: =[1]应收账款!$Q$12 -> 3064 | R18: 数据取于营运资金预算表-> | T18: =P18 -> 3064 | V18: 数据取于营运资金预算表-> | X18: =[1]应收账款!$Q$17 -> 4599
B19: 应收余额增（+）减（-） | H19: =H18-H17 -> 348 | L19: =L18-L17 -> -398 | P19: =P18-P17 -> -131 | T19: =T18-T17 -> -529 | X19: =P19+T19 -> -660
B20: 应收款控制策略说明：

Sheet 销售差异分析底稿
B2: 产品名称 | C2: 产品大类 | D2: 产品子类 | E2: 产品类型 | F2: A2020FY | G2: A2020FY | H2: A2020FY | I2: A202109YTD | J2: A202109YTD | K2: A202109YTD | L2: E202109YTG | M2: E202109YTG | N2: E202109YTG | O2: E2021FY | P2: E2021FY | Q2: E2021FY | R2: E2021/A2020 | AE2: B2022FY | AF2: B2022FY | AG2: B2022FY | AH2: B2022/E2021
F3: 销量 | G3: 销售额 | H3: 毛利 | I3: 销量 | J3: 销售额 | K3: 毛利 | L3: 销量 | M3: 销售额 | N3: 毛利 | O3: 销量 | P3: 销售额 | Q3: 毛利 | R3: p1 | S3: p2 | T3: q2*p1 | U3: 量差 | V3: 价差 | W3: STV | X3: c1 | Y3: c2 | Z3: q2*c1 | AA3: 量差c | AB3: 成本差 | AC3: CTV | AD3: 结构差 | AE3: 销量 | AF3: 销售额 | AG3: 毛利 | AH3: p1 | AI3: p2 | AJ3: q2*p1 | AK3: 量差p | AL3: 价差 | AM3: STV | AN3: c1 | AO3: c2 | AP3: q2*c1 | AQ3: 量差c | AR3: 成本差 | AS3: CTV | AT3: 结构差
B4: A0111 | C4: PA | D4: PA01 | E4: 外购 | F4: 198 | G4: 3300 | H4: 330 | I4: 100 | J4: 1800 | K4: 300 | L4: 70 | M4: 1800 | N4: 750 | O4: 170 | P4: 3600 | Q4: 1050 | R4: 16.666667 | S4: 21.176471 | T4: 2833.3333 | U4: -466.66667 | V4: 766.66667 | W4: 300 | X4: 15 | Y4: 15 | Z4: 2550 | AA4: -420 | AB4: 0 | AC4: -420 | AD4: -373.46743 | AE4: 280 | AF4: 4800 | AG4: 880 | AH4: 21.176471 | AI4: 17.142857 | AJ4: 5929.4118 | AK4: 2329.4118 | AL4: -1129.4118 | AM4: 1200 | AN4: 15 | AO4: 14 | AP4: 4200 | AQ4: 1650 | AR4: -280 | AS4: 1370 | AT4: -301.6367
B5: B0122 | C5: PB | D5: PB01 | E5: 自制 | F5: 245 | G5: 3980 | H5: 550 | I5: 124 | J5: 2000 | K5: 264 | L5: 178 | M5: 3980 | N5: 1488 | O5: 302 | P5: 5980 | Q5: 1752 | R5: 16.244898 | S5: 19.801325 | T5: 4905.9592 | U5: 925.95918 | V5: 1074.0408 | W5: 2000 | X5: 14 | Y5: 14 | Z5: 4228 | AA5: 798 | AB5: 0 | AC5: 798 | AD5: 27.501634 | AE5: 640 | AF5: 10000 | AG5: 1040 | AH5: 19.801325 | AI5: 15.625 | AJ5: 12672.848 | AK5: 6692.8477 | AL5: -2672.8477 | AM5: 4020 | AN5: 14 | AO5: 14 | AP5: 8960 | AQ5: 4732 | AR5: 0 | AS5: 4732 | AT5: -73.459839
B6: C0122 | C6: PC | D6: PC01 | E6: 自制 | F6: 200 | G6: 2200 | H6: 800 | I6: 112 | J6: 1200 | K6: 416 | L6: 142 | M6: 2200 | N6: 1206 | O6: 254 | P6: 3400 | Q6: 1622 | R6: 11 | S6: 13.385827 | T6: 2794 | U6: 594 | V6: 606 | W6: 1200 | X6: 7 | Y6: 7 | Z6: 1778 | AA6: 378 | AB6: 0 | AC6: 378 | AD6: 69.822403 | AE6: 533 | AF6: 5200 | AG6: 693 | AH6: 13.385827 | AI6: 9.7560976 | AJ6: 7134.6457 | AK6: 3734.6457 | AL6: -1934.6457 | AM6: 1800 | AN6: 7 | AO6: 8.4559099 | AP6: 3731 | AQ6: 1953 | AR6: 776 | AS6: 2729 | AT6: -118.23904
B7: C0199 | C7: SE | D7: SE99 | E7: 设计服务 | F7: 3 | G7: 566.03774 | H7: 206.03774 | I7: 0 | J7: 0 | K7: 0 | L7: 2 | M7: 377.35849 | N7: 137.35849 | O7: 2 | P7: 377.35849 | Q7: 137.35849 | R7: 188.67925 | S7: 188.67925 | T7: 377.35849 | U7: -188.67925 | V7: 0 | W7: -188.67925 | X7: 120 | Y7: 120 | Z7: 240 | AA7: -120 | AB7: 0 | AC7: -120 | AD7: -167.35632 | AE7: 9 | AF7: 2600 | AG7: 1538 | AH7: 188.67925 | AI7: 288.88889 | AJ7: 1698.1132 | AK7: 1320.7547 | AL7: 901.88679 | AM7: 2222.6415 | AN7: 120 | AO7: 118 | AP7: 1080 | AQ7: 840 | AR7: -18 | AS7: 822 | AT7: 1138.3525
B8: A0111 | C8: PA | D8: PA01 | E8: 自制 | F8: 0 | G8: 0 | H8: 0 | I8: 0 | J8: 0 | K8: 0 | L8: 65 | M8: 1500 | N8: 525 | O8: 65 | P8: 1500 | Q8: 525 | R8: na | S8: 23.076923 | T8: 1500 | U8: 1500 | V8: 0 | W8: 1500 | X8: NA | Y8: 15 | Z8: 975 | AA8: 975 | AB8: 0 | AC8: 975 | AD8: 525 | AE8: 240 | AF8: 4000 | AG8: 640 | AH8: 23.076923 | AI8: 16.666667 | AJ8: 5538.4615 | AK8: 4038.4615 | AL8: -1538.4615 | AM8: 2500 | AN8: 15 | AO8: 14 | AP8: 3600 | AQ8: 2625 | AR8: -240 | AS8: 2385 | AT8: 210.31393

Sheet 生产、采购及付现
B2: 金额单位：万元 | F2: ="实际"&YEAR(主页!$D$5)-1&"全年" -> 实际2020全年 | H2: ="实际"&"截止"&YEAR(主页!$D$5)-1&"年"&MONTH(主页!$D$5)&"月" -> 实际截止2020年9月 | J2: ="估计"&"从"&YEAR(主页!$D$5)-1&"年"&MONTH(主页!$D$5)+1&"月到年底" -> 估计从2020年10月到年底 | L2: ="估计"&YEAR(主页!$D$5)&"全年" -> 估计2021全年 | N2: ="预算"&YEAR(主页!$D$5)+1&"全年" -> 预算2022全年
F3: ="A"&YEAR(主页!$D$5)-1&"FY" -> A2020FY | H3: ="A"&YEAR(主页!$D$5)&TEXT(MONTH(主页!$D$5),"00")&"YTD" -> A202109YTD | J3: ="E"&YEAR(主页!$D$5)&TEXT(MONTH(主页!$D$5),"00")&"YTG" -> E202109YTG | L3: ="E"&YEAR(主页!$D$5)&"FY" -> E2021FY | N3: ="B"&YEAR(主页!$D$5)+1&"FY" -> B2022FY
B4: 外购成品
C5: 期初库存 | F5: =[1]存货!$F$8 -> 1026.9 | H5: =F8 -> 1077.9 | J5: =H8 -> 958.5 | L5: =F8 -> 1077.9 | N5: =L8 -> 919.2 | O5: 数据取于营运资金预算表
C6: 外购成品销售成本 | F6: =销售收入及毛利!E7 -> 2970 | H6: =销售收入及毛利!G7 -> 1500 | J6: =销售收入及毛利!I7 -> 1050 | L6: =销售收入及毛利!K7 -> 2550 | N6: =销售收入及毛利!M7 -> 3920 | O6: 数据来自于销售成本预算
C7: 领用损耗 | F7: 12 | H7: 3 | J7: 1 | L7: =H7+J7 -> 4 | N7: 4 | O7: 根据经验估计
C8: 期末库存 | F8: =[1]存货!$R$8 -> 1077.9 | H8: =INDEX([1]存货!$16:$16,1,MATCH(MONTH(主页!$D$5),[1]存货!$3:$3,0)) -> 958.5 | J8: =[1]存货!$R$16 -> 919.2 | L8: =J8 -> 919.2 | N8: =[1]存货!$R$24 -> 1048.572 | O8: 数据取于营运资金预算表
C9: 本期采购额 | F9: =F6-F5+F7+F8 -> 3033 | H9: =H6-H5+H7+H8 -> 1383.6 | J9: =J6-J5+J7+J8 -> 1011.7 | L9: =L6-L5+L7+L8 -> 2395.3 | N9: =N6-N5+N7+N8 -> 4053.372 | O9: 自动计算
B11: 自制产品
C12: 期初库存 | F12: =[1]存货!$F$10 -> 684.6 | H12: =F15 -> 718.6 | J12: =H15 -> 639 | L12: =F15 -> 718.6 | N12: =L15 -> 612.8 | O12: 数据取于营运资金预算表
C13: 自制产品销售成本 | F13: =销售收入及毛利!E13 -> 4830 | H13: =销售收入及毛利!G13 -> 2520 | J13: =销售收入及毛利!I13 -> 4461 | L13: =销售收入及毛利!K13 -> 6981 | N13: =销售收入及毛利!M13 -> 16827 | O13: 数据来自于销售成本预算
C14: 领用损耗 | F14: 10 | H14: 5 | J14: 3 | L14: =H14+J14 -> 8 | N14: 7 | O14: 根据经验估计
C15: 期末库存 | F15: =[1]存货!$R$10 -> 718.6 | H15: =INDEX([1]存货!$18:$18,1,MATCH(MONTH(主页!$D$5),[1]存货!$3:$3,0)) -> 639 | J15: =[1]存货!$R$18 -> 612.8 | L15: =J15 -> 612.8 | N15: =[1]存货!$R$26 -> 699.048 | O15: 数据取于营运资金预算表
C16: 本期生产成本 | F16: =F13-F12+F14+F15 -> 4874 | H16: =H13-H12+H14+H15 -> 2445.4 | J16: =J13-J12+J14+J15 -> 4437.8 | L16: =L13-L12+L14+L15 -> 6883.2 | N16: =N13-N12+N14+N15 -> 16920.248 | O16: 自动计算
C17: 其中： | D17: 自制成品的材料成本 | F17: 3500 | H17: =H16-H18-H19 -> 1515.4 | J17: =J16-J18-J19 -> 4014.8 | L17: =H17+J17 -> 5530.2 | N17: =N16-N18-N19 -> 12020.248 | O17: 数据来自于制造成本实际核算和预算
D18: 外协加工费 | F18: 890 | H18: 600 | J18: 300 | L18: =H18+J18 -> 900 | N18: 3600 | O18: 数据来自于制造成本实际核算和预算
D19: 人工及制造费用 | F19: =F13-F17-F18 -> 440 | H19: 330 | J19: 123 | L19: =H19+J19 -> 453 | N19: 1300 | O19: 数据来自于制造成本实际核算和预算
B21: 材料及半成品
C22: 期初库存 | F22: =[1]存货!$F$9 -> 1711.5 | H22: =F25 -> 1329.41 | J22: =H25 -> 1597.5 | L22: =F25 -> 1329.41 | N22: =L25 -> 1532 | O22: 数据取于营运资金预算表
C23: 生产消耗 | F23: =F17 -> 3500 | H23: =H17 -> 1515.4 | J23: =J17 -> 4014.8 | L23: =L17 -> 5530.2 | N23: =N17 -> 12020.248 | O23: 数据来自于销售成本预算
C24: 领用损耗 | F24: 5 | H24: 2 | J24: 1 | L24: =H24+J24 -> 3 | N24: 4 | O24: 根据经验估计
C25: 期末库存 | F25: =[1]存货!$R$9 -> 1329.41 | H25: =INDEX([1]存货!$1:$17,17,MATCH(MONTH(主页!$D$5),[1]存货!$3:$3,0)) -> 1597.5 | J25: =[1]存货!$R$17 -> 1532 | L25: =J25 -> 1532 | N25: =[1]存货!$R$25 -> 1747.62 | O25: 数据取于营运资金预算表
C26: 本期采购额 | F26: =F23-F22+F24+F25 -> 3122.91 | H26: =H23-H22+H24+H25 -> 1785.49 | J26: =J23-J22+J24+J25 -> 3950.3 | L26: =L23-L22+L24+L25 -> 5735.79 | N26: =N23-N22+N24+N25 -> 12239.868 | O26: 自动计算
B28: 其中：采购付现 | F28: =F26-F32 -> 3011.11 | H28: =H26-H32 -> 2024.29 | J28: =J26-J32 -> 4028.9 | L28: =L26-L32 -> 6053.19 | N28: =N26-N32 -> 11318.868 | O28: 自动计算
B30: 期初应付账款 | F30: =[1]应付账款!$E$7 -> 2044 | H30: =F31 -> 2155.8 | J30: =H31 -> 1917 | L30: =F31 -> 2155.8 | N30: =L31 -> 1838.4 | O30: 数据取于营运资金预算表
B31: 期末应付账款 | F31: =[1]应付账款!$Q$7 -> 2155.8 | H31: =INDEX([1]应付账款!$12:$12,1,MATCH(MONTH(主页!$D$5),[1]应付账款!$3:$3,0)) -> 1917 | J31: =[1]应付账款!$Q$12 -> 1838.4 | L31: =[1]应付账款!$Q$12 -> 1838.4 | N31: =[1]应付账款!$Q$17 -> 2759.4 | O31: 数据取于营运资金预算表
B32: 应付账款增（+）减（-） | F32: =F31-F30 -> 111.8 | H32: =H31-H30 -> -238.8 | J32: =J31-J30 -> -78.6 | L32: =L31-L30 -> -317.4 | N32: =N31-N30 -> 921 | O32: 自动计算
B33: 应付款控制策略说明：

Sheet 人力资源
B2: 人力资源分类汇总表
C3: 当年实际截止月份 | G3: =主页!D5 -> 44469
B4: 数据来自于人力资源预算表
B5: 金额单位：万元 | G5: ="A"&YEAR($G$3)-1&"FY" -> A2020FY | H5: 其中： | T5: ="E"&YEAR($G$3)&"FY" -> E2021FY | U5: ="A"&YEAR($G$3)&TEXT(MONTH($G$3),"00")&"YTD" -> A202109YTD | V5: 其中： | AH5: ="E"&YEAR($G$3)&TEXT(MONTH($G$3),"00")&"YTG" -> E202109YTG | AI5: 其中： | AU5: ="B"&YEAR($G$3)+1&"FY" -> B2022FY | AV5: 其中：
G6: =LEFT(G5,1) -> A | H6: =LEFT(G5,1) -> A | I6: =H6 -> A | J6: =I6 -> A | K6: =J6 -> A | L6: =K6 -> A | M6: =L6 -> A | N6: =M6 -> A | O6: =N6 -> A | P6: =O6 -> A | ... S6: =R6 -> A | T6: =LEFT(T5,1) -> E | U6: =LEFT(U5,1) -> A | V6: =LEFT(U5,1) -> A | W6: =V6 -> A | X6: =W6 -> A | Y6: =X6 -> A | Z6: =Y6 -> A | AA6: =Z6 -> A | AB6: =AA6 -> A | AC6: =AB6 -> A | AD6: =AC6 -> A | ... AG6: =AF6 -> A | AH6: =LEFT(AH5,1) -> E | AI6: =LEFT(AH5,1) -> E | AJ6: =AI6 -> E | AK6: =AJ6 -> E | AL6: =AK6 -> E | AM6: =AL6 -> E | AN6: =AM6 -> E | AO6: =AN6 -> E | AP6: =AO6 -> E | AQ6: =AP6 -> E | ... AT6: =AS6 -> E | AU6: =LEFT(AU5,1) -> B | AV6: =LEFT(AU5,1) -> B | AW6: =AV6 -> B | AX6: =AW6 -> B | AY6: =AX6 -> B | AZ6: =AY6 -> B | BA6: =AZ6 -> B | BB6: =BA6 -> B | BC6: =BB6 -> B | BD6: =BC6 -> B | ... BG6: =BF6 -> B
G7: 合计 | H7: =YEAR($G$3)-1 -> 2020 | I7: =H7 -> 2020 | J7: =I7 -> 2020 | K7: =J7 -> 2020 | L7: =K7 -> 2020 | M7: =L7 -> 2020 | N7: =M7 -> 2020 | O7: =N7 -> 2020 | P7: =O7 -> 2020 | ... S7: =R7 -> 2020 | T7: 合计 | U7: 合计 | V7: =YEAR($G$3) -> 2021 | W7: =V7 -> 2021 | X7: =W7 -> 2021 | Y7: =X7 -> 2021 | Z7: =Y7 -> 2021 | AA7: =Z7 -> 2021 | AB7: =AA7 -> 2021 | AC7: =AB7 -> 2021 | AD7: =AC7 -> 2021 | ... AG7: =AF7 -> 2021 | AH7: 合计 | AI7: =YEAR($G$3) -> 2021 | AJ7: =AI7 -> 2021 | AK7: =AJ7 -> 2021 | AL7: =AK7 -> 2021 | AM7: =AL7 -> 2021 | AN7: =AM7 -> 2021 | AO7: =AN7 -> 2021 | AP7: =AO7 -> 2021 | AQ7: =AP7 -> 2021 | ... AT7: =AS7 -> 2021 | AU7: 合计 | AV7: =YEAR($G$3)+1 -> 2022 | AW7: =AV7 -> 2022 | AX7: =AW7 -> 2022 | AY7: =AX7 -> 2022 | AZ7: =AY7 -> 2022 | BA7: =AZ7 -> 2022 | BB7: =BA7 -> 2022 | BC7: =BB7 -> 2022 | BD7: =BC7 -> 2022 | ... BG7: =BF7 -> 2022
H8: 1 | I8: 2 | J8: 3 | K8: 4 | L8: 5 | M8: 6 | N8: 7 | O8: 8 | P8: 9 | Q8: 10 | R8: 11 | S8: 12 | V8: 1 | W8: 2 | X8: 3 | Y8: 4 | Z8: 5 | AA8: 6 | AB8: 7 | AC8: 8 | AD8: 9 | AE8: 10 | AF8: 11 | AG8: 12 | AI8: 1 | AJ8: 2 | AK8: 3 | AL8: 4 | AM8: 5 | AN8: 6 | AO8: 7 | AP8: 8 | AQ8: 9 | AR8: 10 | AS8: 11 | AT8: 12 | AV8: 1 | AW8: 2 | AX8: 3 | AY8: 4 | AZ8: 5 | BA8: 6 | BB8: 7 | BC8: 8 | BD8: 9 | BE8: 10 | BF8: 11 | BG8: 12
G9: =DATE(YEAR($G$3)-1,1,1) -> 43831 | H9: =DATE(H7,H8,1) -> 43831 | I9: =DATE(I7,I8,1) -> 43862 | J9: =DATE(J7,J8,1) -> 43891 | K9: =DATE(K7,K8,1) -> 43922 | L9: =DATE(L7,L8,1) -> 43952 | M9: =DATE(M7,M8,1) -> 43983 | N9: =DATE(N7,N8,1) -> 44013 | O9: =DATE(O7,O8,1) -> 44044 | ... S9: =DATE(S7,S8,1) -> 44166 | T9: =DATE(YEAR($G$3),1,1) -> 44197 | U9: =DATE(YEAR($G$3),1,1) -> 44197 | V9: =DATE(V7,V8,1) -> 44197 | W9: =DATE(W7,W8,1) -> 44228 | X9: =DATE(X7,X8,1) -> 44256 | Y9: =DATE(Y7,Y8,1) -> 44287 | Z9: =DATE(Z7,Z8,1) -> 44317 | AA9: =DATE(AA7,AA8,1) -> 44348 | AB9: =DATE(AB7,AB8,1) -> 44378 | AC9: =DATE(AC7,AC8,1) -> 44409 | ... AG9: =DATE(AG7,AG8,1) -> 44531 | AH9: =DATE(YEAR($G$3),MONTH($G$3)+1,1) -> 44470 | AI9: =DATE(AI7,AI8,1) -> 44197 | AJ9: =DATE(AJ7,AJ8,1) -> 44228 | AK9: =DATE(AK7,AK8,1) -> 44256 | AL9: =DATE(AL7,AL8,1) -> 44287 | AM9: =DATE(AM7,AM8,1) -> 44317 | AN9: =DATE(AN7,AN8,1) -> 44348 | AO9: =DATE(AO7,AO8,1) -> 44378 | AP9: =DATE(AP7,AP8,1) -> 44409 | ... AT9: =DATE(AT7,AT8,1) -> 44531 | AU9: =DATE(YEAR($G$3)+1,1,1) -> 44562 | AV9: =DATE(AV7,AV8,1) -> 44562 | AW9: =DATE(AW7,AW8,1) -> 44593 | AX9: =DATE(AX7,AX8,1) -> 44621 | AY9: =DATE(AY7,AY8,1) -> 44652 | AZ9: =DATE(AZ7,AZ8,1) -> 44682 | BA9: =DATE(BA7,BA8,1) -> 44713 | BB9: =DATE(BB7,BB8,1) -> 44743 | BC9: =DATE(BC7,BC8,1) -> 44774 | ... BG9: =DATE(BG7,BG8,1) -> 44896
G10: =EOMONTH(DATE(YEAR($G$3)-1,12,1),0) -> 44196 | H10: =EOMONTH(H9,0) -> 43861 | I10: =EOMONTH(I9,0) -> 43890 | J10: =EOMONTH(J9,0) -> 43921 | K10: =EOMONTH(K9,0) -> 43951 | L10: =EOMONTH(L9,0) -> 43982 | M10: =EOMONTH(M9,0) -> 44012 | N10: =EOMONTH(N9,0) -> 44043 | O10: =EOMONTH(O9,0) -> 44074 | ... S10: =EOMONTH(S9,0) -> 44196 | T10: =EOMONTH(DATE(YEAR($G$3),12,1),0) -> 44561 | U10: =EOMONTH(DATE(YEAR($G$3),MONTH(G3),1),0) -> 44469 | V10: =EOMONTH(V9,0) -> 44227 | W10: =EOMONTH(W9,0) -> 44255 | X10: =EOMONTH(X9,0) -> 44286 | Y10: =EOMONTH(Y9,0) -> 44316 | Z10: =EOMONTH(Z9,0) -> 44347 | AA10: =EOMONTH(AA9,0) -> 44377 | AB10: =EOMONTH(AB9,0) -> 44408 | AC10: =EOMONTH(AC9,0) -> 44439 | ... AG10: =EOMONTH(AG9,0) -> 44561 | AH10: =EOMONTH(DATE(YEAR($G$3),12,1),0) -> 44561 | AI10: =EOMONTH(AI9,0) -> 44227 | AJ10: =EOMONTH(AJ9,0) -> 44255 | AK10: =EOMONTH(AK9,0) -> 44286 | AL10: =EOMONTH(AL9,0) -> 44316 | AM10: =EOMONTH(AM9,0) -> 44347 | AN10: =EOMONTH(AN9,0) -> 44377 | AO10: =EOMONTH(AO9,0) -> 44408 | AP10: =EOMONTH(AP9,0) -> 44439 | ... AT10: =EOMONTH(AT9,0) -> 44561 | AU10: =EOMONTH(DATE(YEAR($G$3)+1,12,1),0) -> 44926 | AV10: =EOMONTH(AV9,0) -> 44592 | AW10: =EOMONTH(AW9,0) -> 44620 | AX10: =EOMONTH(AX9,0) -> 44651 | AY10: =EOMONTH(AY9,0) -> 44681 | AZ10: =EOMONTH(AZ9,0) -> 44712 | BA10: =EOMONTH(BA9,0) -> 44742 | BB10: =EOMONTH(BB9,0) -> 44773 | BC10: =EOMONTH(BC9,0) -> 44804 | ... BG10: =EOMONTH(BG9,0) -> 44926
B11: 注册人数
B12: 合计 | E12: * | F12: * | G12: 70 | H12: 71 | I12: 71 | J12: 71 | K12: 71 | L12: 71 | M12: 71 | N12: 71 | O12: 71 | P12: 71 | Q12: 71 | R12: 70 | S12: 70 | T12: =AT12 -> 68 | U12: 69 | V12: 70 | W12: 70 | X12: 70 | Y12: 68 | Z12: 69 | AA12: 69 | AB12: 70 | AC12: 69 | AD12: 69 | AE12: 0 | AF12: 0 | AG12: 0 | AH12: =AT12 -> 68 | AI12: 0 | AJ12: 0 | AK12: 0 | AL12: 0 | AM12: 0 | AN12: 0 | AO12: 0 | AP12: 0 | AQ12: 0 | AR12: 69 | AS12: 70 | AT12: 68 | AU12: =BG12 -> 74 | AV12: 68 | AW12: 68 | AX12: 73 | AY12: 73 | AZ12: 74 | BA12: 74 | BB12: 74 | BC12: 74 | BD12: 74 | BE12: 74 | BF12: 74 | BG12: 74
C13: 流程中心 | E13: =IF(C13<>"",C13,#REF!) -> 流程中心 | F13: =IF(D13<>"",D13,"*") -> * | G13: 34 | H13: 35 | I13: 35 | J13: 35 | K13: 35 | L13: 35 | M13: 35 | N13: 35 | O13: 35 | P13: 35 | Q13: 35 | R13: 34 | S13: 34 | T13: =AT13 -> 31 | U13: 32 | V13: 34 | W13: 34 | X13: 34 | Y13: 32 | Z13: 33 | AA13: 33 | AB13: 33 | AC13: 32 | AD13: 32 | AE13: 0 | AF13: 0 | AG13: 0 | AH13: =AT13 -> 31 | AI13: 0 | AJ13: 0 | AK13: 0 | AL13: 0 | AM13: 0 | AN13: 0 | AO13: 0 | AP13: 0 | AQ13: 0 | AR13: 32 | AS13: 33 | AT13: 31 | AU13: =BG13 -> 37 | AV13: 31 | AW13: 31 | AX13: 36 | AY13: 36 | AZ13: 37 | BA13: 37 | BB13: 37 | BC13: 37 | BD13: 37 | BE13: 37 | BF13: 37 | BG13: 37
D14: 销售中心 | E14: =IF(C14<>"",C14,E13) -> 流程中心 | F14: =IF(D14<>"",D14,"*") -> 销售中心 | G14: 13 | H14: 13 | I14: 13 | J14: 13 | K14: 13 | L14: 13 | M14: 13 | N14: 13 | O14: 13 | P14: 13 | Q14: 13 | R14: 13 | S14: 13 | T14: =AT14 -> 13 | U14: 13 | V14: 13 | W14: 13 | X14: 13 | Y14: 13 | Z14: 14 | AA14: 14 | AB14: 14 | AC14: 13 | AD14: 13 | AE14: 0 | AF14: 0 | AG14: 0 | AH14: =AT14 -> 13 | AI14: 0 | AJ14: 0 | AK14: 0 | AL14: 0 | AM14: 0 | AN14: 0 | AO14: 0 | AP14: 0 | AQ14: 0 | AR14: 13 | AS14: 13 | AT14: 13 | AU14: =BG14 -> 14 | AV14: 13 | AW14: 13 | AX14: 13 | AY14: 13 | AZ14: 14 | BA14: 14 | BB14: 14 | BC14: 14 | BD14: 14 | BE14: 14 | BF14: 14 | BG14: 14
D15: 制造中心 | E15: =IF(C15<>"",C15,E14) -> 流程中心 | F15: =IF(D15<>"",D15,"*") -> 制造中心 | G15: 21 | H15: 22 | I15: 22 | J15: 22 | K15: 22 | L15: 22 | M15: 22 | N15: 22 | O15: 22 | P15: 22 | Q15: 22 | R15: 21 | S15: 21 | T15: =AT15 -> 18 | U15: 19 | V15: 21 | W15: 21 | X15: 21 | Y15: 19 | Z15: 19 | AA15: 19 | AB15: 19 | AC15: 19 | AD15: 19 | AE15: 0 | AF15: 0 | AG15: 0 | AH15: =AT15 -> 18 | AI15: 0 | AJ15: 0 | AK15: 0 | AL15: 0 | AM15: 0 | AN15: 0 | AO15: 0 | AP15: 0 | AQ15: 0 | AR15: 19 | AS15: 20 | AT15: 18 | AU15: =BG15 -> 23 | AV15: 18 | AW15: 18 | AX15: 23 | AY15: 23 | AZ15: 23 | BA15: 23 | BB15: 23 | BC15: 23 | BD15: 23 | BE15: 23 | BF15: 23 | BG15: 23
C16: 创新中心 | E16: =IF(C16<>"",C16,E15) -> 创新中心 | F16: =IF(D16<>"",D16,"*") -> * | G16: 19 | H16: 19 | I16: 19 | J16: 19 | K16: 19 | L16: 19 | M16: 19 | N16: 19 | O16: 19 | P16: 19 | Q16: 19 | R16: 19 | S16: 19 | T16: =AT16 -> 20 | U16: 20 | V16: 19 | W16: 19 | X16: 19 | Y16: 19 | Z16: 19 | AA16: 19 | AB16: 20 | AC16: 20 | AD16: 20 | AE16: 0 | AF16: 0 | AG16: 0 | AH16: =AT16 -> 20 | AI16: 0 | AJ16: 0 | AK16: 0 | AL16: 0 | AM16: 0 | AN16: 0 | AO16: 0 | AP16: 0 | AQ16: 0 | AR16: 20 | AS16: 20 | AT16: 20 | AU16: =BG16 -> 20 | AV16: 20 | AW16: 20 | AX16: 20 | AY16: 20 | AZ16: 20 | BA16: 20 | BB16: 20 | BC16: 20 | BD16: 20 | BE16: 20 | BF16: 20 | BG16: 20
D17: 产品 研发部 | E17: =IF(C17<>"",C17,E16) -> 创新中心 | F17: =IF(D17<>"",D17,"*") -> 产品 研发部 | G17: 8 | H17: 8 | I17: 8 | J17: 8 | K17: 8 | L17: 8 | M17: 8 | N17: 8 | O17: 8 | P17: 8 | Q17: 8 | R17: 8 | S17: 8 | T17: =AT17 -> 8 | U17: 8 | V17: 8 | W17: 8 | X17: 8 | Y17: 8 | Z17: 8 | AA17: 8 | AB17: 8 | AC17: 8 | AD17: 8 | AE17: 0 | AF17: 0 | AG17: 0 | AH17: =AT17 -> 8 | AI17: 0 | AJ17: 0 | AK17: 0 | AL17: 0 | AM17: 0 | AN17: 0 | AO17: 0 | AP17: 0 | AQ17: 0 | AR17: 8 | AS17: 8 | AT17: 8 | AU17: =BG17 -> 8 | AV17: 8 | AW17: 8 | AX17: 8 | AY17: 8 | AZ17: 8 | BA17: 8 | BB17: 8 | BC17: 8 | BD17: 8 | BE17: 8 | BF17: 8 | BG17: 8
D18: XX 试验室 | E18: =IF(C18<>"",C18,E17) -> 创新中心 | F18: =IF(D18<>"",D18,"*") -> XX 试验室 | G18: 5 | H18: 5 | I18: 5 | J18: 5 | K18: 5 | L18: 5 | M18: 5 | N18: 5 | O18: 5 | P18: 5 | Q18: 5 | R18: 5 | S18: 5 | T18: =AT18 -> 5 | U18: 5 | V18: 5 | W18: 5 | X18: 5 | Y18: 5 | Z18: 5 | AA18: 5 | AB18: 5 | AC18: 5 | AD18: 5 | AE18: 0 | AF18: 0 | AG18: 0 | AH18: =AT18 -> 5 | AI18: 0 | AJ18: 0 | AK18: 0 | AL18: 0 | AM18: 0 | AN18: 0 | AO18: 0 | AP18: 0 | AQ18: 0 | AR18: 5 | AS18: 5 | AT18: 5 | AU18: =BG18 -> 5 | AV18: 5 | AW18: 5 | AX18: 5 | AY18: 5 | AZ18: 5 | BA18: 5 | BB18: 5 | BC18: 5 | BD18: 5 | BE18: 5 | BF18: 5 | BG18: 5
D19: XX 孵化业务 | E19: =IF(C19<>"",C19,E18) -> 创新中心 | F19: =IF(D19<>"",D19,"*") -> XX 孵化业务 | G19: 6 | H19: 6 | I19: 6 | J19: 6 | K19: 6 | L19: 6 | M19: 6 | N19: 6 | O19: 6 | P19: 6 | Q19: 6 | R19: 6 | S19: 6 | T19: =AT19 -> 7 | U19: 7 | V19: 6 | W19: 6 | X19: 6 | Y19: 6 | Z19: 6 | AA19: 6 | AB19: 7 | AC19: 7 | AD19: 7 | AE19: 0 | AF19: 0 | AG19: 0 | AH19: =AT19 -> 7 | AI19: 0 | AJ19: 0 | AK19: 0 | AL19: 0 | AM19: 0 | AN19: 0 | AO19: 0 | AP19: 0 | AQ19: 0 | AR19: 7 | AS19: 7 | AT19: 7 | AU19: =BG19 -> 7 | AV19: 7 | AW19: 7 | AX19: 7 | AY19: 7 | AZ19: 7 | BA19: 7 | BB19: 7 | BC19: 7 | BD19: 7 | BE19: 7 | BF19: 7 | BG19: 7
C20: 支持中心 | E20: =IF(C20<>"",C20,E19) -> 支持中心 | F20: =IF(D20<>"",D20,"*") -> * | G20: 17 | H20: 17 | I20: 17 | J20: 17 | K20: 17 | L20: 17 | M20: 17 | N20: 17 | O20: 17 | P20: 17 | Q20: 17 | R20: 17 | S20: 17 | T20: =AT20 -> 17 | U20: 17 | V20: 17 | W20: 17 | X20: 17 | Y20: 17 | Z20: 17 | AA20: 17 | AB20: 17 | AC20: 17 | AD20: 17 | AE20: 0 | AF20: 0 | AG20: 0 | AH20: =AT20 -> 17 | AI20: 0 | AJ20: 0 | AK20: 0 | AL20: 0 | AM20: 0 | AN20: 0 | AO20: 0 | AP20: 0 | AQ20: 0 | AR20: 17 | AS20: 17 | AT20: 17 | AU20: =BG20 -> 17 | AV20: 17 | AW20: 17 | AX20: 17 | AY20: 17 | AZ20: 17 | BA20: 17 | BB20: 17 | BC20: 17 | BD20: 17 | BE20: 17 | BF20: 17 | BG20: 17
D21: 财务部 | E21: =IF(C21<>"",C21,E20) -> 支持中心 | F21: =IF(D21<>"",D21,"*") -> 财务部 | G21: 7 | H21: 7 | I21: 7 | J21: 7 | K21: 7 | L21: 7 | M21: 7 | N21: 7 | O21: 7 | P21: 7 | Q21: 7 | R21: 7 | S21: 7 | T21: =AT21 -> 7 | U21: 7 | V21: 7 | W21: 7 | X21: 7 | Y21: 7 | Z21: 7 | AA21: 7 | AB21: 7 | AC21: 7 | AD21: 7 | AE21: 0 | AF21: 0 | AG21: 0 | AH21: =AT21 -> 7 | AI21: 0 | AJ21: 0 | AK21: 0 | AL21: 0 | AM21: 0 | AN21: 0 | AO21: 0 | AP21: 0 | AQ21: 0 | AR21: 7 | AS21: 7 | AT21: 7 | AU21: =BG21 -> 7 | AV21: 7 | AW21: 7 | AX21: 7 | AY21: 7 | AZ21: 7 | BA21: 7 | BB21: 7 | BC21: 7 | BD21: 7 | BE21: 7 | BF21: 7 | BG21: 7
D22: 人力资源部 | E22: =IF(C22<>"",C22,E21) -> 支持中心 | F22: =IF(D22<>"",D22,"*") -> 人力资源部 | G22: 6 | H22: 6 | I22: 6 | J22: 6 | K22: 6 | L22: 6 | M22: 6 | N22: 6 | O22: 6 | P22: 6 | Q22: 6 | R22: 6 | S22: 6 | T22: =AT22 -> 6 | U22: 6 | V22: 6 | W22: 6 | X22: 6 | Y22: 6 | Z22: 6 | AA22: 6 | AB22: 6 | AC22: 6 | AD22: 6 | AE22: 0 | AF22: 0 | AG22: 0 | AH22: =AT22 -> 6 | AI22: 0 | AJ22: 0 | AK22: 0 | AL22: 0 | AM22: 0 | AN22: 0 | AO22: 0 | AP22: 0 | AQ22: 0 | AR22: 6 | AS22: 6 | AT22: 6 | AU22: =BG22 -> 6 | AV22: 6 | AW22: 6 | AX22: 6 | AY22: 6 | AZ22: 6 | BA22: 6 | BB22: 6 | BC22: 6 | BD22: 6 | BE22: 6 | BF22: 6 | BG22: 6
D23: IT部 | E23: =IF(C23<>"",C23,E22) -> 支持中心 | F23: =IF(D23<>"",D23,"*") -> IT部 | G23: 3 | H23: 3 | I23: 3 | J23: 3 | K23: 3 | L23: 3 | M23: 3 | N23: 3 | O23: 3 | P23: 3 | Q23: 3 | R23: 3 | S23: 3 | T23: =AT23 -> 3 | U23: 3 | V23: 3 | W23: 3 | X23: 3 | Y23: 3 | Z23: 3 | AA23: 3 | AB23: 3 | AC23: 3 | AD23: 3 | AE23: 0 | AF23: 0 | AG23: 0 | AH23: =AT23 -> 3 | AI23: 0 | AJ23: 0 | AK23: 0 | AL23: 0 | AM23: 0 | AN23: 0 | AO23: 0 | AP23: 0 | AQ23: 0 | AR23: 3 | AS23: 3 | AT23: 3 | AU23: =BG23 -> 3 | AV23: 3 | AW23: 3 | AX23: 3 | AY23: 3 | AZ23: 3 | BA23: 3 | BB23: 3 | BC23: 3 | BD23: 3 | BE23: 3 | BF23: 3 | BG23: 3
D24: 总经办 | E24: =IF(C24<>"",C24,E23) -> 支持中心 | F24: =IF(D24<>"",D24,"*") -> 总经办 | G24: 1 | H24: 1 | I24: 1 | J24: 1 | K24: 1 | L24: 1 | M24: 1 | N24: 1 | O24: 1 | P24: 1 | Q24: 1 | R24: 1 | S24: 1 | T24: =AT24 -> 1 | U24: 1 | V24: 1 | W24: 1 | X24: 1 | Y24: 1 | Z24: 1 | AA24: 1 | AB24: 1 | AC24: 1 | AD24: 1 | AE24: 0 | AF24: 0 | AG24: 0 | AH24: =AT24 -> 1 | AI24: 0 | AJ24: 0 | AK24: 0 | AL24: 0 | AM24: 0 | AN24: 0 | AO24: 0 | AP24: 0 | AQ24: 0 | AR24: 1 | AS24: 1 | AT24: 1 | AU24: =BG24 -> 1 | AV24: 1 | AW24: 1 | AX24: 1 | AY24: 1 | AZ24: 1 | BA24: 1 | BB24: 1 | BC24: 1 | BD24: 1 | BE24: 1 | BF24: 1 | BG24: 1
B26: 平均人数
B27: 合计 | E27: * | F27: * | G27: 73 | H27: 73 | I27: 73 | J27: 73 | K27: 73 | L27: 73 | M27: 73 | N27: 73 | O27: 73 | P27: 73 | Q27: 73 | R27: 73 | S27: 73 | T27: =(U27*MONTH($G$3)+AH27*(12-MONTH($G$3)))/12 -> 73 | U27: 73 | V27: 73 | W27: 73 | X27: 73 | Y27: 73 | Z27: 73 | AA27: 73 | AB27: 73 | AC27: 73 | AD27: 73 | AE27: 0 | AF27: 0 | AG27: 0 | AH27: 73 | AI27: 0 | AJ27: 0 | AK27: 0 | AL27: 0 | AM27: 0 | AN27: 0 | AO27: 0 | AP27: 0 | AQ27: 0 | AR27: 73 | AS27: 73 | AT27: 73 | AU27: 73 | AV27: 73 | AW27: 73 | AX27: 73 | AY27: 73 | AZ27: 73 | BA27: 73 | BB27: 73 | BC27: 73 | BD27: 73 | BE27: 73 | BF27: 73 | BG27: 73
C28: 流程中心 | E28: =IF(C28<>"",C28,#REF!) -> 流程中心 | F28: =IF(D28<>"",D28,"*") -> * | G28: 36 | H28: 36 | I28: 36 | J28: 36 | K28: 36 | L28: 36 | M28: 36 | N28: 36 | O28: 36 | P28: 36 | Q28: 36 | R28: 36 | S28: 36 | T28: =(U28*MONTH($G$3)+AH28*(12-MONTH($G$3)))/12 -> 36 | U28: 36 | V28: 36 | W28: 36 | X28: 36 | Y28: 36 | Z28: 36 | AA28: 36 | AB28: 36 | AC28: 36 | AD28: 36 | AE28: 0 | AF28: 0 | AG28: 0 | AH28: 36 | AI28: 0 | AJ28: 0 | AK28: 0 | AL28: 0 | AM28: 0 | AN28: 0 | AO28: 0 | AP28: 0 | AQ28: 0 | AR28: 36 | AS28: 36 | AT28: 36 | AU28: 36 | AV28: 36 | AW28: 36 | AX28: 36 | AY28: 36 | AZ28: 36 | BA28: 36 | BB28: 36 | BC28: 36 | BD28: 36 | BE28: 36 | BF28: 36 | BG28: 36
D29: 销售中心 | E29: =IF(C29<>"",C29,E28) -> 流程中心 | F29: =IF(D29<>"",D29,"*") -> 销售中心 | G29: 14 | H29: 14 | I29: 14 | J29: 14 | K29: 14 | L29: 14 | M29: 14 | N29: 14 | O29: 14 | P29: 14 | Q29: 14 | R29: 14 | S29: 14 | T29: =(U29*MONTH($G$3)+AH29*(12-MONTH($G$3)))/12 -> 14 | U29: 14 | V29: 14 | W29: 14 | X29: 14 | Y29: 14 | Z29: 14 | AA29: 14 | AB29: 14 | AC29: 14 | AD29: 14 | AE29: 0 | AF29: 0 | AG29: 0 | AH29: 14 | AI29: 0 | AJ29: 0 | AK29: 0 | AL29: 0 | AM29: 0 | AN29: 0 | AO29: 0 | AP29: 0 | AQ29: 0 | AR29: 14 | AS29: 14 | AT29: 14 | AU29: 14 | AV29: 14 | AW29: 14 | AX29: 14 | AY29: 14 | AZ29: 14 | BA29: 14 | BB29: 14 | BC29: 14 | BD29: 14 | BE29: 14 | BF29: 14 | BG29: 14
D30: 制造中心 | E30: =IF(C30<>"",C30,E29) -> 流程中心 | F30: =IF(D30<>"",D30,"*") -> 制造中心 | G30: 22 | H30: 22 | I30: 22 | J30: 22 | K30: 22 | L30: 22 | M30: 22 | N30: 22 | O30: 22 | P30: 22 | Q30: 22 | R30: 22 | S30: 22 | T30: =(U30*MONTH($G$3)+AH30*(12-MONTH($G$3)))/12 -> 22 | U30: 22 | V30: 22 | W30: 22 | X30: 22 | Y30: 22 | Z30: 22 | AA30: 22 | AB30: 22 | AC30: 22 | AD30: 22 | AE30: 0 | AF30: 0 | AG30: 0 | AH30: 22 | AI30: 0 | AJ30: 0 | AK30: 0 | AL30: 0 | AM30: 0 | AN30: 0 | AO30: 0 | AP30: 0 | AQ30: 0 | AR30: 22 | AS30: 22 | AT30: 22 | AU30: 22 | AV30: 22 | AW30: 22 | AX30: 22 | AY30: 22 | AZ30: 22 | BA30: 22 | BB30: 22 | BC30: 22 | BD30: 22 | BE30: 22 | BF30: 22 | BG30: 22
C31: 创新中心 | E31: =IF(C31<>"",C31,E30) -> 创新中心 | F31: =IF(D31<>"",D31,"*") -> * | G31: 20 | H31: 20 | I31: 20 | J31: 20 | K31: 20 | L31: 20 | M31: 20 | N31: 20 | O31: 20 | P31: 20 | Q31: 20 | R31: 20 | S31: 20 | T31: =(U31*MONTH($G$3)+AH31*(12-MONTH($G$3)))/12 -> 20 | U31: 20 | V31: 20 | W31: 20 | X31: 20 | Y31: 20 | Z31: 20 | AA31: 20 | AB31: 20 | AC31: 20 | AD31: 20 | AE31: 0 | AF31: 0 | AG31: 0 | AH31: 20 | AI31: 0 | AJ31: 0 | AK31: 0 | AL31: 0 | AM31: 0 | AN31: 0 | AO31: 0 | AP31: 0 | AQ31: 0 | AR31: 20 | AS31: 20 | AT31: 20 | AU31: 20 | AV31: 20 | AW31: 20 | AX31: 20 | AY31: 20 | AZ31: 20 | BA31: 20 | BB31: 20 | BC31: 20 | BD31: 20 | BE31: 20 | BF31: 20 | BG31: 20
D32: 产品 研发部 | E32: =IF(C32<>"",C32,E31) -> 创新中心 | F32: =IF(D32<>"",D32,"*") -> 产品 研发部 | G32: 8 | H32: 8 | I32: 8 | J32: 8 | K32: 8 | L32: 8 | M32: 8 | N32: 8 | O32: 8 | P32: 8 | Q32: 8 | R32: 8 | S32: 8 | T32: =(U32*MONTH($G$3)+AH32*(12-MONTH($G$3)))/12 -> 8 | U32: 8 | V32: 8 | W32: 8 | X32: 8 | Y32: 8 | Z32: 8 | AA32: 8 | AB32: 8 | AC32: 8 | AD32: 8 | AE32: 0 | AF32: 0 | AG32: 0 | AH32: 8 | AI32: 0 | AJ32: 0 | AK32: 0 | AL32: 0 | AM32: 0 | AN32: 0 | AO32: 0 | AP32: 0 | AQ32: 0 | AR32: 8 | AS32: 8 | AT32: 8 | AU32: 8 | AV32: 8 | AW32: 8 | AX32: 8 | AY32: 8 | AZ32: 8 | BA32: 8 | BB32: 8 | BC32: 8 | BD32: 8 | BE32: 8 | BF32: 8 | BG32: 8
D33: XX 试验室 | E33: =IF(C33<>"",C33,E32) -> 创新中心 | F33: =IF(D33<>"",D33,"*") -> XX 试验室 | G33: 5 | H33: 5 | I33: 5 | J33: 5 | K33: 5 | L33: 5 | M33: 5 | N33: 5 | O33: 5 | P33: 5 | Q33: 5 | R33: 5 | S33: 5 | T33: =(U33*MONTH($G$3)+AH33*(12-MONTH($G$3)))/12 -> 5 | U33: 5 | V33: 5 | W33: 5 | X33: 5 | Y33: 5 | Z33: 5 | AA33: 5 | AB33: 5 | AC33: 5 | AD33: 5 | AE33: 0 | AF33: 0 | AG33: 0 | AH33: 5 | AI33: 0 | AJ33: 0 | AK33: 0 | AL33: 0 | AM33: 0 | AN33: 0 | AO33: 0 | AP33: 0 | AQ33: 0 | AR33: 5 | AS33: 5 | AT33: 5 | AU33: 5 | AV33: 5 | AW33: 5 | AX33: 5 | AY33: 5 | AZ33: 5 | BA33: 5 | BB33: 5 | BC33: 5 | BD33: 5 | BE33: 5 | BF33: 5 | BG33: 5
D34: XX 孵化业务 | E34: =IF(C34<>"",C34,E33) -> 创新中心 | F34: =IF(D34<>"",D34,"*") -> XX 孵化业务 | G34: 7 | H34: 7 | I34: 7 | J34: 7 | K34: 7 | L34: 7 | M34: 7 | N34: 7 | O34: 7 | P34: 7 | Q34: 7 | R34: 7 | S34: 7 | T34: =(U34*MONTH($G$3)+AH34*(12-MONTH($G$3)))/12 -> 7 | U34: 7 | V34: 7 | W34: 7 | X34: 7 | Y34: 7 | Z34: 7 | AA34: 7 | AB34: 7 | AC34: 7 | AD34: 7 | AE34: 0 | AF34: 0 | AG34: 0 | AH34: 7 | AI34: 0 | AJ34: 0 | AK34: 0 | AL34: 0 | AM34: 0 | AN34: 0 | AO34: 0 | AP34: 0 | AQ34: 0 | AR34: 7 | AS34: 7 | AT34: 7 | AU34: 7 | AV34: 7 | AW34: 7 | AX34: 7 | AY34: 7 | AZ34: 7 | BA34: 7 | BB34: 7 | BC34: 7 | BD34: 7 | BE34: 7 | BF34: 7 | BG34: 7
C35: 支持中心 | E35: =IF(C35<>"",C35,E34) -> 支持中心 | F35: =IF(D35<>"",D35,"*") -> * | G35: 17 | H35: 17 | I35: 17 | J35: 17 | K35: 17 | L35: 17 | M35: 17 | N35: 17 | O35: 17 | P35: 17 | Q35: 17 | R35: 17 | S35: 17 | T35: =(U35*MONTH($G$3)+AH35*(12-MONTH($G$3)))/12 -> 17 | U35: 17 | V35: 17 | W35: 17 | X35: 17 | Y35: 17 | Z35: 17 | AA35: 17 | AB35: 17 | AC35: 17 | AD35: 17 | AE35: 0 | AF35: 0 | AG35: 0 | AH35: 17 | AI35: 0 | AJ35: 0 | AK35: 0 | AL35: 0 | AM35: 0 | AN35: 0 | AO35: 0 | AP35: 0 | AQ35: 0 | AR35: 17 | AS35: 17 | AT35: 17 | AU35: 17 | AV35: 17 | AW35: 17 | AX35: 17 | AY35: 17 | AZ35: 17 | BA35: 17 | BB35: 17 | BC35: 17 | BD35: 17 | BE35: 17 | BF35: 17 | BG35: 17
D36: 财务部 | E36: =IF(C36<>"",C36,E35) -> 支持中心 | F36: =IF(D36<>"",D36,"*") -> 财务部 | G36: 7 | H36: 7 | I36: 7 | J36: 7 | K36: 7 | L36: 7 | M36: 7 | N36: 7 | O36: 7 | P36: 7 | Q36: 7 | R36: 7 | S36: 7 | T36: =(U36*MONTH($G$3)+AH36*(12-MONTH($G$3)))/12 -> 7 | U36: 7 | V36: 7 | W36: 7 | X36: 7 | Y36: 7 | Z36: 7 | AA36: 7 | AB36: 7 | AC36: 7 | AD36: 7 | AE36: 0 | AF36: 0 | AG36: 0 | AH36: 7 | AI36: 0 | AJ36: 0 | AK36: 0 | AL36: 0 | AM36: 0 | AN36: 0 | AO36: 0 | AP36: 0 | AQ36: 0 | AR36: 7 | AS36: 7 | AT36: 7 | AU36: 7 | AV36: 7 | AW36: 7 | AX36: 7 | AY36: 7 | AZ36: 7 | BA36: 7 | BB36: 7 | BC36: 7 | BD36: 7 | BE36: 7 | BF36: 7 | BG36: 7
D37: 人力资源部 | E37: =IF(C37<>"",C37,E36) -> 支持中心 | F37: =IF(D37<>"",D37,"*") -> 人力资源部 | G37: 6 | H37: 6 | I37: 6 | J37: 6 | K37: 6 | L37: 6 | M37: 6 | N37: 6 | O37: 6 | P37: 6 | Q37: 6 | R37: 6 | S37: 6 | T37: =(U37*MONTH($G$3)+AH37*(12-MONTH($G$3)))/12 -> 6 | U37: 6 | V37: 6 | W37: 6 | X37: 6 | Y37: 6 | Z37: 6 | AA37: 6 | AB37: 6 | AC37: 6 | AD37: 6 | AE37: 0 | AF37: 0 | AG37: 0 | AH37: 6 | AI37: 0 | AJ37: 0 | AK37: 0 | AL37: 0 | AM37: 0 | AN37: 0 | AO37: 0 | AP37: 0 | AQ37: 0 | AR37: 6 | AS37: 6 | AT37: 6 | AU37: 6 | AV37: 6 | AW37: 6 | AX37: 6 | AY37: 6 | AZ37: 6 | BA37: 6 | BB37: 6 | BC37: 6 | BD37: 6 | BE37: 6 | BF37: 6 | BG37: 6
D38: IT部 | E38: =IF(C38<>"",C38,E37) -> 支持中心 | F38: =IF(D38<>"",D38,"*") -> IT部 | G38: 3 | H38: 3 | I38: 3 | J38: 3 | K38: 3 | L38: 3 | M38: 3 | N38: 3 | O38: 3 | P38: 3 | Q38: 3 | R38: 3 | S38: 3 | T38: =(U38*MONTH($G$3)+AH38*(12-MONTH($G$3)))/12 -> 3 | U38: 3 | V38: 3 | W38: 3 | X38: 3 | Y38: 3 | Z38: 3 | AA38: 3 | AB38: 3 | AC38: 3 | AD38: 3 | AE38: 0 | AF38: 0 | AG38: 0 | AH38: 3 | AI38: 0 | AJ38: 0 | AK38: 0 | AL38: 0 | AM38: 0 | AN38: 0 | AO38: 0 | AP38: 0 | AQ38: 0 | AR38: 3 | AS38: 3 | AT38: 3 | AU38: 3 | AV38: 3 | AW38: 3 | AX38: 3 | AY38: 3 | AZ38: 3 | BA38: 3 | BB38: 3 | BC38: 3 | BD38: 3 | BE38: 3 | BF38: 3 | BG38: 3
D39: 总经办 | E39: =IF(C39<>"",C39,E38) -> 支持中心 | F39: =IF(D39<>"",D39,"*") -> 总经办 | G39: 1 | H39: 1 | I39: 1 | J39: 1 | K39: 1 | L39: 1 | M39: 1 | N39: 1 | O39: 1 | P39: 1 | Q39: 1 | R39: 1 | S39: 1 | T39: =(U39*MONTH($G$3)+AH39*(12-MONTH($G$3)))/12 -> 1 | U39: 1 | V39: 1 | W39: 1 | X39: 1 | Y39: 1 | Z39: 1 | AA39: 1 | AB39: 1 | AC39: 1 | AD39: 1 | AE39: 0 | AF39: 0 | AG39: 0 | AH39: 1 | AI39: 0 | AJ39: 0 | AK39: 0 | AL39: 0 | AM39: 0 | AN39: 0 | AO39: 0 | AP39: 0 | AQ39: 0 | AR39: 1 | AS39: 1 | AT39: 1 | AU39: 1 | AV39: 1 | AW39: 1 | AX39: 1 | AY39: 1 | AZ39: 1 | BA39: 1 | BB39: 1 | BC39: 1 | BD39: 1 | BE39: 1 | BF39: 1 | BG39: 1
B41: 固定工资
B42: 合计 | E42: * | F42: * | G42: 710.10124 | H42: 59.260488 | I42: 59.105741 | J42: 59.129369 | K42: 59.129574 | L42: 59.144403 | M42: 59.264234 | N42: 59.36844 | O42: 59.213341 | P42: 59.404849 | Q42: 58.873232 | R42: 59.153304 | S42: 59.054263 | T42: =U42+AH42 -> 710.06266 | U42: 532.37749 | V42: 59.345351 | W42: 59.180223 | X42: 59.189103 | Y42: 59.18707 | Z42: 58.810737 | AA42: 59.117967 | AB42: 59.073285 | AC42: 59.183913 | AD42: 59.289837 | AE42: 0 | AF42: 0 | AG42: 0 | AH42: 177.68518 | AI42: 0 | AJ42: 0 | AK42: 0 | AL42: 0 | AM42: 0 | AN42: 0 | AO42: 0 | AP42: 0 | AQ42: 0 | AR42: 59.343942 | AS42: 59.49469 | AT42: 58.846545 | AU42: 709.81109 | AV42: 59.046236 | AW42: 59.507313 | AX42: 59.242299 | AY42: 59.183162 | AZ42: 59.398796 | BA42: 59.009558 | BB42: 59.104384 | BC42: 59.278429 | BD42: 59.181318 | BE42: 59.358979 | BF42: 58.571179 | BG42: 58.929434
C43: 流程中心 | E43: =IF(C43<>"",C43,E10) -> 流程中心 | F43: =IF(D43<>"",D43,"*") -> * | G43: 261.53308 | H43: 21.716272 | I43: 21.73396 | J43: 21.891732 | K43: 21.668929 | L43: 21.904793 | M43: 21.694205 | N43: 21.946395 | O43: 21.796895 | P43: 21.907518 | Q43: 21.754735 | R43: 21.795594 | S43: 21.72205 | T43: =U43+AH43 -> 260.49755 | U43: 195.36958 | V43: 21.892134 | W43: 21.702368 | X43: 21.629345 | Y43: 21.773223 | Z43: 21.532599 | AA43: 21.594651 | AB43: 21.594805 | AC43: 21.711472 | AD43: 21.938984 | AE43: 0 | AF43: 0 | AG43: 0 | AH43: 65.127973 | AI43: 0 | AJ43: 0 | AK43: 0 | AL43: 0 | AM43: 0 | AN43: 0 | AO43: 0 | AP43: 0 | AQ43: 0 | AR43: 21.762175 | AS43: 21.812886 | AT43: 21.552912 | AU43: 261.08139 | AV43: 21.653745 | AW43: 21.840451 | AX43: 22.028228 | AY43: 21.775478 | AZ43: 21.813125 | BA43: 21.743572 | BB43: 21.756288 | BC43: 21.923546 | BD43: 21.551819 | BE43: 21.733236 | BF43: 21.599116 | BG43: 21.662786
...

Sheet 财务折旧
G1: 实际2020全年 | I1: 实际截止2020年10月 | K1: 估计从2020年11月到年底 | M1: 估计2021全年 | O1: 预算2022全年
G2: A2020FY | I2: A202110YTD | K2: E202110YTG | M2: E2021FY | O2: B2022FY
G3: 金额 | I3: 金额 | K3: 金额 | M3: 金额 | O3: 金额
B4: 合计 | E4: * | F4: * | G4: 122.135 | I4: 155.09167 | K4: 47.673333 | M4: 202.765 | O4: 284.02
C5: 流程中心 | E5: =IF(C5<>"",C5,E4) -> 流程中心 | F5: =IF(D5<>"",D5,"*") -> * | G5: 120.175 | I5: 152.79167 | K5: 47.183333 | M5: 199.975 | O5: 280.25
A6: 销售及管理费用 | D6: 销售中心 | E6: =IF(C6<>"",C6,E5) -> 流程中心 | F6: =IF(D6<>"",D6,"*") -> 销售中心 | G6: 0 | I6: 0 | K6: 0 | M6: 0 | O6: 0
D7: 制造中心 | E7: =IF(C7<>"",C7,E6) -> 流程中心 | F7: =IF(D7<>"",D7,"*") -> 制造中心 | G7: 120.175 | I7: 152.79167 | K7: 47.183333 | M7: 199.975 | O7: 280.25
C8: 改善中心 | E8: =IF(C8<>"",C8,E7) -> 改善中心 | F8: =IF(D8<>"",D8,"*") -> * | G8: 0 | I8: 0 | K8: 0 | M8: 0 | O8: 0
A9: 销售及管理费用 | C9: =C8 -> 改善中心 | D9: 流程优化项目小组 | E9: =IF(C9<>"",C9,E8) -> 改善中心 | F9: =IF(D9<>"",D9,"*") -> 流程优化项目小组 | G9: 0 | I9: 0 | K9: 0 | M9: 0 | O9: 0
A10: 销售及管理费用 | C10: =C9 -> 改善中心 | D10: 战略预算项目小组 | E10: =IF(C10<>"",C10,E9) -> 改善中心 | F10: =IF(D10<>"",D10,"*") -> 战略预算项目小组 | G10: 0 | I10: 0 | K10: 0 | M10: 0 | O10: 0
C11: 创新中心 | E11: =IF(C11<>"",C11,E10) -> 创新中心 | F11: =IF(D11<>"",D11,"*") -> * | G11: 0 | I11: 0 | K11: 0 | M11: 0 | O11: 0
A12: 销售及管理费用 | C12: =C11 -> 创新中心 | D12: 产品研发部 | E12: =IF(C12<>"",C12,E11) -> 创新中心 | F12: =IF(D12<>"",D12,"*") -> 产品研发部 | G12: 0 | I12: 0 | K12: 0 | M12: 0 | O12: 0
A13: 销售及管理费用 | C13: =C12 -> 创新中心 | D13: XX试验室 | E13: =IF(C13<>"",C13,E12) -> 创新中心 | F13: =IF(D13<>"",D13,"*") -> XX试验室 | G13: 0 | I13: 0 | K13: 0 | M13: 0 | O13: 0
A14: 销售及管理费用 | C14: =C13 -> 创新中心 | D14: XX孵化业务 | E14: =IF(C14<>"",C14,E13) -> 创新中心 | F14: =IF(D14<>"",D14,"*") -> XX孵化业务 | G14: 0 | I14: 0 | K14: 0 | M14: 0 | O14: 0
